Workbook

Sheet Summary
A1: T standard model (trial) · research run 2026-10-23
A2: The supervisor's reconciled assumption set as a live model. Trial: shown beside the blended page target, not used for trade levels until its weight is decided. Edit blue cells on Model (drivers) and Valuation (assumptions).
A3: Price target box | B3: Value
A4: Live price | B4: =IFERROR(GOOGLEFINANCE("T","price"),Valuation!$B$68)
A5: Price as of | B5: =NOW()
A6: Model target (12-month median) | B6: =Distribution!$B$13
A7: Upside to model target from live price | B7: =B6/B4-1
A8: Research target (12m) (no scenario deltas) | B8: =Valuation!$D$8
A9: Probability-weighted mean | B9: =Distribution!$B$10
A10: 10th percentile | B10: =Distribution!$B$14
A11: 25th percentile | B11: =Distribution!$B$15
A12: 75th percentile | B12: =Distribution!$B$16
A13: 90th percentile | B13: =Distribution!$B$17
A14: Target date | B14: =Valuation!$B$46
A15: Price at the run | B15: =Valuation!$B$68
A16: Blended page target (options 67% + agents 33%, not live) | B16: 22.6484
A17: Supervisor research target (12m) (its own methods) | B17: 23.16
A18: Thesis break price (supervisor) | B18: 16.5
A19: Supervisor confidence | B19: low
A21: Key estimates | B21: FY2025A | C21: =Model!E5 | D21: =Model!F5
A22: Net sales | B22: =IF(Model!D36="","",Model!D36) | C22: =Model!E36 | D22: =Model!F36
A23: % YoY | B23: =IF(Model!D37="","",Model!D37) | C23: =Model!E37 | D23: =Model!F37
A24: Pretax margin | B24: =IF(Model!D47="","",Model!D47) | C24: =Model!E47 | D24: =Model!F47
A25: Diluted EPS (model) | B25: =IF(Model!D54="","",Model!D54) | C25: =Model!E54 | D25: =Model!F54
A26: % YoY | B26: =IF(Model!D55="","",Model!D55) | C26: =Model!E55 | D26: =Model!F55
A27: Free cash flow to firm | B27: =IF(Model!D64="","",Model!D64) | C27: =Model!E64 | D27: =Model!F64
A28: Guidance midpoint: EPS (adjusted) | C28: 2.4
A29: Consensus: EPS (MarketScreener consensus basis) | D29: 2.621
A31: Valuation method | B31: Value per share | C31: Weight
A32: =Valuation!A4 | B32: =Valuation!D4 | C32: =Valuation!E4
A33: =Valuation!A5 | B33: =Valuation!D5 | C33: =Valuation!E5
A34: =Valuation!A6 | B34: =Valuation!D6 | C34: =Valuation!E6
A35: =Valuation!A7 | B35: =Valuation!D7 | C35: =Valuation!E7
A37: Scenario | B37: Probability | C37: Value at target date | D37: What has to happen
A38: =Distribution!A4 | B38: =Distribution!B4 | C38: =Distribution!C4 | D38: =Distribution!D4
A39: =Distribution!A5 | B39: =Distribution!B5 | C39: =Distribution!C5 | D39: =Distribution!D5
A40: =Distribution!A6 | B40: =Distribution!B6 | C40: =Distribution!C6 | D40: =Distribution!D6
A42: Price at target date | B42: Probability above
A43: =ROUND(Valuation!$B$68*0.7,0) | B43: =SUMPRODUCT(Distribution!$B$4:$B$6,1-NORMSDIST((LN(A43)-LN(Distribution!$C$4:$C$6))/Distribution!$B$9))
A44: =ROUND(Valuation!$B$68*0.8,0) | B44: =SUMPRODUCT(Distribution!$B$4:$B$6,1-NORMSDIST((LN(A44)-LN(Distribution!$C$4:$C$6))/Distribution!$B$9))
...

Sheet Model
A1: T: annual model, base case
A2: (M of US dollars except per share; fiscal years named by the calendar year they end in)
A3: Blue = input · black = formula · green = link to another tab · actuals from SEC filings (fact ids in the last column, links on Sources)
A5: Fiscal year | B5: FY2023A | C5: FY2024A | D5: FY2025A | E5: FY2026E | F5: FY2027E | G5: FY2028E | H5: Source / note
A6: Period end | B6: 45291 | C6: 45657 | D6: 46022 | E6: =IF(DAY(Valuation!$B$50+1)=1,EOMONTH(Valuation!$B$50,12*E7),EDATE(Valuation!$B$50,12*E7)) | F6: =IF(DAY(Valuation!$B$50+1)=1,EOMONTH(Valuation!$B$50,12*F7),EDATE(Valuation!$B$50,12*F7)) | G6: =IF(DAY(Valuation!$B$50+1)=1,EOMONTH(Valuation!$B$50,12*G7),EDATE(Valuation!$B$50,12*G7))
A7: Projection year | B7: -2 | C7: -1 | D7: 0 | E7: 1 | F7: 2 | G7: 3
A10: Segment build (blue = input: revenue growth and EBIT margin by segment and year)
A11: AC Wireless and Home | D11: =Valuation!$B$91 | E11: =Valuation!$B$91*(1+E12) | F11: =E11*(1+F12) | G11: =F11*(1+G12)
A12: Revenue growth | E12: 0.05340247 | F12: 0.041366921 | G12: 0.032735299
A13: Segment EBIT | E13: =E11*E14 | F13: =F11*F14 | G13: =G11*G14
A14: EBIT margin | E14: 0.24723 | F14: 0.25654 | G14: 0.26693
A15: AC Business Wireline and Other | D15: =Valuation!$B$92 | E15: =Valuation!$B$92*(1+E16) | F15: =E15*(1+F16) | G15: =F15*(1+G16)
A16: Revenue growth | E16: -0.015 | F16: -0.008 | G16: -0.003
A17: Segment EBIT | E17: =E15*E18 | F17: =F15*F18 | G17: =G15*G18
A18: EBIT margin | E18: 0.24723 | F18: 0.25654 | G18: 0.26693
A19: Legacy | D19: =Valuation!$B$93 | E19: =Valuation!$B$93*(1+E20) | F19: =E19*(1+F20) | G19: =F19*(1+G20)
A20: Revenue growth | E20: -0.2541 | F20: -0.27 | G20: -0.3
A21: Segment EBIT | E21: =E19*E22 | F21: =F19*F22 | G21: =G19*G22
A22: EBIT margin | E22: 0.3214 | F22: 0.2 | G22: -0.05
A23: Latin America | D23: =Valuation!$B$94 | E23: =Valuation!$B$94*(1+E24) | F23: =E23*(1+F24) | G23: =F23*(1+G24)
A24: Revenue growth | E24: 0.13 | F24: -0.83 | G24: -1
A25: Segment EBIT | E25: =E23*E26 | F25: =F23*F26 | G25: =G23*G26
A26: EBIT margin | E26: 0.18 | F26: 0.18 | G26: 0
A27: Corporate and Other | D27: =Valuation!$B$95 | E27: =Valuation!$B$95*(1+E28) | F27: =E27*(1+F28) | G27: =F27*(1+G28)
A28: Revenue growth | E28: -0.05 | F28: =E28 | G28: =F28
A29: Segment EBIT | E29: =E27*E30 | F29: =F27*F30 | G29: =G27*G30
A30: EBIT margin | E30: 0 | F30: =E30 | G30: =F30
A31: Total segment revenue (= net sales) | D31: =D11+D15+D19+D23+D27 | E31: =E11+E15+E19+E23+E27 | F31: =F11+F15+F19+F23+F27 | G31: =G11+G15+G19+G23+G27 | H31: base revenues on Valuation (segment build); net sales = this total
A32: Total segment EBIT | E32: =E13+E17+E21+E25+E29 | F32: =F13+F17+F21+F25+F29 | G32: =G13+G17+G21+G25+G29
A33: Corporate / unallocated EBIT (blue = input) | E33: -3495 | F33: -2445 | G33: -2445 | H33: years[].corporate_ebit; EBIT = total segment EBIT + corporate
A35: Sales
A36: Net sales | B36: 122428 | C36: 122336 | D36: 125648 | E36: =E31 | F36: =F31 | G36: =G31 | H36: SEC XBRL F1, F2, F3
A37: % YoY | C37: =IF(OR(C36="",B36="",B36=0),"",C36/B36-1) | D37: =IF(OR(D36="",C36="",C36=0),"",D36/C36-1) | E37: =E36/Valuation!$B$51-1 | F37: =F36/E36-1 | G37: =G36/F36-1
A39: Operating profit
A40: EBIT (operating income) | E40: =E32+E33 | F40: =F32+F33 | G40: =G32+G33
A41: EBIT margin | E41: =E40/E36 | F41: =F40/F36 | G41: =G40/G36
A42: D&A | B42: 18777 | C42: 20580 | D42: 20886 | E42: =E36*E76 | F42: =F36*F76 | G42: =G36*G76 | H42: SEC XBRL F34, F35, F36
A43: EBITDA | E43: =E40+E42 | F43: =F40+F42 | G43: =G40+G42
A44: EBITDA margin | E44: =E43/E36 | F44: =F43/F36 | G44: =G43/G36
A45: Net interest income / (expense) | E45: =-Valuation!$B$59*Valuation!$B$57 | F45: =-Valuation!$B$59*E70 | G45: =-Valuation!$B$59*F70 | H45: rate x prior year-end net debt (memo roll)
...

Sheet Valuation
A1: T: valuation and price target derivation
A2: Value per share at the target date = weighted methods below; the 12-month target is the median of the scenario mix (Distribution tab).
A3: Method | B3: Multiple | C3: Metric at target date | D3: Value per share | E3: Weight | F3: Contribution
A4: ='Calc - research target (12m)'!A67 | B4: =IF('Calc - research target (12m)'!C67="","",'Calc - research target (12m)'!C67) | C4: =IF('Calc - research target (12m)'!I67="","",'Calc - research target (12m)'!I67) | D4: ='Calc - research target (12m)'!F67 | E4: ='Calc - research target (12m)'!G67 | F4: =D4*E4/SUM($E$4:$E$7)
A5: ='Calc - research target (12m)'!A68 | B5: =IF('Calc - research target (12m)'!C68="","",'Calc - research target (12m)'!C68) | C5: =IF('Calc - research target (12m)'!I68="","",'Calc - research target (12m)'!I68) | D5: ='Calc - research target (12m)'!F68 | E5: ='Calc - research target (12m)'!G68 | F5: =D5*E5/SUM($E$4:$E$7)
A6: ='Calc - research target (12m)'!A69 | B6: =IF('Calc - research target (12m)'!C69="","",'Calc - research target (12m)'!C69) | C6: =IF('Calc - research target (12m)'!I69="","",'Calc - research target (12m)'!I69) | D6: ='Calc - research target (12m)'!F69 | E6: ='Calc - research target (12m)'!G69 | F6: =D6*E6/SUM($E$4:$E$7)
A7: ='Calc - research target (12m)'!A70 | B7: =IF('Calc - research target (12m)'!C70="","",'Calc - research target (12m)'!C70) | C7: =IF('Calc - research target (12m)'!I70="","",'Calc - research target (12m)'!I70) | D7: ='Calc - research target (12m)'!F70 | E7: ='Calc - research target (12m)'!G70 | F7: =D7*E7/SUM($E$4:$E$7)
A8: Research target (12m) per share | D8: ='Calc - research target (12m)'!$F$71 | F8: =SUM(F4:F7)
A10: 12-month EPS basis (what the P/E is applied to)
A11: Fiscal year | B11: =Model!E5 | C11: =Model!F5 | D11: =Model!G5
A12: Share of the 12 months after the target date | B12: ='Calc - research target (12m)'!C38 | C12: ='Calc - research target (12m)'!D38 | D12: ='Calc - research target (12m)'!E38
A13: Model EPS (Model tab) | B13: =Model!E54 | C13: =Model!F54 | D13: =Model!G54
A14: Model EPS, next 12 months after the target date | B14: =SUMPRODUCT(B12:D12,B13:D13)
A15: Stated next-12-month EPS used by the P/E method (consensus basis, cited) | B15: =Valuation!F72 | C15: =B15/B14-1 | D15: vs model EPS
A17: DCF build (free cash flow to firm, discounted to the target date)
A18: Fiscal year | B18: =Model!E5 | C18: =Model!F5 | D18: =Model!G5
A19: Free cash flow to firm | B19: ='Calc - research target (12m)'!C31 | C19: ='Calc - research target (12m)'!D31 | D19: ='Calc - research target (12m)'!E31
A20: Share of the year after the target date | B20: ='Calc - research target (12m)'!C35 | C20: ='Calc - research target (12m)'!D35 | D20: ='Calc - research target (12m)'!E35
A21: PV at target date | B21: ='Calc - research target (12m)'!C36 | C21: ='Calc - research target (12m)'!D36 | D21: ='Calc - research target (12m)'!E36
A23: PV of free cash flow after the target date | B23: ='Calc - research target (12m)'!B42
A24: Terminal value (final year) | B24: ='Calc - research target (12m)'!B43
A25: PV of terminal value | B25: ='Calc - research target (12m)'!B44
A26: Enterprise value at target date | B26: ='Calc - research target (12m)'!B45
A27: Terminal value share of DCF | B27: ='Calc - research target (12m)'!B46
A28: Net debt at target date | B28: ='Calc - research target (12m)'!B50
A29: Minority interests | B29: ='Calc - research target (12m)'!B51
A30: Adjustments | B30: ='Calc - research target (12m)'!B52
A31: Diluted shares at target date (M) | B31: ='Calc - research target (12m)'!B53
A32: DCF value per share | B32: ='Calc - research target (12m)'!F67
A33: WACC | B33: ='Calc - research target (12m)'!B12
A43: Assumptions (blue = input; sources on the Sources tab)
A44: Input | B44: Value | C44: Basis / note
A45: Run date (valuation as of) | B45: 46318
A46: Target date (run date + 365 days) | B46: =B45+365 | C46: 12-month horizon
A47: Money unit | B47: $M
A48: EBIT basis (gaap / adjusted) | B48: adjusted | C48: gaap = after stock comp
A49: Stock comp treatment (cost / dilution) | B49: cost | C49: used only when EBIT is adjusted
A50: Last reported fiscal year end | B50: 46022
A51: Net sales, last reported year ($M) | B51: 125648
A52: WACC | B52: 0.1 | C52: not used: no DCF leg (Kilian 2026-10-21); a placeholder so the DCF block still computes
...

Sheet Sensitivity
A1: T: sensitivity tables (bold = current inputs; every cell recalculates from the live model)
A3: DCF value per share: WACC (down) x terminal growth (across)
A4: WACC \ growth | B4: =Valuation!$B$54+(-0.01) | C4: =Valuation!$B$54+(-0.005) | D4: =Valuation!$B$54+(0) | E4: =Valuation!$B$54+(0.005) | F4: =Valuation!$B$54+(0.01)
A5: =Valuation!$B$52+(-0.01) | B5: =IF($A5-B$4<=0.01,"n/a",((SUMPRODUCT('Calc - research target (12m)'!$C$31:$E$31,'Calc - research target (12m)'!$C$35:$E$35,(1+$A5)^(-('Calc - research target (12m)'!$C$19:$E$19-'Calc - research target (12m)'!$B$13)))+'Calc - research target (12m)'!$E$31*(1+B$4)/($A5-B$4)/(1+$A5)^('Calc - research target (12m)'!$B$16-'Calc - research target (12m)'!$B$13))-'Calc - research target (12m)'!$B$50-'Calc - research target (12m)'!$B$51+'Calc - research target (12m)'!$B$52)/'Calc - research target (12m)'!$B$53) | C5: =IF($A5-C$4<=0.01,"n/a",((SUMPRODUCT('Calc - research target (12m)'!$C$31:$E$31,'Calc - research target (12m)'!$C$35:$E$35,(1+$A5)^(-('Calc - research target (12m)'!$C$19:$E$19-'Calc - research target (12m)'!$B$13)))+'Calc - research target (12m)'!$E$31*(1+C$4)/($A5-C$4)/(1+$A5)^('Calc - research target (12m)'!$B$16-'Calc - research target (12m)'!$B$13))-'Calc - research target (12m)'!$B$50-'Calc - research target (12m)'!$B$51+'Calc - research target (12m)'!$B$52)/'Calc - research target (12m)'!$B$53) | D5: =IF($A5-D$4<=0.01,"n/a",((SUMPRODUCT('Calc - research target (12m)'!$C$31:$E$31,'Calc - research target (12m)'!$C$35:$E$35,(1+$A5)^(-('Calc - research target (12m)'!$C$19:$E$19-'Calc - research target (12m)'!$B$13)))+'Calc - research target (12m)'!$E$31*(1+D$4)/($A5-D$4)/(1+$A5)^('Calc - research target (12m)'!$B$16-'Calc - research target (12m)'!$B$13))-'Calc - research target (12m)'!$B$50-'Calc - research target (12m)'!$B$51+'Calc - research target (12m)'!$B$52)/'Calc - research target (12m)'!$B$53) | E5: =IF($A5-E$4<=0.01,"n/a",((SUMPRODUCT('Calc - research target (12m)'!$C$31:$E$31,'Calc - research target (12m)'!$C$35:$E$35,(1+$A5)^(-('Calc - research target (12m)'!$C$19:$E$19-'Calc - research target (12m)'!$B$13)))+'Calc - research target (12m)'!$E$31*(1+E$4)/($A5-E$4)/(1+$A5)^('Calc - research target (12m)'!$B$16-'Calc - research target (12m)'!$B$13))-'Calc - research target (12m)'!$B$50-'Calc - research target (12m)'!$B$51+'Calc - research target (12m)'!$B$52)/'Calc - research target (12m)'!$B$53) | F5: =IF($A5-F$4<=0.01,"n/a",((SUMPRODUCT('Calc - research target (12m)'!$C$31:$E$31,'Calc - research target (12m)'!$C$35:$E$35,(1+$A5)^(-('Calc - research target (12m)'!$C$19:$E$19-'Calc - research target (12m)'!$B$13)))+'Calc - research target (12m)'!$E$31*(1+F$4)/($A5-F$4)/(1+$A5)^('Calc - research target (12m)'!$B$16-'Calc - research target (12m)'!$B$13))-'Calc - research target (12m)'!$B$50-'Calc - research target (12m)'!$B$51+'Calc - research target (12m)'!$B$52)/'Calc - research target (12m)'!$B$53)
A6: =Valuation!$B$52+(-0.005) | B6: =IF($A6-B$4<=0.01,"n/a",((SUMPRODUCT('Calc - research target (12m)'!$C$31:$E$31,'Calc - research target (12m)'!$C$35:$E$35,(1+$A6)^(-('Calc - research target (12m)'!$C$19:$E$19-'Calc - research target (12m)'!$B$13)))+'Calc - research target (12m)'!$E$31*(1+B$4)/($A6-B$4)/(1+$A6)^('Calc - research target (12m)'!$B$16-'Calc - research target (12m)'!$B$13))-'Calc - research target (12m)'!$B$50-'Calc - research target (12m)'!$B$51+'Calc - research target (12m)'!$B$52)/'Calc - research target (12m)'!$B$53) | C6: =IF($A6-C$4<=0.01,"n/a",((SUMPRODUCT('Calc - research target (12m)'!$C$31:$E$31,'Calc - research target (12m)'!$C$35:$E$35,(1+$A6)^(-('Calc - research target (12m)'!$C$19:$E$19-'Calc - research target (12m)'!$B$13)))+'Calc - research target (12m)'!$E$31*(1+C$4)/($A6-C$4)/(1+$A6)^('Calc - research target (12m)'!$B$16-'Calc - research target (12m)'!$B$13))-'Calc - research target (12m)'!$B$50-'Calc - research target (12m)'!$B$51+'Calc - research target (12m)'!$B$52)/'Calc - research target (12m)'!$B$53) | D6: =IF($A6-D$4<=0.01,"n/a",((SUMPRODUCT('Calc - research target (12m)'!$C$31:$E$31,'Calc - research target (12m)'!$C$35:$E$35,(1+$A6)^(-('Calc - research target (12m)'!$C$19:$E$19-'Calc - research target (12m)'!$B$13)))+'Calc - research target (12m)'!$E$31*(1+D$4)/($A6-D$4)/(1+$A6)^('Calc - research target (12m)'!$B$16-'Calc - research target (12m)'!$B$13))-'Calc - research target (12m)'!$B$50-'Calc - research target (12m)'!$B$51+'Calc - research target (12m)'!$B$52)/'Calc - research target (12m)'!$B$53) | E6: =IF($A6-E$4<=0.01,"n/a",((SUMPRODUCT('Calc - research target (12m)'!$C$31:$E$31,'Calc - research target (12m)'!$C$35:$E$35,(1+$A6)^(-('Calc - research target (12m)'!$C$19:$E$19-'Calc - research target (12m)'!$B$13)))+'Calc - research target (12m)'!$E$31*(1+E$4)/($A6-E$4)/(1+$A6)^('Calc - research target (12m)'!$B$16-'Calc - research target (12m)'!$B$13))-'Calc - research target (12m)'!$B$50-'Calc - research target (12m)'!$B$51+'Calc - research target (12m)'!$B$52)/'Calc - research target (12m)'!$B$53) | F6: =IF($A6-F$4<=0.01,"n/a",((SUMPRODUCT('Calc - research target (12m)'!$C$31:$E$31,'Calc - research target (12m)'!$C$35:$E$35,(1+$A6)^(-('Calc - research target (12m)'!$C$19:$E$19-'Calc - research target (12m)'!$B$13)))+'Calc - research target (12m)'!$E$31*(1+F$4)/($A6-F$4)/(1+$A6)^('Calc - research target (12m)'!$B$16-'Calc - research target (12m)'!$B$13))-'Calc - research target (12m)'!$B$50-'Calc - research target (12m)'!$B$51+'Calc - research target (12m)'!$B$52)/'Calc - research target (12m)'!$B$53)
A7: =Valuation!$B$52+(0) | B7: =IF($A7-B$4<=0.01,"n/a",((SUMPRODUCT('Calc - research target (12m)'!$C$31:$E$31,'Calc - research target (12m)'!$C$35:$E$35,(1+$A7)^(-('Calc - research target (12m)'!$C$19:$E$19-'Calc - research target (12m)'!$B$13)))+'Calc - research target (12m)'!$E$31*(1+B$4)/($A7-B$4)/(1+$A7)^('Calc - research target (12m)'!$B$16-'Calc - research target (12m)'!$B$13))-'Calc - research target (12m)'!$B$50-'Calc - research target (12m)'!$B$51+'Calc - research target (12m)'!$B$52)/'Calc - research target (12m)'!$B$53) | C7: =IF($A7-C$4<=0.01,"n/a",((SUMPRODUCT('Calc - research target (12m)'!$C$31:$E$31,'Calc - research target (12m)'!$C$35:$E$35,(1+$A7)^(-('Calc - research target (12m)'!$C$19:$E$19-'Calc - research target (12m)'!$B$13)))+'Calc - research target (12m)'!$E$31*(1+C$4)/($A7-C$4)/(1+$A7)^('Calc - research target (12m)'!$B$16-'Calc - research target (12m)'!$B$13))-'Calc - research target (12m)'!$B$50-'Calc - research target (12m)'!$B$51+'Calc - research target (12m)'!$B$52)/'Calc - research target (12m)'!$B$53) | D7: =IF($A7-D$4<=0.01,"n/a",((SUMPRODUCT('Calc - research target (12m)'!$C$31:$E$31,'Calc - research target (12m)'!$C$35:$E$35,(1+$A7)^(-('Calc - research target (12m)'!$C$19:$E$19-'Calc - research target (12m)'!$B$13)))+'Calc - research target (12m)'!$E$31*(1+D$4)/($A7-D$4)/(1+$A7)^('Calc - research target (12m)'!$B$16-'Calc - research target (12m)'!$B$13))-'Calc - research target (12m)'!$B$50-'Calc - research target (12m)'!$B$51+'Calc - research target (12m)'!$B$52)/'Calc - research target (12m)'!$B$53) | E7: =IF($A7-E$4<=0.01,"n/a",((SUMPRODUCT('Calc - research target (12m)'!$C$31:$E$31,'Calc - research target (12m)'!$C$35:$E$35,(1+$A7)^(-('Calc - research target (12m)'!$C$19:$E$19-'Calc - research target (12m)'!$B$13)))+'Calc - research target (12m)'!$E$31*(1+E$4)/($A7-E$4)/(1+$A7)^('Calc - research target (12m)'!$B$16-'Calc - research target (12m)'!$B$13))-'Calc - research target (12m)'!$B$50-'Calc - research target (12m)'!$B$51+'Calc - research target (12m)'!$B$52)/'Calc - research target (12m)'!$B$53) | F7: =IF($A7-F$4<=0.01,"n/a",((SUMPRODUCT('Calc - research target (12m)'!$C$31:$E$31,'Calc - research target (12m)'!$C$35:$E$35,(1+$A7)^(-('Calc - research target (12m)'!$C$19:$E$19-'Calc - research target (12m)'!$B$13)))+'Calc - research target (12m)'!$E$31*(1+F$4)/($A7-F$4)/(1+$A7)^('Calc - research target (12m)'!$B$16-'Calc - research target (12m)'!$B$13))-'Calc - research target (12m)'!$B$50-'Calc - research target (12m)'!$B$51+'Calc - research target (12m)'!$B$52)/'Calc - research target (12m)'!$B$53)
A8: =Valuation!$B$52+(0.005) | B8: =IF($A8-B$4<=0.01,"n/a",((SUMPRODUCT('Calc - research target (12m)'!$C$31:$E$31,'Calc - research target (12m)'!$C$35:$E$35,(1+$A8)^(-('Calc - research target (12m)'!$C$19:$E$19-'Calc - research target (12m)'!$B$13)))+'Calc - research target (12m)'!$E$31*(1+B$4)/($A8-B$4)/(1+$A8)^('Calc - research target (12m)'!$B$16-'Calc - research target (12m)'!$B$13))-'Calc - research target (12m)'!$B$50-'Calc - research target (12m)'!$B$51+'Calc - research target (12m)'!$B$52)/'Calc - research target (12m)'!$B$53) | C8: =IF($A8-C$4<=0.01,"n/a",((SUMPRODUCT('Calc - research target (12m)'!$C$31:$E$31,'Calc - research target (12m)'!$C$35:$E$35,(1+$A8)^(-('Calc - research target (12m)'!$C$19:$E$19-'Calc - research target (12m)'!$B$13)))+'Calc - research target (12m)'!$E$31*(1+C$4)/($A8-C$4)/(1+$A8)^('Calc - research target (12m)'!$B$16-'Calc - research target (12m)'!$B$13))-'Calc - research target (12m)'!$B$50-'Calc - research target (12m)'!$B$51+'Calc - research target (12m)'!$B$52)/'Calc - research target (12m)'!$B$53) | D8: =IF($A8-D$4<=0.01,"n/a",((SUMPRODUCT('Calc - research target (12m)'!$C$31:$E$31,'Calc - research target (12m)'!$C$35:$E$35,(1+$A8)^(-('Calc - research target (12m)'!$C$19:$E$19-'Calc - research target (12m)'!$B$13)))+'Calc - research target (12m)'!$E$31*(1+D$4)/($A8-D$4)/(1+$A8)^('Calc - research target (12m)'!$B$16-'Calc - research target (12m)'!$B$13))-'Calc - research target (12m)'!$B$50-'Calc - research target (12m)'!$B$51+'Calc - research target (12m)'!$B$52)/'Calc - research target (12m)'!$B$53) | E8: =IF($A8-E$4<=0.01,"n/a",((SUMPRODUCT('Calc - research target (12m)'!$C$31:$E$31,'Calc - research target (12m)'!$C$35:$E$35,(1+$A8)^(-('Calc - research target (12m)'!$C$19:$E$19-'Calc - research target (12m)'!$B$13)))+'Calc - research target (12m)'!$E$31*(1+E$4)/($A8-E$4)/(1+$A8)^('Calc - research target (12m)'!$B$16-'Calc - research target (12m)'!$B$13))-'Calc - research target (12m)'!$B$50-'Calc - research target (12m)'!$B$51+'Calc - research target (12m)'!$B$52)/'Calc - research target (12m)'!$B$53) | F8: =IF($A8-F$4<=0.01,"n/a",((SUMPRODUCT('Calc - research target (12m)'!$C$31:$E$31,'Calc - research target (12m)'!$C$35:$E$35,(1+$A8)^(-('Calc - research target (12m)'!$C$19:$E$19-'Calc - research target (12m)'!$B$13)))+'Calc - research target (12m)'!$E$31*(1+F$4)/($A8-F$4)/(1+$A8)^('Calc - research target (12m)'!$B$16-'Calc - research target (12m)'!$B$13))-'Calc - research target (12m)'!$B$50-'Calc - research target (12m)'!$B$51+'Calc - research target (12m)'!$B$52)/'Calc - research target (12m)'!$B$53)
A9: =Valuation!$B$52+(0.01) | B9: =IF($A9-B$4<=0.01,"n/a",((SUMPRODUCT('Calc - research target (12m)'!$C$31:$E$31,'Calc - research target (12m)'!$C$35:$E$35,(1+$A9)^(-('Calc - research target (12m)'!$C$19:$E$19-'Calc - research target (12m)'!$B$13)))+'Calc - research target (12m)'!$E$31*(1+B$4)/($A9-B$4)/(1+$A9)^('Calc - research target (12m)'!$B$16-'Calc - research target (12m)'!$B$13))-'Calc - research target (12m)'!$B$50-'Calc - research target (12m)'!$B$51+'Calc - research target (12m)'!$B$52)/'Calc - research target (12m)'!$B$53) | C9: =IF($A9-C$4<=0.01,"n/a",((SUMPRODUCT('Calc - research target (12m)'!$C$31:$E$31,'Calc - research target (12m)'!$C$35:$E$35,(1+$A9)^(-('Calc - research target (12m)'!$C$19:$E$19-'Calc - research target (12m)'!$B$13)))+'Calc - research target (12m)'!$E$31*(1+C$4)/($A9-C$4)/(1+$A9)^('Calc - research target (12m)'!$B$16-'Calc - research target (12m)'!$B$13))-'Calc - research target (12m)'!$B$50-'Calc - research target (12m)'!$B$51+'Calc - research target (12m)'!$B$52)/'Calc - research target (12m)'!$B$53) | D9: =IF($A9-D$4<=0.01,"n/a",((SUMPRODUCT('Calc - research target (12m)'!$C$31:$E$31,'Calc - research target (12m)'!$C$35:$E$35,(1+$A9)^(-('Calc - research target (12m)'!$C$19:$E$19-'Calc - research target (12m)'!$B$13)))+'Calc - research target (12m)'!$E$31*(1+D$4)/($A9-D$4)/(1+$A9)^('Calc - research target (12m)'!$B$16-'Calc - research target (12m)'!$B$13))-'Calc - research target (12m)'!$B$50-'Calc - research target (12m)'!$B$51+'Calc - research target (12m)'!$B$52)/'Calc - research target (12m)'!$B$53) | E9: =IF($A9-E$4<=0.01,"n/a",((SUMPRODUCT('Calc - research target (12m)'!$C$31:$E$31,'Calc - research target (12m)'!$C$35:$E$35,(1+$A9)^(-('Calc - research target (12m)'!$C$19:$E$19-'Calc - research target (12m)'!$B$13)))+'Calc - research target (12m)'!$E$31*(1+E$4)/($A9-E$4)/(1+$A9)^('Calc - research target (12m)'!$B$16-'Calc - research target (12m)'!$B$13))-'Calc - research target (12m)'!$B$50-'Calc - research target (12m)'!$B$51+'Calc - research target (12m)'!$B$52)/'Calc - research target (12m)'!$B$53) | F9: =IF($A9-F$4<=0.01,"n/a",((SUMPRODUCT('Calc - research target (12m)'!$C$31:$E$31,'Calc - research target (12m)'!$C$35:$E$35,(1+$A9)^(-('Calc - research target (12m)'!$C$19:$E$19-'Calc - research target (12m)'!$B$13)))+'Calc - research target (12m)'!$E$31*(1+F$4)/($A9-F$4)/(1+$A9)^('Calc - research target (12m)'!$B$16-'Calc - research target (12m)'!$B$13))-'Calc - research target (12m)'!$B$50-'Calc - research target (12m)'!$B$51+'Calc - research target (12m)'!$B$52)/'Calc - research target (12m)'!$B$53)
A11: Research target (12m) per share: EV/EBITDA multiple (down) x metric at target date (across)
A12: Multiple \ metric | B12: ='Calc - research target (12m)'!$E$68*0.9 | C12: ='Calc - research target (12m)'!$E$68*0.95 | D12: ='Calc - research target (12m)'!$E$68*1.0 | E12: ='Calc - research target (12m)'!$E$68*1.05 | F12: ='Calc - research target (12m)'!$E$68*1.1
A13: =Valuation!$B$71+(-3) | B13: =((SUMPRODUCT('Calc - research target (12m)'!$F$67:$F$70,'Calc - research target (12m)'!$G$67:$G$70)-'Calc - research target (12m)'!$F$68*'Calc - research target (12m)'!$G$68)+'Calc - research target (12m)'!$G$68*((($A13*B$12)-'Calc - research target (12m)'!$B$50-'Calc - research target (12m)'!$B$51+'Calc - research target (12m)'!$B$52)/'Calc - research target (12m)'!$B$53))/SUM('Calc - research target (12m)'!$G$67:$G$70) | C13: =((SUMPRODUCT('Calc - research target (12m)'!$F$67:$F$70,'Calc - research target (12m)'!$G$67:$G$70)-'Calc - research target (12m)'!$F$68*'Calc - research target (12m)'!$G$68)+'Calc - research target (12m)'!$G$68*((($A13*C$12)-'Calc - research target (12m)'!$B$50-'Calc - research target (12m)'!$B$51+'Calc - research target (12m)'!$B$52)/'Calc - research target (12m)'!$B$53))/SUM('Calc - research target (12m)'!$G$67:$G$70) | D13: =((SUMPRODUCT('Calc - research target (12m)'!$F$67:$F$70,'Calc - research target (12m)'!$G$67:$G$70)-'Calc - research target (12m)'!$F$68*'Calc - research target (12m)'!$G$68)+'Calc - research target (12m)'!$G$68*((($A13*D$12)-'Calc - research target (12m)'!$B$50-'Calc - research target (12m)'!$B$51+'Calc - research target (12m)'!$B$52)/'Calc - research target (12m)'!$B$53))/SUM('Calc - research target (12m)'!$G$67:$G$70) | E13: =((SUMPRODUCT('Calc - research target (12m)'!$F$67:$F$70,'Calc - research target (12m)'!$G$67:$G$70)-'Calc - research target (12m)'!$F$68*'Calc - research target (12m)'!$G$68)+'Calc - research target (12m)'!$G$68*((($A13*E$12)-'Calc - research target (12m)'!$B$50-'Calc - research target (12m)'!$B$51+'Calc - research target (12m)'!$B$52)/'Calc - research target (12m)'!$B$53))/SUM('Calc - research target (12m)'!$G$67:$G$70) | F13: =((SUMPRODUCT('Calc - research target (12m)'!$F$67:$F$70,'Calc - research target (12m)'!$G$67:$G$70)-'Calc - research target (12m)'!$F$68*'Calc - research target (12m)'!$G$68)+'Calc - research target (12m)'!$G$68*((($A13*F$12)-'Calc - research target (12m)'!$B$50-'Calc - research target (12m)'!$B$51+'Calc - research target (12m)'!$B$52)/'Calc - research target (12m)'!$B$53))/SUM('Calc - research target (12m)'!$G$67:$G$70)
A14: =Valuation!$B$71+(-2) | B14: =((SUMPRODUCT('Calc - research target (12m)'!$F$67:$F$70,'Calc - research target (12m)'!$G$67:$G$70)-'Calc - research target (12m)'!$F$68*'Calc - research target (12m)'!$G$68)+'Calc - research target (12m)'!$G$68*((($A14*B$12)-'Calc - research target (12m)'!$B$50-'Calc - research target (12m)'!$B$51+'Calc - research target (12m)'!$B$52)/'Calc - research target (12m)'!$B$53))/SUM('Calc - research target (12m)'!$G$67:$G$70) | C14: =((SUMPRODUCT('Calc - research target (12m)'!$F$67:$F$70,'Calc - research target (12m)'!$G$67:$G$70)-'Calc - research target (12m)'!$F$68*'Calc - research target (12m)'!$G$68)+'Calc - research target (12m)'!$G$68*((($A14*C$12)-'Calc - research target (12m)'!$B$50-'Calc - research target (12m)'!$B$51+'Calc - research target (12m)'!$B$52)/'Calc - research target (12m)'!$B$53))/SUM('Calc - research target (12m)'!$G$67:$G$70) | D14: =((SUMPRODUCT('Calc - research target (12m)'!$F$67:$F$70,'Calc - research target (12m)'!$G$67:$G$70)-'Calc - research target (12m)'!$F$68*'Calc - research target (12m)'!$G$68)+'Calc - research target (12m)'!$G$68*((($A14*D$12)-'Calc - research target (12m)'!$B$50-'Calc - research target (12m)'!$B$51+'Calc - research target (12m)'!$B$52)/'Calc - research target (12m)'!$B$53))/SUM('Calc - research target (12m)'!$G$67:$G$70) | E14: =((SUMPRODUCT('Calc - research target (12m)'!$F$67:$F$70,'Calc - research target (12m)'!$G$67:$G$70)-'Calc - research target (12m)'!$F$68*'Calc - research target (12m)'!$G$68)+'Calc - research target (12m)'!$G$68*((($A14*E$12)-'Calc - research target (12m)'!$B$50-'Calc - research target (12m)'!$B$51+'Calc - research target (12m)'!$B$52)/'Calc - research target (12m)'!$B$53))/SUM('Calc - research target (12m)'!$G$67:$G$70) | F14: =((SUMPRODUCT('Calc - research target (12m)'!$F$67:$F$70,'Calc - research target (12m)'!$G$67:$G$70)-'Calc - research target (12m)'!$F$68*'Calc - research target (12m)'!$G$68)+'Calc - research target (12m)'!$G$68*((($A14*F$12)-'Calc - research target (12m)'!$B$50-'Calc - research target (12m)'!$B$51+'Calc - research target (12m)'!$B$52)/'Calc - research target (12m)'!$B$53))/SUM('Calc - research target (12m)'!$G$67:$G$70)
A15: =Valuation!$B$71+(-1) | B15: =((SUMPRODUCT('Calc - research target (12m)'!$F$67:$F$70,'Calc - research target (12m)'!$G$67:$G$70)-'Calc - research target (12m)'!$F$68*'Calc - research target (12m)'!$G$68)+'Calc - research target (12m)'!$G$68*((($A15*B$12)-'Calc - research target (12m)'!$B$50-'Calc - research target (12m)'!$B$51+'Calc - research target (12m)'!$B$52)/'Calc - research target (12m)'!$B$53))/SUM('Calc - research target (12m)'!$G$67:$G$70) | C15: =((SUMPRODUCT('Calc - research target (12m)'!$F$67:$F$70,'Calc - research target (12m)'!$G$67:$G$70)-'Calc - research target (12m)'!$F$68*'Calc - research target (12m)'!$G$68)+'Calc - research target (12m)'!$G$68*((($A15*C$12)-'Calc - research target (12m)'!$B$50-'Calc - research target (12m)'!$B$51+'Calc - research target (12m)'!$B$52)/'Calc - research target (12m)'!$B$53))/SUM('Calc - research target (12m)'!$G$67:$G$70) | D15: =((SUMPRODUCT('Calc - research target (12m)'!$F$67:$F$70,'Calc - research target (12m)'!$G$67:$G$70)-'Calc - research target (12m)'!$F$68*'Calc - research target (12m)'!$G$68)+'Calc - research target (12m)'!$G$68*((($A15*D$12)-'Calc - research target (12m)'!$B$50-'Calc - research target (12m)'!$B$51+'Calc - research target (12m)'!$B$52)/'Calc - research target (12m)'!$B$53))/SUM('Calc - research target (12m)'!$G$67:$G$70) | E15: =((SUMPRODUCT('Calc - research target (12m)'!$F$67:$F$70,'Calc - research target (12m)'!$G$67:$G$70)-'Calc - research target (12m)'!$F$68*'Calc - research target (12m)'!$G$68)+'Calc - research target (12m)'!$G$68*((($A15*E$12)-'Calc - research target (12m)'!$B$50-'Calc - research target (12m)'!$B$51+'Calc - research target (12m)'!$B$52)/'Calc - research target (12m)'!$B$53))/SUM('Calc - research target (12m)'!$G$67:$G$70) | F15: =((SUMPRODUCT('Calc - research target (12m)'!$F$67:$F$70,'Calc - research target (12m)'!$G$67:$G$70)-'Calc - research target (12m)'!$F$68*'Calc - research target (12m)'!$G$68)+'Calc - research target (12m)'!$G$68*((($A15*F$12)-'Calc - research target (12m)'!$B$50-'Calc - research target (12m)'!$B$51+'Calc - research target (12m)'!$B$52)/'Calc - research target (12m)'!$B$53))/SUM('Calc - research target (12m)'!$G$67:$G$70)
A16: =Valuation!$B$71+(0) | B16: =((SUMPRODUCT('Calc - research target (12m)'!$F$67:$F$70,'Calc - research target (12m)'!$G$67:$G$70)-'Calc - research target (12m)'!$F$68*'Calc - research target (12m)'!$G$68)+'Calc - research target (12m)'!$G$68*((($A16*B$12)-'Calc - research target (12m)'!$B$50-'Calc - research target (12m)'!$B$51+'Calc - research target (12m)'!$B$52)/'Calc - research target (12m)'!$B$53))/SUM('Calc - research target (12m)'!$G$67:$G$70) | C16: =((SUMPRODUCT('Calc - research target (12m)'!$F$67:$F$70,'Calc - research target (12m)'!$G$67:$G$70)-'Calc - research target (12m)'!$F$68*'Calc - research target (12m)'!$G$68)+'Calc - research target (12m)'!$G$68*((($A16*C$12)-'Calc - research target (12m)'!$B$50-'Calc - research target (12m)'!$B$51+'Calc - research target (12m)'!$B$52)/'Calc - research target (12m)'!$B$53))/SUM('Calc - research target (12m)'!$G$67:$G$70) | D16: =((SUMPRODUCT('Calc - research target (12m)'!$F$67:$F$70,'Calc - research target (12m)'!$G$67:$G$70)-'Calc - research target (12m)'!$F$68*'Calc - research target (12m)'!$G$68)+'Calc - research target (12m)'!$G$68*((($A16*D$12)-'Calc - research target (12m)'!$B$50-'Calc - research target (12m)'!$B$51+'Calc - research target (12m)'!$B$52)/'Calc - research target (12m)'!$B$53))/SUM('Calc - research target (12m)'!$G$67:$G$70) | E16: =((SUMPRODUCT('Calc - research target (12m)'!$F$67:$F$70,'Calc - research target (12m)'!$G$67:$G$70)-'Calc - research target (12m)'!$F$68*'Calc - research target (12m)'!$G$68)+'Calc - research target (12m)'!$G$68*((($A16*E$12)-'Calc - research target (12m)'!$B$50-'Calc - research target (12m)'!$B$51+'Calc - research target (12m)'!$B$52)/'Calc - research target (12m)'!$B$53))/SUM('Calc - research target (12m)'!$G$67:$G$70) | F16: =((SUMPRODUCT('Calc - research target (12m)'!$F$67:$F$70,'Calc - research target (12m)'!$G$67:$G$70)-'Calc - research target (12m)'!$F$68*'Calc - research target (12m)'!$G$68)+'Calc - research target (12m)'!$G$68*((($A16*F$12)-'Calc - research target (12m)'!$B$50-'Calc - research target (12m)'!$B$51+'Calc - research target (12m)'!$B$52)/'Calc - research target (12m)'!$B$53))/SUM('Calc - research target (12m)'!$G$67:$G$70)
A17: =Valuation!$B$71+(1) | B17: =((SUMPRODUCT('Calc - research target (12m)'!$F$67:$F$70,'Calc - research target (12m)'!$G$67:$G$70)-'Calc - research target (12m)'!$F$68*'Calc - research target (12m)'!$G$68)+'Calc - research target (12m)'!$G$68*((($A17*B$12)-'Calc - research target (12m)'!$B$50-'Calc - research target (12m)'!$B$51+'Calc - research target (12m)'!$B$52)/'Calc - research target (12m)'!$B$53))/SUM('Calc - research target (12m)'!$G$67:$G$70) | C17: =((SUMPRODUCT('Calc - research target (12m)'!$F$67:$F$70,'Calc - research target (12m)'!$G$67:$G$70)-'Calc - research target (12m)'!$F$68*'Calc - research target (12m)'!$G$68)+'Calc - research target (12m)'!$G$68*((($A17*C$12)-'Calc - research target (12m)'!$B$50-'Calc - research target (12m)'!$B$51+'Calc - research target (12m)'!$B$52)/'Calc - research target (12m)'!$B$53))/SUM('Calc - research target (12m)'!$G$67:$G$70) | D17: =((SUMPRODUCT('Calc - research target (12m)'!$F$67:$F$70,'Calc - research target (12m)'!$G$67:$G$70)-'Calc - research target (12m)'!$F$68*'Calc - research target (12m)'!$G$68)+'Calc - research target (12m)'!$G$68*((($A17*D$12)-'Calc - research target (12m)'!$B$50-'Calc - research target (12m)'!$B$51+'Calc - research target (12m)'!$B$52)/'Calc - research target (12m)'!$B$53))/SUM('Calc - research target (12m)'!$G$67:$G$70) | E17: =((SUMPRODUCT('Calc - research target (12m)'!$F$67:$F$70,'Calc - research target (12m)'!$G$67:$G$70)-'Calc - research target (12m)'!$F$68*'Calc - research target (12m)'!$G$68)+'Calc - research target (12m)'!$G$68*((($A17*E$12)-'Calc - research target (12m)'!$B$50-'Calc - research target (12m)'!$B$51+'Calc - research target (12m)'!$B$52)/'Calc - research target (12m)'!$B$53))/SUM('Calc - research target (12m)'!$G$67:$G$70) | F17: =((SUMPRODUCT('Calc - research target (12m)'!$F$67:$F$70,'Calc - research target (12m)'!$G$67:$G$70)-'Calc - research target (12m)'!$F$68*'Calc - research target (12m)'!$G$68)+'Calc - research target (12m)'!$G$68*((($A17*F$12)-'Calc - research target (12m)'!$B$50-'Calc - research target (12m)'!$B$51+'Calc - research target (12m)'!$B$52)/'Calc - research target (12m)'!$B$53))/SUM('Calc - research target (12m)'!$G$67:$G$70)
A18: =Valuation!$B$71+(2) | B18: =((SUMPRODUCT('Calc - research target (12m)'!$F$67:$F$70,'Calc - research target (12m)'!$G$67:$G$70)-'Calc - research target (12m)'!$F$68*'Calc - research target (12m)'!$G$68)+'Calc - research target (12m)'!$G$68*((($A18*B$12)-'Calc - research target (12m)'!$B$50-'Calc - research target (12m)'!$B$51+'Calc - research target (12m)'!$B$52)/'Calc - research target (12m)'!$B$53))/SUM('Calc - research target (12m)'!$G$67:$G$70) | C18: =((SUMPRODUCT('Calc - research target (12m)'!$F$67:$F$70,'Calc - research target (12m)'!$G$67:$G$70)-'Calc - research target (12m)'!$F$68*'Calc - research target (12m)'!$G$68)+'Calc - research target (12m)'!$G$68*((($A18*C$12)-'Calc - research target (12m)'!$B$50-'Calc - research target (12m)'!$B$51+'Calc - research target (12m)'!$B$52)/'Calc - research target (12m)'!$B$53))/SUM('Calc - research target (12m)'!$G$67:$G$70) | D18: =((SUMPRODUCT('Calc - research target (12m)'!$F$67:$F$70,'Calc - research target (12m)'!$G$67:$G$70)-'Calc - research target (12m)'!$F$68*'Calc - research target (12m)'!$G$68)+'Calc - research target (12m)'!$G$68*((($A18*D$12)-'Calc - research target (12m)'!$B$50-'Calc - research target (12m)'!$B$51+'Calc - research target (12m)'!$B$52)/'Calc - research target (12m)'!$B$53))/SUM('Calc - research target (12m)'!$G$67:$G$70) | E18: =((SUMPRODUCT('Calc - research target (12m)'!$F$67:$F$70,'Calc - research target (12m)'!$G$67:$G$70)-'Calc - research target (12m)'!$F$68*'Calc - research target (12m)'!$G$68)+'Calc - research target (12m)'!$G$68*((($A18*E$12)-'Calc - research target (12m)'!$B$50-'Calc - research target (12m)'!$B$51+'Calc - research target (12m)'!$B$52)/'Calc - research target (12m)'!$B$53))/SUM('Calc - research target (12m)'!$G$67:$G$70) | F18: =((SUMPRODUCT('Calc - research target (12m)'!$F$67:$F$70,'Calc - research target (12m)'!$G$67:$G$70)-'Calc - research target (12m)'!$F$68*'Calc - research target (12m)'!$G$68)+'Calc - research target (12m)'!$G$68*((($A18*F$12)-'Calc - research target (12m)'!$B$50-'Calc - research target (12m)'!$B$51+'Calc - research target (12m)'!$B$52)/'Calc - research target (12m)'!$B$53))/SUM('Calc - research target (12m)'!$G$67:$G$70)
A19: =Valuation!$B$71+(3) | B19: =((SUMPRODUCT('Calc - research target (12m)'!$F$67:$F$70,'Calc - research target (12m)'!$G$67:$G$70)-'Calc - research target (12m)'!$F$68*'Calc - research target (12m)'!$G$68)+'Calc - research target (12m)'!$G$68*((($A19*B$12)-'Calc - research target (12m)'!$B$50-'Calc - research target (12m)'!$B$51+'Calc - research target (12m)'!$B$52)/'Calc - research target (12m)'!$B$53))/SUM('Calc - research target (12m)'!$G$67:$G$70) | C19: =((SUMPRODUCT('Calc - research target (12m)'!$F$67:$F$70,'Calc - research target (12m)'!$G$67:$G$70)-'Calc - research target (12m)'!$F$68*'Calc - research target (12m)'!$G$68)+'Calc - research target (12m)'!$G$68*((($A19*C$12)-'Calc - research target (12m)'!$B$50-'Calc - research target (12m)'!$B$51+'Calc - research target (12m)'!$B$52)/'Calc - research target (12m)'!$B$53))/SUM('Calc - research target (12m)'!$G$67:$G$70) | D19: =((SUMPRODUCT('Calc - research target (12m)'!$F$67:$F$70,'Calc - research target (12m)'!$G$67:$G$70)-'Calc - research target (12m)'!$F$68*'Calc - research target (12m)'!$G$68)+'Calc - research target (12m)'!$G$68*((($A19*D$12)-'Calc - research target (12m)'!$B$50-'Calc - research target (12m)'!$B$51+'Calc - research target (12m)'!$B$52)/'Calc - research target (12m)'!$B$53))/SUM('Calc - research target (12m)'!$G$67:$G$70) | E19: =((SUMPRODUCT('Calc - research target (12m)'!$F$67:$F$70,'Calc - research target (12m)'!$G$67:$G$70)-'Calc - research target (12m)'!$F$68*'Calc - research target (12m)'!$G$68)+'Calc - research target (12m)'!$G$68*((($A19*E$12)-'Calc - research target (12m)'!$B$50-'Calc - research target (12m)'!$B$51+'Calc - research target (12m)'!$B$52)/'Calc - research target (12m)'!$B$53))/SUM('Calc - research target (12m)'!$G$67:$G$70) | F19: =((SUMPRODUCT('Calc - research target (12m)'!$F$67:$F$70,'Calc - research target (12m)'!$G$67:$G$70)-'Calc - research target (12m)'!$F$68*'Calc - research target (12m)'!$G$68)+'Calc - research target (12m)'!$G$68*((($A19*F$12)-'Calc - research target (12m)'!$B$50-'Calc - research target (12m)'!$B$51+'Calc - research target (12m)'!$B$52)/'Calc - research target (12m)'!$B$53))/SUM('Calc - research target (12m)'!$G$67:$G$70)
A22: FY2027E diluted EPS: revenue growth change in every year (down) x EBIT margin change (across)
A23: Growth Δ \ margin Δ | B23: -0.01 | C23: -0.005 | D23: 0 | E23: 0.005 | F23: 0.01
A24: -0.02 | B24: =(Valuation!$B$91*(1+Model!E12+$A24)*(1+Model!F12+$A24)*(Model!F14+B$23)+Valuation!$B$92*(1+Model!E16+$A24)*(1+Model!F16+$A24)*(Model!F18+B$23)+Valuation!$B$93*(1+Model!E20+$A24)*(1+Model!F20+$A24)*(Model!F22+B$23)+Valuation!$B$94*(1+Model!E24+$A24)*(1+Model!F24+$A24)*(Model!F26+B$23)+Valuation!$B$95*(1+Model!E28+$A24)*(1+Model!F28+$A24)*(Model!F30+B$23)+Model!F33+Model!F45)*(1-Model!F75)/Model!F52 | C24: =(Valuation!$B$91*(1+Model!E12+$A24)*(1+Model!F12+$A24)*(Model!F14+C$23)+Valuation!$B$92*(1+Model!E16+$A24)*(1+Model!F16+$A24)*(Model!F18+C$23)+Valuation!$B$93*(1+Model!E20+$A24)*(1+Model!F20+$A24)*(Model!F22+C$23)+Valuation!$B$94*(1+Model!E24+$A24)*(1+Model!F24+$A24)*(Model!F26+C$23)+Valuation!$B$95*(1+Model!E28+$A24)*(1+Model!F28+$A24)*(Model!F30+C$23)+Model!F33+Model!F45)*(1-Model!F75)/Model!F52 | D24: =(Valuation!$B$91*(1+Model!E12+$A24)*(1+Model!F12+$A24)*(Model!F14+D$23)+Valuation!$B$92*(1+Model!E16+$A24)*(1+Model!F16+$A24)*(Model!F18+D$23)+Valuation!$B$93*(1+Model!E20+$A24)*(1+Model!F20+$A24)*(Model!F22+D$23)+Valuation!$B$94*(1+Model!E24+$A24)*(1+Model!F24+$A24)*(Model!F26+D$23)+Valuation!$B$95*(1+Model!E28+$A24)*(1+Model!F28+$A24)*(Model!F30+D$23)+Model!F33+Model!F45)*(1-Model!F75)/Model!F52 | E24: =(Valuation!$B$91*(1+Model!E12+$A24)*(1+Model!F12+$A24)*(Model!F14+E$23)+Valuation!$B$92*(1+Model!E16+$A24)*(1+Model!F16+$A24)*(Model!F18+E$23)+Valuation!$B$93*(1+Model!E20+$A24)*(1+Model!F20+$A24)*(Model!F22+E$23)+Valuation!$B$94*(1+Model!E24+$A24)*(1+Model!F24+$A24)*(Model!F26+E$23)+Valuation!$B$95*(1+Model!E28+$A24)*(1+Model!F28+$A24)*(Model!F30+E$23)+Model!F33+Model!F45)*(1-Model!F75)/Model!F52 | F24: =(Valuation!$B$91*(1+Model!E12+$A24)*(1+Model!F12+$A24)*(Model!F14+F$23)+Valuation!$B$92*(1+Model!E16+$A24)*(1+Model!F16+$A24)*(Model!F18+F$23)+Valuation!$B$93*(1+Model!E20+$A24)*(1+Model!F20+$A24)*(Model!F22+F$23)+Valuation!$B$94*(1+Model!E24+$A24)*(1+Model!F24+$A24)*(Model!F26+F$23)+Valuation!$B$95*(1+Model!E28+$A24)*(1+Model!F28+$A24)*(Model!F30+F$23)+Model!F33+Model!F45)*(1-Model!F75)/Model!F52
A25: -0.01 | B25: =(Valuation!$B$91*(1+Model!E12+$A25)*(1+Model!F12+$A25)*(Model!F14+B$23)+Valuation!$B$92*(1+Model!E16+$A25)*(1+Model!F16+$A25)*(Model!F18+B$23)+Valuation!$B$93*(1+Model!E20+$A25)*(1+Model!F20+$A25)*(Model!F22+B$23)+Valuation!$B$94*(1+Model!E24+$A25)*(1+Model!F24+$A25)*(Model!F26+B$23)+Valuation!$B$95*(1+Model!E28+$A25)*(1+Model!F28+$A25)*(Model!F30+B$23)+Model!F33+Model!F45)*(1-Model!F75)/Model!F52 | C25: =(Valuation!$B$91*(1+Model!E12+$A25)*(1+Model!F12+$A25)*(Model!F14+C$23)+Valuation!$B$92*(1+Model!E16+$A25)*(1+Model!F16+$A25)*(Model!F18+C$23)+Valuation!$B$93*(1+Model!E20+$A25)*(1+Model!F20+$A25)*(Model!F22+C$23)+Valuation!$B$94*(1+Model!E24+$A25)*(1+Model!F24+$A25)*(Model!F26+C$23)+Valuation!$B$95*(1+Model!E28+$A25)*(1+Model!F28+$A25)*(Model!F30+C$23)+Model!F33+Model!F45)*(1-Model!F75)/Model!F52 | D25: =(Valuation!$B$91*(1+Model!E12+$A25)*(1+Model!F12+$A25)*(Model!F14+D$23)+Valuation!$B$92*(1+Model!E16+$A25)*(1+Model!F16+$A25)*(Model!F18+D$23)+Valuation!$B$93*(1+Model!E20+$A25)*(1+Model!F20+$A25)*(Model!F22+D$23)+Valuation!$B$94*(1+Model!E24+$A25)*(1+Model!F24+$A25)*(Model!F26+D$23)+Valuation!$B$95*(1+Model!E28+$A25)*(1+Model!F28+$A25)*(Model!F30+D$23)+Model!F33+Model!F45)*(1-Model!F75)/Model!F52 | E25: =(Valuation!$B$91*(1+Model!E12+$A25)*(1+Model!F12+$A25)*(Model!F14+E$23)+Valuation!$B$92*(1+Model!E16+$A25)*(1+Model!F16+$A25)*(Model!F18+E$23)+Valuation!$B$93*(1+Model!E20+$A25)*(1+Model!F20+$A25)*(Model!F22+E$23)+Valuation!$B$94*(1+Model!E24+$A25)*(1+Model!F24+$A25)*(Model!F26+E$23)+Valuation!$B$95*(1+Model!E28+$A25)*(1+Model!F28+$A25)*(Model!F30+E$23)+Model!F33+Model!F45)*(1-Model!F75)/Model!F52 | F25: =(Valuation!$B$91*(1+Model!E12+$A25)*(1+Model!F12+$A25)*(Model!F14+F$23)+Valuation!$B$92*(1+Model!E16+$A25)*(1+Model!F16+$A25)*(Model!F18+F$23)+Valuation!$B$93*(1+Model!E20+$A25)*(1+Model!F20+$A25)*(Model!F22+F$23)+Valuation!$B$94*(1+Model!E24+$A25)*(1+Model!F24+$A25)*(Model!F26+F$23)+Valuation!$B$95*(1+Model!E28+$A25)*(1+Model!F28+$A25)*(Model!F30+F$23)+Model!F33+Model!F45)*(1-Model!F75)/Model!F52
A26: 0 | B26: =(Valuation!$B$91*(1+Model!E12+$A26)*(1+Model!F12+$A26)*(Model!F14+B$23)+Valuation!$B$92*(1+Model!E16+$A26)*(1+Model!F16+$A26)*(Model!F18+B$23)+Valuation!$B$93*(1+Model!E20+$A26)*(1+Model!F20+$A26)*(Model!F22+B$23)+Valuation!$B$94*(1+Model!E24+$A26)*(1+Model!F24+$A26)*(Model!F26+B$23)+Valuation!$B$95*(1+Model!E28+$A26)*(1+Model!F28+$A26)*(Model!F30+B$23)+Model!F33+Model!F45)*(1-Model!F75)/Model!F52 | C26: =(Valuation!$B$91*(1+Model!E12+$A26)*(1+Model!F12+$A26)*(Model!F14+C$23)+Valuation!$B$92*(1+Model!E16+$A26)*(1+Model!F16+$A26)*(Model!F18+C$23)+Valuation!$B$93*(1+Model!E20+$A26)*(1+Model!F20+$A26)*(Model!F22+C$23)+Valuation!$B$94*(1+Model!E24+$A26)*(1+Model!F24+$A26)*(Model!F26+C$23)+Valuation!$B$95*(1+Model!E28+$A26)*(1+Model!F28+$A26)*(Model!F30+C$23)+Model!F33+Model!F45)*(1-Model!F75)/Model!F52 | D26: =(Valuation!$B$91*(1+Model!E12+$A26)*(1+Model!F12+$A26)*(Model!F14+D$23)+Valuation!$B$92*(1+Model!E16+$A26)*(1+Model!F16+$A26)*(Model!F18+D$23)+Valuation!$B$93*(1+Model!E20+$A26)*(1+Model!F20+$A26)*(Model!F22+D$23)+Valuation!$B$94*(1+Model!E24+$A26)*(1+Model!F24+$A26)*(Model!F26+D$23)+Valuation!$B$95*(1+Model!E28+$A26)*(1+Model!F28+$A26)*(Model!F30+D$23)+Model!F33+Model!F45)*(1-Model!F75)/Model!F52 | E26: =(Valuation!$B$91*(1+Model!E12+$A26)*(1+Model!F12+$A26)*(Model!F14+E$23)+Valuation!$B$92*(1+Model!E16+$A26)*(1+Model!F16+$A26)*(Model!F18+E$23)+Valuation!$B$93*(1+Model!E20+$A26)*(1+Model!F20+$A26)*(Model!F22+E$23)+Valuation!$B$94*(1+Model!E24+$A26)*(1+Model!F24+$A26)*(Model!F26+E$23)+Valuation!$B$95*(1+Model!E28+$A26)*(1+Model!F28+$A26)*(Model!F30+E$23)+Model!F33+Model!F45)*(1-Model!F75)/Model!F52 | F26: =(Valuation!$B$91*(1+Model!E12+$A26)*(1+Model!F12+$A26)*(Model!F14+F$23)+Valuation!$B$92*(1+Model!E16+$A26)*(1+Model!F16+$A26)*(Model!F18+F$23)+Valuation!$B$93*(1+Model!E20+$A26)*(1+Model!F20+$A26)*(Model!F22+F$23)+Valuation!$B$94*(1+Model!E24+$A26)*(1+Model!F24+$A26)*(Model!F26+F$23)+Valuation!$B$95*(1+Model!E28+$A26)*(1+Model!F28+$A26)*(Model!F30+F$23)+Model!F33+Model!F45)*(1-Model!F75)/Model!F52
A27: 0.01 | B27: =(Valuation!$B$91*(1+Model!E12+$A27)*(1+Model!F12+$A27)*(Model!F14+B$23)+Valuation!$B$92*(1+Model!E16+$A27)*(1+Model!F16+$A27)*(Model!F18+B$23)+Valuation!$B$93*(1+Model!E20+$A27)*(1+Model!F20+$A27)*(Model!F22+B$23)+Valuation!$B$94*(1+Model!E24+$A27)*(1+Model!F24+$A27)*(Model!F26+B$23)+Valuation!$B$95*(1+Model!E28+$A27)*(1+Model!F28+$A27)*(Model!F30+B$23)+Model!F33+Model!F45)*(1-Model!F75)/Model!F52 | C27: =(Valuation!$B$91*(1+Model!E12+$A27)*(1+Model!F12+$A27)*(Model!F14+C$23)+Valuation!$B$92*(1+Model!E16+$A27)*(1+Model!F16+$A27)*(Model!F18+C$23)+Valuation!$B$93*(1+Model!E20+$A27)*(1+Model!F20+$A27)*(Model!F22+C$23)+Valuation!$B$94*(1+Model!E24+$A27)*(1+Model!F24+$A27)*(Model!F26+C$23)+Valuation!$B$95*(1+Model!E28+$A27)*(1+Model!F28+$A27)*(Model!F30+C$23)+Model!F33+Model!F45)*(1-Model!F75)/Model!F52 | D27: =(Valuation!$B$91*(1+Model!E12+$A27)*(1+Model!F12+$A27)*(Model!F14+D$23)+Valuation!$B$92*(1+Model!E16+$A27)*(1+Model!F16+$A27)*(Model!F18+D$23)+Valuation!$B$93*(1+Model!E20+$A27)*(1+Model!F20+$A27)*(Model!F22+D$23)+Valuation!$B$94*(1+Model!E24+$A27)*(1+Model!F24+$A27)*(Model!F26+D$23)+Valuation!$B$95*(1+Model!E28+$A27)*(1+Model!F28+$A27)*(Model!F30+D$23)+Model!F33+Model!F45)*(1-Model!F75)/Model!F52 | E27: =(Valuation!$B$91*(1+Model!E12+$A27)*(1+Model!F12+$A27)*(Model!F14+E$23)+Valuation!$B$92*(1+Model!E16+$A27)*(1+Model!F16+$A27)*(Model!F18+E$23)+Valuation!$B$93*(1+Model!E20+$A27)*(1+Model!F20+$A27)*(Model!F22+E$23)+Valuation!$B$94*(1+Model!E24+$A27)*(1+Model!F24+$A27)*(Model!F26+E$23)+Valuation!$B$95*(1+Model!E28+$A27)*(1+Model!F28+$A27)*(Model!F30+E$23)+Model!F33+Model!F45)*(1-Model!F75)/Model!F52 | F27: =(Valuation!$B$91*(1+Model!E12+$A27)*(1+Model!F12+$A27)*(Model!F14+F$23)+Valuation!$B$92*(1+Model!E16+$A27)*(1+Model!F16+$A27)*(Model!F18+F$23)+Valuation!$B$93*(1+Model!E20+$A27)*(1+Model!F20+$A27)*(Model!F22+F$23)+Valuation!$B$94*(1+Model!E24+$A27)*(1+Model!F24+$A27)*(Model!F26+F$23)+Valuation!$B$95*(1+Model!E28+$A27)*(1+Model!F28+$A27)*(Model!F30+F$23)+Model!F33+Model!F45)*(1-Model!F75)/Model!F52
A28: 0.02 | B28: =(Valuation!$B$91*(1+Model!E12+$A28)*(1+Model!F12+$A28)*(Model!F14+B$23)+Valuation!$B$92*(1+Model!E16+$A28)*(1+Model!F16+$A28)*(Model!F18+B$23)+Valuation!$B$93*(1+Model!E20+$A28)*(1+Model!F20+$A28)*(Model!F22+B$23)+Valuation!$B$94*(1+Model!E24+$A28)*(1+Model!F24+$A28)*(Model!F26+B$23)+Valuation!$B$95*(1+Model!E28+$A28)*(1+Model!F28+$A28)*(Model!F30+B$23)+Model!F33+Model!F45)*(1-Model!F75)/Model!F52 | C28: =(Valuation!$B$91*(1+Model!E12+$A28)*(1+Model!F12+$A28)*(Model!F14+C$23)+Valuation!$B$92*(1+Model!E16+$A28)*(1+Model!F16+$A28)*(Model!F18+C$23)+Valuation!$B$93*(1+Model!E20+$A28)*(1+Model!F20+$A28)*(Model!F22+C$23)+Valuation!$B$94*(1+Model!E24+$A28)*(1+Model!F24+$A28)*(Model!F26+C$23)+Valuation!$B$95*(1+Model!E28+$A28)*(1+Model!F28+$A28)*(Model!F30+C$23)+Model!F33+Model!F45)*(1-Model!F75)/Model!F52 | D28: =(Valuation!$B$91*(1+Model!E12+$A28)*(1+Model!F12+$A28)*(Model!F14+D$23)+Valuation!$B$92*(1+Model!E16+$A28)*(1+Model!F16+$A28)*(Model!F18+D$23)+Valuation!$B$93*(1+Model!E20+$A28)*(1+Model!F20+$A28)*(Model!F22+D$23)+Valuation!$B$94*(1+Model!E24+$A28)*(1+Model!F24+$A28)*(Model!F26+D$23)+Valuation!$B$95*(1+Model!E28+$A28)*(1+Model!F28+$A28)*(Model!F30+D$23)+Model!F33+Model!F45)*(1-Model!F75)/Model!F52 | E28: =(Valuation!$B$91*(1+Model!E12+$A28)*(1+Model!F12+$A28)*(Model!F14+E$23)+Valuation!$B$92*(1+Model!E16+$A28)*(1+Model!F16+$A28)*(Model!F18+E$23)+Valuation!$B$93*(1+Model!E20+$A28)*(1+Model!F20+$A28)*(Model!F22+E$23)+Valuation!$B$94*(1+Model!E24+$A28)*(1+Model!F24+$A28)*(Model!F26+E$23)+Valuation!$B$95*(1+Model!E28+$A28)*(1+Model!F28+$A28)*(Model!F30+E$23)+Model!F33+Model!F45)*(1-Model!F75)/Model!F52 | F28: =(Valuation!$B$91*(1+Model!E12+$A28)*(1+Model!F12+$A28)*(Model!F14+F$23)+Valuation!$B$92*(1+Model!E16+$A28)*(1+Model!F16+$A28)*(Model!F18+F$23)+Valuation!$B$93*(1+Model!E20+$A28)*(1+Model!F20+$A28)*(Model!F22+F$23)+Valuation!$B$94*(1+Model!E24+$A28)*(1+Model!F24+$A28)*(Model!F26+F$23)+Valuation!$B$95*(1+Model!E28+$A28)*(1+Model!F28+$A28)*(Model!F30+F$23)+Model!F33+Model!F45)*(1-Model!F75)/Model!F52
A30: Net interest and the share count are held at the base case in table 3.

Sheet Distribution
A1: T: 12-month distribution (mix of lognormals around each scenario value)
A3: Scenario | B3: Probability | C3: Value at target date | D3: Story
A4: bear | B4: =Valuation!B86 | C4: ='Calc - bear'!$F$71 | D4: =Valuation!J86
A5: base | B5: =Valuation!B87 | C5: ='Calc - base'!$F$71 | D5: =Valuation!J87
A6: bull | B6: =Valuation!B88 | C6: ='Calc - bull'!$F$71 | D6: =Valuation!J88
A8: Probabilities sum to | B8: =SUM(B4:B6)
A9: Spread within each scenario | B9: =Valuation!$B$67
A10: Probability-weighted mean | B10: =($B$4*$C$4+$B$5*$C$5+$B$6*$C$6)*EXP($B$9^2/2)
A12: Quantile | B12: Price
A13: Median (model target) | B13: =SQRT(A60*B60)
A14: 10th percentile | B14: =SQRT(D60*E60)
A15: 25th percentile | B15: =SQRT(G60*H60)
A16: 75th percentile | B16: =SQRT(J60*K60)
A17: 90th percentile | B17: =SQRT(M60*N60)
A19: Each quantile solved by bisection (block: low, high, probability above the midpoint)
A20: Median (model target): low | B20: high | C20: P(above mid) | D20: 10th percentile: low | E20: high | F20: P(above mid) | G20: 25th percentile: low | H20: high | I20: P(above mid) | J20: 75th percentile: low | K20: high | L20: P(above mid) | M20: 90th percentile: low | N20: high | O20: P(above mid)
A21: =MIN($C$4,$C$5,$C$6)*0.2 | B21: =MAX($C$4,$C$5,$C$6)*4 | C21: =SUMPRODUCT($B$4:$B$6,1-NORMSDIST((LN(SQRT(A21*B21))-LN($C$4:$C$6))/$B$9)) | D21: =MIN($C$4,$C$5,$C$6)*0.2 | E21: =MAX($C$4,$C$5,$C$6)*4 | F21: =SUMPRODUCT($B$4:$B$6,1-NORMSDIST((LN(SQRT(D21*E21))-LN($C$4:$C$6))/$B$9)) | G21: =MIN($C$4,$C$5,$C$6)*0.2 | H21: =MAX($C$4,$C$5,$C$6)*4 | I21: =SUMPRODUCT($B$4:$B$6,1-NORMSDIST((LN(SQRT(G21*H21))-LN($C$4:$C$6))/$B$9)) | J21: =MIN($C$4,$C$5,$C$6)*0.2 | K21: =MAX($C$4,$C$5,$C$6)*4 | L21: =SUMPRODUCT($B$4:$B$6,1-NORMSDIST((LN(SQRT(J21*K21))-LN($C$4:$C$6))/$B$9)) | M21: =MIN($C$4,$C$5,$C$6)*0.2 | N21: =MAX($C$4,$C$5,$C$6)*4 | O21: =SUMPRODUCT($B$4:$B$6,1-NORMSDIST((LN(SQRT(M21*N21))-LN($C$4:$C$6))/$B$9))
A22: =IF(C21>0.5,SQRT(A21*B21),A21) | B22: =IF(C21>0.5,B21,SQRT(A21*B21)) | C22: =SUMPRODUCT($B$4:$B$6,1-NORMSDIST((LN(SQRT(A22*B22))-LN($C$4:$C$6))/$B$9)) | D22: =IF(F21>0.9,SQRT(D21*E21),D21) | E22: =IF(F21>0.9,E21,SQRT(D21*E21)) | F22: =SUMPRODUCT($B$4:$B$6,1-NORMSDIST((LN(SQRT(D22*E22))-LN($C$4:$C$6))/$B$9)) | G22: =IF(I21>0.75,SQRT(G21*H21),G21) | H22: =IF(I21>0.75,H21,SQRT(G21*H21)) | I22: =SUMPRODUCT($B$4:$B$6,1-NORMSDIST((LN(SQRT(G22*H22))-LN($C$4:$C$6))/$B$9)) | J22: =IF(L21>0.25,SQRT(J21*K21),J21) | K22: =IF(L21>0.25,K21,SQRT(J21*K21)) | L22: =SUMPRODUCT($B$4:$B$6,1-NORMSDIST((LN(SQRT(J22*K22))-LN($C$4:$C$6))/$B$9)) | M22: =IF(O21>0.09999999999999998,SQRT(M21*N21),M21) | N22: =IF(O21>0.09999999999999998,N21,SQRT(M21*N21)) | O22: =SUMPRODUCT($B$4:$B$6,1-NORMSDIST((LN(SQRT(M22*N22))-LN($C$4:$C$6))/$B$9))
A23: =IF(C22>0.5,SQRT(A22*B22),A22) | B23: =IF(C22>0.5,B22,SQRT(A22*B22)) | C23: =SUMPRODUCT($B$4:$B$6,1-NORMSDIST((LN(SQRT(A23*B23))-LN($C$4:$C$6))/$B$9)) | D23: =IF(F22>0.9,SQRT(D22*E22),D22) | E23: =IF(F22>0.9,E22,SQRT(D22*E22)) | F23: =SUMPRODUCT($B$4:$B$6,1-NORMSDIST((LN(SQRT(D23*E23))-LN($C$4:$C$6))/$B$9)) | G23: =IF(I22>0.75,SQRT(G22*H22),G22) | H23: =IF(I22>0.75,H22,SQRT(G22*H22)) | I23: =SUMPRODUCT($B$4:$B$6,1-NORMSDIST((LN(SQRT(G23*H23))-LN($C$4:$C$6))/$B$9)) | J23: =IF(L22>0.25,SQRT(J22*K22),J22) | K23: =IF(L22>0.25,K22,SQRT(J22*K22)) | L23: =SUMPRODUCT($B$4:$B$6,1-NORMSDIST((LN(SQRT(J23*K23))-LN($C$4:$C$6))/$B$9)) | M23: =IF(O22>0.09999999999999998,SQRT(M22*N22),M22) | N23: =IF(O22>0.09999999999999998,N22,SQRT(M22*N22)) | O23: =SUMPRODUCT($B$4:$B$6,1-NORMSDIST((LN(SQRT(M23*N23))-LN($C$4:$C$6))/$B$9))
A24: =IF(C23>0.5,SQRT(A23*B23),A23) | B24: =IF(C23>0.5,B23,SQRT(A23*B23)) | C24: =SUMPRODUCT($B$4:$B$6,1-NORMSDIST((LN(SQRT(A24*B24))-LN($C$4:$C$6))/$B$9)) | D24: =IF(F23>0.9,SQRT(D23*E23),D23) | E24: =IF(F23>0.9,E23,SQRT(D23*E23)) | F24: =SUMPRODUCT($B$4:$B$6,1-NORMSDIST((LN(SQRT(D24*E24))-LN($C$4:$C$6))/$B$9)) | G24: =IF(I23>0.75,SQRT(G23*H23),G23) | H24: =IF(I23>0.75,H23,SQRT(G23*H23)) | I24: =SUMPRODUCT($B$4:$B$6,1-NORMSDIST((LN(SQRT(G24*H24))-LN($C$4:$C$6))/$B$9)) | J24: =IF(L23>0.25,SQRT(J23*K23),J23) | K24: =IF(L23>0.25,K23,SQRT(J23*K23)) | L24: =SUMPRODUCT($B$4:$B$6,1-NORMSDIST((LN(SQRT(J24*K24))-LN($C$4:$C$6))/$B$9)) | M24: =IF(O23>0.09999999999999998,SQRT(M23*N23),M23) | N24: =IF(O23>0.09999999999999998,N23,SQRT(M23*N23)) | O24: =SUMPRODUCT($B$4:$B$6,1-NORMSDIST((LN(SQRT(M24*N24))-LN($C$4:$C$6))/$B$9))
A25: =IF(C24>0.5,SQRT(A24*B24),A24) | B25: =IF(C24>0.5,B24,SQRT(A24*B24)) | C25: =SUMPRODUCT($B$4:$B$6,1-NORMSDIST((LN(SQRT(A25*B25))-LN($C$4:$C$6))/$B$9)) | D25: =IF(F24>0.9,SQRT(D24*E24),D24) | E25: =IF(F24>0.9,E24,SQRT(D24*E24)) | F25: =SUMPRODUCT($B$4:$B$6,1-NORMSDIST((LN(SQRT(D25*E25))-LN($C$4:$C$6))/$B$9)) | G25: =IF(I24>0.75,SQRT(G24*H24),G24) | H25: =IF(I24>0.75,H24,SQRT(G24*H24)) | I25: =SUMPRODUCT($B$4:$B$6,1-NORMSDIST((LN(SQRT(G25*H25))-LN($C$4:$C$6))/$B$9)) | J25: =IF(L24>0.25,SQRT(J24*K24),J24) | K25: =IF(L24>0.25,K24,SQRT(J24*K24)) | L25: =SUMPRODUCT($B$4:$B$6,1-NORMSDIST((LN(SQRT(J25*K25))-LN($C$4:$C$6))/$B$9)) | M25: =IF(O24>0.09999999999999998,SQRT(M24*N24),M24) | N25: =IF(O24>0.09999999999999998,N24,SQRT(M24*N24)) | O25: =SUMPRODUCT($B$4:$B$6,1-NORMSDIST((LN(SQRT(M25*N25))-LN($C$4:$C$6))/$B$9))
A26: =IF(C25>0.5,SQRT(A25*B25),A25) | B26: =IF(C25>0.5,B25,SQRT(A25*B25)) | C26: =SUMPRODUCT($B$4:$B$6,1-NORMSDIST((LN(SQRT(A26*B26))-LN($C$4:$C$6))/$B$9)) | D26: =IF(F25>0.9,SQRT(D25*E25),D25) | E26: =IF(F25>0.9,E25,SQRT(D25*E25)) | F26: =SUMPRODUCT($B$4:$B$6,1-NORMSDIST((LN(SQRT(D26*E26))-LN($C$4:$C$6))/$B$9)) | G26: =IF(I25>0.75,SQRT(G25*H25),G25) | H26: =IF(I25>0.75,H25,SQRT(G25*H25)) | I26: =SUMPRODUCT($B$4:$B$6,1-NORMSDIST((LN(SQRT(G26*H26))-LN($C$4:$C$6))/$B$9)) | J26: =IF(L25>0.25,SQRT(J25*K25),J25) | K26: =IF(L25>0.25,K25,SQRT(J25*K25)) | L26: =SUMPRODUCT($B$4:$B$6,1-NORMSDIST((LN(SQRT(J26*K26))-LN($C$4:$C$6))/$B$9)) | M26: =IF(O25>0.09999999999999998,SQRT(M25*N25),M25) | N26: =IF(O25>0.09999999999999998,N25,SQRT(M25*N25)) | O26: =SUMPRODUCT($B$4:$B$6,1-NORMSDIST((LN(SQRT(M26*N26))-LN($C$4:$C$6))/$B$9))
A27: =IF(C26>0.5,SQRT(A26*B26),A26) | B27: =IF(C26>0.5,B26,SQRT(A26*B26)) | C27: =SUMPRODUCT($B$4:$B$6,1-NORMSDIST((LN(SQRT(A27*B27))-LN($C$4:$C$6))/$B$9)) | D27: =IF(F26>0.9,SQRT(D26*E26),D26) | E27: =IF(F26>0.9,E26,SQRT(D26*E26)) | F27: =SUMPRODUCT($B$4:$B$6,1-NORMSDIST((LN(SQRT(D27*E27))-LN($C$4:$C$6))/$B$9)) | G27: =IF(I26>0.75,SQRT(G26*H26),G26) | H27: =IF(I26>0.75,H26,SQRT(G26*H26)) | I27: =SUMPRODUCT($B$4:$B$6,1-NORMSDIST((LN(SQRT(G27*H27))-LN($C$4:$C$6))/$B$9)) | J27: =IF(L26>0.25,SQRT(J26*K26),J26) | K27: =IF(L26>0.25,K26,SQRT(J26*K26)) | L27: =SUMPRODUCT($B$4:$B$6,1-NORMSDIST((LN(SQRT(J27*K27))-LN($C$4:$C$6))/$B$9)) | M27: =IF(O26>0.09999999999999998,SQRT(M26*N26),M26) | N27: =IF(O26>0.09999999999999998,N26,SQRT(M26*N26)) | O27: =SUMPRODUCT($B$4:$B$6,1-NORMSDIST((LN(SQRT(M27*N27))-LN($C$4:$C$6))/$B$9))
A28: =IF(C27>0.5,SQRT(A27*B27),A27) | B28: =IF(C27>0.5,B27,SQRT(A27*B27)) | C28: =SUMPRODUCT($B$4:$B$6,1-NORMSDIST((LN(SQRT(A28*B28))-LN($C$4:$C$6))/$B$9)) | D28: =IF(F27>0.9,SQRT(D27*E27),D27) | E28: =IF(F27>0.9,E27,SQRT(D27*E27)) | F28: =SUMPRODUCT($B$4:$B$6,1-NORMSDIST((LN(SQRT(D28*E28))-LN($C$4:$C$6))/$B$9)) | G28: =IF(I27>0.75,SQRT(G27*H27),G27) | H28: =IF(I27>0.75,H27,SQRT(G27*H27)) | I28: =SUMPRODUCT($B$4:$B$6,1-NORMSDIST((LN(SQRT(G28*H28))-LN($C$4:$C$6))/$B$9)) | J28: =IF(L27>0.25,SQRT(J27*K27),J27) | K28: =IF(L27>0.25,K27,SQRT(J27*K27)) | L28: =SUMPRODUCT($B$4:$B$6,1-NORMSDIST((LN(SQRT(J28*K28))-LN($C$4:$C$6))/$B$9)) | M28: =IF(O27>0.09999999999999998,SQRT(M27*N27),M27) | N28: =IF(O27>0.09999999999999998,N27,SQRT(M27*N27)) | O28: =SUMPRODUCT($B$4:$B$6,1-NORMSDIST((LN(SQRT(M28*N28))-LN($C$4:$C$6))/$B$9))
A29: =IF(C28>0.5,SQRT(A28*B28),A28) | B29: =IF(C28>0.5,B28,SQRT(A28*B28)) | C29: =SUMPRODUCT($B$4:$B$6,1-NORMSDIST((LN(SQRT(A29*B29))-LN($C$4:$C$6))/$B$9)) | D29: =IF(F28>0.9,SQRT(D28*E28),D28) | E29: =IF(F28>0.9,E28,SQRT(D28*E28)) | F29: =SUMPRODUCT($B$4:$B$6,1-NORMSDIST((LN(SQRT(D29*E29))-LN($C$4:$C$6))/$B$9)) | G29: =IF(I28>0.75,SQRT(G28*H28),G28) | H29: =IF(I28>0.75,H28,SQRT(G28*H28)) | I29: =SUMPRODUCT($B$4:$B$6,1-NORMSDIST((LN(SQRT(G29*H29))-LN($C$4:$C$6))/$B$9)) | J29: =IF(L28>0.25,SQRT(J28*K28),J28) | K29: =IF(L28>0.25,K28,SQRT(J28*K28)) | L29: =SUMPRODUCT($B$4:$B$6,1-NORMSDIST((LN(SQRT(J29*K29))-LN($C$4:$C$6))/$B$9)) | M29: =IF(O28>0.09999999999999998,SQRT(M28*N28),M28) | N29: =IF(O28>0.09999999999999998,N28,SQRT(M28*N28)) | O29: =SUMPRODUCT($B$4:$B$6,1-NORMSDIST((LN(SQRT(M29*N29))-LN($C$4:$C$6))/$B$9))
