Workbook

Sheet Summary
A1: NFLX 12-month price target model
A2: Close 2026-10-30 · agents' research 2026-10-23 · horizon 2027-10-30. Blue = input you can change, black = formula, green = link to another sheet. Yellow = key assumption.
A4: Inputs | B4: Value | D4: Where it comes from
A5: Last close | B5: 62.08 | D5: Close on 2026-10-30
A6: Weight: options market | B6: 0.67 | D6: AIA Forecaster default (market 67%); flips to 33% when the option chain is thin
A7: Weight: agents | B7: 0.33 | D7: AIA Forecaster default (agents 33%)
A8: Weight: analyst consensus | B8: 0 | D8: Taken pro rata from the two above; 0 when there are no targets or in a special situation
A9: Analysts' median target | B9: 85 | D9: 42 analysts, https://stockanalysis.com/stocks/nflx/forecast/ as of 2026-10-30
A10: Use supervisor ladder (1 = yes) | B10: 0 | D10: Supervisor confidence: low; its ladder replaces the agents' mean only when high
A11: Platt log shift of the agents' curve | B11: 0 | D11: combine.py: P(close >= spot) 0.736 Platt-scaled (a = 1.732) to 0.736, then the whole agents' curve is shifted in log price by this amount
A12: Thesis-break price (supervisor) | B12: 48 | D12: Supervisor's reconciled thesis break (agents' values on the Reasoning sheet)
A13: 30-day implied vol | B13: 0.3414 | D13: Cboe model-free 30D IV as of 2026-10-30; sets the stop noise floor (2 one-month moves)
A15: Options-market median | B15: =EXP(INDEX(Distribution!$B$6:$B$20,MIN(MAX(IFERROR(MATCH(0.5,Distribution!$C$6:$C$20,-1),1),1),14))+(LN(MIN(MAX(0.5,0.0001),0.9999)/(1-MIN(MAX(0.5,0.0001),0.9999)))-INDEX(Distribution!$P$6:$P$20,MIN(MAX(IFERROR(MATCH(0.5,Distribution!$C$6:$C$20,-1),1),1),14)))/(INDEX(Distribution!$P$6:$P$20,MIN(MAX(IFERROR(MATCH(0.5,Distribution!$C$6:$C$20,-1),1),1),14)+1)-INDEX(Distribution!$P$6:$P$20,MIN(MAX(IFERROR(MATCH(0.5,Distribution!$C$6:$C$20,-1),1),1),14)))*(INDEX(Distribution!$B$6:$B$20,MIN(MAX(IFERROR(MATCH(0.5,Distribution!$C$6:$C$20,-1),1),1),14)+1)-INDEX(Distribution!$B$6:$B$20,MIN(MAX(IFERROR(MATCH(0.5,Distribution!$C$6:$C$20,-1),1),1),14)))) -> 64.281125 | D15: Median of the options-implied distribution (Distribution sheet); the analyst curve is this curve re-centred on the analysts' median
A17: Research target (12m) per share | B17: Method blend | C17: Stated | D17: Note
A18: Agent 1 | B18: =Methods!C8 -> 72.726 | C18: =Methods!E8 -> 72.73
A19: Agent 2 | B19: =Methods!C12 -> 73.04 | C19: =Methods!E12 -> 73.04
A20: Agent 3 | B20: =Methods!C16 -> 72.432 | C20: =Methods!E16 -> 72.43
A21: Agent 4 | B21: =Methods!C21 -> 74.25 | C21: =Methods!E21 -> 74.25
A22: Agent 5 | B22: =Methods!C25 -> 74.286 | C22: =Methods!E25 -> 74.28
A23: Agents' average | B23: =AVERAGE(B18:B22) -> 73.3468 | C23: =AVERAGE(C18:C22) -> 73.346
A24: Agents' median | B24: =MEDIAN(B18:B22) -> 73.04 | C24: =MEDIAN(C18:C22) -> 73.04
A25: Supervisor's reconciled research target (12m) | C25: 76.22 | D25: Model update 2026-10-23 (update): peer set refreshed per Kilian 2026-10-26 06:07Z (DIS, SONY, META, GOOGL, AMZN, SPOT on one EPS basis with NFLX; median 21.82x, NFLX 18.44x); the horizon P/E moves 18.0x -> 19.07x by the default exit rule (median x (own/median)^0.8, Kilian card 12:16Z), so the engine value moves $71.93 -> $76.22. No other input changed (the 10-Q filed 2026-10-21 repeats the Q3 letter's figures already in the set). The text from here on is the base round's. Engine base horizon value of model.reconciled_inputs ($72.74): four-region driver DCF $65.21 (w 0.2; WACC 9.4%, g 3%) and 18x NTM GAAP P/E on ~$4.15 model EPS $74.63 (w 0.8). Net debt at the horizon is $7.5B, shares fall 3% a year from 4,195M, less a -$0.8B probability-weighted M&A adjustment. The forecasters' mean fair value is $73.35 (after the gate's agent_1 capex correction). No agent has a share-count, EPS-base or SBC error (all cost SBC in GAAP EBIT). The change from round 1 ($73.11) is the Paramount-WBD margin trim (-$0.4) and the M&A probability 0.25 -> 0.2 (+$0.05).
A26: Research target (12m) vs last close | C26: =C25/Spot-1 -> 0.22777062
A28: Levels | B28: This model | C28: Published | D28: How
A29: NTM target (median) | B29: =EXP(INDEX(Distribution!$B$6:$B$20,MIN(MAX(IFERROR(MATCH(0.5,Distribution!$U$6:$U$20,-1),1),1),14))+(LN(MIN(MAX(0.5,0.0001),0.9999)/(1-MIN(MAX(0.5,0.0001),0.9999)))-INDEX(Distribution!$V$6:$V$20,MIN(MAX(IFERROR(MATCH(0.5,Distribution!$U$6:$U$20,-1),1),1),14)))/(INDEX(Distribution!$V$6:$V$20,MIN(MAX(IFERROR(MATCH(0.5,Distribution!$U$6:$U$20,-1),1),1),14)+1)-INDEX(Distribution!$V$6:$V$20,MIN(MAX(IFERROR(MATCH(0.5,Distribution!$U$6:$U$20,-1),1),1),14)))*(INDEX(Distribution!$B$6:$B$20,MIN(MAX(IFERROR(MATCH(0.5,Distribution!$U$6:$U$20,-1),1),1),14)+1)-INDEX(Distribution!$B$6:$B$20,MIN(MAX(IFERROR(MATCH(0.5,Distribution!$U$6:$U$20,-1),1),1),14)))) -> 65.801321 | C29: 67.3753 | D29: Price with a 50% chance of closing above it on the horizon date
A30: Take-profit (75th percentile) | B30: =EXP(INDEX(Distribution!$B$6:$B$20,MIN(MAX(IFERROR(MATCH(0.25,Distribution!$U$6:$U$20,-1),1),1),14))+(LN(MIN(MAX(0.25,0.0001),0.9999)/(1-MIN(MAX(0.25,0.0001),0.9999)))-INDEX(Distribution!$V$6:$V$20,MIN(MAX(IFERROR(MATCH(0.25,Distribution!$U$6:$U$20,-1),1),1),14)))/(INDEX(Distribution!$V$6:$V$20,MIN(MAX(IFERROR(MATCH(0.25,Distribution!$U$6:$U$20,-1),1),1),14)+1)-INDEX(Distribution!$V$6:$V$20,MIN(MAX(IFERROR(MATCH(0.25,Distribution!$U$6:$U$20,-1),1),1),14)))*(INDEX(Distribution!$B$6:$B$20,MIN(MAX(IFERROR(MATCH(0.25,Distribution!$U$6:$U$20,-1),1),1),14)+1)-INDEX(Distribution!$B$6:$B$20,MIN(MAX(IFERROR(MATCH(0.25,Distribution!$U$6:$U$20,-1),1),1),14)))) -> 84.391532 | C30: 67.22 | D30: 25% chance of closing above
A31: 15th percentile | B31: =EXP(INDEX(Distribution!$B$6:$B$20,MIN(MAX(IFERROR(MATCH(0.85,Distribution!$U$6:$U$20,-1),1),1),14))+(LN(MIN(MAX(0.85,0.0001),0.9999)/(1-MIN(MAX(0.85,0.0001),0.9999)))-INDEX(Distribution!$V$6:$V$20,MIN(MAX(IFERROR(MATCH(0.85,Distribution!$U$6:$U$20,-1),1),1),14)))/(INDEX(Distribution!$V$6:$V$20,MIN(MAX(IFERROR(MATCH(0.85,Distribution!$U$6:$U$20,-1),1),1),14)+1)-INDEX(Distribution!$V$6:$V$20,MIN(MAX(IFERROR(MATCH(0.85,Distribution!$U$6:$U$20,-1),1),1),14)))*(INDEX(Distribution!$B$6:$B$20,MIN(MAX(IFERROR(MATCH(0.85,Distribution!$U$6:$U$20,-1),1),1),14)+1)-INDEX(Distribution!$B$6:$B$20,MIN(MAX(IFERROR(MATCH(0.85,Distribution!$U$6:$U$20,-1),1),1),14)))) -> 44.096682 | C31: 45.4527 | D31: 85% chance of closing above
A32: Stop noise floor | B32: =Spot*EXP(-2*IV30*SQRT(21/252)) -> 50.974041 | D32: Two one-month implied moves below the last close; the stop is never tighter than this
A33: Stop-loss | B33: =MIN(IF(AND(Thesis_Break>0,Thesis_Break<Spot),MAX(B31,Thesis_Break),B31),B32) -> 48 | C33: 48 | D33: Higher of the 15th percentile and the thesis break, capped at the noise floor (published basis: thesis break)
A34: Target vs last close | B34: =B29/Spot-1 -> 0.059943966 | C34: =C29/Spot-1 -> 0.085298003
A35: P(close above last) | C35: 0.588
A36: Expected price (mean) | C36: 69.9101 | D36: Mean of the blended distribution (combine.py integrates the full curve); above the median when right-skewed
A38: Sheets
A39: Assumptions | D39: The supervisor's table of every driver: each agent's value, reasoning and linked sources
A40: Methods | D40: Each agent's valuation methods, values and weights
A41: Scenarios | D41: Downside (10th pct) / base / upside (90th pct) price per agent
A42: Distribution | D42: The probability ladder and the blend, as formulas
A43: Reasoning | D43: Each agent's written reasoning, thesis break and what changed from round 1
A44: Supervisor | D44: Disagreements, fact-checks and changes
A45: Sources | D45: Every cited source with its link

Sheet Assumptions
A1: NFLX key assumptions, aggregated by the supervisor
A2: Each driver of the valuation: the supervisor's reconciled value (grey rows), then what each agent assumed, why, and its sources. Blue values are the agents' own numbers; blank means the agent did not use that driver.
A4: ID | B4: Assumption / who | C4: Value | D4: Reasoning | E4: Source 1 | F4: Source 2 | G4: Source 3 | H4: All sources | I4: Agents low | J4: Agents high | K4: Used in
A5: The supervisor has not aggregated this round yet (model_assumptions.json); see Methods and Reasoning.

Sheet Distribution
A1: NFLX probability of closing at or above each price on 2027-10-30
A2: Each column is P(close >= K). Agents' curve is Platt-shifted, blended with the options market, then analysts at W_Analyst (0 since 2026-10-05). Interpolation is linear in logit(p) vs log(K), as in combine.py.
A5: Price K | B5: ln K | C5: Options market | D5: Agent 1 | E5: Agent 2 | F5: Agent 3 | G5: Agent 4 | H5: Agent 5 | I5: Agents' mean | J5: Supervisor | K5: Agents' curve used | L5: logit(used) | M5: K shifted | N5: seg | O5: Agents Platt-shifted | P5: logit(market) | Q5: K re-centred | R5: seg | S5: Analyst curve | T5: Blend ex analysts | U5: Final blend | V5: logit(final) | W5: Published (combine.py)
A6: 15.52 | B6: =LN(A6) -> 2.7421295 | C6: 0.9998 | D6: 0.9983 | E6: 0.9985 | F6: 0.9977 | G6: 0.9961 | H6: 0.9992 | I6: =AVERAGE(D6:H6) -> 0.99796 | J6: 0.9976 | K6: =IF(AND(Sup_Used=1,ISNUMBER(J6)),J6,I6) -> 0.99796 | L6: =LN(MIN(MAX(K6,0.0001),0.9999)/(1-MIN(MAX(K6,0.0001),0.9999))) -> 6.1927634 | M6: =A6*EXP(-Platt_Shift) -> 15.52 | N6: =MIN(MAX(IFERROR(MATCH(M6,Distribution!$A$6:$A$20,1),1),1),14) -> 1 | O6: =1/(1+EXP(-(INDEX(Distribution!$L$6:$L$20,N6)+(LN(M6)-INDEX(Distribution!$B$6:$B$20,N6))/(INDEX(Distribution!$B$6:$B$20,N6+1)-INDEX(Distribution!$B$6:$B$20,N6))*(INDEX(Distribution!$L$6:$L$20,N6+1)-INDEX(Distribution!$L$6:$L$20,N6))))) -> 0.99796 | P6: =LN(MIN(MAX(C6,0.0001),0.9999)/(1-MIN(MAX(C6,0.0001),0.9999))) -> 8.5169932 | Q6: =IF(Analyst_Median>0,A6*Market_Median/Analyst_Median,A6) -> 11.736977 | R6: =MIN(MAX(IFERROR(MATCH(Q6,Distribution!$A$6:$A$20,1),1),1),14) -> 1 | S6: =1/(1+EXP(-(INDEX(Distribution!$P$6:$P$20,R6)+(LN(Q6)-INDEX(Distribution!$B$6:$B$20,R6))/(INDEX(Distribution!$B$6:$B$20,R6+1)-INDEX(Distribution!$B$6:$B$20,R6))*(INDEX(Distribution!$P$6:$P$20,R6+1)-INDEX(Distribution!$P$6:$P$20,R6))))) -> 0.99997843 | T6: =W_Mkt*C6+W_Agents*O6 -> 0.9991928 | U6: =(1-W_Analyst)*T6+W_Analyst*S6 -> 0.9991928 | V6: =LN(MIN(MAX(U6,0.0001),0.9999)/(1-MIN(MAX(U6,0.0001),0.9999))) -> 7.1211316 | W6: 0.9998
A7: 24.83 | B7: =LN(A7) -> 3.2120526 | C7: 0.9916 | D7: 0.9965 | E7: 0.9944 | F7: 0.992 | G7: 0.9877 | H7: 0.9976 | I7: =AVERAGE(D7:H7) -> 0.99364 | J7: 0.9933 | K7: =IF(AND(Sup_Used=1,ISNUMBER(J7)),J7,I7) -> 0.99364 | L7: =LN(MIN(MAX(K7,0.0001),0.9999)/(1-MIN(MAX(K7,0.0001),0.9999))) -> 5.0513466 | M7: =A7*EXP(-Platt_Shift) -> 24.83 | N7: =MIN(MAX(IFERROR(MATCH(M7,Distribution!$A$6:$A$20,1),1),1),14) -> 2 | O7: =1/(1+EXP(-(INDEX(Distribution!$L$6:$L$20,N7)+(LN(M7)-INDEX(Distribution!$B$6:$B$20,N7))/(INDEX(Distribution!$B$6:$B$20,N7+1)-INDEX(Distribution!$B$6:$B$20,N7))*(INDEX(Distribution!$L$6:$L$20,N7+1)-INDEX(Distribution!$L$6:$L$20,N7))))) -> 0.99364 | P7: =LN(MIN(MAX(C7,0.0001),0.9999)/(1-MIN(MAX(C7,0.0001),0.9999))) -> 4.7710881 | Q7: =IF(Analyst_Median>0,A7*Market_Median/Analyst_Median,A7) -> 18.777651 | R7: =MIN(MAX(IFERROR(MATCH(Q7,Distribution!$A$6:$A$20,1),1),1),14) -> 1 | S7: =1/(1+EXP(-(INDEX(Distribution!$P$6:$P$20,R7)+(LN(Q7)-INDEX(Distribution!$B$6:$B$20,R7))/(INDEX(Distribution!$B$6:$B$20,R7+1)-INDEX(Distribution!$B$6:$B$20,R7))*(INDEX(Distribution!$P$6:$P$20,R7+1)-INDEX(Distribution!$P$6:$P$20,R7))))) -> 0.99908727 | T7: =W_Mkt*C7+W_Agents*O7 -> 0.9922732 | U7: =(1-W_Analyst)*T7+W_Analyst*S7 -> 0.9922732 | V7: =LN(MIN(MAX(U7,0.0001),0.9999)/(1-MIN(MAX(U7,0.0001),0.9999))) -> 4.8553037 | W7: 0.9938
A8: 31.04 | B8: =LN(A8) -> 3.4352767 | C8: 0.9665 | D8: 0.9881 | E8: 0.9848 | F8: 0.9805 | G8: 0.9736 | H8: 0.9911 | I8: =AVERAGE(D8:H8) -> 0.98362 | J8: 0.9833 | K8: =IF(AND(Sup_Used=1,ISNUMBER(J8)),J8,I8) -> 0.98362 | L8: =LN(MIN(MAX(K8,0.0001),0.9999)/(1-MIN(MAX(K8,0.0001),0.9999))) -> 4.0951786 | M8: =A8*EXP(-Platt_Shift) -> 31.04 | N8: =MIN(MAX(IFERROR(MATCH(M8,Distribution!$A$6:$A$20,1),1),1),14) -> 3 | O8: =1/(1+EXP(-(INDEX(Distribution!$L$6:$L$20,N8)+(LN(M8)-INDEX(Distribution!$B$6:$B$20,N8))/(INDEX(Distribution!$B$6:$B$20,N8+1)-INDEX(Distribution!$B$6:$B$20,N8))*(INDEX(Distribution!$L$6:$L$20,N8+1)-INDEX(Distribution!$L$6:$L$20,N8))))) -> 0.98362 | P8: =LN(MIN(MAX(C8,0.0001),0.9999)/(1-MIN(MAX(C8,0.0001),0.9999))) -> 3.3621359 | Q8: =IF(Analyst_Median>0,A8*Market_Median/Analyst_Median,A8) -> 23.473955 | R8: =MIN(MAX(IFERROR(MATCH(Q8,Distribution!$A$6:$A$20,1),1),1),14) -> 1 | S8: =1/(1+EXP(-(INDEX(Distribution!$P$6:$P$20,R8)+(LN(Q8)-INDEX(Distribution!$B$6:$B$20,R8))/(INDEX(Distribution!$B$6:$B$20,R8+1)-INDEX(Distribution!$B$6:$B$20,R8))*(INDEX(Distribution!$P$6:$P$20,R8+1)-INDEX(Distribution!$P$6:$P$20,R8))))) -> 0.99461515 | T8: =W_Mkt*C8+W_Agents*O8 -> 0.9721496 | U8: =(1-W_Analyst)*T8+W_Analyst*S8 -> 0.9721496 | V8: =LN(MIN(MAX(U8,0.0001),0.9999)/(1-MIN(MAX(U8,0.0001),0.9999))) -> 3.5526624 | W8: 0.9755
A9: 37.25 | B9: =LN(A9) -> 3.6176519 | C9: 0.915 | D9: 0.9593 | E9: 0.9556 | F9: 0.9498 | G9: 0.9435 | H9: 0.968 | I9: =AVERAGE(D9:H9) -> 0.95524 | J9: 0.955 | K9: =IF(AND(Sup_Used=1,ISNUMBER(J9)),J9,I9) -> 0.95524 | L9: =LN(MIN(MAX(K9,0.0001),0.9999)/(1-MIN(MAX(K9,0.0001),0.9999))) -> 3.0606477 | M9: =A9*EXP(-Platt_Shift) -> 37.25 | N9: =MIN(MAX(IFERROR(MATCH(M9,Distribution!$A$6:$A$20,1),1),1),14) -> 4 | O9: =1/(1+EXP(-(INDEX(Distribution!$L$6:$L$20,N9)+(LN(M9)-INDEX(Distribution!$B$6:$B$20,N9))/(INDEX(Distribution!$B$6:$B$20,N9+1)-INDEX(Distribution!$B$6:$B$20,N9))*(INDEX(Distribution!$L$6:$L$20,N9+1)-INDEX(Distribution!$L$6:$L$20,N9))))) -> 0.95524 | P9: =LN(MIN(MAX(C9,0.0001),0.9999)/(1-MIN(MAX(C9,0.0001),0.9999))) -> 2.3762728 | Q9: =IF(Analyst_Median>0,A9*Market_Median/Analyst_Median,A9) -> 28.170258 | R9: =MIN(MAX(IFERROR(MATCH(Q9,Distribution!$A$6:$A$20,1),1),1),14) -> 2 | S9: =1/(1+EXP(-(INDEX(Distribution!$P$6:$P$20,R9)+(LN(Q9)-INDEX(Distribution!$B$6:$B$20,R9))/(INDEX(Distribution!$B$6:$B$20,R9+1)-INDEX(Distribution!$B$6:$B$20,R9))*(INDEX(Distribution!$P$6:$P$20,R9+1)-INDEX(Distribution!$P$6:$P$20,R9))))) -> 0.98155684 | T9: =W_Mkt*C9+W_Agents*O9 -> 0.9282792 | U9: =(1-W_Analyst)*T9+W_Analyst*S9 -> 0.9282792 | V9: =LN(MIN(MAX(U9,0.0001),0.9999)/(1-MIN(MAX(U9,0.0001),0.9999))) -> 2.5605517 | W9: 0.9365
A10: 43.46 | B10: =LN(A10) -> 3.771841 | C10: 0.8376 | D10: 0.908 | E10: 0.8934 | F10: 0.8899 | G10: 0.8881 | H10: 0.9213 | I10: =AVERAGE(D10:H10) -> 0.90014 | J10: 0.8999 | K10: =IF(AND(Sup_Used=1,ISNUMBER(J10)),J10,I10) -> 0.90014 | L10: =LN(MIN(MAX(K10,0.0001),0.9999)/(1-MIN(MAX(K10,0.0001),0.9999))) -> 2.1987811 | M10: =A10*EXP(-Platt_Shift) -> 43.46 | N10: =MIN(MAX(IFERROR(MATCH(M10,Distribution!$A$6:$A$20,1),1),1),14) -> 5 | O10: =1/(1+EXP(-(INDEX(Distribution!$L$6:$L$20,N10)+(LN(M10)-INDEX(Distribution!$B$6:$B$20,N10))/(INDEX(Distribution!$B$6:$B$20,N10+1)-INDEX(Distribution!$B$6:$B$20,N10))*(INDEX(Distribution!$L$6:$L$20,N10+1)-INDEX(Distribution!$L$6:$L$20,N10))))) -> 0.90014 | P10: =LN(MIN(MAX(C10,0.0001),0.9999)/(1-MIN(MAX(C10,0.0001),0.9999))) -> 1.6404782 | Q10: =IF(Analyst_Median>0,A10*Market_Median/Analyst_Median,A10) -> 32.866561 | R10: =MIN(MAX(IFERROR(MATCH(Q10,Distribution!$A$6:$A$20,1),1),1),14) -> 3 | S10: =1/(1+EXP(-(INDEX(Distribution!$P$6:$P$20,R10)+(LN(Q10)-INDEX(Distribution!$B$6:$B$20,R10))/(INDEX(Distribution!$B$6:$B$20,R10+1)-INDEX(Distribution!$B$6:$B$20,R10))*(INDEX(Distribution!$P$6:$P$20,R10+1)-INDEX(Distribution!$P$6:$P$20,R10))))) -> 0.95491376 | T10: =W_Mkt*C10+W_Agents*O10 -> 0.8582382 | U10: =(1-W_Analyst)*T10+W_Analyst*S10 -> 0.8582382 | V10: =LN(MIN(MAX(U10,0.0001),0.9999)/(1-MIN(MAX(U10,0.0001),0.9999))) -> 1.8007335 | W10: 0.8743
A11: 49.66 | B11: =LN(A11) -> 3.9051998 | C11: 0.7418 | D11: 0.834 | E11: 0.8061 | F11: 0.8084 | G11: 0.801 | H11: 0.8491 | I11: =AVERAGE(D11:H11) -> 0.81972 | J11: 0.82 | K11: =IF(AND(Sup_Used=1,ISNUMBER(J11)),J11,I11) -> 0.81972 | L11: =LN(MIN(MAX(K11,0.0001),0.9999)/(1-MIN(MAX(K11,0.0001),0.9999))) -> 1.5144516 | M11: =A11*EXP(-Platt_Shift) -> 49.66 | N11: =MIN(MAX(IFERROR(MATCH(M11,Distribution!$A$6:$A$20,1),1),1),14) -> 6 | O11: =1/(1+EXP(-(INDEX(Distribution!$L$6:$L$20,N11)+(LN(M11)-INDEX(Distribution!$B$6:$B$20,N11))/(INDEX(Distribution!$B$6:$B$20,N11+1)-INDEX(Distribution!$B$6:$B$20,N11))*(INDEX(Distribution!$L$6:$L$20,N11+1)-INDEX(Distribution!$L$6:$L$20,N11))))) -> 0.81972 | P11: =LN(MIN(MAX(C11,0.0001),0.9999)/(1-MIN(MAX(C11,0.0001),0.9999))) -> 1.0553452 | Q11: =IF(Analyst_Median>0,A11*Market_Median/Analyst_Median,A11) -> 37.555302 | R11: =MIN(MAX(IFERROR(MATCH(Q11,Distribution!$A$6:$A$20,1),1),1),14) -> 4 | S11: =1/(1+EXP(-(INDEX(Distribution!$P$6:$P$20,R11)+(LN(Q11)-INDEX(Distribution!$B$6:$B$20,R11))/(INDEX(Distribution!$B$6:$B$20,R11+1)-INDEX(Distribution!$B$6:$B$20,R11))*(INDEX(Distribution!$P$6:$P$20,R11+1)-INDEX(Distribution!$P$6:$P$20,R11))))) -> 0.9119211 | T11: =W_Mkt*C11+W_Agents*O11 -> 0.7675136 | U11: =(1-W_Analyst)*T11+W_Analyst*S11 -> 0.7675136 | V11: =LN(MIN(MAX(U11,0.0001),0.9999)/(1-MIN(MAX(U11,0.0001),0.9999))) -> 1.1943245 | W11: 0.7909
A12: 55.87 | B12: =LN(A12) -> 4.0230276 | C12: 0.6378 | D12: 0.7367 | E12: 0.7055 | F12: 0.709 | G12: 0.701 | H12: 0.7561 | I12: =AVERAGE(D12:H12) -> 0.72166 | J12: 0.7217 | K12: =IF(AND(Sup_Used=1,ISNUMBER(J12)),J12,I12) -> 0.72166 | L12: =LN(MIN(MAX(K12,0.0001),0.9999)/(1-MIN(MAX(K12,0.0001),0.9999))) -> 0.95271073 | M12: =A12*EXP(-Platt_Shift) -> 55.87 | N12: =MIN(MAX(IFERROR(MATCH(M12,Distribution!$A$6:$A$20,1),1),1),14) -> 7 | O12: =1/(1+EXP(-(INDEX(Distribution!$L$6:$L$20,N12)+(LN(M12)-INDEX(Distribution!$B$6:$B$20,N12))/(INDEX(Distribution!$B$6:$B$20,N12+1)-INDEX(Distribution!$B$6:$B$20,N12))*(INDEX(Distribution!$L$6:$L$20,N12+1)-INDEX(Distribution!$L$6:$L$20,N12))))) -> 0.72166 | P12: =LN(MIN(MAX(C12,0.0001),0.9999)/(1-MIN(MAX(C12,0.0001),0.9999))) -> 0.56582821 | Q12: =IF(Analyst_Median>0,A12*Market_Median/Analyst_Median,A12) -> 42.251606 | R12: =MIN(MAX(IFERROR(MATCH(Q12,Distribution!$A$6:$A$20,1),1),1),14) -> 4 | S12: =1/(1+EXP(-(INDEX(Distribution!$P$6:$P$20,R12)+(LN(Q12)-INDEX(Distribution!$B$6:$B$20,R12))/(INDEX(Distribution!$B$6:$B$20,R12+1)-INDEX(Distribution!$B$6:$B$20,R12))*(INDEX(Distribution!$P$6:$P$20,R12+1)-INDEX(Distribution!$P$6:$P$20,R12))))) -> 0.85508368 | T12: =W_Mkt*C12+W_Agents*O12 -> 0.6654738 | U12: =(1-W_Analyst)*T12+W_Analyst*S12 -> 0.6654738 | V12: =LN(MIN(MAX(U12,0.0001),0.9999)/(1-MIN(MAX(U12,0.0001),0.9999))) -> 0.68778407 | W12: 0.6926
A13: 62.08 | B13: =LN(A13) -> 4.1284239 | C13: 0.5349 | D13: 0.6204 | E13: 0.5985 | F13: 0.6056 | G13: 0.5987 | H13: 0.6496 | I13: =AVERAGE(D13:H13) -> 0.61456 | J13: 0.6146 | K13: =IF(AND(Sup_Used=1,ISNUMBER(J13)),J13,I13) -> 0.61456 | L13: =LN(MIN(MAX(K13,0.0001),0.9999)/(1-MIN(MAX(K13,0.0001),0.9999))) -> 0.46652103 | M13: =A13*EXP(-Platt_Shift) -> 62.08 | N13: =MIN(MAX(IFERROR(MATCH(M13,Distribution!$A$6:$A$20,1),1),1),14) -> 8 | O13: =1/(1+EXP(-(INDEX(Distribution!$L$6:$L$20,N13)+(LN(M13)-INDEX(Distribution!$B$6:$B$20,N13))/(INDEX(Distribution!$B$6:$B$20,N13+1)-INDEX(Distribution!$B$6:$B$20,N13))*(INDEX(Distribution!$L$6:$L$20,N13+1)-INDEX(Distribution!$L$6:$L$20,N13))))) -> 0.61456 | P13: =LN(MIN(MAX(C13,0.0001),0.9999)/(1-MIN(MAX(C13,0.0001),0.9999))) -> 0.13982738 | Q13: =IF(Analyst_Median>0,A13*Market_Median/Analyst_Median,A13) -> 46.947909 | R13: =MIN(MAX(IFERROR(MATCH(Q13,Distribution!$A$6:$A$20,1),1),1),14) -> 5 | S13: =1/(1+EXP(-(INDEX(Distribution!$P$6:$P$20,R13)+(LN(Q13)-INDEX(Distribution!$B$6:$B$20,R13))/(INDEX(Distribution!$B$6:$B$20,R13+1)-INDEX(Distribution!$B$6:$B$20,R13))*(INDEX(Distribution!$P$6:$P$20,R13+1)-INDEX(Distribution!$P$6:$P$20,R13))))) -> 0.78613121 | T13: =W_Mkt*C13+W_Agents*O13 -> 0.5611878 | U13: =(1-W_Analyst)*T13+W_Analyst*S13 -> 0.5611878 | V13: =LN(MIN(MAX(U13,0.0001),0.9999)/(1-MIN(MAX(U13,0.0001),0.9999))) -> 0.24598408 | W13: 0.588
A14: 68.29 | B14: =LN(A14) -> 4.2237633 | C14: 0.4396 | D14: 0.4967 | E14: 0.4872 | F14: 0.4997 | G14: 0.4963 | H14: 0.5403 | I14: =AVERAGE(D14:H14) -> 0.50404 | J14: 0.5042 | K14: =IF(AND(Sup_Used=1,ISNUMBER(J14)),J14,I14) -> 0.50404 | L14: =LN(MIN(MAX(K14,0.0001),0.9999)/(1-MIN(MAX(K14,0.0001),0.9999))) -> 0.016160352 | M14: =A14*EXP(-Platt_Shift) -> 68.29 | N14: =MIN(MAX(IFERROR(MATCH(M14,Distribution!$A$6:$A$20,1),1),1),14) -> 9 | O14: =1/(1+EXP(-(INDEX(Distribution!$L$6:$L$20,N14)+(LN(M14)-INDEX(Distribution!$B$6:$B$20,N14))/(INDEX(Distribution!$B$6:$B$20,N14+1)-INDEX(Distribution!$B$6:$B$20,N14))*(INDEX(Distribution!$L$6:$L$20,N14+1)-INDEX(Distribution!$L$6:$L$20,N14))))) -> 0.50404 | P14: =LN(MIN(MAX(C14,0.0001),0.9999)/(1-MIN(MAX(C14,0.0001),0.9999))) -> -0.24278559 | Q14: =IF(Analyst_Median>0,A14*Market_Median/Analyst_Median,A14) -> 51.644212 | R14: =MIN(MAX(IFERROR(MATCH(Q14,Distribution!$A$6:$A$20,1),1),1),14) -> 6 | S14: =1/(1+EXP(-(INDEX(Distribution!$P$6:$P$20,R14)+(LN(Q14)-INDEX(Distribution!$B$6:$B$20,R14))/(INDEX(Distribution!$B$6:$B$20,R14+1)-INDEX(Distribution!$B$6:$B$20,R14))*(INDEX(Distribution!$P$6:$P$20,R14+1)-INDEX(Distribution!$P$6:$P$20,R14))))) -> 0.70942194 | T14: =W_Mkt*C14+W_Agents*O14 -> 0.4608652 | U14: =(1-W_Analyst)*T14+W_Analyst*S14 -> 0.4608652 | V14: =LN(MIN(MAX(U14,0.0001),0.9999)/(1-MIN(MAX(U14,0.0001),0.9999))) -> -0.15686004 | W14: 0.4854
A15: 74.5 | B15: =LN(A15) -> 4.3107991 | C15: 0.3554 | D15: 0.3796 | E15: 0.3829 | F15: 0.3993 | G15: 0.393 | H15: 0.4364 | I15: =AVERAGE(D15:H15) -> 0.39824 | J15: 0.3985 | K15: =IF(AND(Sup_Used=1,ISNUMBER(J15)),J15,I15) -> 0.39824 | L15: =LN(MIN(MAX(K15,0.0001),0.9999)/(1-MIN(MAX(K15,0.0001),0.9999))) -> -0.41280386 | M15: =A15*EXP(-Platt_Shift) -> 74.5 | N15: =MIN(MAX(IFERROR(MATCH(M15,Distribution!$A$6:$A$20,1),1),1),14) -> 10 | O15: =1/(1+EXP(-(INDEX(Distribution!$L$6:$L$20,N15)+(LN(M15)-INDEX(Distribution!$B$6:$B$20,N15))/(INDEX(Distribution!$B$6:$B$20,N15+1)-INDEX(Distribution!$B$6:$B$20,N15))*(INDEX(Distribution!$L$6:$L$20,N15+1)-INDEX(Distribution!$L$6:$L$20,N15))))) -> 0.39824 | P15: =LN(MIN(MAX(C15,0.0001),0.9999)/(1-MIN(MAX(C15,0.0001),0.9999))) -> -0.59538605 | Q15: =IF(Analyst_Median>0,A15*Market_Median/Analyst_Median,A15) -> 56.340516 | R15: =MIN(MAX(IFERROR(MATCH(Q15,Distribution!$A$6:$A$20,1),1),1),14) -> 7 | S15: =1/(1+EXP(-(INDEX(Distribution!$P$6:$P$20,R15)+(LN(Q15)-INDEX(Distribution!$B$6:$B$20,R15))/(INDEX(Distribution!$B$6:$B$20,R15+1)-INDEX(Distribution!$B$6:$B$20,R15))*(INDEX(Distribution!$P$6:$P$20,R15+1)-INDEX(Distribution!$P$6:$P$20,R15))))) -> 0.62993348 | T15: =W_Mkt*C15+W_Agents*O15 -> 0.3695372 | U15: =(1-W_Analyst)*T15+W_Analyst*S15 -> 0.3695372 | V15: =LN(MIN(MAX(U15,0.0001),0.9999)/(1-MIN(MAX(U15,0.0001),0.9999))) -> -0.53420274 | W15: 0.3868
A16: 83.81 | B16: =LN(A16) -> 4.4285523 | C16: 0.2523 | D16: 0.236 | E16: 0.2519 | F16: 0.2703 | G16: 0.2609 | H16: 0.3016 | I16: =AVERAGE(D16:H16) -> 0.26414 | J16: 0.264 | K16: =IF(AND(Sup_Used=1,ISNUMBER(J16)),J16,I16) -> 0.26414 | L16: =LN(MIN(MAX(K16,0.0001),0.9999)/(1-MIN(MAX(K16,0.0001),0.9999))) -> -1.0245606 | M16: =A16*EXP(-Platt_Shift) -> 83.81 | N16: =MIN(MAX(IFERROR(MATCH(M16,Distribution!$A$6:$A$20,1),1),1),14) -> 11 | O16: =1/(1+EXP(-(INDEX(Distribution!$L$6:$L$20,N16)+(LN(M16)-INDEX(Distribution!$B$6:$B$20,N16))/(INDEX(Distribution!$B$6:$B$20,N16+1)-INDEX(Distribution!$B$6:$B$20,N16))*(INDEX(Distribution!$L$6:$L$20,N16+1)-INDEX(Distribution!$L$6:$L$20,N16))))) -> 0.26414 | P16: =LN(MIN(MAX(C16,0.0001),0.9999)/(1-MIN(MAX(C16,0.0001),0.9999))) -> -1.086383 | Q16: =IF(Analyst_Median>0,A16*Market_Median/Analyst_Median,A16) -> 63.38119 | R16: =MIN(MAX(IFERROR(MATCH(Q16,Distribution!$A$6:$A$20,1),1),1),14) -> 8 | S16: =1/(1+EXP(-(INDEX(Distribution!$P$6:$P$20,R16)+(LN(Q16)-INDEX(Distribution!$B$6:$B$20,R16))/(INDEX(Distribution!$B$6:$B$20,R16+1)-INDEX(Distribution!$B$6:$B$20,R16))*(INDEX(Distribution!$P$6:$P$20,R16+1)-INDEX(Distribution!$P$6:$P$20,R16))))) -> 0.51414155 | T16: =W_Mkt*C16+W_Agents*O16 -> 0.2562072 | U16: =(1-W_Analyst)*T16+W_Analyst*S16 -> 0.2562072 | V16: =LN(MIN(MAX(U16,0.0001),0.9999)/(1-MIN(MAX(U16,0.0001),0.9999))) -> -1.065776 | W16: 0.2385
A17: 93.12 | B17: =LN(A17) -> 4.533889 | C17: 0.1756 | D17: 0.1389 | E17: 0.1589 | F17: 0.1739 | G17: 0.1639 | H17: 0.1998 | I17: =AVERAGE(D17:H17) -> 0.16708 | J17: 0.1669 | K17: =IF(AND(Sup_Used=1,ISNUMBER(J17)),J17,I17) -> 0.16708 | L17: =LN(MIN(MAX(K17,0.0001),0.9999)/(1-MIN(MAX(K17,0.0001),0.9999))) -> -1.6064649 | M17: =A17*EXP(-Platt_Shift) -> 93.12 | N17: =MIN(MAX(IFERROR(MATCH(M17,Distribution!$A$6:$A$20,1),1),1),14) -> 12 | O17: =1/(1+EXP(-(INDEX(Distribution!$L$6:$L$20,N17)+(LN(M17)-INDEX(Distribution!$B$6:$B$20,N17))/(INDEX(Distribution!$B$6:$B$20,N17+1)-INDEX(Distribution!$B$6:$B$20,N17))*(INDEX(Distribution!$L$6:$L$20,N17+1)-INDEX(Distribution!$L$6:$L$20,N17))))) -> 0.16708 | P17: =LN(MIN(MAX(C17,0.0001),0.9999)/(1-MIN(MAX(C17,0.0001),0.9999))) -> -1.5464472 | Q17: =IF(Analyst_Median>0,A17*Market_Median/Analyst_Median,A17) -> 70.421864 | R17: =MIN(MAX(IFERROR(MATCH(Q17,Distribution!$A$6:$A$20,1),1),1),14) -> 9 | S17: =1/(1+EXP(-(INDEX(Distribution!$P$6:$P$20,R17)+(LN(Q17)-INDEX(Distribution!$B$6:$B$20,R17))/(INDEX(Distribution!$B$6:$B$20,R17+1)-INDEX(Distribution!$B$6:$B$20,R17))*(INDEX(Distribution!$P$6:$P$20,R17+1)-INDEX(Distribution!$P$6:$P$20,R17))))) -> 0.40918837 | T17: =W_Mkt*C17+W_Agents*O17 -> 0.1727884 | U17: =(1-W_Analyst)*T17+W_Analyst*S17 -> 0.1727884 | V17: =LN(MIN(MAX(U17,0.0001),0.9999)/(1-MIN(MAX(U17,0.0001),0.9999))) -> -1.5659928 | W17: 0.1424
... A20: 155.2 | B20: =LN(A20) -> 5.0447146 | C20: 0.0133 | D20: 0.0024 | E20: 0.0041 | F20: 0.005 | G20: 0.006 | H20: 0.0071 | I20: =AVERAGE(D20:H20) -> 0.00492 | J20: 0.0047 | K20: =IF(AND(Sup_Used=1,ISNUMBER(J20)),J20,I20) -> 0.00492 | L20: =LN(MIN(MAX(K20,0.0001),0.9999)/(1-MIN(MAX(K20,0.0001),0.9999))) -> -5.3095146 | M20: =A20*EXP(-Platt_Shift) -> 155.2 | N20: =MIN(MAX(IFERROR(MATCH(M20,Distribution!$A$6:$A$20,1),1),1),14) -> 14 | O20: =1/(1+EXP(-(INDEX(Distribution!$L$6:$L$20,N20)+(LN(M20)-INDEX(Distribution!$B$6:$B$20,N20))/(INDEX(Distribution!$B$6:$B$20,N20+1)-INDEX(Distribution!$B$6:$B$20,N20))*(INDEX(Distribution!$L$6:$L$20,N20+1)-INDEX(Distribution!$L$6:$L$20,N20))))) -> 0.00492 | P20: =LN(MIN(MAX(C20,0.0001),0.9999)/(1-MIN(MAX(C20,0.0001),0.9999))) -> -4.306602 | Q20: =IF(Analyst_Median>0,A20*Market_Median/Analyst_Median,A20) -> 117.36977 | R20: =MIN(MAX(IFERROR(MATCH(Q20,Distribution!$A$6:$A$20,1),1),1),14) -> 13 | S20: =1/(1+EXP(-(INDEX(Distribution!$P$6:$P$20,R20)+(LN(Q20)-INDEX(Distribution!$B$6:$B$20,R20))/(INDEX(Distribution!$B$6:$B$20,R20+1)-INDEX(Distribution!$B$6:$B$20,R20))*(INDEX(Distribution!$P$6:$P$20,R20+1)-INDEX(Distribution!$P$6:$P$20,R20))))) -> 0.064458518 | T20: =W_Mkt*C20+W_Agents*O20 -> 0.0105346 | U20: =(1-W_Analyst)*T20+W_Analyst*S20 -> 0.0105346 | V20: =LN(MIN(MAX(U20,0.0001),0.9999)/(1-MIN(MAX(U20,0.0001),0.9999))) -> -4.5424997 | W20: 0.0083
A22: Agents' curves are their final-round answers (Reasoning sheet shows round 1). Market and published columns come from combine.py; the model reproduces the final blend within rounding (combine.py also enforces a non-increasing curve).

Sheet Methods
A1: NFLX valuation methods by agent
A2: Each agent's methods, the value per share and the weight it gave each. Blended value = weight-averaged methods; stated value = what the agent reported (it may round or add a deduction).
A4: Agent | B4: Method | C4: Value / share | D4: Weight | E4: Value x weight | F4: Calculation (assumption IDs on the Assumptions sheet) | G4: Inputs and reasoning
A5: Agent 1 | B5: P/E | C5: 75.49 | D5: 0.55 | E5: =C5*D5 -> 41.5195 | G5: NTM GAAP EPS at horizon ~$4.19 (model; consensus FY27 $3.80 / FY28 $4.52) x 18x (single-basis peer median 20.4x, gate-corrected from a mixed-basis 22.4x; NFLX today 18.2x NTM)
A6: Agent 1 | B6: DCF | C6: 67.82 | D6: 0.2 | E6: =C6*D6 -> 13.564 | G6: WACC 9.3%, terminal g 3%, FY30 revenue $70.7B, margin 36.0%, capex+content gap 3.8%, tax 15.5%; TV 84% of DCF
A7: Agent 1 | B7: EV/EBITDA | C7: 70.57 | D7: 0.25 | E7: =C7*D7 -> 17.6425 | G7: NTM GAAP EBITDA at horizon x 14x, less net debt $7.6B, / horizon shares (-3%/yr from 4,195M)
A8: Agent 1 | B8: Blended value | C8: =IF(SUM(D5:D7)>0,SUMPRODUCT(C5:C7,D5:D7)/SUM(D5:D7),"") -> 72.726 | D8: =SUM(D5:D7) -> 1 | E8: 72.73 | F8: Stated research target (12m) | G8: Engine-valued driver set: four-region revenue build ($56.3B FY27, +10.2%) with GAAP margin 31.5% -> 36.0% by FY30; blend of P/E 18x NTM model EPS (~$4.19) $75.49 (w0.55), driver DCF at 9.3% WACC / 3% g $67.82 (w0.20), EV/EBITDA 14x $70.57 (w0.25) = $72.73 at the 2027-10-20 horizon, after a -$1.0B expected M&A adjustment.
A10: Agent 2 | B10: P/E | C10: 75.19 | D10: 0.8 | E10: =C10*D10 -> 60.152 | G10: 18.0x x engine NTM EPS at horizon ~$4.19 (FY27 $3.77, FY28 ~$4.40: revenue $56.2B/$61.1B, EBIT margin 33.0%/34.2%, tax 15.5%, shares -3.5% a year). Reconciled 8-peer median NTM P/E 22.45x, range 11.1-35.4x.
A11: Agent 2 | B11: DCF | C11: 64.44 | D11: 0.2 | E11: =C11*D11 -> 12.888 | G11: Regional segment build FY26-30 (revenue $51.1B -> $69.3B), EBIT margin 31.5% -> 36%, tax 15.5%, capex 1.6%, D&A 0.8%, content cash gap 35% of incremental revenue, WACC 9.6% (beta 1.05), Gordon g 3.0%, net debt $7.1B, 4,050M shares at the horizon.
A12: Agent 2 | B12: Blended value | C12: =IF(SUM(D10:D11)>0,SUMPRODUCT(C10:C11,D10:D11)/SUM(D10:D11),"") -> 73.04 | D12: =SUM(D10:D11) -> 1 | E12: 73.04 | F12: Stated research target (12m) | G12: Engine blend of a GAAP P/E leg (18x engine NTM EPS at the horizon of ~$4.19 = $75.19, weight 0.8) and a regional driver DCF to FY2030 (WACC 9.6%, g 3%: $64.44, weight 0.2 per the 17.1x forward-P/E band), less a $0.20 M&A adjustment = $73.04 per share at 2027-10-20.
A14: Agent 3 | B14: P/E | C14: 74.76 | D14: 0.8 | E14: =C14*D14 -> 59.808 | G14: Horizon NTM GAAP EPS ~$4.15 (model; consensus ~$4.30) x 18.0x (NFLX now 18.2x NTM; core 8-peer median 22.4x, range 11.1x-35.4x)
A15: Agent 3 | B15: DCF | C15: 63.12 | D15: 0.2 | E15: =C15*D15 -> 12.624 | G15: Regional revenue build 2026-2030 (+13.1%, +10.0%, ~+8.6%, ~+7.7%, ~+6.7%), EBIT margin 31.5%->35%, tax 15%, capex+content gap 5.5%->4.0%, WACC 9.5%, terminal g 3%, TV 83% of EV
A16: Agent 3 | B16: Blended value | C16: =IF(SUM(D14:D15)>0,SUMPRODUCT(C14:C15,D14:D15)/SUM(D14:D15),"") -> 72.432 | D16: =SUM(D14:D15) -> 1 | E16: 72.43 | F16: Stated research target (12m) | G16: Engine set: 0.8 x P/E 18.0x on horizon NTM GAAP EPS ~$4.15 ($74.76) + 0.2 x driver DCF ($63.12; regional build to ~$70B revenue and 35% margin in 2030, WACC 9.5%, g 3%), less a probability-weighted acquisition-overpayment adjustment (-$2.25B); 4,062M horizon shares.
A18: Agent 4 | B18: DCF | C18: 69.71 | D18: 0.2 | E18: =C18*D18 -> 13.942 | G18: Segment build: UCAN subscription $18.96B (+10%,+7%,+5.5%,+5%,+4%), international subscription $24.72B (+11.4%,+10%,+9%,+8%,+7%), advertising $1.5B (+80%,+44%,+30%,+22%,+15%) => revenue $51.1B FY2026, $56.5B FY2027 (+10.6%), ~$70.8B FY2030; GAAP EBIT margin 31.5/33.3/34.5/35.5/36.0%; tax 15.5%; content cash gap 30% of incremental revenue; capex 2.7% then 1.8%; WACC 9.2% (rf 5.12%, beta 1.03, ERP 4.20%); Gordon g 3.0%; net debt $7.1B now, $7.5B at horizon; shares 4,195M -3%/yr; M&A adjustment -$0.8B.
A19: Agent 4 | B19: P/E | C19: 75.98 | D19: 0.7 | E19: =C19*D19 -> 53.186 | G19: 18.0x x model NTM GAAP EPS at the horizon (~$4.3: FY2027 ~$3.79 vs $3.80 consensus, FY2028 ~$4.42 vs $4.52); peer NTM P/E median 22.2x (11 names; core ex-outliers 20.4x); NFLX at 17.1x FY2027 consensus today.
A20: Agent 4 | B20: EV/EBITDA | C20: 71.22 | D20: 0.1 | E20: =C20*D20 -> 7.122 | G20: 14.0x x model NTM EBITDA (GAAP EBIT + D&A, ~$21B) less $7.5B horizon net debt; peer TTM median 13.9x. Cross-check weight only.
A21: Agent 4 | B21: Blended value | C21: =IF(SUM(D18:D20)>0,SUMPRODUCT(C18:C20,D18:D20)/SUM(D18:D20),"") -> 74.25 | D21: =SUM(D18:D20) -> 1 | E21: 74.25 | F21: Stated research target (12m) | G21: Engine blend at the 2027-10-20 horizon: segment-driven DCF $69.71 (w 0.20; WACC 9.2% on a 5.12% risk-free, g 3%, GAAP EBIT margin 31.5% to 36.0%, tax 15.5%), 18.0x NTM GAAP P/E $75.98 (w 0.70) and 14.0x NTM EV/EBITDA $71.22 (w 0.10), less a $0.8B probability-weighted M&A adjustment = $74.25, +14.5% vs the $64.85 after-hours price.
A23: Agent 5 | B23: DCF | C23: 67.07 | D23: 0.2 | E23: =C23*D23 -> 13.414 | G23: Regional segment build FY2026-30 (revenue $51.1B -> ~$72.7B), EBIT margin 31.5% -> 36.5%, tax 15.5-16%, capex incl. content cash excess 6.0% -> 4.4%, WACC 9.4%, Gordon g 3.0%, net debt at horizon $7.5B, shares -3.25%/yr, M&A adjustment -$0.8B
A24: Agent 5 | B24: P/E | C24: 76.09 | D24: 0.8 | E24: =C24*D24 -> 60.872 | G24: 18.0x x NTM GAAP EPS at 2027-10-20 of ~$4.23 per model share count (model: FY2027 ~$3.75, FY2028 ~$4.40); peer median 22.45x (10 peers); current 17.1x on FY2027 consensus $3.80
A25: Agent 5 | B25: Blended value | C25: =IF(SUM(D23:D24)>0,SUMPRODUCT(C23:C24,D23:D24)/SUM(D23:D24),"") -> 74.286 | D25: =SUM(D23:D24) -> 1 | E25: 74.28 | F25: Stated research target (12m) | G25: Engine blend: driver DCF $67.07 (weight 0.2; regional members x ARM build, 31.5%->36.5% EBIT margin, WACC 9.4%, g 3.0%) and 18x NTM GAAP P/E on model EPS at the horizon = $76.09 (weight 0.8), with a -$0.8B probability-weighted M&A adjustment -> $74.28.

Sheet Scenarios
A1: NFLX cases by agent
A2: Base case = median; downside = 10th percentile, upside = 90th percentile (no probabilities; older rounds' bear/bull shown as downside/upside).
A4: Agent | B4: Downside (P10) | C4: Base (median) | D4: Upside (P90) | E4: Downside story | F4: Base story | G4: Upside story
A5: Agent 1 | B5: 48.22 | C5: 72.73 | D5: 92.54 | E5: Engagement share keeps sliding to YouTube/creator and AI-generated video while a closed Paramount-WBD (HBO Max + Paramount+ under one owner) bids up content and pulls licensed titles; price increases meet churn, revenue growth ~7% in FY27 and ~4-5% after; margin stalls ~32-33% as live-sports costs rise; P/E de-rates to 14x (below DIS). | F5: Revenue +10.3% in FY27 (management: 'sustain double-digit revenue growth') fading to ~7% by FY30 on pricing, ads (15 new ad countries from March 2027) and emerging-market members; margin +1-2pt a year to 36% by FY30 as content spend grows slower than revenue; 18x NTM P/E, NFLX's own post-print multiple. | G5: Ads re-accelerate after the ad-tech rollout and 15-country launch (ad growth stays near the 80%+ of 2026), churn keeps improving, the January FY2027 guide shows margin above 34%; re-rates to ~21x, near the 22.4x peer median.
A6: Agent 2 | B6: 49.89 | C6: 73.04 | D6: 95.37 | E6: YouTube and short-form keep taking TV time (Netflix US share toward 7%), the 2026 price rises start to show in churn, CTV CPMs keep falling as Amazon, YouTube and a Fox-Roku combination add inventory, and the now-closed Paramount-WBD (HBO Max + Paramount+) bids up content and sports: revenue growth ~7%, margin stuck near 31-32%, P/E 14x. | F6: Growth decelerates to ~10% in 2027 (CFO: 'sustain double-digit revenue growth'; I sit at the low end, ~1.3% below consensus revenue) as engagement softness offsets pricing and ads (~$3.8B in 2027); margin +1.5pt in 2027 then ~1pt a year to 36% in 2030; the market keeps a derated 18x NTM P/E. | G6: The 15-country ad expansion and live events lift ad revenue toward ~$4.5B in 2027 and the Omdia ~$8B path by 2030 (WARC: ~9.2% of global CTV ad spend in 2027); pricing sticks with churn improving; margins reach ~35% in 2028; multiple re-rates to ~22x, the peer median.
A7: Agent 3 | B7: 48.69 | C7: 72.43 | D7: 94.34 | E7: Engagement keeps sliding (US TV share below 7.5%, and fewer disclosed engagement data to disprove it), 2027 ads miss again (~$3.2B), price increases meet churn, and a closed Paramount-WBD (Paramount+ + HBO Max) bids up content and sports rights: revenue growth ~3pts lower every year, margin ~2.5pts lower, P/E de-rates to ~14x (DIS/WMG level), WACC +0.5pt. | F7: Revenue growth decelerates from 13% (2026) to ~10% (2027, the bottom of management's 'sustain double-digit' objective) and ~7% by 2030; ads ~$2.7B -> ~$3.7B in 2027; margin +1.5pts in 2027 then +0.5pt/yr to 35% (sports/content inflation absorbs leverage); buybacks cut the share count ~3%/yr; the stock holds today's ~18x NTM GAAP EPS. | G7: Ads-led: the 15-country ad-tier expansion from March 2027 and ad-tech fixes put ads on WARC's path (Netflix ~9.2% of CTV ad spend in 2027, ~$4.5B) and toward Omdia's $8B by 2030; high-margin ad revenue adds ~2.5pts of growth and ~2pts of margin, engagement stabilises on the slate, P/E re-rates to ~21x (still below the 22.4x peer median).
A8: Agent 4 | B8: 50.29 | C8: 74.25 | D8: 93.49 | E8: Engagement keeps sliding to YouTube/creator video (Nielsen share 8.3% to 7.9% in a year) and the newly closed Paramount-WBD combination (HBO Max + Paramount+, ~200M subs) bids up content and pulls licensed titles; price rises meet churn, subscription growth falls toward 5%, ads stall near $3.3B in 2027, margin stalls ~33%, and the market pays ~14x P/E. Engine: growth -3pt, margin -2.5pt, multiple -4 turns, WACC +0.5pt. | F8: Revenue +10.6% in 2027 (ads ~$3.9B with 15 new ad markets), margin +1.8pt as acquisition and layoff costs lap, EPS ~$3.8 in line with consensus; the engagement debate stays open, so the stock holds ~18x NTM P/E. | G8: Live sports (NFL, Women's World Cup), ad-tech catch-up and pricing reaccelerate growth; the first annual engagement report shows per-member hours stabilising and Gauge share turning up; rerates to ~21x. Engine: growth +2pt, margin +1.5pt, multiple +3 turns.
A9: Agent 5 | B9: 50.37 | C9: 74.28 | D9: 98.6 | E9: Engagement share keeps slipping to YouTube/AI video, the ad ramp disappoints again, price rises meet churn: growth ~7-8%, margins stall near 32%, P/E 14x on lower EPS, rates stay high. | F9: Growth fades 13% -> ~10.7% in 2027 with ads ~$4B, margin +1.5pts a year, buybacks shrink the count ~3.25% a year; P/E holds ~18x. | G9: Ad tier in 15 new countries and programmatic scale lift ads toward $5B, growth holds ~12-13%, margin 34.5%+; multiple re-rates toward the 22x peer median.
A10: Average | B10: =AVERAGE(B5:B9) -> 49.492 | C10: =AVERAGE(C5:C9) -> 73.346 | D10: =AVERAGE(D5:D9) -> 94.868

Sheet Reasoning
A1: NFLX each agent's reasoning
A2: Final round, with round 1 for comparison. Revisions list what each agent changed after the supervisor's feedback.
A4: Agent | B4: Research target (12m) r1 | C4: Research target (12m) r2 | D4: Thesis break | E4: Reasoning | F4: Thesis break reason | G4: Key uncertainties | H4: Revisions after feedback
A5: Agent 1 | C5: 72.73 | D5: 48 | E5: Round 2 after the supervisor's review. Q3 2026 (letter and call, read directly): revenue $12.87B, op margin 34.6%, EPS $0.87 beat; Q4 guide 26.0% margin / $0.67 EPS, 2026 ads ~$2.7B (from ~$3B), FCF ~$12.0B; the CFO said 2027 aims to 'sustain double-digit revenue growth' and expand margins, guide in January. After hours $64.85 is my starting price. Changes: horizon P/E 19x -> 18x (NFLX's own 18.2x NTM; 22.4x 8-peer median; no evidenced re-rating catalyst); SOTP leg dropped (5x ad EV/sales unsupported); FY27 growth 9.9% -> 10.2% (CFO wording); FY30 margin 36.5% -> 36.0% and Paramount-WBD added to long_dated_risks and the bear case; share change -2.7% -> -3.0% (round-1 dilution derivation was wrong); the unsupported 'Roku pursuit' claim removed. Engine values the set at $72.73 (P/E $75.49, DCF $67.82, EV/EBITDA $70.57); scenarios $48.2/$72.7/$92.5 at 25/50/25. Model NTM EPS at the horizon ~$4.19. Because the market price beats valuation blends as a 12-month forecast, the ladder is a scenario mixture with medians $49/$69/$86 (shaded toward $64.85 vs the engine values) and in-scenario sigma 0.22-0.28; total spread ~37% realized vol. P(>= $69) 0.483, P(>= $48) 0.856, P(>= $103) 0.075. Research: 8 follow-up fetches/searches (call transcript, Q3 letter re-read, Nasdaq consensus for NFLX/GOOGL/SPOT/META/AMZN, Paramount 8-K exhibit, NPR on the state AG suit); post-print consensus has not updated yet. | F5: $48 is ~12.6x FY2027 consensus EPS ($3.80), ~26% below the $64.85 post-print price and at my bear value ($48.0). A close there would most likely mean earnings themselves are breaking, not only a lower multiple: revenue growth falling to mid-single digits (price rises no longer sticking, churn up), ads stuck near $3B and no margin expansion in the January FY2027 guide, or a large value-destroying acquisition. The one-sigma 12-month range at 37% vol is ~$45-95, so I place the break at the fundamental bear case rather than at ordinary volatility. | G5: • Engagement: H1'26 view hours +2% y/y while YouTube hit a record 14.2% of US TV time; does pricing power hold if share of time keeps falling? (management points to churn improving y/y) • Advertising: ~$2.7B in 2026 after a cut from ~$3B ('a bit behind our aggressive target'); the FY27 path is the widest driver range • Margin path: 2026's underlying expansion is ~1pt; the January FY2027 guide (the CFO would not quantify layoff savings) is the test • Content competition: whether Paramount-WBD closes over the state AG suit, and the cost of live-sports rights • Capital allocation: appetite for large M&A after the withdrawn WBD agreement • Disclosure: no member or ARM figures since 2025, so the regional driver split rests on revenue growth and management wording • Rates: 10y UST at 5.12% compresses long-duration multiples | H5: • fair value: 73.31 → 72.47 (Engine value after the changes below (P/E 19x -> 18x, SOTP leg dropped, FY27 growth and FY30 margin re-set, share change -3.0%).) • a method: P/E: 19x NTM, $79.42, weight 0.45 → 18x NTM, $75.49 (model EPS ~$4.19), weight 0.55 (Supervisor: 19x sat above NFLX's own post-print NTM multiple with no catalyst argued. Re-checked: $64.85 / ($0.67 Q4 guide + 0.93 + 0.98 + 0.98 Nasdaq/Zacks quarters) = 18.2x; 8-peer median 22.4x recomputed with GOOGL 340.27/14.97 and SPOT 526.12/17.28 at Nasdaq. I found no evidenced re-rating catalyst, so 18x.) • a method: SOTP: $67.25, weight 0.15 (subscription EBITDA x13 + ad revenue x5 EV/sales) → dropped (weight 0; P/E and EV/EBITDA take it in their 0.45:0.20 ratio) (Supervisor: the 5x ad EV/sales had no ad-margin or peer-ad-business evidence; I found none either, so the leg goes rather than an unsupported multiple.) • a method: EV/EBITDA: 14x, $70.31, weight 0.20, 6-peer trailing median incl. CMCSA/LYV → 14x, $70.57, weight 0.25, 4 core peers (median 13.9x unchanged) (Weight redistribution from the SOTP; CMCSA and LYV dropped as not comparable (supervisor's comps review, which I agree with).) • a method: DCF: $67.12 → $66.53 (FY27 growth 9.9% -> 10.2% (CFO on the Q3 call: 'We look to sustain double-digit revenue growth'), FY30 margin 36.5% -> 36.0% (live-sports inflation plus a combined Paramount-WBD bidding for content), share change -2.7% -> -3.0%. WACC kept at 9.3%: same inputs as the supervisor's 9.4% (5.12% 10y, beta 1.0); the gap is the debt weight and rounding.) • a fact: share count change: -2.7%/yr (dilution taken as the 1.5% diluted-basic gap) → -3.0%/yr (My round-1 derivation treated a stock gap as an annual flow; rebuilt from ~$11.5B buybacks at ~$70 (Q3 average $75.1) less ~0.9%/yr issuance seen in FY2025 (F29, F30, F64).) • a fact: M&A adjustment basis: WBD agreement plus a 'reported Roku pursuit' (KASU/NPR) → WBD agreement only (Netflix agreed ~$83B and withdrew when Paramount raised; Paramount funded the $2.8B break fee) (Supervisor found the cited source does not say Netflix pursued Roku; claim and source removed. Value unchanged (-$4B x 25%).) • a fact: long_dated_risks: no Paramount-WBD entry; ad upside '$10B+ by 2030' with no source for the figure → Paramount-WBD added (p 0.55, -$1.2/share, terminal value and bear case); ad upside restated as ~$7-8B by 2030 from $2.7B x ~1.3^4 (Supervisor flagged the missing Paramount-WBD risk; verified at NPR: 12 state AGs sued in July 2026 after DOJ clearance. I disagree that the rest of the approvals are in hand: NPR says the FCC had not signed off and the UK regulator may review, so I use 0.55 rather than a higher close probability. The $10B ad figure had no source, so it was replaced by arithmetic on the letter's 2026 figure.) • a scenario: bear $50.5 / base $73.3 / bull $91.5 → bear $48.0 / base $72.5 / bull $92.3 (Engine values of the revised set; the bear story now includes a closed Paramount-WBD and goes to 14x, the bull re-rates toward the 22.4x peer median.) • P(close >= K): P(>=69) 0.505, P(>=48) 0.866, P(>=103) 0.085 → P(>=69) 0.483, P(>=48) 0.856, P(>=103) 0.075 (Scenario mixture medians moved from $50/$70/$88 to $49/$69/$86 with the lower fair value and bear case; spread unchanged (~37% vol).) • thesis break: 50.0 → 48.0 (Set at my revised bear value ($48.0, ~12.6x FY2027 consensus EPS), the level that needs earnings, not only the multiple, to break.) • a fact: comps: 11 peers, median NTM P/E 22.2x (GOOGL 19.1x on a stake-gain-inflated FY26 blend) → 8 peers, median 22.4x (GOOGL 22.7x on FY27 EPS, SPOT 30.4x added; LYV, TTWO, ROKU, CMCSA dropped) (Supervisor's comps review; GOOGL and SPOT EPS re-checked at Nasdaq/Zacks.)
A6: Agent 2 | C6: 73.04 | D6: 46 | E6: Round 2. Q3 print (letter, re-read): revenue $12.87B +12%, op margin 34.6%, EPS $0.87; FY26 revenue $51.1B, ads ~$2.7B (from ~$3B), FCF ~$12.0B (from $12.5B, real-estate timing); Q4 margin 26% incl. ~120bp of layoff cost; gross debt $15.3B, net debt $7.1B; no FY27 guide, but the CFO said 'We look to sustain double-digit revenue growth' and 'steadily growing margin each year'. Start price $64.85 (after hours; Nasdaq $64.89). Supervisor findings acted on: (1) WACC rebuilt from measured beta: my own weekly regressions vs SPY give 0.92 (2y), 1.04 (3y), 1.41 (5y), 1.10 ex-2022, so beta 1.05 and WACC 9.6% (I sit 0.2pt above the supervisor's 9.4% because the 3y and ex-2022 betas are above 1.0); (2) peer median rebuilt on 8 comparable names at 22.45x (checked: GOOGL 340.27/14.97, SPOT 526.12/17.28), and ROKU is now takeover-priced (Fox 8-K); (3) explicit years extended to FY2030 with growth fading to 5.6% and margin to 36%; (4) P/E cut from 19x to 18x (round 1 sat above the ~18.2x NTM the stock trades at). Industry lane updates: Paramount-WBD is no longer a pending risk (settlement approved 2026-09-30, deal reported closed 2026-10-06), so its content-bidding effect is a near-certain long-dated cost; Fox-Roku consolidates CTV distribution; WARC/Omdia see Netflix at 9.2% of CTV ad spend in 2027 and $8B ads by 2030, which I use only in the bull case. Engine: P/E $75.19 (0.8), DCF $64.44 (0.2, now 14% below), M&A -$0.20 => $73.04; scenarios $49.9/$73.0/$95.4 at 25/50/25. Ladder: scenario centres shaded halfway from value toward the $64.85 start (x0.942) because today's price beats research blends as a forecast and post-guide-cut drift is negative; within-scenario vol ~0.24 gives ~35% total vol, near the 1-year realized 35-37%. Median ~$67.4, P(>= $69) 0.475 (round 1: 0.505). Research in round 2: 7 searches/fetches plus Nasdaq consensus and Yahoo price pulls. | F6: $46 is ~29% below the $64.85 start and 12.1x FY27 consensus EPS ($3.80), about 8% under my bear value ($49.9) and beyond a one-sigma move (~35% vol). Trading there would mean the market prices revenue growth sliding to mid-single digits and margin expansion ending: pricing power broken (churn after the 2026 price rises, US TV share toward 7%) or content costs bid up by the merged Paramount-WBD, not ordinary volatility. Round 1 had $45; moved up with the slightly higher bear value. | G6: • Whether the fall in Netflix's share of TV time (8.3% -> 7.8-7.9%) and per-member viewing (-8% vs 2023) turns into churn and weaker pricing power, or stays a mix shift that ARM gains offset. • Ad monetisation: the 2026 ad guide was cut by ~$300M while the ad tier reaches 250M viewers and upfront commitments nearly doubled; CPMs are falling industry-wide (-5%). • Content and sports cost inflation now that Paramount-WBD has closed (HBO Max + Paramount+), Fox-Roku is pending, and NFL/sports rights reset. • Margin trajectory: no FY27 guide yet; Q4'26 26% includes restructuring; consensus implies ~33% in FY27. • Reduced disclosure (no subscriber counts; engagement report once a year from Jan 2027) keeps the multiple under pressure. | H6: • fair value: 74.62 → 73.04 (18x P/E (was 19x), WACC 9.6% from measured beta (was 10.0% on a judgment beta 1.2), build extended to FY2030, FY27 margin 33.0% (was 32.8%), -$0.20 M&A adjustment; supervisor's DCF-check, peer-median and P/E findings.) • a method: P/E 19x = $79.10 → P/E 18x = $75.19 (Supervisor: 19x sat above the ~18.2x NTM the stock trades at and my 28.2x median was inflated; rebuilt 8-peer median 22.45x verified at Nasdaq (GOOGL FY27, SPOT close).) • a method: DCF $56.70 (WACC 10.0%, FY26-29) → DCF $64.44 (WACC 9.6%, FY26-30) (Supervisor's beta finding verified by my own regressions (0.92/1.04/1.41/1.10 ex-2022); FY2030 steady-state year added; gap to the P/E leg now -14% (was -28%).) • a fact: peer median NTM P/E 28.2x (11 peers ex GOOGL) → 22.45x (8 peers, GOOGL on FY27 EPS) (Supervisor comps review; ROKU additionally takeover-priced (Fox 8-K, $160/share), SPOT re-priced at the $526.12 close.) • a fact: Paramount-WBD: only a state lawsuit stands in the way → settlement approved 2026-09-30; deal reported closed 2026-10-06 (New evidence (AP via ABC News; iHeart); long-dated risk probability 0.7 -> 0.9, value effect -$2.1 -> -$2.7.) • a fact: gross debt ~$15.1B → $15.3B (Q3 letter re-read; net debt $7.1B unchanged.) • a scenario: bear $48.84 / base $74.62 / bull $100.46 (multiple +/-5x) → bear $49.89 / base $73.04 / bull $95.37 (multiple +/-4x) (Lower base multiple, bull capped at the 22.45x peer median, bear at 14x; new WACC and FY2030 year.) • P(close >= K): P(>=69) 0.505, P(>=76) 0.385, P(>=93) 0.168 → P(>=69) 0.475, P(>=76) 0.36, P(>=93) 0.16 (Lower fair value (73.04) and bull case; median ~$67.4 (was ~$70).) • thesis break: 45 → 46 (Bear value rose to $49.9; level kept ~8% below it (12.1x FY27 consensus).) • a method: no M&A adjustment → -$4B x 0.2 = -$0.20/share (Supervisor long-dated review flagged that I missed the acquisition risk; Netflix bid for WBD before Paramount won (Feb 2026).)
A7: Agent 3 | C7: 72.43 | D7: 50 | E7: Skeptic lane, round 2. Supervisor findings acted on: (1) my 17x horizon P/E was a further de-rating below NFLX's own 18.2x NTM ($64.85/$3.56), not 'current level held'; I now hold ~18x and keep the skeptic view in below-consensus EPS (~$4.15 vs ~$4.30 street NTM at the horizon) and the bear case, so the worry is counted once. (2) Scenario weights 30/50/20 had no base rate and the downside news is in the $64.85 start: equalised to 25/50/25; asymmetry stays in severity (bear -4 turns, -3pt growth, -2.5pt margin). (3) Added an ads-led bull path (WARC 9.2% CTV share 2027, Omdia $8B by 2030: +2.5pt growth, +2pt margin, 21x). (4) Dropped the 13.2x content subset (it included cable); core 8-peer median 22.4x with SPOT added (526.08/17.28, my check at Nasdaq/Yahoo). (5) Added the Paramount-WBD long-dated risk I missed (12 states suing; $7B break fee if not closed by June 4, 2027). New evidence: the CFO's objective to 'sustain double-digit revenue growth' moved FY2027 growth 9.6% -> 10.0%; ads 'a bit behind our aggressive target'; Netflix moving to annual engagement reports (less disclosure, supports the discount); July target cuts (Pivotal $70 Street-low on short-form shift and content costs). WACC kept at 9.5% (Blume beta 0.94 on 2y weekly; supervisor's 9.4% with beta 1.0 differs by 0.1pt, under $0.5/share). FY2030 margin kept at 35% (supervisor 36%): live sports and a possible Paramount-WBD rights war argue for a lower cap. Engine: P/E $74.76 (0.8) + DCF $63.12 (0.2) - M&A adjustment -> $72.43; scenarios $48.7 / $72.4 / $94.3 at 25/50/25. Ladder: 50% scenario mixture (20% within-scenario vol) + 50% 37%-vol lognormal centred on the $64.85 start (today's price beats any blend as a 12-month forecast), with slightly fatter far-left tail; median ~$68.3, P(>=69) 0.49. 1-month ladder unchanged (no new in-window information). Option data not used; research limited to ~9 follow-up lookups; post-print analyst reactions not yet indexed. | F7: $50 is ~12x my horizon NTM EPS (~$4.15) and ~13x FY2027 consensus ($3.80), 23% below the $64.85 post-print price and just above my bear value ($48.7): trading there would mean the market is pricing falling earnings, not a multiple wobble: a January FY2027 guide below double-digit growth or with flat margins, churn after price increases, ads stuck near $3B after the 15-country launch, an expensive large acquisition, or a closed Paramount-WBD forcing a content/sports cost war. Unchanged from round 1 because my bear value moved only $2.5. | G7: • Whether the engagement slide (hours/member, US TV share 7.8%) is a slate gap that hits can fix or a structural loss of attention to YouTube/creator video • Ad revenue trajectory after the 2026 cut (~$2.7B vs ~$3B): ad tech delays vs the 15-country 2027 expansion • FY2027 margin: layoff savings vs sports/live and content cost inflation; street implies ~33%+ • Capital allocation: record buybacks now, but management agreed an $82.7B WBD deal in late 2025 and could pursue another large deal • Pricing power: 2026 price increases 'consistent with prior' per management, but industry cancellations rising (streamflation) • Rates: 10-year at 5.12% keeps the discount rate high for a long-duration stock • Disclosure: Netflix stopped reporting memberships in 2025 and moves its engagement report to once a year, so the engagement debate will be settled on revenue and third-party data (Nielsen) rather than company hours • Paramount-WBD: whether the 12-state suit blocks the deal before the June 4, 2027 outside date | H7: • a method: P/E 17.0x -> $70.88 → P/E 18.0x -> $74.76 (Supervisor: 17x was a further de-rating below NFLX's own 18.2x NTM ($64.85/$3.56, my figure); I hold today's multiple and carry the bear view in EPS and the bear scenario.) • a fact: Peer reference 22.7x (11 peers) and 13.2x content subset incl. CMCSA → Core 8-peer median 22.4x (CMCSA, LYV, TTWO, ROKU excluded; SPOT 30.4x added) (Supervisor comps review; SPOT re-checked at Nasdaq (FY2027 EPS 17.28) and Yahoo (close 526.08).) • a method: FY2027 revenue growth +9.6% (UCAN 8%, EMEA 10%) → +10.0% (UCAN 8.5%, EMEA 10.5%) (Q3 call transcript: CFO objective to 'sustain double-digit revenue growth' (supervisor finding, re-verified at the transcript).) • a method: DCF $63.45 → DCF $63.12 (FY2027 growth change and the -$2.25B acquisition-overpayment adjustment moved into model_inputs (was scenario-only).) • a scenario: bear $46.2 p0.30 / base $69.4 p0.50 / bull $91.8 p0.20 → bear $48.7 p0.25 / base $72.4 p0.50 / bull $94.3 p0.25 (Supervisor: weights had no base rate and downside news is in the start price; bull now ads-led (WARC/Omdia, re-verified at Advanced Television); bull multiple +3 turns to 21x (was +4 to 21x from 17x).) • fair value: 69.39 → 72.43 (18x horizon P/E, FY2027 growth +10.0%, M&A adjustment; engine base horizon value.) • P(close >= K): P(>=69) 0.435, P(>=48) 0.80, P(>=93) 0.145; median ~$65.5 → P(>=69) 0.488, P(>=48) 0.832, P(>=93) 0.175; median ~$68.3 (Higher scenario values and equal tail weights; still 50% anchored on the $64.85 start.) • a fact: Paramount-WBD not in long-dated risks → Added: p 0.55, -$1.0/share, in the bear scenario (Supervisor long-dated review; re-verified at NPR (12 states, ~$111B, $7B owed if not closed by June 4, 2027).) • a fact: M&A risk p 0.20, -$0.7/share (scenario only) → p 0.15, -$0.55/share, as an equity adjustment (WBD went to Paramount (NPR), fewer targets of that size; priced into the base value instead of only the scenarios.) • thesis break: 50 → 50 (unchanged) (Bear value moved only from $46.2 to $48.7; $50 still ~12x horizon EPS and means earnings, not the multiple, are breaking.)
