Workbook

Sheet Summary
A1: GOOGL 12-month price target model
A2: Close 2026-10-30 · agents' research 2026-10-28 · horizon 2027-10-30. Blue = input you can change, black = formula, green = link to another sheet. Yellow = key assumption.
A4: Inputs | B4: Value | D4: Where it comes from
A5: Last close | B5: 279.84 | D5: Close on 2026-10-30
A6: Weight: options market | B6: 0.67 | D6: AIA Forecaster default (market 67%); flips to 33% when the option chain is thin
A7: Weight: agents | B7: 0.33 | D7: AIA Forecaster default (agents 33%)
A8: Weight: analyst consensus | B8: 0 | D8: Taken pro rata from the two above; 0 when there are no targets or in a special situation
A9: Analysts' median target | B9: 400 | D9: 49 analysts, https://stockanalysis.com/stocks/googl/forecast/ as of 2026-10-30
A10: Use supervisor ladder (1 = yes) | B10: 0 | D10: Supervisor confidence: medium; its ladder replaces the agents' mean only when high
A11: Platt log shift of the agents' curve | B11: 0 | D11: combine.py: P(close >= spot) 0.634 Platt-scaled (a = 1.732) to 0.634, then the whole agents' curve is shifted in log price by this amount
A12: Thesis-break price (supervisor) | B12: 250 | D12: Supervisor's reconciled thesis break (agents' values on the Reasoning sheet)
A13: 30-day implied vol | B13: 0.3086 | D13: Cboe model-free 30D IV as of 2026-10-30; sets the stop noise floor (2 one-month moves)
A15: Options-market median | B15: =EXP(INDEX(Distribution!$B$6:$B$20,MIN(MAX(IFERROR(MATCH(0.5,Distribution!$C$6:$C$20,-1),1),1),14))+(LN(MIN(MAX(0.5,0.0001),0.9999)/(1-MIN(MAX(0.5,0.0001),0.9999)))-INDEX(Distribution!$N$6:$N$20,MIN(MAX(IFERROR(MATCH(0.5,Distribution!$C$6:$C$20,-1),1),1),14)))/(INDEX(Distribution!$N$6:$N$20,MIN(MAX(IFERROR(MATCH(0.5,Distribution!$C$6:$C$20,-1),1),1),14)+1)-INDEX(Distribution!$N$6:$N$20,MIN(MAX(IFERROR(MATCH(0.5,Distribution!$C$6:$C$20,-1),1),1),14)))*(INDEX(Distribution!$B$6:$B$20,MIN(MAX(IFERROR(MATCH(0.5,Distribution!$C$6:$C$20,-1),1),1),14)+1)-INDEX(Distribution!$B$6:$B$20,MIN(MAX(IFERROR(MATCH(0.5,Distribution!$C$6:$C$20,-1),1),1),14)))) -> 297.34066 | D15: Median of the options-implied distribution (Distribution sheet); the analyst curve is this curve re-centred on the analysts' median
A17: Research target (12m) per share | B17: Method blend | C17: Stated | D17: Note
A18: Agent 1 | B18: =Methods!C7 -> 362.4 | C18: =Methods!E7 -> 362
A19: Agent 2 | B19: =Methods!C11 -> 369.8 | C19: =Methods!E11 -> 370
A20: Agent 3 | B20: =Methods!C15 -> 345.845 | C20: =Methods!E15 -> 346
A21: Agents' average | B21: =AVERAGE(B18:B20) -> 359.34833 | C21: =AVERAGE(C18:C20) -> 359.33333
A22: Agents' median | B22: =MEDIAN(B18:B20) -> 362.4 | C22: =MEDIAN(C18:C20) -> 362
A23: Supervisor's reconciled research target (12m) | C23: 317.4896 | D23: Model update 2026-10-28 (update): Q3 2026 rolled in from the release and call (10-Q not filed). Cloud beat the path ($30.7B vs ~$27.2B, backlog $561B) and lifts the 2027-28 Cloud path; Search (+12%) and Alphabet-level AI R&D (-$7.66B) cut Services revenue and raise central costs; research target (12m) $321.16 -> $329.15 (engine: P/E $338.79 x 0.5; SOTP $319.52 x 0.5; scenarios bear $212.77 / base $329.15 / bull $406.51, median $324.11). ANTHROPIC S-1 UPDATE 2026-10-27: Google's stake from the public S-1 cap table 7.36% at the IPO (was 11.28%), staged lock-up 11.50% (was 10.37%), carrying $81.20B (was $105B): Anthropic increment +$51.21B -> +$25.35B, conglomerate overlay -$28.97B -> -$26.38B; adjustments -$23.27B (-$1.87/share on each leg, 12,423M). Research target (12m) $323.03 -> $321.16 (engine: P/E $332.28 x 0.5; SOTP $310.04 x 0.5; scenarios bear $207.66 / base $321.16 / bull $394.09, median $315.83). Write-up: file:///mnt/project-files/valuation/runs/2026-10-23/GOOGL/anthropic_stake_s1_2026-10-27.md | EXIT k=0.8 RE-SET 2026-10-26 (Kilian card 12:16Z: exit = peer median x (own / median)^0.8): P/E 20.8x -> 21.2x. Research target (12m) $320.11 -> $323.03 (engine: multiple: P/E (ntm) $334.15 x 0.5; sotp $311.91 x 0.5; scenarios bear $209.53 / base $323.03 / bull $395.97, median $317.65). Multiples and values quoted in the older text below are superseded by these. Model update 2026-10-23 (update): peer set refresh (Kilian 2026-10-26 06:07Z). P/E leg on the refreshed 5-name set's CY2027 median 20.8x (was 21.7x) and a new SOTP leg like AMZN's (Services 18.25x, Cloud 23.3x, Alphabet costs 18.25x, Other Bets 20.8x on CY2028E after-tax OI), 0.5 / 0.5, in place of the agents' cross-check leg; research target (12m) $320.11 = 0.5 x 328.31 + 0.5 x 311.91 (was $338.72). The rest of this text is the 10-06 round's reasoning (history; its $370 blend is superseded). 60% P/E + 40% cross-check, priced at the 2027-10-06 horizon. P/E leg: 21.7x (reconciled peer median, no premium) x CY2028E EPS of $17.54 (consensus $17.89 less $0.35 of extra D&A from the standing view's capex base of consensus +10%) = $380.6. Add $14.97/share of net financial assets at the horizon ($185.6B / 12.40B diluted shares) for $395.6. Cross-check leg: the mean of the agents' SOTP/EV legs, with their unsourced -$15B H2-26 burn replaced by consensus FCF (citation gate 2026-10-06): $349.9 agent_1, $327.1 agent_2, $320.3 agent_3 = $332.4. Their factual inputs are verified in the 8-K; their segment growth and multiples are judgments that sit below consensus EBIT. Blend 0.6 x 395.6 + 0.4 x 332.4 = $370.3, about $370 (+6.4% vs $347.68). Corrections vs the agents: consensus basis $14.95 (agent_1), peer median 21.7x (all), CY2028 not NTM (agent_3), net cash included at the horizon on consensus FCF (agents 1-3), Polymarket/press items removed (agent_2's bull, agent_3's bear weight, the 10-02 +$4).
A24: Research target (12m) vs last close | C24: =C23/Spot-1 -> 0.13453974
A26: Levels | B26: This model | C26: Published | D26: How
A27: NTM target (median) | B27: =EXP(INDEX(Distribution!$B$6:$B$20,MIN(MAX(IFERROR(MATCH(0.5,Distribution!$S$6:$S$20,-1),1),1),14))+(LN(MIN(MAX(0.5,0.0001),0.9999)/(1-MIN(MAX(0.5,0.0001),0.9999)))-INDEX(Distribution!$T$6:$T$20,MIN(MAX(IFERROR(MATCH(0.5,Distribution!$S$6:$S$20,-1),1),1),14)))/(INDEX(Distribution!$T$6:$T$20,MIN(MAX(IFERROR(MATCH(0.5,Distribution!$S$6:$S$20,-1),1),1),14)+1)-INDEX(Distribution!$T$6:$T$20,MIN(MAX(IFERROR(MATCH(0.5,Distribution!$S$6:$S$20,-1),1),1),14)))*(INDEX(Distribution!$B$6:$B$20,MIN(MAX(IFERROR(MATCH(0.5,Distribution!$S$6:$S$20,-1),1),1),14)+1)-INDEX(Distribution!$B$6:$B$20,MIN(MAX(IFERROR(MATCH(0.5,Distribution!$S$6:$S$20,-1),1),1),14)))) -> 317.72676 | C27: 305.9226 | D27: Price with a 50% chance of closing above it on the horizon date
A28: Take-profit (75th percentile) | B28: =EXP(INDEX(Distribution!$B$6:$B$20,MIN(MAX(IFERROR(MATCH(0.25,Distribution!$S$6:$S$20,-1),1),1),14))+(LN(MIN(MAX(0.25,0.0001),0.9999)/(1-MIN(MAX(0.25,0.0001),0.9999)))-INDEX(Distribution!$T$6:$T$20,MIN(MAX(IFERROR(MATCH(0.25,Distribution!$S$6:$S$20,-1),1),1),14)))/(INDEX(Distribution!$T$6:$T$20,MIN(MAX(IFERROR(MATCH(0.25,Distribution!$S$6:$S$20,-1),1),1),14)+1)-INDEX(Distribution!$T$6:$T$20,MIN(MAX(IFERROR(MATCH(0.25,Distribution!$S$6:$S$20,-1),1),1),14)))*(INDEX(Distribution!$B$6:$B$20,MIN(MAX(IFERROR(MATCH(0.25,Distribution!$S$6:$S$20,-1),1),1),14)+1)-INDEX(Distribution!$B$6:$B$20,MIN(MAX(IFERROR(MATCH(0.25,Distribution!$S$6:$S$20,-1),1),1),14)))) -> 397.93089 | C28: 305.81 | D28: 25% chance of closing above
A29: 15th percentile | B29: =EXP(INDEX(Distribution!$B$6:$B$20,MIN(MAX(IFERROR(MATCH(0.85,Distribution!$S$6:$S$20,-1),1),1),14))+(LN(MIN(MAX(0.85,0.0001),0.9999)/(1-MIN(MAX(0.85,0.0001),0.9999)))-INDEX(Distribution!$T$6:$T$20,MIN(MAX(IFERROR(MATCH(0.85,Distribution!$S$6:$S$20,-1),1),1),14)))/(INDEX(Distribution!$T$6:$T$20,MIN(MAX(IFERROR(MATCH(0.85,Distribution!$S$6:$S$20,-1),1),1),14)+1)-INDEX(Distribution!$T$6:$T$20,MIN(MAX(IFERROR(MATCH(0.85,Distribution!$S$6:$S$20,-1),1),1),14)))*(INDEX(Distribution!$B$6:$B$20,MIN(MAX(IFERROR(MATCH(0.85,Distribution!$S$6:$S$20,-1),1),1),14)+1)-INDEX(Distribution!$B$6:$B$20,MIN(MAX(IFERROR(MATCH(0.85,Distribution!$S$6:$S$20,-1),1),1),14)))) -> 220.18742 | C29: 215.5451 | D29: 85% chance of closing above
A30: Stop noise floor | B30: =Spot*EXP(-2*IV30*SQRT(21/252)) -> 234.17009 | D30: Two one-month implied moves below the last close; the stop is never tighter than this
A31: Stop-loss | B31: =MIN(IF(AND(Thesis_Break>0,Thesis_Break<Spot),MAX(B29,Thesis_Break),B29),B30) -> 234.17009 | C31: 234.1701 | D31: Higher of the 15th percentile and the thesis break, capped at the noise floor (published basis: noise floor (2 x 1M IV))
A32: Target vs last close | B32: =B27/Spot-1 -> 0.13538722 | C32: =C27/Spot-1 -> 0.093205403
A33: P(close above last) | C33: 0.6038
A34: Expected price (mean) | C34: 314.8643 | D34: Mean of the blended distribution (combine.py integrates the full curve); above the median when right-skewed
A36: Sheets
A37: Assumptions | D37: The supervisor's table of every driver: each agent's value, reasoning and linked sources
A38: Methods | D38: Each agent's valuation methods, values and weights
A39: Scenarios | D39: Downside (10th pct) / base / upside (90th pct) price per agent
A40: Distribution | D40: The probability ladder and the blend, as formulas
A41: Reasoning | D41: Each agent's written reasoning, thesis break and what changed from round 1
A42: Supervisor | D42: Disagreements, fact-checks and changes
A43: Sources | D43: Every cited source with its link

Sheet Assumptions
A1: GOOGL key assumptions, aggregated by the supervisor
A2: Each driver of the valuation: the supervisor's reconciled value (grey rows), then what each agent assumed, why, and its sources. Blue values are the agents' own numbers; blank means the agent did not use that driver.
A4: ID | B4: Assumption / who | C4: Value | D4: Reasoning | E4: Source 1 | F4: Source 2 | G4: Source 3 | H4: All sources | I4: Agents low | J4: Agents high | K4: Used in
A5: The supervisor has not aggregated this round yet (model_assumptions.json); see Methods and Reasoning.

Sheet Distribution
A1: GOOGL probability of closing at or above each price on 2027-10-30
A2: Each column is P(close >= K). Agents' curve is Platt-shifted, blended with the options market, then analysts at W_Analyst (0 since 2026-10-05). Interpolation is linear in logit(p) vs log(K), as in combine.py.
A5: Price K | B5: ln K | C5: Options market | D5: Agent 1 | E5: Agent 2 | F5: Agent 3 | G5: Agents' mean | H5: Supervisor | I5: Agents' curve used | J5: logit(used) | K5: K shifted | L5: seg | M5: Agents Platt-shifted | N5: logit(market) | O5: K re-centred | P5: seg | Q5: Analyst curve | R5: Blend ex analysts | S5: Final blend | T5: logit(final) | U5: Published (combine.py)
A6: 69.96 | B6: =LN(A6) -> 4.2479237 | C6: 1 | D6: 0.9983 | E6: 0.9983 | F6: 0.9983 | G6: =AVERAGE(D6:F6) -> 0.9983 | H6: 0.9981 | I6: =IF(AND(Sup_Used=1,ISNUMBER(H6)),H6,G6) -> 0.9983 | J6: =LN(MIN(MAX(I6,0.0001),0.9999)/(1-MIN(MAX(I6,0.0001),0.9999))) -> 6.3754256 | K6: =A6*EXP(-Platt_Shift) -> 69.96 | L6: =MIN(MAX(IFERROR(MATCH(K6,Distribution!$A$6:$A$20,1),1),1),14) -> 1 | M6: =1/(1+EXP(-(INDEX(Distribution!$J$6:$J$20,L6)+(LN(K6)-INDEX(Distribution!$B$6:$B$20,L6))/(INDEX(Distribution!$B$6:$B$20,L6+1)-INDEX(Distribution!$B$6:$B$20,L6))*(INDEX(Distribution!$J$6:$J$20,L6+1)-INDEX(Distribution!$J$6:$J$20,L6))))) -> 0.9983 | N6: =LN(MIN(MAX(C6,0.0001),0.9999)/(1-MIN(MAX(C6,0.0001),0.9999))) -> 9.2102404 | O6: =IF(Analyst_Median>0,A6*Market_Median/Analyst_Median,A6) -> 52.004881 | P6: =MIN(MAX(IFERROR(MATCH(O6,Distribution!$A$6:$A$20,1),1),1),14) -> 1 | Q6: =1/(1+EXP(-(INDEX(Distribution!$N$6:$N$20,P6)+(LN(O6)-INDEX(Distribution!$B$6:$B$20,P6))/(INDEX(Distribution!$B$6:$B$20,P6+1)-INDEX(Distribution!$B$6:$B$20,P6))*(INDEX(Distribution!$N$6:$N$20,P6+1)-INDEX(Distribution!$N$6:$N$20,P6))))) -> 0.99998656 | R6: =W_Mkt*C6+W_Agents*M6 -> 0.999439 | S6: =(1-W_Analyst)*R6+W_Analyst*Q6 -> 0.999439 | T6: =LN(MIN(MAX(S6,0.0001),0.9999)/(1-MIN(MAX(S6,0.0001),0.9999))) -> 7.4852285 | U6: 0.9999
A7: 111.94 | B7: =LN(A7) -> 4.717963 | C7: 0.9976 | D7: 0.9975 | E7: 0.9943 | F7: 0.9943 | G7: =AVERAGE(D7:F7) -> 0.99536667 | H7: 0.9949 | I7: =IF(AND(Sup_Used=1,ISNUMBER(H7)),H7,G7) -> 0.99536667 | J7: =LN(MIN(MAX(I7,0.0001),0.9999)/(1-MIN(MAX(I7,0.0001),0.9999))) -> 5.3698346 | K7: =A7*EXP(-Platt_Shift) -> 111.94 | L7: =MIN(MAX(IFERROR(MATCH(K7,Distribution!$A$6:$A$20,1),1),1),14) -> 2 | M7: =1/(1+EXP(-(INDEX(Distribution!$J$6:$J$20,L7)+(LN(K7)-INDEX(Distribution!$B$6:$B$20,L7))/(INDEX(Distribution!$B$6:$B$20,L7+1)-INDEX(Distribution!$B$6:$B$20,L7))*(INDEX(Distribution!$J$6:$J$20,L7+1)-INDEX(Distribution!$J$6:$J$20,L7))))) -> 0.99536667 | N7: =LN(MIN(MAX(C7,0.0001),0.9999)/(1-MIN(MAX(C7,0.0001),0.9999))) -> 6.0298837 | O7: =IF(Analyst_Median>0,A7*Market_Median/Analyst_Median,A7) -> 83.210784 | P7: =MIN(MAX(IFERROR(MATCH(O7,Distribution!$A$6:$A$20,1),1),1),14) -> 1 | Q7: =1/(1+EXP(-(INDEX(Distribution!$N$6:$N$20,P7)+(LN(O7)-INDEX(Distribution!$B$6:$B$20,P7))/(INDEX(Distribution!$B$6:$B$20,P7+1)-INDEX(Distribution!$B$6:$B$20,P7))*(INDEX(Distribution!$N$6:$N$20,P7+1)-INDEX(Distribution!$N$6:$N$20,P7))))) -> 0.99967671 | R7: =W_Mkt*C7+W_Agents*M7 -> 0.996863 | S7: =(1-W_Analyst)*R7+W_Analyst*Q7 -> 0.996863 | T7: =LN(MIN(MAX(S7,0.0001),0.9999)/(1-MIN(MAX(S7,0.0001),0.9999))) -> 5.7613464 | U7: 0.9982
A8: 139.92 | B8: =LN(A8) -> 4.9410708 | C8: 0.9851 | D8: 0.9969 | E8: 0.9898 | F8: 0.9898 | G8: =AVERAGE(D8:F8) -> 0.99216667 | H8: 0.9918 | I8: =IF(AND(Sup_Used=1,ISNUMBER(H8)),H8,G8) -> 0.99216667 | J8: =LN(MIN(MAX(I8,0.0001),0.9999)/(1-MIN(MAX(I8,0.0001),0.9999))) -> 4.841503 | K8: =A8*EXP(-Platt_Shift) -> 139.92 | L8: =MIN(MAX(IFERROR(MATCH(K8,Distribution!$A$6:$A$20,1),1),1),14) -> 3 | M8: =1/(1+EXP(-(INDEX(Distribution!$J$6:$J$20,L8)+(LN(K8)-INDEX(Distribution!$B$6:$B$20,L8))/(INDEX(Distribution!$B$6:$B$20,L8+1)-INDEX(Distribution!$B$6:$B$20,L8))*(INDEX(Distribution!$J$6:$J$20,L8+1)-INDEX(Distribution!$J$6:$J$20,L8))))) -> 0.99216667 | N8: =LN(MIN(MAX(C8,0.0001),0.9999)/(1-MIN(MAX(C8,0.0001),0.9999))) -> 4.1913819 | O8: =IF(Analyst_Median>0,A8*Market_Median/Analyst_Median,A8) -> 104.00976 | P8: =MIN(MAX(IFERROR(MATCH(O8,Distribution!$A$6:$A$20,1),1),1),14) -> 1 | Q8: =1/(1+EXP(-(INDEX(Distribution!$N$6:$N$20,P8)+(LN(O8)-INDEX(Distribution!$B$6:$B$20,P8))/(INDEX(Distribution!$B$6:$B$20,P8+1)-INDEX(Distribution!$B$6:$B$20,P8))*(INDEX(Distribution!$N$6:$N$20,P8+1)-INDEX(Distribution!$N$6:$N$20,P8))))) -> 0.99853882 | R8: =W_Mkt*C8+W_Agents*M8 -> 0.987432 | S8: =(1-W_Analyst)*R8+W_Analyst*Q8 -> 0.987432 | T8: =LN(MIN(MAX(S8,0.0001),0.9999)/(1-MIN(MAX(S8,0.0001),0.9999))) -> 4.3639537 | U8: 0.989
A9: 167.9 | B9: =LN(A9) -> 5.1233686 | C9: 0.9503 | D9: 0.9904 | E9: 0.9806 | F9: 0.9821 | G9: =AVERAGE(D9:F9) -> 0.98436667 | H9: 0.9842 | I9: =IF(AND(Sup_Used=1,ISNUMBER(H9)),H9,G9) -> 0.98436667 | J9: =LN(MIN(MAX(I9,0.0001),0.9999)/(1-MIN(MAX(I9,0.0001),0.9999))) -> 4.1425931 | K9: =A9*EXP(-Platt_Shift) -> 167.9 | L9: =MIN(MAX(IFERROR(MATCH(K9,Distribution!$A$6:$A$20,1),1),1),14) -> 4 | M9: =1/(1+EXP(-(INDEX(Distribution!$J$6:$J$20,L9)+(LN(K9)-INDEX(Distribution!$B$6:$B$20,L9))/(INDEX(Distribution!$B$6:$B$20,L9+1)-INDEX(Distribution!$B$6:$B$20,L9))*(INDEX(Distribution!$J$6:$J$20,L9+1)-INDEX(Distribution!$J$6:$J$20,L9))))) -> 0.98436667 | N9: =LN(MIN(MAX(C9,0.0001),0.9999)/(1-MIN(MAX(C9,0.0001),0.9999))) -> 2.9507728 | O9: =IF(Analyst_Median>0,A9*Market_Median/Analyst_Median,A9) -> 124.80874 | P9: =MIN(MAX(IFERROR(MATCH(O9,Distribution!$A$6:$A$20,1),1),1),14) -> 2 | Q9: =1/(1+EXP(-(INDEX(Distribution!$N$6:$N$20,P9)+(LN(O9)-INDEX(Distribution!$B$6:$B$20,P9))/(INDEX(Distribution!$B$6:$B$20,P9+1)-INDEX(Distribution!$B$6:$B$20,P9))*(INDEX(Distribution!$N$6:$N$20,P9+1)-INDEX(Distribution!$N$6:$N$20,P9))))) -> 0.99413672 | R9: =W_Mkt*C9+W_Agents*M9 -> 0.961542 | S9: =(1-W_Analyst)*R9+W_Analyst*Q9 -> 0.961542 | T9: =LN(MIN(MAX(S9,0.0001),0.9999)/(1-MIN(MAX(S9,0.0001),0.9999))) -> 3.2189715 | U9: 0.961
A10: 195.89 | B10: =LN(A10) -> 5.2775533 | C10: 0.8855 | D10: 0.9738 | E10: 0.9615 | F10: 0.9637 | G10: =AVERAGE(D10:F10) -> 0.96633333 | H10: 0.9664 | I10: =IF(AND(Sup_Used=1,ISNUMBER(H10)),H10,G10) -> 0.96633333 | J10: =LN(MIN(MAX(I10,0.0001),0.9999)/(1-MIN(MAX(I10,0.0001),0.9999))) -> 3.3570006 | K10: =A10*EXP(-Platt_Shift) -> 195.89 | L10: =MIN(MAX(IFERROR(MATCH(K10,Distribution!$A$6:$A$20,1),1),1),14) -> 5 | M10: =1/(1+EXP(-(INDEX(Distribution!$J$6:$J$20,L10)+(LN(K10)-INDEX(Distribution!$B$6:$B$20,L10))/(INDEX(Distribution!$B$6:$B$20,L10+1)-INDEX(Distribution!$B$6:$B$20,L10))*(INDEX(Distribution!$J$6:$J$20,L10+1)-INDEX(Distribution!$J$6:$J$20,L10))))) -> 0.96633333 | N10: =LN(MIN(MAX(C10,0.0001),0.9999)/(1-MIN(MAX(C10,0.0001),0.9999))) -> 2.0455776 | O10: =IF(Analyst_Median>0,A10*Market_Median/Analyst_Median,A10) -> 145.61515 | P10: =MIN(MAX(IFERROR(MATCH(O10,Distribution!$A$6:$A$20,1),1),1),14) -> 3 | Q10: =1/(1+EXP(-(INDEX(Distribution!$N$6:$N$20,P10)+(LN(O10)-INDEX(Distribution!$B$6:$B$20,P10))/(INDEX(Distribution!$B$6:$B$20,P10+1)-INDEX(Distribution!$B$6:$B$20,P10))*(INDEX(Distribution!$N$6:$N$20,P10+1)-INDEX(Distribution!$N$6:$N$20,P10))))) -> 0.98054246 | R10: =W_Mkt*C10+W_Agents*M10 -> 0.912175 | S10: =(1-W_Analyst)*R10+W_Analyst*Q10 -> 0.912175 | T10: =LN(MIN(MAX(S10,0.0001),0.9999)/(1-MIN(MAX(S10,0.0001),0.9999))) -> 2.3404857 | U10: 0.9054
A11: 223.87 | B11: =LN(A11) -> 5.4110655 | C11: 0.7934 | D11: 0.9397 | E11: 0.9245 | F11: 0.9279 | G11: =AVERAGE(D11:F11) -> 0.9307 | H11: 0.9333 | I11: =IF(AND(Sup_Used=1,ISNUMBER(H11)),H11,G11) -> 0.9307 | J11: =LN(MIN(MAX(I11,0.0001),0.9999)/(1-MIN(MAX(I11,0.0001),0.9999))) -> 2.5974921 | K11: =A11*EXP(-Platt_Shift) -> 223.87 | L11: =MIN(MAX(IFERROR(MATCH(K11,Distribution!$A$6:$A$20,1),1),1),14) -> 6 | M11: =1/(1+EXP(-(INDEX(Distribution!$J$6:$J$20,L11)+(LN(K11)-INDEX(Distribution!$B$6:$B$20,L11))/(INDEX(Distribution!$B$6:$B$20,L11+1)-INDEX(Distribution!$B$6:$B$20,L11))*(INDEX(Distribution!$J$6:$J$20,L11+1)-INDEX(Distribution!$J$6:$J$20,L11))))) -> 0.9307 | N11: =LN(MIN(MAX(C11,0.0001),0.9999)/(1-MIN(MAX(C11,0.0001),0.9999))) -> 1.345543 | O11: =IF(Analyst_Median>0,A11*Market_Median/Analyst_Median,A11) -> 166.41413 | P11: =MIN(MAX(IFERROR(MATCH(O11,Distribution!$A$6:$A$20,1),1),1),14) -> 3 | Q11: =1/(1+EXP(-(INDEX(Distribution!$N$6:$N$20,P11)+(LN(O11)-INDEX(Distribution!$B$6:$B$20,P11))/(INDEX(Distribution!$B$6:$B$20,P11+1)-INDEX(Distribution!$B$6:$B$20,P11))*(INDEX(Distribution!$N$6:$N$20,P11+1)-INDEX(Distribution!$N$6:$N$20,P11))))) -> 0.95308053 | R11: =W_Mkt*C11+W_Agents*M11 -> 0.838709 | S11: =(1-W_Analyst)*R11+W_Analyst*Q11 -> 0.838709 | T11: =LN(MIN(MAX(S11,0.0001),0.9999)/(1-MIN(MAX(S11,0.0001),0.9999))) -> 1.6486536 | U11: 0.8215
A12: 251.86 | B12: =LN(A12) -> 5.5288734 | C12: 0.6839 | D12: 0.883 | E12: 0.8633 | F12: 0.8684 | G12: =AVERAGE(D12:F12) -> 0.87156667 | H12: 0.8806 | I12: =IF(AND(Sup_Used=1,ISNUMBER(H12)),H12,G12) -> 0.87156667 | J12: =LN(MIN(MAX(I12,0.0001),0.9999)/(1-MIN(MAX(I12,0.0001),0.9999))) -> 1.9148824 | K12: =A12*EXP(-Platt_Shift) -> 251.86 | L12: =MIN(MAX(IFERROR(MATCH(K12,Distribution!$A$6:$A$20,1),1),1),14) -> 7 | M12: =1/(1+EXP(-(INDEX(Distribution!$J$6:$J$20,L12)+(LN(K12)-INDEX(Distribution!$B$6:$B$20,L12))/(INDEX(Distribution!$B$6:$B$20,L12+1)-INDEX(Distribution!$B$6:$B$20,L12))*(INDEX(Distribution!$J$6:$J$20,L12+1)-INDEX(Distribution!$J$6:$J$20,L12))))) -> 0.87156667 | N12: =LN(MIN(MAX(C12,0.0001),0.9999)/(1-MIN(MAX(C12,0.0001),0.9999))) -> 0.77175309 | O12: =IF(Analyst_Median>0,A12*Market_Median/Analyst_Median,A12) -> 187.22055 | P12: =MIN(MAX(IFERROR(MATCH(O12,Distribution!$A$6:$A$20,1),1),1),14) -> 4 | Q12: =1/(1+EXP(-(INDEX(Distribution!$N$6:$N$20,P12)+(LN(O12)-INDEX(Distribution!$B$6:$B$20,P12))/(INDEX(Distribution!$B$6:$B$20,P12+1)-INDEX(Distribution!$B$6:$B$20,P12))*(INDEX(Distribution!$N$6:$N$20,P12+1)-INDEX(Distribution!$N$6:$N$20,P12))))) -> 0.90981082 | R12: =W_Mkt*C12+W_Agents*M12 -> 0.74583 | S12: =(1-W_Analyst)*R12+W_Analyst*Q12 -> 0.74583 | T12: =LN(MIN(MAX(S12,0.0001),0.9999)/(1-MIN(MAX(S12,0.0001),0.9999))) -> 1.0764944 | U12: 0.7171
A13: 279.84 | B13: =LN(A13) -> 5.634218 | C13: 0.5694 | D13: 0.8032 | E13: 0.7846 | F13: 0.7836 | G13: =AVERAGE(D13:F13) -> 0.79046667 | H13: 0.8044 | I13: =IF(AND(Sup_Used=1,ISNUMBER(H13)),H13,G13) -> 0.79046667 | J13: =LN(MIN(MAX(I13,0.0001),0.9999)/(1-MIN(MAX(I13,0.0001),0.9999))) -> 1.3277407 | K13: =A13*EXP(-Platt_Shift) -> 279.84 | L13: =MIN(MAX(IFERROR(MATCH(K13,Distribution!$A$6:$A$20,1),1),1),14) -> 8 | M13: =1/(1+EXP(-(INDEX(Distribution!$J$6:$J$20,L13)+(LN(K13)-INDEX(Distribution!$B$6:$B$20,L13))/(INDEX(Distribution!$B$6:$B$20,L13+1)-INDEX(Distribution!$B$6:$B$20,L13))*(INDEX(Distribution!$J$6:$J$20,L13+1)-INDEX(Distribution!$J$6:$J$20,L13))))) -> 0.79046667 | N13: =LN(MIN(MAX(C13,0.0001),0.9999)/(1-MIN(MAX(C13,0.0001),0.9999))) -> 0.27940359 | O13: =IF(Analyst_Median>0,A13*Market_Median/Analyst_Median,A13) -> 208.01953 | P13: =MIN(MAX(IFERROR(MATCH(O13,Distribution!$A$6:$A$20,1),1),1),14) -> 5 | Q13: =1/(1+EXP(-(INDEX(Distribution!$N$6:$N$20,P13)+(LN(O13)-INDEX(Distribution!$B$6:$B$20,P13))/(INDEX(Distribution!$B$6:$B$20,P13+1)-INDEX(Distribution!$B$6:$B$20,P13))*(INDEX(Distribution!$N$6:$N$20,P13+1)-INDEX(Distribution!$N$6:$N$20,P13))))) -> 0.84948553 | R13: =W_Mkt*C13+W_Agents*M13 -> 0.642352 | S13: =(1-W_Analyst)*R13+W_Analyst*Q13 -> 0.642352 | T13: =LN(MIN(MAX(S13,0.0001),0.9999)/(1-MIN(MAX(S13,0.0001),0.9999))) -> 0.58558718 | U13: 0.6038
A14: 307.82 | B14: =LN(A14) -> 5.7295152 | C14: 0.4602 | D14: 0.7057 | E14: 0.6947 | F14: 0.6764 | G14: =AVERAGE(D14:F14) -> 0.69226667 | H14: 0.7092 | I14: =IF(AND(Sup_Used=1,ISNUMBER(H14)),H14,G14) -> 0.69226667 | J14: =LN(MIN(MAX(I14,0.0001),0.9999)/(1-MIN(MAX(I14,0.0001),0.9999))) -> 0.81073763 | K14: =A14*EXP(-Platt_Shift) -> 307.82 | L14: =MIN(MAX(IFERROR(MATCH(K14,Distribution!$A$6:$A$20,1),1),1),14) -> 9 | M14: =1/(1+EXP(-(INDEX(Distribution!$J$6:$J$20,L14)+(LN(K14)-INDEX(Distribution!$B$6:$B$20,L14))/(INDEX(Distribution!$B$6:$B$20,L14+1)-INDEX(Distribution!$B$6:$B$20,L14))*(INDEX(Distribution!$J$6:$J$20,L14+1)-INDEX(Distribution!$J$6:$J$20,L14))))) -> 0.69226667 | N14: =LN(MIN(MAX(C14,0.0001),0.9999)/(1-MIN(MAX(C14,0.0001),0.9999))) -> -0.15953752 | O14: =IF(Analyst_Median>0,A14*Market_Median/Analyst_Median,A14) -> 228.8185 | P14: =MIN(MAX(IFERROR(MATCH(O14,Distribution!$A$6:$A$20,1),1),1),14) -> 6 | Q14: =1/(1+EXP(-(INDEX(Distribution!$N$6:$N$20,P14)+(LN(O14)-INDEX(Distribution!$B$6:$B$20,P14))/(INDEX(Distribution!$B$6:$B$20,P14+1)-INDEX(Distribution!$B$6:$B$20,P14))*(INDEX(Distribution!$N$6:$N$20,P14+1)-INDEX(Distribution!$N$6:$N$20,P14))))) -> 0.77539948 | R14: =W_Mkt*C14+W_Agents*M14 -> 0.536782 | S14: =(1-W_Analyst)*R14+W_Analyst*Q14 -> 0.536782 | T14: =LN(MIN(MAX(S14,0.0001),0.9999)/(1-MIN(MAX(S14,0.0001),0.9999))) -> 0.14739427 | U14: 0.4927
A15: 335.81 | B15: =LN(A15) -> 5.8165455 | C15: 0.3629 | D15: 0.599 | E15: 0.6002 | F15: 0.5537 | G15: =AVERAGE(D15:F15) -> 0.5843 | H15: 0.6044 | I15: =IF(AND(Sup_Used=1,ISNUMBER(H15)),H15,G15) -> 0.5843 | J15: =LN(MIN(MAX(I15,0.0001),0.9999)/(1-MIN(MAX(I15,0.0001),0.9999))) -> 0.3404507 | K15: =A15*EXP(-Platt_Shift) -> 335.81 | L15: =MIN(MAX(IFERROR(MATCH(K15,Distribution!$A$6:$A$20,1),1),1),14) -> 10 | M15: =1/(1+EXP(-(INDEX(Distribution!$J$6:$J$20,L15)+(LN(K15)-INDEX(Distribution!$B$6:$B$20,L15))/(INDEX(Distribution!$B$6:$B$20,L15+1)-INDEX(Distribution!$B$6:$B$20,L15))*(INDEX(Distribution!$J$6:$J$20,L15+1)-INDEX(Distribution!$J$6:$J$20,L15))))) -> 0.5843 | N15: =LN(MIN(MAX(C15,0.0001),0.9999)/(1-MIN(MAX(C15,0.0001),0.9999))) -> -0.56279931 | O15: =IF(Analyst_Median>0,A15*Market_Median/Analyst_Median,A15) -> 249.62492 | P15: =MIN(MAX(IFERROR(MATCH(O15,Distribution!$A$6:$A$20,1),1),1),14) -> 6 | Q15: =1/(1+EXP(-(INDEX(Distribution!$N$6:$N$20,P15)+(LN(O15)-INDEX(Distribution!$B$6:$B$20,P15))/(INDEX(Distribution!$B$6:$B$20,P15+1)-INDEX(Distribution!$B$6:$B$20,P15))*(INDEX(Distribution!$N$6:$N$20,P15+1)-INDEX(Distribution!$N$6:$N$20,P15))))) -> 0.69320985 | R15: =W_Mkt*C15+W_Agents*M15 -> 0.435962 | S15: =(1-W_Analyst)*R15+W_Analyst*Q15 -> 0.435962 | T15: =LN(MIN(MAX(S15,0.0001),0.9999)/(1-MIN(MAX(S15,0.0001),0.9999))) -> -0.25756654 | U15: 0.3674
A16: 377.78 | B16: =LN(A16) -> 5.934312 | C16: 0.245 | D16: 0.4435 | E16: 0.4567 | F16: 0.3714 | G16: =AVERAGE(D16:F16) -> 0.42386667 | H16: 0.4469 | I16: =IF(AND(Sup_Used=1,ISNUMBER(H16)),H16,G16) -> 0.42386667 | J16: =LN(MIN(MAX(I16,0.0001),0.9999)/(1-MIN(MAX(I16,0.0001),0.9999))) -> -0.30692018 | K16: =A16*EXP(-Platt_Shift) -> 377.78 | L16: =MIN(MAX(IFERROR(MATCH(K16,Distribution!$A$6:$A$20,1),1),1),14) -> 11 | M16: =1/(1+EXP(-(INDEX(Distribution!$J$6:$J$20,L16)+(LN(K16)-INDEX(Distribution!$B$6:$B$20,L16))/(INDEX(Distribution!$B$6:$B$20,L16+1)-INDEX(Distribution!$B$6:$B$20,L16))*(INDEX(Distribution!$J$6:$J$20,L16+1)-INDEX(Distribution!$J$6:$J$20,L16))))) -> 0.42386667 | N16: =LN(MIN(MAX(C16,0.0001),0.9999)/(1-MIN(MAX(C16,0.0001),0.9999))) -> -1.1254595 | O16: =IF(Analyst_Median>0,A16*Market_Median/Analyst_Median,A16) -> 280.82339 | P16: =MIN(MAX(IFERROR(MATCH(O16,Distribution!$A$6:$A$20,1),1),1),14) -> 8 | Q16: =1/(1+EXP(-(INDEX(Distribution!$N$6:$N$20,P16)+(LN(O16)-INDEX(Distribution!$B$6:$B$20,P16))/(INDEX(Distribution!$B$6:$B$20,P16+1)-INDEX(Distribution!$B$6:$B$20,P16))*(INDEX(Distribution!$N$6:$N$20,P16+1)-INDEX(Distribution!$N$6:$N$20,P16))))) -> 0.56543404 | R16: =W_Mkt*C16+W_Agents*M16 -> 0.304026 | S16: =(1-W_Analyst)*R16+W_Analyst*Q16 -> 0.304026 | T16: =LN(MIN(MAX(S16,0.0001),0.9999)/(1-MIN(MAX(S16,0.0001),0.9999))) -> -0.82819908 | U16: 0.2176
A17: 419.76 | B17: =LN(A17) -> 6.0396831 | C17: 0.1601 | D17: 0.3111 | E17: 0.3249 | F17: 0.2213 | G17: =AVERAGE(D17:F17) -> 0.28576667 | H17: 0.3099 | I17: =IF(AND(Sup_Used=1,ISNUMBER(H17)),H17,G17) -> 0.28576667 | J17: =LN(MIN(MAX(I17,0.0001),0.9999)/(1-MIN(MAX(I17,0.0001),0.9999))) -> -0.91603408 | K17: =A17*EXP(-Platt_Shift) -> 419.76 | L17: =MIN(MAX(IFERROR(MATCH(K17,Distribution!$A$6:$A$20,1),1),1),14) -> 12 | M17: =1/(1+EXP(-(INDEX(Distribution!$J$6:$J$20,L17)+(LN(K17)-INDEX(Distribution!$B$6:$B$20,L17))/(INDEX(Distribution!$B$6:$B$20,L17+1)-INDEX(Distribution!$B$6:$B$20,L17))*(INDEX(Distribution!$J$6:$J$20,L17+1)-INDEX(Distribution!$J$6:$J$20,L17))))) -> 0.28576667 | N17: =LN(MIN(MAX(C17,0.0001),0.9999)/(1-MIN(MAX(C17,0.0001),0.9999))) -> -1.6574842 | O17: =IF(Analyst_Median>0,A17*Market_Median/Analyst_Median,A17) -> 312.02929 | P17: =MIN(MAX(IFERROR(MATCH(O17,Distribution!$A$6:$A$20,1),1),1),14) -> 9 | Q17: =1/(1+EXP(-(INDEX(Distribution!$N$6:$N$20,P17)+(LN(O17)-INDEX(Distribution!$B$6:$B$20,P17))/(INDEX(Distribution!$B$6:$B$20,P17+1)-INDEX(Distribution!$B$6:$B$20,P17))*(INDEX(Distribution!$N$6:$N$20,P17+1)-INDEX(Distribution!$N$6:$N$20,P17))))) -> 0.44461073 | R17: =W_Mkt*C17+W_Agents*M17 -> 0.20157 | S17: =(1-W_Analyst)*R17+W_Analyst*Q17 -> 0.20157 | T17: =LN(MIN(MAX(S17,0.0001),0.9999)/(1-MIN(MAX(S17,0.0001),0.9999))) -> -1.3765106 | U17: 0.1268
... A20: 699.6 | B20: =LN(A20) -> 6.5505087 | C20: 0.0068 | D20: 0.0201 | E20: 0.0192 | F20: 0.0029 | G20: =AVERAGE(D20:F20) -> 0.014066667 | H20: 0.0172 | I20: =IF(AND(Sup_Used=1,ISNUMBER(H20)),H20,G20) -> 0.014066667 | J20: =LN(MIN(MAX(I20,0.0001),0.9999)/(1-MIN(MAX(I20,0.0001),0.9999))) -> -4.2497808 | K20: =A20*EXP(-Platt_Shift) -> 699.6 | L20: =MIN(MAX(IFERROR(MATCH(K20,Distribution!$A$6:$A$20,1),1),1),14) -> 14 | M20: =1/(1+EXP(-(INDEX(Distribution!$J$6:$J$20,L20)+(LN(K20)-INDEX(Distribution!$B$6:$B$20,L20))/(INDEX(Distribution!$B$6:$B$20,L20+1)-INDEX(Distribution!$B$6:$B$20,L20))*(INDEX(Distribution!$J$6:$J$20,L20+1)-INDEX(Distribution!$J$6:$J$20,L20))))) -> 0.014066667 | N20: =LN(MIN(MAX(C20,0.0001),0.9999)/(1-MIN(MAX(C20,0.0001),0.9999))) -> -4.9840094 | O20: =IF(Analyst_Median>0,A20*Market_Median/Analyst_Median,A20) -> 520.04881 | P20: =MIN(MAX(IFERROR(MATCH(O20,Distribution!$A$6:$A$20,1),1),1),14) -> 13 | Q20: =1/(1+EXP(-(INDEX(Distribution!$N$6:$N$20,P20)+(LN(O20)-INDEX(Distribution!$B$6:$B$20,P20))/(INDEX(Distribution!$B$6:$B$20,P20+1)-INDEX(Distribution!$B$6:$B$20,P20))*(INDEX(Distribution!$N$6:$N$20,P20+1)-INDEX(Distribution!$N$6:$N$20,P20))))) -> 0.052866631 | R20: =W_Mkt*C20+W_Agents*M20 -> 0.009198 | S20: =(1-W_Analyst)*R20+W_Analyst*Q20 -> 0.009198 | T20: =LN(MIN(MAX(S20,0.0001),0.9999)/(1-MIN(MAX(S20,0.0001),0.9999))) -> -4.6795286 | U20: 0.005
A22: Agents' curves are their final-round answers (Reasoning sheet shows round 1). Market and published columns come from combine.py; the model reproduces the final blend within rounding (combine.py also enforces a non-increasing curve).

Sheet Methods
A1: GOOGL valuation methods by agent
A2: Each agent's methods, the value per share and the weight it gave each. Blended value = weight-averaged methods; stated value = what the agent reported (it may round or add a deduction).
A4: Agent | B4: Method | C4: Value / share | D4: Weight | E4: Value x weight | F4: Calculation (assumption IDs on the Assumptions sheet) | G4: Inputs and reasoning
A5: Agent 1 | B5: P/E | C5: 372 | D5: 0.6 | E5: =C5*D5 -> 223.2 | G5: At Oct 2027 the market prices CY2028 EPS. Consensus CY2028 EPS is $17.89 (MarketScreener); I trim about 5% for 2027-capex D&A and use $17.0. The core multiple is 21x: inside the 10-peer range of 8.6-33.7x, about 7% above the peer median of 19.6x and below the mega-cap median of 24.4x. That gives $357, plus about $15/share of after-tax net financial assets (cash net of debt, SpaceX, non-marketable book) that consensus EPS does not capture. Total about $372.
A6: Agent 1 | B6: SOTP | C6: 348 | D6: 0.4 | E6: =C6*D6 -> 139.2 | G6: Services: 2027E OI $175B x (1-18%) x 20 = $2.87T. Cloud: 2027E revenue $150B x 7 = $1.05T. Other Bets/Waymo: $0.15T. Alphabet-level AI costs: -$23.2B x 0.82 x 20 = -$0.38T. Net financial assets: $0.24T, i.e. cash net of debt $40B + other equity $7B + SpaceX $94.1B x 0.85 + non-marketable $131.5B x 0.85. Total $3.93T / 12.30B = $319 today; rolled forward 9% to $348.
A7: Agent 1 | B7: Blended value | C7: =IF(SUM(D5:D6)>0,SUMPRODUCT(C5:C6,D5:D6)/SUM(D5:D6),"") -> 362.4 | D7: =SUM(D5:D6) -> 1 | E7: 362 | F7: Stated research target (12m) | G7: 60% P/E plus 40% SOTP. The P/E leg is 21x core on CY2028E EPS of $17.0 (= $357), plus about $15/share of after-tax net financial assets, for $372. The SOTP leg is $348. The blend is about $362, against $361 on 2026-10-02.
A9: Agent 2 | B9: P/E | C9: 399 | D9: 0.6 | E9: =C9*D9 -> 239.4 | G9: FY2028E core EPS $17.5 x 21.8x (peer median next-FY P/E) = $381.5, plus ~$17.8/share net financial assets = ~$399
A10: Agent 2 | B10: SOTP | C10: 326 | D10: 0.4 | E10: =C10*D10 -> 130.4 | G10: Services 2028E after-tax OI ~$164.7B x 18 = $2.96T; Cloud 2028E revenue ~$185B x 7 = $1.30T; Alphabet-level + Other Bets ~-$25.2B after tax x 18 = -$0.45T; net financial assets $0.22T; total ~$4.03T / 12.35B shares = ~$326
A11: Agent 2 | B11: Blended value | C11: =IF(SUM(D9:D10)>0,SUMPRODUCT(C9:C10,D9:D10)/SUM(D9:D10),"") -> 369.8 | D11: =SUM(D9:D10) -> 1 | E11: 370 | F11: Stated research target (12m) | G11: Blend at the Oct-2027 horizon: forward P/E at the 11-peer median (21.8x) on FY2028E core EPS of $17.5 (consensus $17.89 less ~$0.4 for capex-file base-case D&A) plus ~$17.8/share of net financial assets = $399 (weight 0.6), and a 2028E sum-of-the-parts (Services 18x after-tax OI, Cloud 7x 2028E sales, less capitalised Alphabet-level and Other Bets costs, plus net financial assets) = $326 (weight 0.4); blend ~$370.
A13: Agent 3 | B13: P/E | C13: 359.6 | D13: 0.65 | E13: =C13*D13 -> 233.74 | G13: NTM EPS at Oct-27 $16.08 (consensus 2027 $14.95, 2028 $17.89 cut 8%) x 21.8x x (1-0.5% dilution) + $10.75 equity stakes
A14: Agent 3 | B14: EV/EBITDA | C14: 320.3 | D14: 0.35 | E14: =C14*D14 -> 112.105 | G14: 10.5x x NTM EBITDA $361.8B = $3,799B EV + net cash $24.0B + equity stakes $132.8B = $3,956B / 12.35B shares
A15: Agent 3 | B15: Blended value | C15: =IF(SUM(D13:D14)>0,SUMPRODUCT(C13:C14,D13:D14)/SUM(D13:D14),"") -> 345.845 | D15: =SUM(D13:D14) -> 1 | E15: 346 | F15: Stated research target (12m) | G15: Blend of P/E (65%) and EV/EBITDA (35%) priced at the 2027-10-06 horizon on NTM estimates. P/E: 21.8x x haircut NTM EPS $16.08 x 0.995 + $10.75/share haircut equity stakes = $360. EV/EBITDA: 10.5x x NTM EBITDA $361.8B + $156.7B non-operating assets, / 12.35B shares = $320. Blend = $346.

Sheet Scenarios
A1: GOOGL cases by agent
A2: Base case = median; downside = 10th percentile, upside = 90th percentile (no probabilities; older rounds' bear/bull shown as downside/upside).
A4: Agent | B4: Downside (P10) | C4: Base (median) | D4: Upside (P90) | E4: Downside story | F4: Base story | G4: Upside story
A5: Agent 1 | B5: 245 | C5: 368 | D5: 475 | E5: The Q3 or Q4 print guides 2027 capex near $370B (the standing view's Big-4 high case of +86% y/y, applied to Alphabet's $200B 2026 midpoint). FCF stays negative and the market treats the 2026 equity, convert and $25B debt raises as overreach. Search growth slows from 17% to single digits as Q3 laps the 2025 acceleration and AI answers cannibalise clicks, and the DC Circuit tightens the Search remedies. The stock trades at about 15x core on $15 of CY2027 EPS plus reduced stake value. | F5: Cloud converts its backlog (2027 revenue about $150B at 30%+ margins) and Services grows low double digits. D&A from about $295B of 2027 capex holds CY2028 EPS growth to about 12-13% ($17.0). The stock trades at 21x core plus about $15/share of stakes. | G5: TPU system sales land in 2027 as guided, Gemini 4 broadens from the Fairwind preview to GA and monetises across Search, the Gemini app and Cloud, and consensus CY2028 of $17.89 proves too low (about $19). The stock re-rates to about 24x core, the mega-cap median, plus stake re-marks. The capped calls limit convert dilution up to about $530.
A6: Agent 2 | B6: 255 | C6: 375 | D6: 495 | E6: The Q3/Q4 2027 capex framework lands at or above the standing view's high case, D&A drags FY2028 EPS to ~$15 (-16% vs consensus), Search growth slows toward high single digits as Meta, Amazon and AI assistants take incremental budgets, and the DC Circuit reopens default payments; ~16x core plus ~$14/share of stakes (deeper haircut) = ~$255. | F6: Cloud converts backlog (~$185B 2028E revenue) helped by external TPU sales, Search grows low double digits, ad-tech stays behavioural; 21.8x peer-median multiple on ~$17.5 FY2028 core EPS plus ~$17.8/share of financial assets, cross-checked by the $326 SOTP: ~$375. | G6: External TPU sales become a visible third engine, Cloud margins pass 40%, Gemini holds the top model slot (Polymarket 42.5% for end-2026), FY2028 EPS ~$19 and the multiple re-rates to ~25x (near the upper mega-cap peers) as capex intensity peaks; an Anthropic IPO (Polymarket 67% by Nov 30) re-marks the non-marketable book: ~25 x $19 + ~$22 = ~$495. [citation gate 2026-10-06: the Polymarket best-model and Anthropic-IPO odds are prediction-market prices and the stake re-mark is not in Alphabet's filings: not verified, not used in any supervisor number]
A7: Agent 3 | B7: 257 | C7: 348 | D7: 440 | E7: AI-capex payback doubts deepen: the 2027 capex guide (consensus ~$301B) lands with Cloud growth slowing as third-party bridging capacity and depreciation squeeze margins. Anthropic-concentrated backlog [31] and circular financing [32] become the story. The ATM is drawn, search share keeps slipping (StatCounter 89.9% in Sep-26 [35]) and the DOJ cross-appeal keeps a structural search remedy alive. NTM EPS ~10% below my already-haircut $16.08 (~$14.5) at 17x (ORCL/NFLX level) + $10.75 stakes = ~$257. [citation gate 2026-10-06: [31]/[32] are press-only; context, not used in any supervisor number] | F7: Search grows low-teens and Cloud converts backlog, but depreciation caps margin expansion and FCF stays near zero through 2027. Equity issuance replaces buybacks. Multiple drifts from 23x to ~22x NTM: roughly flat over 12 months, in line with fair value ~$346. | G7: Consensus proves right or low: 2028 EPS ~$17.9, TPU external sales ramp in 2027 [10], Cloud margin keeps expanding (Q2 OI $8.8B on $24.8B revenue [1]), ATM left unused. 25x NTM consensus EPS $17.16 + $10.75 stakes = ~$440, near the $429 average analyst target [16].
A8: Average | B8: =AVERAGE(B5:B7) -> 252.33333 | C8: =AVERAGE(C5:C7) -> 363.66667 | D8: =AVERAGE(D5:D7) -> 470

Sheet Reasoning
A1: GOOGL each agent's reasoning
A2: Final round, with round 1 for comparison. Revisions list what each agent changed after the supervisor's feedback.
A4: Agent | B4: Research target (12m) r1 | C4: Research target (12m) r2 | D4: Thesis break | E4: Reasoning | F4: Thesis break reason | G4: Key uncertainties | H4: Revisions after feedback
A5: Agent 1 | C5: 362 | D5: 255 | E5: Delta refresh of my 2026-10-02 file. I re-checked filings first. EDGAR shows no 8-K, 10-Q or proxy since Aug 10; the only new filing is an Oct 2 Form 4. So I re-opened and confirmed every reported figure that feeds my fair value at source: the Q2 8-K, the 10-Q, the Q2 call transcript, and the June 5 and Aug 10 8-Ks. The only company releases are the Oct 6 Constellation PPA (890 MW of uprates, 20 years; a separate 2,700 MW, 15-year supply deal; first uprate 2028; cost undisclosed) and the Sep 30/Oct 1 Gemini 4 Argon preview (Fairwind-only, no GA date). Neither changes a 12-month number. Neither does the stock's move: +1.2% Oct 2-6, in line with QQQ's +1.3%. What did change is consensus. CY2027 EPS is now $15.10 (S&P Global; 24/7 Wall St shows $14.47 to $15.10 in 90 days), against $14.84 in my last file. MarketScreener carries CY2028 at $17.89. I also built the 10-peer comp set my prior file lacked, on one CY2027 basis. Its median is 19.6x P/E and 11.9x EV/EBITDA; GOOGL is at 23.0x all-in and 22.0x core. I now apply 21x core, down from 21.5x and anchored to that peer set, to CY2028E EPS of $17.0 (consensus less about 5% for 2027-capex D&A, sized from the standing capex view: Big-4 2027 base +47%), up from $16.5. With about $15/share of stakes, the P/E leg is $372. The SOTP is unchanged at $348. The blend is $362, against $361. The ladder uses median ≈ fair value $362 (+4%), a fat-tailed lognormal mixture (27% sigma at 70%, 40% at 30%, about 31% effective vs 32% realised), and P(≥ spot) of 0.55. The scenario mean is $368 (22/53/25 at $245/$368/$475), consistent with right skew. Thesis break stays $255. For one month, the Q3 print is about 97% inside the window, two-sided, centred at about $349. Lane: 9 of the 15 non-comp sources are primary (60%). The 30 data pages behind the comp table (3 per peer, required by the 2026-10-03 peer rule) are not counted. No option data was used. | F5: $255 is about 15.9x CY2027 consensus core EPS ($15.10, after about $15/share of after-tax stakes and net cash), below the 19.6x peer median and roughly at the cheapest non-de-rated peers (ORCL 14.8x, RDDT 15.4x). It is about 8% above the 52-week low of $235.84. At that level the market would be saying either that consensus is being cut (Search breaking under AI substitution or an adverse appellate ruling on default payments), or that the $513.9B Cloud backlog is not converting at margins near Q2's 35.6%. A capex guide alone, even at the high end, should take the stock to the high-$200s, not $255. Unchanged from 2026-10-02: the consensus rise (+1.8%) is too small to move it. | G5: • Size of 2027 capex (standing-view base about $295B for Alphabet; range about $240-370B) and the D&A drag it puts on CY2028 EPS • Search growth as Q3 laps the 2025 acceleration and AI answers spread, plus the Search remedies appeal • Conversion and margin of the $513.9B Cloud backlog, including the third-party capacity bridge and TPU system sales • Gemini 4 Argon reception and the timing of broad availability: limited preview only, no GA date • Volatility in stake marks: $94.1B of restricted SpaceX and a $131.5B non-marketable book, mostly one private company • Dilution from the ATM and mandatory converts, with buybacks suspended
A6: Agent 2 | C6: 370 | D6: 245 | E6: Delta refresh from 2026-10-02. No new filings. The Q3 print is now fixed for Oct 28, inside the 1-month window. The stock rose 1.2%, matching QQQ and the mega-cap peers, so price action since 10-02 carries no GOOGL-specific information. Industry read-through stays constructive for Cloud and TPU: the Constellation 20-year 890 MW uprate PPA plus 2,700 MW supply deal shows Alphabet contracting power years ahead (supplier-side confirmation of a long build-out, and a Gemini Enterprise customer win); Marvell's investor day lifted ASIC peers on the custom-silicon share thesis; Wells Fargo now sees $9.2B and $11.5B of external TPU sales in Q3/Q4. Gemini 4 Argon tops the Arena leaderboard and Polymarket moved Google to 42.5% for best model at end-2026. The ad side is unchanged: the last tracker (Tinuiti Q2) shows click-led Search growth with CPC +1%, and Meta and Amazon ads outgrew Search. Valuation: consensus FY27 rose to $14.95 and FY28 is verified at $17.89. I take $17.5 after a D&A adjustment for the standing capex view (Alphabet 2027 capex ~10% above consensus). The new 11-peer set gives a 21.8x median next-FY P/E; GOOGL's ~22.1x core multiple is already at the median and its FY28 growth matches the mega-cap median, so I apply 21.8x with no premium: P/E leg $399. I corrected my SOTP to deduct unallocated costs and moved it to the 2028 horizon: $326. Blend 60/40 = $370 (+6.4%). Distribution: two-piece lognormal, median ~$366, sigma ~0.30 up / 0.34 down (realised vol 32%), with fatter tails for regulatory and capex outcomes. The scenario mean ($375) is close to the ladder mean (~$379). Thesis break $245 (~15x core FY27, Baidu-to-Netflix territory). Research limits: Alpha Vantage was rate-limited, Twelve Data estimates are paywalled, DCD and Benzinga returned 403, and the Tinuiti Q3 report is not yet out. I did not use Anthropic stake-size claims (not disclosed in Alphabet filings) in any number. | F6: $245 is ~15.2x FY2027 consensus core EPS ($14.95) after ~$17.8/share of financial assets, below every mega-cap peer (lowest ORCL 21.4x) and between Baidu (13.2x, flat revenue) and Netflix (17.8x). The market would be pricing Search as ex-growth, and $245 is ~4% above the 52-week low of $235.84. Industry signals that would accompany a fundamental break: Broadcom or Marvell cutting custom-ASIC/TPU outlooks or hyperscalers signalling digestion (an AI-demand air pocket that would also stall Cloud backlog conversion), search-ad trackers showing Google spend growth below ~5% with CPC falling, or an adverse DC Circuit ruling on default payments. Capex anxiety alone has not taken the stock there. | G6: • Size of the 2027 capex step-up (standing view ~$350B vs $285-357B consensus) and how long FCF stays near zero • Search pricing: click-led growth with CPC +1% while Meta and Amazon ads grow faster • External TPU sales: magnitude and margins (Wells Fargo $9.2B Q3) vs Broadcom/Marvell custom-silicon competition • Value and timing of realisation of the $131.5B non-marketable book (Anthropic IPO odds) and the $94.1B SpaceX stake • DC Circuit appeal on search distribution payments; EU/Poland publisher cases • Whether Gemini keeps model leadership (Arena #1 today; Polymarket 42.5% for end-2026)
A7: Agent 3 | C7: 346 | D7: 255 | E7: Skeptic lane. Starting facts (filings): Q2-26 revenue $119.8B (+24%), operating income $40.8B, Cloud $24.8B (+82%) with $8.8B OI, Cloud backlog $513.9B [1][2]. What the consensus may be underweighting: (1) Earnings quality. H1-26 pretax income $216.2B includes $135.9B of equity-security gains (SpaceX IPO and other marks; $94.1B of SpaceX stock, mostly locked up [2][42]) [9][1], so trailing P/E of ~17x is misleading. On ex-gains consensus the stock is 23.2x CY27 [14]. (2) Cash. Q2 FCF -$5.9B, TTM $53.3B [1]. Consensus FCF is $8.4B in 2026 and -$36.7B in 2027 on capex of $201.7B and $301.0B [15], consistent with the standing AI-capex view (Alphabet 2027 consensus $285-357B) [40]. Purchase commitments jumped to $707B [3]. (3) Funding mix. Buybacks went from $13.2B in Q2-25 to zero [1]. Alphabet sold 58M Class A/C shares (net $20.5B) plus $10B to Berkshire, $19B of 6.25% mandatory convertibles, and set up a $40B ATM [4][5][6], plus $45B of bonds in Feb/Aug [7][8][39]. (4) Credit is pricing more risk. On like-for-like tenors, new-issue spreads widened from Feb to Aug: 10y T+63 -> T+85, 40y T+95 -> T+130, despite unchanged AA+/Aa2 ratings [7][8]. The Feb sterling deal included a 2126 century bond at gilts +120bp [41]. That is a mild, not alarming, signal. (5) Concentration and circularity. Anthropic reportedly accounts for over 40% of the backlog [31], and Google backstops financing of Anthropic's TPU purchases [32]. These are press reports (The Information, via Silicon UK), used here only to size bear-case probability, not as valuation inputs. (6) Sentiment is crowded: 0 sells and 4 holds out of 55 analysts; insiders sold ~$8.7M and bought $0 over 3 months [37]. Visible Form 4s are routine 10b5-1 or vesting [11][12][13], so this is not a red flag. Alt-data and markets: StatCounter puts Google at 89.94% of worldwide search in Sep-26 [35]. On Kalshi (via Octagon, Oct 2, week of Oct 5), 'Above 20.5%' Google share of OpenRouter text-model requests traded ~75% and 'Above 19.9%' 97%, with 30,430 contracts on the latter [36]. That reads as a solid but not dominant AI-model position. Privacy litigation remains a recurring cost (shareholder proponents cite a $425.7M privacy jury verdict [38]; PriceRunner $2.1B damages and the $5.2B EU Android payment in Q2-Q3 [3]). What weakens the bear case: the ad tech remedy decision rejected the AdX divestiture and imposed a 6-year behavioral decree [27][28][29][30], removing the largest structural legal tail. The balance sheet remains AA+. Operating momentum is real. Valuation: P/E (21.8x, between the all-peer median 19.8x and the US median 23.5x) on haircut NTM EPS gives $360. EV/EBITDA at the peer median (10.5x) gives $320. Blended fair value is $346, about 0.5% below spot. Scenarios: 257/348/440 at 25/50/25 (mean ~$348). The ladder is a lognormal mixture around those (sigma 0.22/0.17/0.17), giving a log-sd of ~0.27 and median ~$348. This is somewhat tighter than the 32% realized vol, because the realized figure includes the Mar-May 2026 re-rating (weekly close $274 in late March to a $408.61 high in May) [43], and wider than base-rate large-cap moves only in the left tail. Research limits: Twelve Data and Alpha Vantage estimate and statistics endpoints were plan-restricted, so consensus comes from MarketScreener and StockAnalysis. Seeking Alpha, Axios and some trade press were not fetchable. | F7: $255 is the bear-case value: ~17x a 10%-lower NTM EPS plus haircut stakes, and below the Mar-2026 trough ($274.34 weekly close [43]). Trading there would mean the market has stopped capitalizing the AI build-out at peer multiples. Likely causes: a 2027 capex guide with no matching Cloud/TPU revenue, an Anthropic-concentrated backlog wobble, a visible step-down in Search growth, or heavy ATM use. That is a fundamental re-rating, not ordinary 32%-vol noise around fair value $346. | G7: • Whether 2027 capex (consensus ~$301B, after ~$200B in 2026) earns a return before depreciation catches up. Consensus 2027 FCF is -$36.7B. • Backlog quality: over 40% of the $514B Cloud backlog reportedly sits with Anthropic, which Google also funds (up to $40B) and whose TPU purchases Google helps finance. • Per-share dilution path: $40B ATM, mandatory convertible preferred (converts May-2029), no buybacks since Q1-26. • GAAP earnings quality: equity-security gains were $135.9B of $216.2B H1-26 pretax income (63%), so headline EPS and P/E (17.4x trailing) look cheaper than the operating business is. • Search share erosion to chat assistants (StatCounter <90% in Sep-26) versus record Search usage claimed by management. • Search-case cross-appeal (DOJ seeking stronger remedies) and the EU DMA decision. • Credit-market tolerance: new-issue spreads widened 16-35bp between the Feb-26 and Aug-26 deals despite AA+/Aa2 ratings.

Sheet Supervisor
A1: GOOGL supervisor
A2: Confidence: medium. My checks settled four disagreements that move the number: one consensus basis, a GAAP-consistent peer median (21.7x), agent_3's NTM/next-FY mismatch, and a consensus-based (not assumed) H2 cash path. Together they lift fair value about $10 above the agent mean ($359.3) and raise P(>= spot) by about 2 points. The size is modest and agent_3's skeptic margin view remains a legitimate judgment, so this is not a 'high' update.
A4: Summary | B4: ANTHROPIC S-1 UPDATE 2026-10-27: Google's stake from the public S-1 cap table 7.36% at the IPO (was 11.28%), staged lock-up 11.50% (was 10.37%), carrying $81.20B (was $105B): Anthropic increment +$51.21B -> +$25.35B, conglomerate overlay -$28.97B -> -$26.38B; adjustments -$23.27B (-$1.87/share on each leg, 12,423M). Research target (12m) $323.03 -> $321.16 (engine: P/E $332.28 x 0.5; SOTP $310.04 x 0.5; scenarios bear $207.66 / base $321.16 / bull $394.09, median $315.83); the $323.03 figures below are superseded. | EXIT k=0.8 RE-SET 2026-10-26 (Kilian card 12:16Z: exit = peer median x (own / median)^0.8): P/E 20.8x -> 21.2x. Research target (12m) $320.11 -> $323.03 (engine: multiple: P/E (ntm) $334.15 x 0.5; sotp $311.91 x 0.5; scenarios bear $209.53 / base $323.03 / bull $395.97, median $317.65). Multiples and values quoted in the older text below are superseded by these. Peer refresh 2026-10-26 (model update 2026-10-23): research target (12m) $320.11 (was $338.72; the $370 below is the 10-06 stated value, history): P/E 20.8x on the refreshed 5-name set, SOTP leg added at 0.5. Since 10-02 nothing fundamental is new: no filings. Alphabet confirmed the Q3 print for Oct 28 after the close, inside the 1-month window, and the stock moved +1.2%. Reconciling the three agents on one verified basis gives a fair value of $370 (+6.4%), up $4 from 10-02. The basis is CY27 EPS $14.95 and CY28 $17.89, an 11-peer GAAP-consistent median of 21.7x, and net cash rolled to the horizon on consensus FCF. The 10-02 Anthropic uplift is removed, and the blind agent's lower $346 comes from its skeptic judgment and a basis mismatch, not from different facts. Thesis break $250; P(close >= spot in 12 months) 0.558. No add before the print: keep the staged third share for Oct 29 or later, and fix the staged entry's date and its $257B capex condition (consensus is $301B).
A5: Research target (12m) | B5: Model update 2026-10-28 (update): Q3 2026 rolled in from the release and call (10-Q not filed). Cloud beat the path ($30.7B vs ~$27.2B, backlog $561B) and lifts the 2027-28 Cloud path; Search (+12%) and Alphabet-level AI R&D (-$7.66B) cut Services revenue and raise central costs; research target (12m) $321.16 -> $329.15 (engine: P/E $338.79 x 0.5; SOTP $319.52 x 0.5; scenarios bear $212.77 / base $329.15 / bull $406.51, median $324.11). ANTHROPIC S-1 UPDATE 2026-10-27: Google's stake from the public S-1 cap table 7.36% at the IPO (was 11.28%), staged lock-up 11.50% (was 10.37%), carrying $81.20B (was $105B): Anthropic increment +$51.21B -> +$25.35B, conglomerate overlay -$28.97B -> -$26.38B; adjustments -$23.27B (-$1.87/share on each leg, 12,423M). Research target (12m) $323.03 -> $321.16 (engine: P/E $332.28 x 0.5; SOTP $310.04 x 0.5; scenarios bear $207.66 / base $321.16 / bull $394.09, median $315.83). Write-up: file:///mnt/project-files/valuation/runs/2026-10-23/GOOGL/anthropic_stake_s1_2026-10-27.md | EXIT k=0.8 RE-SET 2026-10-26 (Kilian card 12:16Z: exit = peer median x (own / median)^0.8): P/E 20.8x -> 21.2x. Research target (12m) $320.11 -> $323.03 (engine: multiple: P/E (ntm) $334.15 x 0.5; sotp $311.91 x 0.5; scenarios bear $209.53 / base $323.03 / bull $395.97, median $317.65). Multiples and values quoted in the older text below are superseded by these. Model update 2026-10-23 (update): peer set refresh (Kilian 2026-10-26 06:07Z). P/E leg on the refreshed 5-name set's CY2027 median 20.8x (was 21.7x) and a new SOTP leg like AMZN's (Services 18.25x, Cloud 23.3x, Alphabet costs 18.25x, Other Bets 20.8x on CY2028E after-tax OI), 0.5 / 0.5, in place of the agents' cross-check leg; research target (12m) $320.11 = 0.5 x 328.31 + 0.5 x 311.91 (was $338.72). The rest of this text is the 10-06 round's reasoning (history; its $370 blend is superseded). 60% P/E + 40% cross-check, priced at the 2027-10-06 horizon. P/E leg: 21.7x (reconciled peer median, no premium) x CY2028E EPS of $17.54 (consensus $17.89 less $0.35 of extra D&A from the standing view's capex base of consensus +10%) = $380.6. Add $14.97/share of net financial assets at the horizon ($185.6B / 12.40B diluted shares) for $395.6. Cross-check leg: the mean of the agents' SOTP/EV legs, with their unsourced -$15B H2-26 burn replaced by consensus FCF (citation gate 2026-10-06): $349.9 agent_1, $327.1 agent_2, $320.3 agent_3 = $332.4. Their factual inputs are verified in the 8-K; their segment growth and multiples are judgments that sit below consensus EBIT. Blend 0.6 x 395.6 + 0.4 x 332.4 = $370.3, about $370 (+6.4% vs $347.68). Corrections vs the agents: consensus basis $14.95 (agent_1), peer median 21.7x (all), CY2028 not NTM (agent_3), net cash included at the horizon on consensus FCF (agents 1-3), Polymarket/press items removed (agent_2's bull, agent_3's bear weight, the 10-02 +$4).
A6: Key drivers | B6: • Google Search & other paid clicks: 100 -> 110.4/119.2/127.5 (estimate; quarterly, mean) • Google Search & other cost-per-click: 100 -> 103.5/106.6/109.8 (estimate; quarterly, wmean:paid_clicks) • Google Cloud backlog (remaining performance obligations) at the end of the period: 242.8 -> 595.4/693.3/810.9 (estimate; quarterly, end) • Google Cloud revenue / opening backlog: 0.6299 -> 0.4527/0.3289/0.3392 (estimate; quarterly, mean) • Capital expenditures (purchases of property and equipment): 91.45 -> 196/301/339.5 (estimate; quarterly, sum)
A8: Disagreements (final round)
A9: Topic | B9: Positions | C9: Resolution | D9: Evidence
A10: CY2027 consensus EPS: $15.10 (agent_1) vs $14.95 (agents 2 and 3) | B10: agent_1 uses $15.10 (S&P Global via stockanalysis; 24/7 Wall St). agents 2 and 3 use $14.95 (Yahoo; MarketScreener). | C10: Use $14.95. Alphabet's fiscal year is the calendar year, so both figures are CY2027; the gap is between vendors, not calendars. $14.95 shows at two sources on 2026-10-06 (Yahoo: 53 analysts; MarketScreener). The same MarketScreener page gives the CY2028 $17.89 used for the horizon, so EPS, capex and FCF all sit on one vendor basis. The stockanalysis page agent_1 cites hides 2027+ EPS behind 'Pro', so $15.10 cannot be seen there. 24/7 Wall St shows $15.1008 but names no vendor. The 1% gap is about $3/share at 21.7x and does not change the conclusion. | D10: Yahoo analysis page and MarketScreener finances page, both opened 2026-10-06; stockanalysis GOOGL forecast (2027 EPS shown as 'Pro'); 24/7 Wall St 2026-10-05.
A11: Peer set and median (19.6x / 21.8x / 19.8x) | B11: agent_1: 10 names, median 19.6x, on S&P Global (stockanalysis) EPS. agent_2: 11 names, median 21.8x, MarketScreener fiscal year ending in 2027, not calendarized; includes BIDU, PINS, SPOT. agent_3: 10 names, median 19.8x, calendarized MarketScreener; includes TCEHY, BABA, BIDU. | C11: Reconciled set of 11 names on one basis: MarketScreener consensus calendarized to CY2027, P/E = 2026-10-06 close / CY2027 EPS. Median 21.7x; mega-cap five (MSFT, AMZN, META, AAPL, ORCL) 24.4x. agent_1's software and ads multiples use S&P Global adjusted (ex-SBC) EPS while GOOGL's consensus includes SBC. Examples: ORCL FY27 adjusted $8.14 vs MarketScreener $6.643; CRM 14.0x vs 23.5x; RDDT 15.4x (adjusted $9.69) vs 21.1x. That biases agent_1's median down by about 2 turns. agent_2's MSFT 26.7x and ORCL 21.4x are fiscal-year multiples; calendarized they are 24.5x and 17.9x. China ADRs (regulatory/ADR discount), PINS (EPS $0.78 off a low base) and SPOT (EUR) are dropped as not comparable. | D11: MarketScreener finances pages for all 11 peers, opened 2026-10-06; stockanalysis ORCL/CRM/RDDT forecast pages (S&P Global adjusted EPS).
A12: Horizon EPS: capex D&A adjustment to CY2028 consensus ($17.0 / $17.5 / $16.46) | B12: agent_1 -5%, sized from a $295B 2027 capex base. agent_2 -$0.4, from the standing view's consensus +10%. agent_3 -8%, holding the EBIT margin flat as a skeptic. | C12: Use $17.54 ($17.89 - $0.35). The standing view's base case is consensus +10%. Verified consensus 2027 capex is $301.0B (MarketScreener), so the base is about $331B, $30B over consensus. At the call's ~60% servers / 40% DC mix that adds about $3.5-4B of pre-tax 2028 D&A, roughly $0.3-0.35/share after tax on 12.4B shares. agent_1's $295B base is below the verified $301B consensus, so by its own logic it implies no haircut, not 5%. agent_3's -8% is a view against consensus (EBIT margin 35.3% in 2027 to 35.9% in 2028), not a correction; it is kept as the bear-case driver. | D12: MarketScreener GOOGL finances (capex 2027 $300,979M, 2028 $339,451M; EBIT 2027 $216,996M on sales $615,038M; 2028 $263,325M on $734,199M); standing capex view (base = consensus +10%); Q2 transcript ('continue to expect our CapEx to increase significantly in 2027').
A13: Net financial assets per share ($15 / $17.8 / $10.75) | B13: agents 1 and 2 net cash ~$40-42B after an assumed -$15B H2 burn, haircuts 15% and 20%. agent_3 stakes only in its P/E leg ($10.75), using the $124.3B measurement-alternative book with 25-50% haircuts. | C13: $15.0/share at the horizon (estimate). Cash and debt securities ($55.911B + $99.500B) less debt ($98.165B + $1.999B) = $55.2B at 6/30. Add consensus H2-26 FCF of +$4.2B: MarketScreener 2026 FCF $8.448B less H1 FCF of $4.261B (OCF $84.859B - capex $80.598B). The agents' -$15B H2 burn is unsourced. Add 0.75 x the 2027 consensus FCF of -$36.658B and deduct five quarters of common dividends ($0.22 x 12.23B) and preferred dividends (6.25% x $19.0B x 1.25 years). That gives about $17.0B of net cash at Oct 2027. Stakes: other marketable equity $7.06B x 0.85, SpaceX $94.1B x 0.75 and the $131.461B non-marketable line x 0.70, for $185.6B in total. Over 12.40B diluted shares that is $14.97. Net cash at the horizon is an estimate (see inputs_detail). The $14.1B long-term-restricted SpaceX block is in other non-current assets, not the non-marketable line, so there is no double count. agent_3's $124.3B is the measurement-alternative subset of the $131.461B line; both are 10-Q figures. | D13: 10-Q (SpaceX $80.0B short-term / $14.1B long-term restricted; marketable equity $87.063B incl. the $80.0B; non-marketable $131.461B); XBRL company facts at 2026-06-30; MarketScreener FCF consensus.
A14: Multiple basis at the horizon (agent_3) | B14: agent_3 applies 21.8x, a CY2027 multiple measured today about 9 months ahead of the earnings midpoint, to an NTM base at Oct 2027 (0.25 x CY27 + 0.75 x CY28), about 6 months ahead. | C14: Like-for-like is the same next-calendar-year multiple on CY2028 at the horizon. On consensus, NTM ($17.16) is 4.1% below CY2028 ($17.89), so agent_3's P/E leg is about $15 low. The same correction was sent to agent_5 on 2026-10-02. | D14: Arithmetic: 0.25 x 14.95 + 0.75 x 17.89 = 17.155.
A15: Q3 report date and the 1-month window | B15: agent_2: confirmed Oct 28. agent_1: S&P Global estimate of Oct 28, not yet announced (~97% inside). agent_3: late October, not announced. | C15: Confirmed: Wednesday 2026-10-28, call at 1:30pm PT (after the close), announced by Alphabet on 2026-10-06. It falls inside the window ending 2026-11-05, with six trading sessions of reaction (Oct 29 - Nov 5). Note: review_settings.json staged_entries.GOOGL says 'Q3 results (Oct 27)' with after = 2026-10-28. The print is after the close on Oct 28, so 'after' should be 2026-10-29 so that the second tranche is not bought before the print. | D15: abc.xyz press release 2026-10-06; EDGAR submissions (no 8-K, so the date release was not furnished on EDGAR).
