Workbook

Sheet Summary
A1: AMZN standard model (trial) · research run 2026-10-23
A2: The supervisor's reconciled assumption set as a live model. Trial: shown beside the blended page target, not used for trade levels until its weight is decided. Edit blue cells on Model (drivers) and Valuation (assumptions).
A3: Price target box | B3: Value
A4: Live price | B4: =IFERROR(GOOGLEFINANCE("AMZN","price"),Valuation!$B$67)
A5: Price as of | B5: =NOW()
A6: Model target (12-month median) | B6: =Distribution!$B$13
A7: Upside to model target from live price | B7: =B6/B4-1
A8: Research target (12m) (no scenario deltas) | B8: =Valuation!$D$7
A9: Probability-weighted mean | B9: =Distribution!$B$10
A10: 10th percentile | B10: =Distribution!$B$14
A11: 25th percentile | B11: =Distribution!$B$15
A12: 75th percentile | B12: =Distribution!$B$16
A13: 90th percentile | B13: =Distribution!$B$17
A14: Target date | B14: =Valuation!$B$45
A15: Price at the run | B15: =Valuation!$B$67
A16: Blended page target (options 67% + agents 33%, not live) | B16: 265.6556
A17: Supervisor research target (12m) (its own methods) | B17: 266.05
A18: Thesis break price (supervisor) | B18: 188
A19: Supervisor confidence | B19: low
A21: Key estimates | B21: FY2025A | C21: =Model!E5 | D21: =Model!F5
A22: Net sales | B22: =IF(Model!D24="","",Model!D24) | C22: =Model!E24 | D22: =Model!F24
A23: % YoY | B23: =IF(Model!D25="","",Model!D25) | C23: =Model!E25 | D23: =Model!F25
A24: Pretax margin | B24: =IF(Model!D35="","",Model!D35) | C24: =Model!E35 | D24: =Model!F35
A25: Diluted EPS (model) | B25: =IF(Model!D42="","",Model!D42) | C25: =Model!E42 | D25: =Model!F42
A26: % YoY | B26: =IF(Model!D43="","",Model!D43) | C26: =Model!E43 | D26: =Model!F43
A27: Free cash flow to firm | B27: =IF(Model!D52="","",Model!D52) | C27: =Model!E52 | D27: =Model!F52
A28: Consensus: EPS (GAAP (consensus; excludes mark-to-market) | D28: 10.51
A30: Valuation method | B30: Value per share | C30: Weight
A31: =Valuation!A4 | B31: =Valuation!D4 | C31: =Valuation!E4
A32: =Valuation!A5 | B32: =Valuation!D5 | C32: =Valuation!E5
A33: =Valuation!A6 | B33: =Valuation!D6 | C33: =Valuation!E6
A35: Scenario | B35: Probability | C35: Value at target date | D35: What has to happen
A36: =Distribution!A4 | B36: =Distribution!B4 | C36: =Distribution!C4 | D36: =Distribution!D4
A37: =Distribution!A5 | B37: =Distribution!B5 | C37: =Distribution!C5 | D37: =Distribution!D5
A38: =Distribution!A6 | B38: =Distribution!B6 | C38: =Distribution!C6 | D38: =Distribution!D6
A40: Price at target date | B40: Probability above
A41: =ROUND(Valuation!$B$67*0.7,0) | B41: =SUMPRODUCT(Distribution!$B$4:$B$6,1-NORMSDIST((LN(A41)-LN(Distribution!$C$4:$C$6))/Distribution!$B$9))
A42: =ROUND(Valuation!$B$67*0.8,0) | B42: =SUMPRODUCT(Distribution!$B$4:$B$6,1-NORMSDIST((LN(A42)-LN(Distribution!$C$4:$C$6))/Distribution!$B$9))
A43: =ROUND(Valuation!$B$67*0.9,0) | B43: =SUMPRODUCT(Distribution!$B$4:$B$6,1-NORMSDIST((LN(A43)-LN(Distribution!$C$4:$C$6))/Distribution!$B$9))
A44: =ROUND(Valuation!$B$67*1.0,0) | B44: =SUMPRODUCT(Distribution!$B$4:$B$6,1-NORMSDIST((LN(A44)-LN(Distribution!$C$4:$C$6))/Distribution!$B$9))
...

Sheet Model
A1: AMZN: annual model, base case
A2: (M of US dollars except per share; fiscal years named by the calendar year they end in)
A3: Blue = input · black = formula · green = link to another tab · actuals from SEC filings (fact ids in the last column, links on Sources)
A5: Fiscal year | B5: FY2023A | C5: FY2024A | D5: FY2025A | E5: FY2026E | F5: FY2027E | G5: FY2028E | H5: Source / note
A6: Period end | B6: 45291 | C6: 45657 | D6: 46022 | E6: =IF(DAY(Valuation!$B$49+1)=1,EOMONTH(Valuation!$B$49,12*E7),EDATE(Valuation!$B$49,12*E7)) | F6: =IF(DAY(Valuation!$B$49+1)=1,EOMONTH(Valuation!$B$49,12*F7),EDATE(Valuation!$B$49,12*F7)) | G6: =IF(DAY(Valuation!$B$49+1)=1,EOMONTH(Valuation!$B$49,12*G7),EDATE(Valuation!$B$49,12*G7))
A7: Projection year | B7: -2 | C7: -1 | D7: 0 | E7: 1 | F7: 2 | G7: 3
A10: Segment build (blue = input: revenue growth and EBIT margin by segment and year)
A11: AWS | D11: =Valuation!$B$99 | E11: =Valuation!$B$99*(1+E12) | F11: =E11*(1+F12) | G11: =F11*(1+G12)
A12: Revenue growth | E12: 0.34992415 | F12: 0.35009192 | G12: 0.25209242
A13: Segment EBIT | E13: =E11*E14 | F13: =F11*F14 | G13: =G11*G14
A14: EBIT margin | E14: 0.35653922 | F14: 0.33059331 | G14: 0.31842317
A15: North America + International | D15: =Valuation!$B$100 | E15: =Valuation!$B$100*(1+E16) | F15: =E15*(1+F16) | G15: =F15*(1+G16)
A16: Revenue growth | E16: 0.13097268 | F16: 0.095405096 | G16: 0.09407798
A17: Segment EBIT | E17: =E15*E18 | F17: =F15*F18 | G17: =G15*G18
A18: EBIT margin | E18: 0.065627402 | F18: 0.071738884 | G18: 0.077246006
A19: Total segment revenue (= net sales) | D19: =D11+D15 | E19: =E11+E15 | F19: =F11+F15 | G19: =G11+G15 | H19: base revenues on Valuation (segment build); net sales = this total
A20: Total segment EBIT | E20: =E13+E17 | F20: =F13+F17 | G20: =G13+G17
A21: Corporate / unallocated EBIT (blue = input) | E21: 0 | F21: =E21 | G21: =F21 | H21: years[].corporate_ebit; EBIT = total segment EBIT + corporate
A23: Sales
A24: Net sales | B24: 574785 | C24: 637959 | D24: 716924 | E24: =E19 | F24: =F19 | G24: =G19 | H24: SEC XBRL F1, F2, F3
A25: % YoY | C25: =IF(OR(C24="",B24="",B24=0),"",C24/B24-1) | D25: =IF(OR(D24="",C24="",C24=0),"",D24/C24-1) | E25: =E24/Valuation!$B$50-1 | F25: =F24/E24-1 | G25: =G24/F24-1
A27: Operating profit
A28: EBIT (operating income) | E28: =E20+E21 | F28: =F20+F21 | G28: =G20+G21
A29: EBIT margin | E29: =E28/E24 | F29: =F28/F24 | G29: =G28/G24
A30: D&A | B30: 48663 | C30: 52795 | D30: 65756 | E30: =E24*E64 | F30: =F24*F64 | G30: =G24*G64 | H30: SEC XBRL F34, F35, F36
A31: EBITDA | E31: =E28+E30 | F31: =F28+F30 | G31: =G28+G30
A32: EBITDA margin | E32: =E31/E24 | F32: =F31/F24 | G32: =G31/G24
A33: Net interest income / (expense) | E33: =-Valuation!$B$58*Valuation!$B$56 | F33: =-Valuation!$B$58*E58 | G33: =-Valuation!$B$58*F58 | H33: rate x prior year-end net debt (memo roll)
A34: Pretax income | B34: 37557 | C34: 68614 | D34: 97311 | E34: =E28+E33 | F34: =F28+F33 | G34: =G28+G33 | H34: SEC XBRL F76, F77, F78
A35: Pretax margin | B35: =B34/B24 | C35: =C34/C24 | D35: =D34/D24 | E35: =E34/E24 | F35: =F34/F24 | G35: =G34/G24
A36: Income tax | B36: 7120 | C36: 9265 | D36: 19087 | E36: =E34*E63 | F36: =F34*F63 | G36: =G34*G63 | H36: SEC XBRL F69, F70, F71
A37: Effective tax rate | B37: =B36/B34 | C37: =C36/C34 | D37: =D36/D34 | E37: =E36/E34 | F37: =F36/F34 | G37: =G36/G34
A38: Net income | B38: 30425 | C38: 59248 | D38: 77670 | E38: =E34-E36 | F38: =F34-F36 | G38: =G34-G36 | H38: SEC XBRL F15, F16, F17
A39: % YoY | C39: =IF(OR(C38="",B38="",B38=0),"",C38/B38-1) | D39: =IF(OR(D38="",C38="",C38=0),"",D38/C38-1) | E39: =IF(OR(D38="",D38=0),"",E38/D38-1) | F39: =IF(OR(E38="",E38=0),"",F38/E38-1) | G39: =IF(OR(F38="",F38=0),"",G38/F38-1)
A40: Diluted shares (M, average) | B40: 10492 | C40: 10721 | D40: 10827 | E40: =Valuation!$B$60*(1+Valuation!$B$62)^(E7-0.5-((Valuation!$B$61-Valuation!$B$49)/365.25)) | F40: =Valuation!$B$60*(1+Valuation!$B$62)^(F7-0.5-((Valuation!$B$61-Valuation!$B$49)/365.25)) | G40: =Valuation!$B$60*(1+Valuation!$B$62)^(G7-0.5-((Valuation!$B$61-Valuation!$B$49)/365.25)) | H40: diluted count rolled at the annual change to mid-year
A41: % YoY | C41: =IF(OR(C40="",B40="",B40=0),"",C40/B40-1) | D41: =IF(OR(D40="",C40="",C40=0),"",D40/C40-1) | E41: =IF(OR(D40="",D40=0),"",E40/D40-1) | F41: =IF(OR(E40="",E40=0),"",F40/E40-1) | G41: =IF(OR(F40="",F40=0),"",G40/F40-1)
A42: Diluted EPS | B42: 2.9 | C42: 5.53 | D42: 7.17 | E42: =E38/E40 | F42: =F38/F40 | G42: =G38/G40 | H42: SEC XBRL F22, F23, F24
A43: % YoY | C43: =IF(OR(C42="",B42="",B42=0),"",C42/B42-1) | D43: =IF(OR(D42="",C42="",C42=0),"",D42/C42-1) | E43: =IF(OR(D42="",D42=0),"",E42/D42-1) | F43: =IF(OR(E42="",E42=0),"",F42/E42-1) | G43: =IF(OR(F42="",F42=0),"",G42/F42-1)
A45: Cash flow
A46: NOPAT (EBIT x (1 - tax)) | E46: =E28*(1-E63) | F46: =F28*(1-F63) | G46: =G28*(1-G63)
...

Sheet Valuation
A1: AMZN: valuation and price target derivation
A2: Value per share at the target date = weighted methods below; the 12-month target is the median of the scenario mix (Distribution tab).
A3: Method | B3: Multiple | C3: Metric at target date | D3: Value per share | E3: Weight | F3: Contribution
A4: ='Calc - research target (12m)'!A67 | B4: =IF('Calc - research target (12m)'!C67="","",'Calc - research target (12m)'!C67) | C4: =IF('Calc - research target (12m)'!I67="","",'Calc - research target (12m)'!I67) | D4: ='Calc - research target (12m)'!F67 | E4: ='Calc - research target (12m)'!G67 | F4: =D4*E4/SUM($E$4:$E$6)
A5: ='Calc - research target (12m)'!A68 | B5: =IF('Calc - research target (12m)'!C68="","",'Calc - research target (12m)'!C68) | C5: =IF('Calc - research target (12m)'!I68="","",'Calc - research target (12m)'!I68) | D5: ='Calc - research target (12m)'!F68 | E5: ='Calc - research target (12m)'!G68 | F5: =D5*E5/SUM($E$4:$E$6)
A6: ='Calc - research target (12m)'!A69 | B6: =IF('Calc - research target (12m)'!C69="","",'Calc - research target (12m)'!C69) | C6: =IF('Calc - research target (12m)'!I69="","",'Calc - research target (12m)'!I69) | D6: ='Calc - research target (12m)'!F69 | E6: ='Calc - research target (12m)'!G69 | F6: =D6*E6/SUM($E$4:$E$6)
A7: Research target (12m) per share | D7: ='Calc - research target (12m)'!$F$70 | F7: =SUM(F4:F6)
A9: 12-month EPS basis (what the P/E is applied to)
A10: Fiscal year | B10: =Model!E5 | C10: =Model!F5 | D10: =Model!G5
A11: Share of the 12 months after the target date | B11: ='Calc - research target (12m)'!C38 | C11: ='Calc - research target (12m)'!D38 | D11: ='Calc - research target (12m)'!E38
A12: Model EPS (Model tab) | B12: =Model!E42 | C12: =Model!F42 | D12: =Model!G42
A13: Model EPS, next 12 months after the target date | B13: =SUMPRODUCT(B11:D11,B12:D12)
A14: Stated next-12-month EPS used by the P/E method (consensus basis, cited) | B14: =Valuation!F70 | C14: =B14/B13-1 | D14: vs model EPS
A16: DCF build (free cash flow to firm, discounted to the target date)
A17: Fiscal year | B17: =Model!E5 | C17: =Model!F5 | D17: =Model!G5
A18: Free cash flow to firm | B18: ='Calc - research target (12m)'!C31 | C18: ='Calc - research target (12m)'!D31 | D18: ='Calc - research target (12m)'!E31
A19: Share of the year after the target date | B19: ='Calc - research target (12m)'!C35 | C19: ='Calc - research target (12m)'!D35 | D19: ='Calc - research target (12m)'!E35
A20: PV at target date | B20: ='Calc - research target (12m)'!C36 | C20: ='Calc - research target (12m)'!D36 | D20: ='Calc - research target (12m)'!E36
A22: PV of free cash flow after the target date | B22: ='Calc - research target (12m)'!B42
A23: Terminal value (final year) | B23: ='Calc - research target (12m)'!B43
A24: PV of terminal value | B24: ='Calc - research target (12m)'!B44
A25: Enterprise value at target date | B25: ='Calc - research target (12m)'!B45
A26: Terminal value share of DCF | B26: ='Calc - research target (12m)'!B46
A27: Net debt at target date | B27: ='Calc - research target (12m)'!B50
A28: Minority interests | B28: ='Calc - research target (12m)'!B51
A29: Adjustments | B29: ='Calc - research target (12m)'!B52
A30: Diluted shares at target date (M) | B30: ='Calc - research target (12m)'!B53
A31: DCF value per share | B31: ='Calc - research target (12m)'!F67
A32: WACC | B32: ='Calc - research target (12m)'!B12
A42: Assumptions (blue = input; sources on the Sources tab)
A43: Input | B43: Value | C43: Basis / note
A44: Run date (valuation as of) | B44: 46318
A45: Target date (run date + 365 days) | B45: =B44+365 | C45: 12-month horizon
A46: Money unit | B46: $M
A47: EBIT basis (gaap / adjusted) | B47: gaap | C47: gaap = after stock comp
A48: Stock comp treatment (cost / dilution) | B48: cost | C48: used only when EBIT is adjusted
A49: Last reported fiscal year end | B49: 46022
A50: Net sales, last reported year ($M) | B50: 716924
A51: WACC | B51: 0.1044 | C51: filled in (not stated in this set's original work): agent_3's stated 10.44% WACC (cost of equity 5.31% + 1.31 x 4.20% = 10.79%; debt at 5.6% pre-tax, 21% tax), the only discount rate in the run. The supervisor gave the DCF no weight, so it is a diagnostic only (dcf_weight 0).
A52: Terminal method (gordon / exit_multiple / steady_state) | B52: gordon
...

Sheet Sensitivity
A1: AMZN: sensitivity tables (bold = current inputs; every cell recalculates from the live model)
A3: DCF value per share: WACC (down) x terminal growth (across)
A4: WACC \ growth | B4: =Valuation!$B$53+(-0.01) | C4: =Valuation!$B$53+(-0.005) | D4: =Valuation!$B$53+(0) | E4: =Valuation!$B$53+(0.005) | F4: =Valuation!$B$53+(0.01)
A5: =Valuation!$B$51+(-0.01) | B5: =IF($A5-B$4<=0.01,"n/a",((SUMPRODUCT('Calc - research target (12m)'!$C$31:$E$31,'Calc - research target (12m)'!$C$35:$E$35,(1+$A5)^(-('Calc - research target (12m)'!$C$19:$E$19-'Calc - research target (12m)'!$B$13)))+'Calc - research target (12m)'!$E$31*(1+B$4)/($A5-B$4)/(1+$A5)^('Calc - research target (12m)'!$B$16-'Calc - research target (12m)'!$B$13))-'Calc - research target (12m)'!$B$50-'Calc - research target (12m)'!$B$51+'Calc - research target (12m)'!$B$52)/'Calc - research target (12m)'!$B$53) | C5: =IF($A5-C$4<=0.01,"n/a",((SUMPRODUCT('Calc - research target (12m)'!$C$31:$E$31,'Calc - research target (12m)'!$C$35:$E$35,(1+$A5)^(-('Calc - research target (12m)'!$C$19:$E$19-'Calc - research target (12m)'!$B$13)))+'Calc - research target (12m)'!$E$31*(1+C$4)/($A5-C$4)/(1+$A5)^('Calc - research target (12m)'!$B$16-'Calc - research target (12m)'!$B$13))-'Calc - research target (12m)'!$B$50-'Calc - research target (12m)'!$B$51+'Calc - research target (12m)'!$B$52)/'Calc - research target (12m)'!$B$53) | D5: =IF($A5-D$4<=0.01,"n/a",((SUMPRODUCT('Calc - research target (12m)'!$C$31:$E$31,'Calc - research target (12m)'!$C$35:$E$35,(1+$A5)^(-('Calc - research target (12m)'!$C$19:$E$19-'Calc - research target (12m)'!$B$13)))+'Calc - research target (12m)'!$E$31*(1+D$4)/($A5-D$4)/(1+$A5)^('Calc - research target (12m)'!$B$16-'Calc - research target (12m)'!$B$13))-'Calc - research target (12m)'!$B$50-'Calc - research target (12m)'!$B$51+'Calc - research target (12m)'!$B$52)/'Calc - research target (12m)'!$B$53) | E5: =IF($A5-E$4<=0.01,"n/a",((SUMPRODUCT('Calc - research target (12m)'!$C$31:$E$31,'Calc - research target (12m)'!$C$35:$E$35,(1+$A5)^(-('Calc - research target (12m)'!$C$19:$E$19-'Calc - research target (12m)'!$B$13)))+'Calc - research target (12m)'!$E$31*(1+E$4)/($A5-E$4)/(1+$A5)^('Calc - research target (12m)'!$B$16-'Calc - research target (12m)'!$B$13))-'Calc - research target (12m)'!$B$50-'Calc - research target (12m)'!$B$51+'Calc - research target (12m)'!$B$52)/'Calc - research target (12m)'!$B$53) | F5: =IF($A5-F$4<=0.01,"n/a",((SUMPRODUCT('Calc - research target (12m)'!$C$31:$E$31,'Calc - research target (12m)'!$C$35:$E$35,(1+$A5)^(-('Calc - research target (12m)'!$C$19:$E$19-'Calc - research target (12m)'!$B$13)))+'Calc - research target (12m)'!$E$31*(1+F$4)/($A5-F$4)/(1+$A5)^('Calc - research target (12m)'!$B$16-'Calc - research target (12m)'!$B$13))-'Calc - research target (12m)'!$B$50-'Calc - research target (12m)'!$B$51+'Calc - research target (12m)'!$B$52)/'Calc - research target (12m)'!$B$53)
A6: =Valuation!$B$51+(-0.005) | B6: =IF($A6-B$4<=0.01,"n/a",((SUMPRODUCT('Calc - research target (12m)'!$C$31:$E$31,'Calc - research target (12m)'!$C$35:$E$35,(1+$A6)^(-('Calc - research target (12m)'!$C$19:$E$19-'Calc - research target (12m)'!$B$13)))+'Calc - research target (12m)'!$E$31*(1+B$4)/($A6-B$4)/(1+$A6)^('Calc - research target (12m)'!$B$16-'Calc - research target (12m)'!$B$13))-'Calc - research target (12m)'!$B$50-'Calc - research target (12m)'!$B$51+'Calc - research target (12m)'!$B$52)/'Calc - research target (12m)'!$B$53) | C6: =IF($A6-C$4<=0.01,"n/a",((SUMPRODUCT('Calc - research target (12m)'!$C$31:$E$31,'Calc - research target (12m)'!$C$35:$E$35,(1+$A6)^(-('Calc - research target (12m)'!$C$19:$E$19-'Calc - research target (12m)'!$B$13)))+'Calc - research target (12m)'!$E$31*(1+C$4)/($A6-C$4)/(1+$A6)^('Calc - research target (12m)'!$B$16-'Calc - research target (12m)'!$B$13))-'Calc - research target (12m)'!$B$50-'Calc - research target (12m)'!$B$51+'Calc - research target (12m)'!$B$52)/'Calc - research target (12m)'!$B$53) | D6: =IF($A6-D$4<=0.01,"n/a",((SUMPRODUCT('Calc - research target (12m)'!$C$31:$E$31,'Calc - research target (12m)'!$C$35:$E$35,(1+$A6)^(-('Calc - research target (12m)'!$C$19:$E$19-'Calc - research target (12m)'!$B$13)))+'Calc - research target (12m)'!$E$31*(1+D$4)/($A6-D$4)/(1+$A6)^('Calc - research target (12m)'!$B$16-'Calc - research target (12m)'!$B$13))-'Calc - research target (12m)'!$B$50-'Calc - research target (12m)'!$B$51+'Calc - research target (12m)'!$B$52)/'Calc - research target (12m)'!$B$53) | E6: =IF($A6-E$4<=0.01,"n/a",((SUMPRODUCT('Calc - research target (12m)'!$C$31:$E$31,'Calc - research target (12m)'!$C$35:$E$35,(1+$A6)^(-('Calc - research target (12m)'!$C$19:$E$19-'Calc - research target (12m)'!$B$13)))+'Calc - research target (12m)'!$E$31*(1+E$4)/($A6-E$4)/(1+$A6)^('Calc - research target (12m)'!$B$16-'Calc - research target (12m)'!$B$13))-'Calc - research target (12m)'!$B$50-'Calc - research target (12m)'!$B$51+'Calc - research target (12m)'!$B$52)/'Calc - research target (12m)'!$B$53) | F6: =IF($A6-F$4<=0.01,"n/a",((SUMPRODUCT('Calc - research target (12m)'!$C$31:$E$31,'Calc - research target (12m)'!$C$35:$E$35,(1+$A6)^(-('Calc - research target (12m)'!$C$19:$E$19-'Calc - research target (12m)'!$B$13)))+'Calc - research target (12m)'!$E$31*(1+F$4)/($A6-F$4)/(1+$A6)^('Calc - research target (12m)'!$B$16-'Calc - research target (12m)'!$B$13))-'Calc - research target (12m)'!$B$50-'Calc - research target (12m)'!$B$51+'Calc - research target (12m)'!$B$52)/'Calc - research target (12m)'!$B$53)
A7: =Valuation!$B$51+(0) | B7: =IF($A7-B$4<=0.01,"n/a",((SUMPRODUCT('Calc - research target (12m)'!$C$31:$E$31,'Calc - research target (12m)'!$C$35:$E$35,(1+$A7)^(-('Calc - research target (12m)'!$C$19:$E$19-'Calc - research target (12m)'!$B$13)))+'Calc - research target (12m)'!$E$31*(1+B$4)/($A7-B$4)/(1+$A7)^('Calc - research target (12m)'!$B$16-'Calc - research target (12m)'!$B$13))-'Calc - research target (12m)'!$B$50-'Calc - research target (12m)'!$B$51+'Calc - research target (12m)'!$B$52)/'Calc - research target (12m)'!$B$53) | C7: =IF($A7-C$4<=0.01,"n/a",((SUMPRODUCT('Calc - research target (12m)'!$C$31:$E$31,'Calc - research target (12m)'!$C$35:$E$35,(1+$A7)^(-('Calc - research target (12m)'!$C$19:$E$19-'Calc - research target (12m)'!$B$13)))+'Calc - research target (12m)'!$E$31*(1+C$4)/($A7-C$4)/(1+$A7)^('Calc - research target (12m)'!$B$16-'Calc - research target (12m)'!$B$13))-'Calc - research target (12m)'!$B$50-'Calc - research target (12m)'!$B$51+'Calc - research target (12m)'!$B$52)/'Calc - research target (12m)'!$B$53) | D7: =IF($A7-D$4<=0.01,"n/a",((SUMPRODUCT('Calc - research target (12m)'!$C$31:$E$31,'Calc - research target (12m)'!$C$35:$E$35,(1+$A7)^(-('Calc - research target (12m)'!$C$19:$E$19-'Calc - research target (12m)'!$B$13)))+'Calc - research target (12m)'!$E$31*(1+D$4)/($A7-D$4)/(1+$A7)^('Calc - research target (12m)'!$B$16-'Calc - research target (12m)'!$B$13))-'Calc - research target (12m)'!$B$50-'Calc - research target (12m)'!$B$51+'Calc - research target (12m)'!$B$52)/'Calc - research target (12m)'!$B$53) | E7: =IF($A7-E$4<=0.01,"n/a",((SUMPRODUCT('Calc - research target (12m)'!$C$31:$E$31,'Calc - research target (12m)'!$C$35:$E$35,(1+$A7)^(-('Calc - research target (12m)'!$C$19:$E$19-'Calc - research target (12m)'!$B$13)))+'Calc - research target (12m)'!$E$31*(1+E$4)/($A7-E$4)/(1+$A7)^('Calc - research target (12m)'!$B$16-'Calc - research target (12m)'!$B$13))-'Calc - research target (12m)'!$B$50-'Calc - research target (12m)'!$B$51+'Calc - research target (12m)'!$B$52)/'Calc - research target (12m)'!$B$53) | F7: =IF($A7-F$4<=0.01,"n/a",((SUMPRODUCT('Calc - research target (12m)'!$C$31:$E$31,'Calc - research target (12m)'!$C$35:$E$35,(1+$A7)^(-('Calc - research target (12m)'!$C$19:$E$19-'Calc - research target (12m)'!$B$13)))+'Calc - research target (12m)'!$E$31*(1+F$4)/($A7-F$4)/(1+$A7)^('Calc - research target (12m)'!$B$16-'Calc - research target (12m)'!$B$13))-'Calc - research target (12m)'!$B$50-'Calc - research target (12m)'!$B$51+'Calc - research target (12m)'!$B$52)/'Calc - research target (12m)'!$B$53)
A8: =Valuation!$B$51+(0.005) | B8: =IF($A8-B$4<=0.01,"n/a",((SUMPRODUCT('Calc - research target (12m)'!$C$31:$E$31,'Calc - research target (12m)'!$C$35:$E$35,(1+$A8)^(-('Calc - research target (12m)'!$C$19:$E$19-'Calc - research target (12m)'!$B$13)))+'Calc - research target (12m)'!$E$31*(1+B$4)/($A8-B$4)/(1+$A8)^('Calc - research target (12m)'!$B$16-'Calc - research target (12m)'!$B$13))-'Calc - research target (12m)'!$B$50-'Calc - research target (12m)'!$B$51+'Calc - research target (12m)'!$B$52)/'Calc - research target (12m)'!$B$53) | C8: =IF($A8-C$4<=0.01,"n/a",((SUMPRODUCT('Calc - research target (12m)'!$C$31:$E$31,'Calc - research target (12m)'!$C$35:$E$35,(1+$A8)^(-('Calc - research target (12m)'!$C$19:$E$19-'Calc - research target (12m)'!$B$13)))+'Calc - research target (12m)'!$E$31*(1+C$4)/($A8-C$4)/(1+$A8)^('Calc - research target (12m)'!$B$16-'Calc - research target (12m)'!$B$13))-'Calc - research target (12m)'!$B$50-'Calc - research target (12m)'!$B$51+'Calc - research target (12m)'!$B$52)/'Calc - research target (12m)'!$B$53) | D8: =IF($A8-D$4<=0.01,"n/a",((SUMPRODUCT('Calc - research target (12m)'!$C$31:$E$31,'Calc - research target (12m)'!$C$35:$E$35,(1+$A8)^(-('Calc - research target (12m)'!$C$19:$E$19-'Calc - research target (12m)'!$B$13)))+'Calc - research target (12m)'!$E$31*(1+D$4)/($A8-D$4)/(1+$A8)^('Calc - research target (12m)'!$B$16-'Calc - research target (12m)'!$B$13))-'Calc - research target (12m)'!$B$50-'Calc - research target (12m)'!$B$51+'Calc - research target (12m)'!$B$52)/'Calc - research target (12m)'!$B$53) | E8: =IF($A8-E$4<=0.01,"n/a",((SUMPRODUCT('Calc - research target (12m)'!$C$31:$E$31,'Calc - research target (12m)'!$C$35:$E$35,(1+$A8)^(-('Calc - research target (12m)'!$C$19:$E$19-'Calc - research target (12m)'!$B$13)))+'Calc - research target (12m)'!$E$31*(1+E$4)/($A8-E$4)/(1+$A8)^('Calc - research target (12m)'!$B$16-'Calc - research target (12m)'!$B$13))-'Calc - research target (12m)'!$B$50-'Calc - research target (12m)'!$B$51+'Calc - research target (12m)'!$B$52)/'Calc - research target (12m)'!$B$53) | F8: =IF($A8-F$4<=0.01,"n/a",((SUMPRODUCT('Calc - research target (12m)'!$C$31:$E$31,'Calc - research target (12m)'!$C$35:$E$35,(1+$A8)^(-('Calc - research target (12m)'!$C$19:$E$19-'Calc - research target (12m)'!$B$13)))+'Calc - research target (12m)'!$E$31*(1+F$4)/($A8-F$4)/(1+$A8)^('Calc - research target (12m)'!$B$16-'Calc - research target (12m)'!$B$13))-'Calc - research target (12m)'!$B$50-'Calc - research target (12m)'!$B$51+'Calc - research target (12m)'!$B$52)/'Calc - research target (12m)'!$B$53)
A9: =Valuation!$B$51+(0.01) | B9: =IF($A9-B$4<=0.01,"n/a",((SUMPRODUCT('Calc - research target (12m)'!$C$31:$E$31,'Calc - research target (12m)'!$C$35:$E$35,(1+$A9)^(-('Calc - research target (12m)'!$C$19:$E$19-'Calc - research target (12m)'!$B$13)))+'Calc - research target (12m)'!$E$31*(1+B$4)/($A9-B$4)/(1+$A9)^('Calc - research target (12m)'!$B$16-'Calc - research target (12m)'!$B$13))-'Calc - research target (12m)'!$B$50-'Calc - research target (12m)'!$B$51+'Calc - research target (12m)'!$B$52)/'Calc - research target (12m)'!$B$53) | C9: =IF($A9-C$4<=0.01,"n/a",((SUMPRODUCT('Calc - research target (12m)'!$C$31:$E$31,'Calc - research target (12m)'!$C$35:$E$35,(1+$A9)^(-('Calc - research target (12m)'!$C$19:$E$19-'Calc - research target (12m)'!$B$13)))+'Calc - research target (12m)'!$E$31*(1+C$4)/($A9-C$4)/(1+$A9)^('Calc - research target (12m)'!$B$16-'Calc - research target (12m)'!$B$13))-'Calc - research target (12m)'!$B$50-'Calc - research target (12m)'!$B$51+'Calc - research target (12m)'!$B$52)/'Calc - research target (12m)'!$B$53) | D9: =IF($A9-D$4<=0.01,"n/a",((SUMPRODUCT('Calc - research target (12m)'!$C$31:$E$31,'Calc - research target (12m)'!$C$35:$E$35,(1+$A9)^(-('Calc - research target (12m)'!$C$19:$E$19-'Calc - research target (12m)'!$B$13)))+'Calc - research target (12m)'!$E$31*(1+D$4)/($A9-D$4)/(1+$A9)^('Calc - research target (12m)'!$B$16-'Calc - research target (12m)'!$B$13))-'Calc - research target (12m)'!$B$50-'Calc - research target (12m)'!$B$51+'Calc - research target (12m)'!$B$52)/'Calc - research target (12m)'!$B$53) | E9: =IF($A9-E$4<=0.01,"n/a",((SUMPRODUCT('Calc - research target (12m)'!$C$31:$E$31,'Calc - research target (12m)'!$C$35:$E$35,(1+$A9)^(-('Calc - research target (12m)'!$C$19:$E$19-'Calc - research target (12m)'!$B$13)))+'Calc - research target (12m)'!$E$31*(1+E$4)/($A9-E$4)/(1+$A9)^('Calc - research target (12m)'!$B$16-'Calc - research target (12m)'!$B$13))-'Calc - research target (12m)'!$B$50-'Calc - research target (12m)'!$B$51+'Calc - research target (12m)'!$B$52)/'Calc - research target (12m)'!$B$53) | F9: =IF($A9-F$4<=0.01,"n/a",((SUMPRODUCT('Calc - research target (12m)'!$C$31:$E$31,'Calc - research target (12m)'!$C$35:$E$35,(1+$A9)^(-('Calc - research target (12m)'!$C$19:$E$19-'Calc - research target (12m)'!$B$13)))+'Calc - research target (12m)'!$E$31*(1+F$4)/($A9-F$4)/(1+$A9)^('Calc - research target (12m)'!$B$16-'Calc - research target (12m)'!$B$13))-'Calc - research target (12m)'!$B$50-'Calc - research target (12m)'!$B$51+'Calc - research target (12m)'!$B$52)/'Calc - research target (12m)'!$B$53)
A11: Research target (12m) per share: P/E multiple (down) x stated EPS (across)
A12: Multiple \ metric | B12: =Valuation!F70*0.9 | C12: =Valuation!F70*0.95 | D12: =Valuation!F70*1.0 | E12: =Valuation!F70*1.05 | F12: =Valuation!F70*1.1
A13: =Valuation!$B$70+(-3) | B13: =((SUMPRODUCT('Calc - research target (12m)'!$F$67:$F$69,'Calc - research target (12m)'!$G$67:$G$69)-'Calc - research target (12m)'!$F$68*'Calc - research target (12m)'!$G$68)+'Calc - research target (12m)'!$G$68*($A13*B$12+'Calc - research target (12m)'!$B$52/'Calc - research target (12m)'!$B$53))/SUM('Calc - research target (12m)'!$G$67:$G$69) | C13: =((SUMPRODUCT('Calc - research target (12m)'!$F$67:$F$69,'Calc - research target (12m)'!$G$67:$G$69)-'Calc - research target (12m)'!$F$68*'Calc - research target (12m)'!$G$68)+'Calc - research target (12m)'!$G$68*($A13*C$12+'Calc - research target (12m)'!$B$52/'Calc - research target (12m)'!$B$53))/SUM('Calc - research target (12m)'!$G$67:$G$69) | D13: =((SUMPRODUCT('Calc - research target (12m)'!$F$67:$F$69,'Calc - research target (12m)'!$G$67:$G$69)-'Calc - research target (12m)'!$F$68*'Calc - research target (12m)'!$G$68)+'Calc - research target (12m)'!$G$68*($A13*D$12+'Calc - research target (12m)'!$B$52/'Calc - research target (12m)'!$B$53))/SUM('Calc - research target (12m)'!$G$67:$G$69) | E13: =((SUMPRODUCT('Calc - research target (12m)'!$F$67:$F$69,'Calc - research target (12m)'!$G$67:$G$69)-'Calc - research target (12m)'!$F$68*'Calc - research target (12m)'!$G$68)+'Calc - research target (12m)'!$G$68*($A13*E$12+'Calc - research target (12m)'!$B$52/'Calc - research target (12m)'!$B$53))/SUM('Calc - research target (12m)'!$G$67:$G$69) | F13: =((SUMPRODUCT('Calc - research target (12m)'!$F$67:$F$69,'Calc - research target (12m)'!$G$67:$G$69)-'Calc - research target (12m)'!$F$68*'Calc - research target (12m)'!$G$68)+'Calc - research target (12m)'!$G$68*($A13*F$12+'Calc - research target (12m)'!$B$52/'Calc - research target (12m)'!$B$53))/SUM('Calc - research target (12m)'!$G$67:$G$69)
A14: =Valuation!$B$70+(-2) | B14: =((SUMPRODUCT('Calc - research target (12m)'!$F$67:$F$69,'Calc - research target (12m)'!$G$67:$G$69)-'Calc - research target (12m)'!$F$68*'Calc - research target (12m)'!$G$68)+'Calc - research target (12m)'!$G$68*($A14*B$12+'Calc - research target (12m)'!$B$52/'Calc - research target (12m)'!$B$53))/SUM('Calc - research target (12m)'!$G$67:$G$69) | C14: =((SUMPRODUCT('Calc - research target (12m)'!$F$67:$F$69,'Calc - research target (12m)'!$G$67:$G$69)-'Calc - research target (12m)'!$F$68*'Calc - research target (12m)'!$G$68)+'Calc - research target (12m)'!$G$68*($A14*C$12+'Calc - research target (12m)'!$B$52/'Calc - research target (12m)'!$B$53))/SUM('Calc - research target (12m)'!$G$67:$G$69) | D14: =((SUMPRODUCT('Calc - research target (12m)'!$F$67:$F$69,'Calc - research target (12m)'!$G$67:$G$69)-'Calc - research target (12m)'!$F$68*'Calc - research target (12m)'!$G$68)+'Calc - research target (12m)'!$G$68*($A14*D$12+'Calc - research target (12m)'!$B$52/'Calc - research target (12m)'!$B$53))/SUM('Calc - research target (12m)'!$G$67:$G$69) | E14: =((SUMPRODUCT('Calc - research target (12m)'!$F$67:$F$69,'Calc - research target (12m)'!$G$67:$G$69)-'Calc - research target (12m)'!$F$68*'Calc - research target (12m)'!$G$68)+'Calc - research target (12m)'!$G$68*($A14*E$12+'Calc - research target (12m)'!$B$52/'Calc - research target (12m)'!$B$53))/SUM('Calc - research target (12m)'!$G$67:$G$69) | F14: =((SUMPRODUCT('Calc - research target (12m)'!$F$67:$F$69,'Calc - research target (12m)'!$G$67:$G$69)-'Calc - research target (12m)'!$F$68*'Calc - research target (12m)'!$G$68)+'Calc - research target (12m)'!$G$68*($A14*F$12+'Calc - research target (12m)'!$B$52/'Calc - research target (12m)'!$B$53))/SUM('Calc - research target (12m)'!$G$67:$G$69)
A15: =Valuation!$B$70+(-1) | B15: =((SUMPRODUCT('Calc - research target (12m)'!$F$67:$F$69,'Calc - research target (12m)'!$G$67:$G$69)-'Calc - research target (12m)'!$F$68*'Calc - research target (12m)'!$G$68)+'Calc - research target (12m)'!$G$68*($A15*B$12+'Calc - research target (12m)'!$B$52/'Calc - research target (12m)'!$B$53))/SUM('Calc - research target (12m)'!$G$67:$G$69) | C15: =((SUMPRODUCT('Calc - research target (12m)'!$F$67:$F$69,'Calc - research target (12m)'!$G$67:$G$69)-'Calc - research target (12m)'!$F$68*'Calc - research target (12m)'!$G$68)+'Calc - research target (12m)'!$G$68*($A15*C$12+'Calc - research target (12m)'!$B$52/'Calc - research target (12m)'!$B$53))/SUM('Calc - research target (12m)'!$G$67:$G$69) | D15: =((SUMPRODUCT('Calc - research target (12m)'!$F$67:$F$69,'Calc - research target (12m)'!$G$67:$G$69)-'Calc - research target (12m)'!$F$68*'Calc - research target (12m)'!$G$68)+'Calc - research target (12m)'!$G$68*($A15*D$12+'Calc - research target (12m)'!$B$52/'Calc - research target (12m)'!$B$53))/SUM('Calc - research target (12m)'!$G$67:$G$69) | E15: =((SUMPRODUCT('Calc - research target (12m)'!$F$67:$F$69,'Calc - research target (12m)'!$G$67:$G$69)-'Calc - research target (12m)'!$F$68*'Calc - research target (12m)'!$G$68)+'Calc - research target (12m)'!$G$68*($A15*E$12+'Calc - research target (12m)'!$B$52/'Calc - research target (12m)'!$B$53))/SUM('Calc - research target (12m)'!$G$67:$G$69) | F15: =((SUMPRODUCT('Calc - research target (12m)'!$F$67:$F$69,'Calc - research target (12m)'!$G$67:$G$69)-'Calc - research target (12m)'!$F$68*'Calc - research target (12m)'!$G$68)+'Calc - research target (12m)'!$G$68*($A15*F$12+'Calc - research target (12m)'!$B$52/'Calc - research target (12m)'!$B$53))/SUM('Calc - research target (12m)'!$G$67:$G$69)
A16: =Valuation!$B$70+(0) | B16: =((SUMPRODUCT('Calc - research target (12m)'!$F$67:$F$69,'Calc - research target (12m)'!$G$67:$G$69)-'Calc - research target (12m)'!$F$68*'Calc - research target (12m)'!$G$68)+'Calc - research target (12m)'!$G$68*($A16*B$12+'Calc - research target (12m)'!$B$52/'Calc - research target (12m)'!$B$53))/SUM('Calc - research target (12m)'!$G$67:$G$69) | C16: =((SUMPRODUCT('Calc - research target (12m)'!$F$67:$F$69,'Calc - research target (12m)'!$G$67:$G$69)-'Calc - research target (12m)'!$F$68*'Calc - research target (12m)'!$G$68)+'Calc - research target (12m)'!$G$68*($A16*C$12+'Calc - research target (12m)'!$B$52/'Calc - research target (12m)'!$B$53))/SUM('Calc - research target (12m)'!$G$67:$G$69) | D16: =((SUMPRODUCT('Calc - research target (12m)'!$F$67:$F$69,'Calc - research target (12m)'!$G$67:$G$69)-'Calc - research target (12m)'!$F$68*'Calc - research target (12m)'!$G$68)+'Calc - research target (12m)'!$G$68*($A16*D$12+'Calc - research target (12m)'!$B$52/'Calc - research target (12m)'!$B$53))/SUM('Calc - research target (12m)'!$G$67:$G$69) | E16: =((SUMPRODUCT('Calc - research target (12m)'!$F$67:$F$69,'Calc - research target (12m)'!$G$67:$G$69)-'Calc - research target (12m)'!$F$68*'Calc - research target (12m)'!$G$68)+'Calc - research target (12m)'!$G$68*($A16*E$12+'Calc - research target (12m)'!$B$52/'Calc - research target (12m)'!$B$53))/SUM('Calc - research target (12m)'!$G$67:$G$69) | F16: =((SUMPRODUCT('Calc - research target (12m)'!$F$67:$F$69,'Calc - research target (12m)'!$G$67:$G$69)-'Calc - research target (12m)'!$F$68*'Calc - research target (12m)'!$G$68)+'Calc - research target (12m)'!$G$68*($A16*F$12+'Calc - research target (12m)'!$B$52/'Calc - research target (12m)'!$B$53))/SUM('Calc - research target (12m)'!$G$67:$G$69)
A17: =Valuation!$B$70+(1) | B17: =((SUMPRODUCT('Calc - research target (12m)'!$F$67:$F$69,'Calc - research target (12m)'!$G$67:$G$69)-'Calc - research target (12m)'!$F$68*'Calc - research target (12m)'!$G$68)+'Calc - research target (12m)'!$G$68*($A17*B$12+'Calc - research target (12m)'!$B$52/'Calc - research target (12m)'!$B$53))/SUM('Calc - research target (12m)'!$G$67:$G$69) | C17: =((SUMPRODUCT('Calc - research target (12m)'!$F$67:$F$69,'Calc - research target (12m)'!$G$67:$G$69)-'Calc - research target (12m)'!$F$68*'Calc - research target (12m)'!$G$68)+'Calc - research target (12m)'!$G$68*($A17*C$12+'Calc - research target (12m)'!$B$52/'Calc - research target (12m)'!$B$53))/SUM('Calc - research target (12m)'!$G$67:$G$69) | D17: =((SUMPRODUCT('Calc - research target (12m)'!$F$67:$F$69,'Calc - research target (12m)'!$G$67:$G$69)-'Calc - research target (12m)'!$F$68*'Calc - research target (12m)'!$G$68)+'Calc - research target (12m)'!$G$68*($A17*D$12+'Calc - research target (12m)'!$B$52/'Calc - research target (12m)'!$B$53))/SUM('Calc - research target (12m)'!$G$67:$G$69) | E17: =((SUMPRODUCT('Calc - research target (12m)'!$F$67:$F$69,'Calc - research target (12m)'!$G$67:$G$69)-'Calc - research target (12m)'!$F$68*'Calc - research target (12m)'!$G$68)+'Calc - research target (12m)'!$G$68*($A17*E$12+'Calc - research target (12m)'!$B$52/'Calc - research target (12m)'!$B$53))/SUM('Calc - research target (12m)'!$G$67:$G$69) | F17: =((SUMPRODUCT('Calc - research target (12m)'!$F$67:$F$69,'Calc - research target (12m)'!$G$67:$G$69)-'Calc - research target (12m)'!$F$68*'Calc - research target (12m)'!$G$68)+'Calc - research target (12m)'!$G$68*($A17*F$12+'Calc - research target (12m)'!$B$52/'Calc - research target (12m)'!$B$53))/SUM('Calc - research target (12m)'!$G$67:$G$69)
A18: =Valuation!$B$70+(2) | B18: =((SUMPRODUCT('Calc - research target (12m)'!$F$67:$F$69,'Calc - research target (12m)'!$G$67:$G$69)-'Calc - research target (12m)'!$F$68*'Calc - research target (12m)'!$G$68)+'Calc - research target (12m)'!$G$68*($A18*B$12+'Calc - research target (12m)'!$B$52/'Calc - research target (12m)'!$B$53))/SUM('Calc - research target (12m)'!$G$67:$G$69) | C18: =((SUMPRODUCT('Calc - research target (12m)'!$F$67:$F$69,'Calc - research target (12m)'!$G$67:$G$69)-'Calc - research target (12m)'!$F$68*'Calc - research target (12m)'!$G$68)+'Calc - research target (12m)'!$G$68*($A18*C$12+'Calc - research target (12m)'!$B$52/'Calc - research target (12m)'!$B$53))/SUM('Calc - research target (12m)'!$G$67:$G$69) | D18: =((SUMPRODUCT('Calc - research target (12m)'!$F$67:$F$69,'Calc - research target (12m)'!$G$67:$G$69)-'Calc - research target (12m)'!$F$68*'Calc - research target (12m)'!$G$68)+'Calc - research target (12m)'!$G$68*($A18*D$12+'Calc - research target (12m)'!$B$52/'Calc - research target (12m)'!$B$53))/SUM('Calc - research target (12m)'!$G$67:$G$69) | E18: =((SUMPRODUCT('Calc - research target (12m)'!$F$67:$F$69,'Calc - research target (12m)'!$G$67:$G$69)-'Calc - research target (12m)'!$F$68*'Calc - research target (12m)'!$G$68)+'Calc - research target (12m)'!$G$68*($A18*E$12+'Calc - research target (12m)'!$B$52/'Calc - research target (12m)'!$B$53))/SUM('Calc - research target (12m)'!$G$67:$G$69) | F18: =((SUMPRODUCT('Calc - research target (12m)'!$F$67:$F$69,'Calc - research target (12m)'!$G$67:$G$69)-'Calc - research target (12m)'!$F$68*'Calc - research target (12m)'!$G$68)+'Calc - research target (12m)'!$G$68*($A18*F$12+'Calc - research target (12m)'!$B$52/'Calc - research target (12m)'!$B$53))/SUM('Calc - research target (12m)'!$G$67:$G$69)
A19: =Valuation!$B$70+(3) | B19: =((SUMPRODUCT('Calc - research target (12m)'!$F$67:$F$69,'Calc - research target (12m)'!$G$67:$G$69)-'Calc - research target (12m)'!$F$68*'Calc - research target (12m)'!$G$68)+'Calc - research target (12m)'!$G$68*($A19*B$12+'Calc - research target (12m)'!$B$52/'Calc - research target (12m)'!$B$53))/SUM('Calc - research target (12m)'!$G$67:$G$69) | C19: =((SUMPRODUCT('Calc - research target (12m)'!$F$67:$F$69,'Calc - research target (12m)'!$G$67:$G$69)-'Calc - research target (12m)'!$F$68*'Calc - research target (12m)'!$G$68)+'Calc - research target (12m)'!$G$68*($A19*C$12+'Calc - research target (12m)'!$B$52/'Calc - research target (12m)'!$B$53))/SUM('Calc - research target (12m)'!$G$67:$G$69) | D19: =((SUMPRODUCT('Calc - research target (12m)'!$F$67:$F$69,'Calc - research target (12m)'!$G$67:$G$69)-'Calc - research target (12m)'!$F$68*'Calc - research target (12m)'!$G$68)+'Calc - research target (12m)'!$G$68*($A19*D$12+'Calc - research target (12m)'!$B$52/'Calc - research target (12m)'!$B$53))/SUM('Calc - research target (12m)'!$G$67:$G$69) | E19: =((SUMPRODUCT('Calc - research target (12m)'!$F$67:$F$69,'Calc - research target (12m)'!$G$67:$G$69)-'Calc - research target (12m)'!$F$68*'Calc - research target (12m)'!$G$68)+'Calc - research target (12m)'!$G$68*($A19*E$12+'Calc - research target (12m)'!$B$52/'Calc - research target (12m)'!$B$53))/SUM('Calc - research target (12m)'!$G$67:$G$69) | F19: =((SUMPRODUCT('Calc - research target (12m)'!$F$67:$F$69,'Calc - research target (12m)'!$G$67:$G$69)-'Calc - research target (12m)'!$F$68*'Calc - research target (12m)'!$G$68)+'Calc - research target (12m)'!$G$68*($A19*F$12+'Calc - research target (12m)'!$B$52/'Calc - research target (12m)'!$B$53))/SUM('Calc - research target (12m)'!$G$67:$G$69)
A22: FY2027E diluted EPS: revenue growth change in every year (down) x EBIT margin change (across)
A23: Growth Δ \ margin Δ | B23: -0.01 | C23: -0.005 | D23: 0 | E23: 0.005 | F23: 0.01
A24: -0.02 | B24: =(Valuation!$B$99*(1+Model!E12+$A24)*(1+Model!F12+$A24)*(Model!F14+B$23)+Valuation!$B$100*(1+Model!E16+$A24)*(1+Model!F16+$A24)*(Model!F18+B$23)+Model!F21+Model!F33)*(1-Model!F63)/Model!F40 | C24: =(Valuation!$B$99*(1+Model!E12+$A24)*(1+Model!F12+$A24)*(Model!F14+C$23)+Valuation!$B$100*(1+Model!E16+$A24)*(1+Model!F16+$A24)*(Model!F18+C$23)+Model!F21+Model!F33)*(1-Model!F63)/Model!F40 | D24: =(Valuation!$B$99*(1+Model!E12+$A24)*(1+Model!F12+$A24)*(Model!F14+D$23)+Valuation!$B$100*(1+Model!E16+$A24)*(1+Model!F16+$A24)*(Model!F18+D$23)+Model!F21+Model!F33)*(1-Model!F63)/Model!F40 | E24: =(Valuation!$B$99*(1+Model!E12+$A24)*(1+Model!F12+$A24)*(Model!F14+E$23)+Valuation!$B$100*(1+Model!E16+$A24)*(1+Model!F16+$A24)*(Model!F18+E$23)+Model!F21+Model!F33)*(1-Model!F63)/Model!F40 | F24: =(Valuation!$B$99*(1+Model!E12+$A24)*(1+Model!F12+$A24)*(Model!F14+F$23)+Valuation!$B$100*(1+Model!E16+$A24)*(1+Model!F16+$A24)*(Model!F18+F$23)+Model!F21+Model!F33)*(1-Model!F63)/Model!F40
A25: -0.01 | B25: =(Valuation!$B$99*(1+Model!E12+$A25)*(1+Model!F12+$A25)*(Model!F14+B$23)+Valuation!$B$100*(1+Model!E16+$A25)*(1+Model!F16+$A25)*(Model!F18+B$23)+Model!F21+Model!F33)*(1-Model!F63)/Model!F40 | C25: =(Valuation!$B$99*(1+Model!E12+$A25)*(1+Model!F12+$A25)*(Model!F14+C$23)+Valuation!$B$100*(1+Model!E16+$A25)*(1+Model!F16+$A25)*(Model!F18+C$23)+Model!F21+Model!F33)*(1-Model!F63)/Model!F40 | D25: =(Valuation!$B$99*(1+Model!E12+$A25)*(1+Model!F12+$A25)*(Model!F14+D$23)+Valuation!$B$100*(1+Model!E16+$A25)*(1+Model!F16+$A25)*(Model!F18+D$23)+Model!F21+Model!F33)*(1-Model!F63)/Model!F40 | E25: =(Valuation!$B$99*(1+Model!E12+$A25)*(1+Model!F12+$A25)*(Model!F14+E$23)+Valuation!$B$100*(1+Model!E16+$A25)*(1+Model!F16+$A25)*(Model!F18+E$23)+Model!F21+Model!F33)*(1-Model!F63)/Model!F40 | F25: =(Valuation!$B$99*(1+Model!E12+$A25)*(1+Model!F12+$A25)*(Model!F14+F$23)+Valuation!$B$100*(1+Model!E16+$A25)*(1+Model!F16+$A25)*(Model!F18+F$23)+Model!F21+Model!F33)*(1-Model!F63)/Model!F40
A26: 0 | B26: =(Valuation!$B$99*(1+Model!E12+$A26)*(1+Model!F12+$A26)*(Model!F14+B$23)+Valuation!$B$100*(1+Model!E16+$A26)*(1+Model!F16+$A26)*(Model!F18+B$23)+Model!F21+Model!F33)*(1-Model!F63)/Model!F40 | C26: =(Valuation!$B$99*(1+Model!E12+$A26)*(1+Model!F12+$A26)*(Model!F14+C$23)+Valuation!$B$100*(1+Model!E16+$A26)*(1+Model!F16+$A26)*(Model!F18+C$23)+Model!F21+Model!F33)*(1-Model!F63)/Model!F40 | D26: =(Valuation!$B$99*(1+Model!E12+$A26)*(1+Model!F12+$A26)*(Model!F14+D$23)+Valuation!$B$100*(1+Model!E16+$A26)*(1+Model!F16+$A26)*(Model!F18+D$23)+Model!F21+Model!F33)*(1-Model!F63)/Model!F40 | E26: =(Valuation!$B$99*(1+Model!E12+$A26)*(1+Model!F12+$A26)*(Model!F14+E$23)+Valuation!$B$100*(1+Model!E16+$A26)*(1+Model!F16+$A26)*(Model!F18+E$23)+Model!F21+Model!F33)*(1-Model!F63)/Model!F40 | F26: =(Valuation!$B$99*(1+Model!E12+$A26)*(1+Model!F12+$A26)*(Model!F14+F$23)+Valuation!$B$100*(1+Model!E16+$A26)*(1+Model!F16+$A26)*(Model!F18+F$23)+Model!F21+Model!F33)*(1-Model!F63)/Model!F40
A27: 0.01 | B27: =(Valuation!$B$99*(1+Model!E12+$A27)*(1+Model!F12+$A27)*(Model!F14+B$23)+Valuation!$B$100*(1+Model!E16+$A27)*(1+Model!F16+$A27)*(Model!F18+B$23)+Model!F21+Model!F33)*(1-Model!F63)/Model!F40 | C27: =(Valuation!$B$99*(1+Model!E12+$A27)*(1+Model!F12+$A27)*(Model!F14+C$23)+Valuation!$B$100*(1+Model!E16+$A27)*(1+Model!F16+$A27)*(Model!F18+C$23)+Model!F21+Model!F33)*(1-Model!F63)/Model!F40 | D27: =(Valuation!$B$99*(1+Model!E12+$A27)*(1+Model!F12+$A27)*(Model!F14+D$23)+Valuation!$B$100*(1+Model!E16+$A27)*(1+Model!F16+$A27)*(Model!F18+D$23)+Model!F21+Model!F33)*(1-Model!F63)/Model!F40 | E27: =(Valuation!$B$99*(1+Model!E12+$A27)*(1+Model!F12+$A27)*(Model!F14+E$23)+Valuation!$B$100*(1+Model!E16+$A27)*(1+Model!F16+$A27)*(Model!F18+E$23)+Model!F21+Model!F33)*(1-Model!F63)/Model!F40 | F27: =(Valuation!$B$99*(1+Model!E12+$A27)*(1+Model!F12+$A27)*(Model!F14+F$23)+Valuation!$B$100*(1+Model!E16+$A27)*(1+Model!F16+$A27)*(Model!F18+F$23)+Model!F21+Model!F33)*(1-Model!F63)/Model!F40
A28: 0.02 | B28: =(Valuation!$B$99*(1+Model!E12+$A28)*(1+Model!F12+$A28)*(Model!F14+B$23)+Valuation!$B$100*(1+Model!E16+$A28)*(1+Model!F16+$A28)*(Model!F18+B$23)+Model!F21+Model!F33)*(1-Model!F63)/Model!F40 | C28: =(Valuation!$B$99*(1+Model!E12+$A28)*(1+Model!F12+$A28)*(Model!F14+C$23)+Valuation!$B$100*(1+Model!E16+$A28)*(1+Model!F16+$A28)*(Model!F18+C$23)+Model!F21+Model!F33)*(1-Model!F63)/Model!F40 | D28: =(Valuation!$B$99*(1+Model!E12+$A28)*(1+Model!F12+$A28)*(Model!F14+D$23)+Valuation!$B$100*(1+Model!E16+$A28)*(1+Model!F16+$A28)*(Model!F18+D$23)+Model!F21+Model!F33)*(1-Model!F63)/Model!F40 | E28: =(Valuation!$B$99*(1+Model!E12+$A28)*(1+Model!F12+$A28)*(Model!F14+E$23)+Valuation!$B$100*(1+Model!E16+$A28)*(1+Model!F16+$A28)*(Model!F18+E$23)+Model!F21+Model!F33)*(1-Model!F63)/Model!F40 | F28: =(Valuation!$B$99*(1+Model!E12+$A28)*(1+Model!F12+$A28)*(Model!F14+F$23)+Valuation!$B$100*(1+Model!E16+$A28)*(1+Model!F16+$A28)*(Model!F18+F$23)+Model!F21+Model!F33)*(1-Model!F63)/Model!F40
A30: Net interest and the share count are held at the base case in table 3.

Sheet Distribution
A1: AMZN: 12-month distribution (mix of lognormals around each scenario value)
A3: Scenario | B3: Probability | C3: Value at target date | D3: Story
A4: bear | B4: =Valuation!B94 | C4: ='Calc - bear'!$F$70 | D4: =Valuation!J94
A5: base | B5: =Valuation!B95 | C5: ='Calc - base'!$F$70 | D5: =Valuation!J95
A6: bull | B6: =Valuation!B96 | C6: ='Calc - bull'!$F$70 | D6: =Valuation!J96
A8: Probabilities sum to | B8: =SUM(B4:B6)
A9: Spread within each scenario | B9: =Valuation!$B$66
A10: Probability-weighted mean | B10: =($B$4*$C$4+$B$5*$C$5+$B$6*$C$6)*EXP($B$9^2/2)
A12: Quantile | B12: Price
A13: Median (model target) | B13: =SQRT(A60*B60)
A14: 10th percentile | B14: =SQRT(D60*E60)
A15: 25th percentile | B15: =SQRT(G60*H60)
A16: 75th percentile | B16: =SQRT(J60*K60)
A17: 90th percentile | B17: =SQRT(M60*N60)
A19: Each quantile solved by bisection (block: low, high, probability above the midpoint)
A20: Median (model target): low | B20: high | C20: P(above mid) | D20: 10th percentile: low | E20: high | F20: P(above mid) | G20: 25th percentile: low | H20: high | I20: P(above mid) | J20: 75th percentile: low | K20: high | L20: P(above mid) | M20: 90th percentile: low | N20: high | O20: P(above mid)
A21: =MIN($C$4,$C$5,$C$6)*0.2 | B21: =MAX($C$4,$C$5,$C$6)*4 | C21: =SUMPRODUCT($B$4:$B$6,1-NORMSDIST((LN(SQRT(A21*B21))-LN($C$4:$C$6))/$B$9)) | D21: =MIN($C$4,$C$5,$C$6)*0.2 | E21: =MAX($C$4,$C$5,$C$6)*4 | F21: =SUMPRODUCT($B$4:$B$6,1-NORMSDIST((LN(SQRT(D21*E21))-LN($C$4:$C$6))/$B$9)) | G21: =MIN($C$4,$C$5,$C$6)*0.2 | H21: =MAX($C$4,$C$5,$C$6)*4 | I21: =SUMPRODUCT($B$4:$B$6,1-NORMSDIST((LN(SQRT(G21*H21))-LN($C$4:$C$6))/$B$9)) | J21: =MIN($C$4,$C$5,$C$6)*0.2 | K21: =MAX($C$4,$C$5,$C$6)*4 | L21: =SUMPRODUCT($B$4:$B$6,1-NORMSDIST((LN(SQRT(J21*K21))-LN($C$4:$C$6))/$B$9)) | M21: =MIN($C$4,$C$5,$C$6)*0.2 | N21: =MAX($C$4,$C$5,$C$6)*4 | O21: =SUMPRODUCT($B$4:$B$6,1-NORMSDIST((LN(SQRT(M21*N21))-LN($C$4:$C$6))/$B$9))
A22: =IF(C21>0.5,SQRT(A21*B21),A21) | B22: =IF(C21>0.5,B21,SQRT(A21*B21)) | C22: =SUMPRODUCT($B$4:$B$6,1-NORMSDIST((LN(SQRT(A22*B22))-LN($C$4:$C$6))/$B$9)) | D22: =IF(F21>0.9,SQRT(D21*E21),D21) | E22: =IF(F21>0.9,E21,SQRT(D21*E21)) | F22: =SUMPRODUCT($B$4:$B$6,1-NORMSDIST((LN(SQRT(D22*E22))-LN($C$4:$C$6))/$B$9)) | G22: =IF(I21>0.75,SQRT(G21*H21),G21) | H22: =IF(I21>0.75,H21,SQRT(G21*H21)) | I22: =SUMPRODUCT($B$4:$B$6,1-NORMSDIST((LN(SQRT(G22*H22))-LN($C$4:$C$6))/$B$9)) | J22: =IF(L21>0.25,SQRT(J21*K21),J21) | K22: =IF(L21>0.25,K21,SQRT(J21*K21)) | L22: =SUMPRODUCT($B$4:$B$6,1-NORMSDIST((LN(SQRT(J22*K22))-LN($C$4:$C$6))/$B$9)) | M22: =IF(O21>0.09999999999999998,SQRT(M21*N21),M21) | N22: =IF(O21>0.09999999999999998,N21,SQRT(M21*N21)) | O22: =SUMPRODUCT($B$4:$B$6,1-NORMSDIST((LN(SQRT(M22*N22))-LN($C$4:$C$6))/$B$9))
A23: =IF(C22>0.5,SQRT(A22*B22),A22) | B23: =IF(C22>0.5,B22,SQRT(A22*B22)) | C23: =SUMPRODUCT($B$4:$B$6,1-NORMSDIST((LN(SQRT(A23*B23))-LN($C$4:$C$6))/$B$9)) | D23: =IF(F22>0.9,SQRT(D22*E22),D22) | E23: =IF(F22>0.9,E22,SQRT(D22*E22)) | F23: =SUMPRODUCT($B$4:$B$6,1-NORMSDIST((LN(SQRT(D23*E23))-LN($C$4:$C$6))/$B$9)) | G23: =IF(I22>0.75,SQRT(G22*H22),G22) | H23: =IF(I22>0.75,H22,SQRT(G22*H22)) | I23: =SUMPRODUCT($B$4:$B$6,1-NORMSDIST((LN(SQRT(G23*H23))-LN($C$4:$C$6))/$B$9)) | J23: =IF(L22>0.25,SQRT(J22*K22),J22) | K23: =IF(L22>0.25,K22,SQRT(J22*K22)) | L23: =SUMPRODUCT($B$4:$B$6,1-NORMSDIST((LN(SQRT(J23*K23))-LN($C$4:$C$6))/$B$9)) | M23: =IF(O22>0.09999999999999998,SQRT(M22*N22),M22) | N23: =IF(O22>0.09999999999999998,N22,SQRT(M22*N22)) | O23: =SUMPRODUCT($B$4:$B$6,1-NORMSDIST((LN(SQRT(M23*N23))-LN($C$4:$C$6))/$B$9))
A24: =IF(C23>0.5,SQRT(A23*B23),A23) | B24: =IF(C23>0.5,B23,SQRT(A23*B23)) | C24: =SUMPRODUCT($B$4:$B$6,1-NORMSDIST((LN(SQRT(A24*B24))-LN($C$4:$C$6))/$B$9)) | D24: =IF(F23>0.9,SQRT(D23*E23),D23) | E24: =IF(F23>0.9,E23,SQRT(D23*E23)) | F24: =SUMPRODUCT($B$4:$B$6,1-NORMSDIST((LN(SQRT(D24*E24))-LN($C$4:$C$6))/$B$9)) | G24: =IF(I23>0.75,SQRT(G23*H23),G23) | H24: =IF(I23>0.75,H23,SQRT(G23*H23)) | I24: =SUMPRODUCT($B$4:$B$6,1-NORMSDIST((LN(SQRT(G24*H24))-LN($C$4:$C$6))/$B$9)) | J24: =IF(L23>0.25,SQRT(J23*K23),J23) | K24: =IF(L23>0.25,K23,SQRT(J23*K23)) | L24: =SUMPRODUCT($B$4:$B$6,1-NORMSDIST((LN(SQRT(J24*K24))-LN($C$4:$C$6))/$B$9)) | M24: =IF(O23>0.09999999999999998,SQRT(M23*N23),M23) | N24: =IF(O23>0.09999999999999998,N23,SQRT(M23*N23)) | O24: =SUMPRODUCT($B$4:$B$6,1-NORMSDIST((LN(SQRT(M24*N24))-LN($C$4:$C$6))/$B$9))
A25: =IF(C24>0.5,SQRT(A24*B24),A24) | B25: =IF(C24>0.5,B24,SQRT(A24*B24)) | C25: =SUMPRODUCT($B$4:$B$6,1-NORMSDIST((LN(SQRT(A25*B25))-LN($C$4:$C$6))/$B$9)) | D25: =IF(F24>0.9,SQRT(D24*E24),D24) | E25: =IF(F24>0.9,E24,SQRT(D24*E24)) | F25: =SUMPRODUCT($B$4:$B$6,1-NORMSDIST((LN(SQRT(D25*E25))-LN($C$4:$C$6))/$B$9)) | G25: =IF(I24>0.75,SQRT(G24*H24),G24) | H25: =IF(I24>0.75,H24,SQRT(G24*H24)) | I25: =SUMPRODUCT($B$4:$B$6,1-NORMSDIST((LN(SQRT(G25*H25))-LN($C$4:$C$6))/$B$9)) | J25: =IF(L24>0.25,SQRT(J24*K24),J24) | K25: =IF(L24>0.25,K24,SQRT(J24*K24)) | L25: =SUMPRODUCT($B$4:$B$6,1-NORMSDIST((LN(SQRT(J25*K25))-LN($C$4:$C$6))/$B$9)) | M25: =IF(O24>0.09999999999999998,SQRT(M24*N24),M24) | N25: =IF(O24>0.09999999999999998,N24,SQRT(M24*N24)) | O25: =SUMPRODUCT($B$4:$B$6,1-NORMSDIST((LN(SQRT(M25*N25))-LN($C$4:$C$6))/$B$9))
A26: =IF(C25>0.5,SQRT(A25*B25),A25) | B26: =IF(C25>0.5,B25,SQRT(A25*B25)) | C26: =SUMPRODUCT($B$4:$B$6,1-NORMSDIST((LN(SQRT(A26*B26))-LN($C$4:$C$6))/$B$9)) | D26: =IF(F25>0.9,SQRT(D25*E25),D25) | E26: =IF(F25>0.9,E25,SQRT(D25*E25)) | F26: =SUMPRODUCT($B$4:$B$6,1-NORMSDIST((LN(SQRT(D26*E26))-LN($C$4:$C$6))/$B$9)) | G26: =IF(I25>0.75,SQRT(G25*H25),G25) | H26: =IF(I25>0.75,H25,SQRT(G25*H25)) | I26: =SUMPRODUCT($B$4:$B$6,1-NORMSDIST((LN(SQRT(G26*H26))-LN($C$4:$C$6))/$B$9)) | J26: =IF(L25>0.25,SQRT(J25*K25),J25) | K26: =IF(L25>0.25,K25,SQRT(J25*K25)) | L26: =SUMPRODUCT($B$4:$B$6,1-NORMSDIST((LN(SQRT(J26*K26))-LN($C$4:$C$6))/$B$9)) | M26: =IF(O25>0.09999999999999998,SQRT(M25*N25),M25) | N26: =IF(O25>0.09999999999999998,N25,SQRT(M25*N25)) | O26: =SUMPRODUCT($B$4:$B$6,1-NORMSDIST((LN(SQRT(M26*N26))-LN($C$4:$C$6))/$B$9))
A27: =IF(C26>0.5,SQRT(A26*B26),A26) | B27: =IF(C26>0.5,B26,SQRT(A26*B26)) | C27: =SUMPRODUCT($B$4:$B$6,1-NORMSDIST((LN(SQRT(A27*B27))-LN($C$4:$C$6))/$B$9)) | D27: =IF(F26>0.9,SQRT(D26*E26),D26) | E27: =IF(F26>0.9,E26,SQRT(D26*E26)) | F27: =SUMPRODUCT($B$4:$B$6,1-NORMSDIST((LN(SQRT(D27*E27))-LN($C$4:$C$6))/$B$9)) | G27: =IF(I26>0.75,SQRT(G26*H26),G26) | H27: =IF(I26>0.75,H26,SQRT(G26*H26)) | I27: =SUMPRODUCT($B$4:$B$6,1-NORMSDIST((LN(SQRT(G27*H27))-LN($C$4:$C$6))/$B$9)) | J27: =IF(L26>0.25,SQRT(J26*K26),J26) | K27: =IF(L26>0.25,K26,SQRT(J26*K26)) | L27: =SUMPRODUCT($B$4:$B$6,1-NORMSDIST((LN(SQRT(J27*K27))-LN($C$4:$C$6))/$B$9)) | M27: =IF(O26>0.09999999999999998,SQRT(M26*N26),M26) | N27: =IF(O26>0.09999999999999998,N26,SQRT(M26*N26)) | O27: =SUMPRODUCT($B$4:$B$6,1-NORMSDIST((LN(SQRT(M27*N27))-LN($C$4:$C$6))/$B$9))
A28: =IF(C27>0.5,SQRT(A27*B27),A27) | B28: =IF(C27>0.5,B27,SQRT(A27*B27)) | C28: =SUMPRODUCT($B$4:$B$6,1-NORMSDIST((LN(SQRT(A28*B28))-LN($C$4:$C$6))/$B$9)) | D28: =IF(F27>0.9,SQRT(D27*E27),D27) | E28: =IF(F27>0.9,E27,SQRT(D27*E27)) | F28: =SUMPRODUCT($B$4:$B$6,1-NORMSDIST((LN(SQRT(D28*E28))-LN($C$4:$C$6))/$B$9)) | G28: =IF(I27>0.75,SQRT(G27*H27),G27) | H28: =IF(I27>0.75,H27,SQRT(G27*H27)) | I28: =SUMPRODUCT($B$4:$B$6,1-NORMSDIST((LN(SQRT(G28*H28))-LN($C$4:$C$6))/$B$9)) | J28: =IF(L27>0.25,SQRT(J27*K27),J27) | K28: =IF(L27>0.25,K27,SQRT(J27*K27)) | L28: =SUMPRODUCT($B$4:$B$6,1-NORMSDIST((LN(SQRT(J28*K28))-LN($C$4:$C$6))/$B$9)) | M28: =IF(O27>0.09999999999999998,SQRT(M27*N27),M27) | N28: =IF(O27>0.09999999999999998,N27,SQRT(M27*N27)) | O28: =SUMPRODUCT($B$4:$B$6,1-NORMSDIST((LN(SQRT(M28*N28))-LN($C$4:$C$6))/$B$9))
A29: =IF(C28>0.5,SQRT(A28*B28),A28) | B29: =IF(C28>0.5,B28,SQRT(A28*B28)) | C29: =SUMPRODUCT($B$4:$B$6,1-NORMSDIST((LN(SQRT(A29*B29))-LN($C$4:$C$6))/$B$9)) | D29: =IF(F28>0.9,SQRT(D28*E28),D28) | E29: =IF(F28>0.9,E28,SQRT(D28*E28)) | F29: =SUMPRODUCT($B$4:$B$6,1-NORMSDIST((LN(SQRT(D29*E29))-LN($C$4:$C$6))/$B$9)) | G29: =IF(I28>0.75,SQRT(G28*H28),G28) | H29: =IF(I28>0.75,H28,SQRT(G28*H28)) | I29: =SUMPRODUCT($B$4:$B$6,1-NORMSDIST((LN(SQRT(G29*H29))-LN($C$4:$C$6))/$B$9)) | J29: =IF(L28>0.25,SQRT(J28*K28),J28) | K29: =IF(L28>0.25,K28,SQRT(J28*K28)) | L29: =SUMPRODUCT($B$4:$B$6,1-NORMSDIST((LN(SQRT(J29*K29))-LN($C$4:$C$6))/$B$9)) | M29: =IF(O28>0.09999999999999998,SQRT(M28*N28),M28) | N29: =IF(O28>0.09999999999999998,N28,SQRT(M28*N28)) | O29: =SUMPRODUCT($B$4:$B$6,1-NORMSDIST((LN(SQRT(M29*N29))-LN($C$4:$C$6))/$B$9))
A30: =IF(C29>0.5,SQRT(A29*B29),A29) | B30: =IF(C29>0.5,B29,SQRT(A29*B29)) | C30: =SUMPRODUCT($B$4:$B$6,1-NORMSDIST((LN(SQRT(A30*B30))-LN($C$4:$C$6))/$B$9)) | D30: =IF(F29>0.9,SQRT(D29*E29),D29) | E30: =IF(F29>0.9,E29,SQRT(D29*E29)) | F30: =SUMPRODUCT($B$4:$B$6,1-NORMSDIST((LN(SQRT(D30*E30))-LN($C$4:$C$6))/$B$9)) | G30: =IF(I29>0.75,SQRT(G29*H29),G29) | H30: =IF(I29>0.75,H29,SQRT(G29*H29)) | I30: =SUMPRODUCT($B$4:$B$6,1-NORMSDIST((LN(SQRT(G30*H30))-LN($C$4:$C$6))/$B$9)) | J30: =IF(L29>0.25,SQRT(J29*K29),J29) | K30: =IF(L29>0.25,K29,SQRT(J29*K29)) | L30: =SUMPRODUCT($B$4:$B$6,1-NORMSDIST((LN(SQRT(J30*K30))-LN($C$4:$C$6))/$B$9)) | M30: =IF(O29>0.09999999999999998,SQRT(M29*N29),M29) | N30: =IF(O29>0.09999999999999998,N29,SQRT(M29*N29)) | O30: =SUMPRODUCT($B$4:$B$6,1-NORMSDIST((LN(SQRT(M30*N30))-LN($C$4:$C$6))/$B$9))
A31: =IF(C30>0.5,SQRT(A30*B30),A30) | B31: =IF(C30>0.5,B30,SQRT(A30*B30)) | C31: =SUMPRODUCT($B$4:$B$6,1-NORMSDIST((LN(SQRT(A31*B31))-LN($C$4:$C$6))/$B$9)) | D31: =IF(F30>0.9,SQRT(D30*E30),D30) | E31: =IF(F30>0.9,E30,SQRT(D30*E30)) | F31: =SUMPRODUCT($B$4:$B$6,1-NORMSDIST((LN(SQRT(D31*E31))-LN($C$4:$C$6))/$B$9)) | G31: =IF(I30>0.75,SQRT(G30*H30),G30) | H31: =IF(I30>0.75,H30,SQRT(G30*H30)) | I31: =SUMPRODUCT($B$4:$B$6,1-NORMSDIST((LN(SQRT(G31*H31))-LN($C$4:$C$6))/$B$9)) | J31: =IF(L30>0.25,SQRT(J30*K30),J30) | K31: =IF(L30>0.25,K30,SQRT(J30*K30)) | L31: =SUMPRODUCT($B$4:$B$6,1-NORMSDIST((LN(SQRT(J31*K31))-LN($C$4:$C$6))/$B$9)) | M31: =IF(O30>0.09999999999999998,SQRT(M30*N30),M30) | N31: =IF(O30>0.09999999999999998,N30,SQRT(M30*N30)) | O31: =SUMPRODUCT($B$4:$B$6,1-NORMSDIST((LN(SQRT(M31*N31))-LN($C$4:$C$6))/$B$9))
A32: =IF(C31>0.5,SQRT(A31*B31),A31) | B32: =IF(C31>0.5,B31,SQRT(A31*B31)) | C32: =SUMPRODUCT($B$4:$B$6,1-NORMSDIST((LN(SQRT(A32*B32))-LN($C$4:$C$6))/$B$9)) | D32: =IF(F31>0.9,SQRT(D31*E31),D31) | E32: =IF(F31>0.9,E31,SQRT(D31*E31)) | F32: =SUMPRODUCT($B$4:$B$6,1-NORMSDIST((LN(SQRT(D32*E32))-LN($C$4:$C$6))/$B$9)) | G32: =IF(I31>0.75,SQRT(G31*H31),G31) | H32: =IF(I31>0.75,H31,SQRT(G31*H31)) | I32: =SUMPRODUCT($B$4:$B$6,1-NORMSDIST((LN(SQRT(G32*H32))-LN($C$4:$C$6))/$B$9)) | J32: =IF(L31>0.25,SQRT(J31*K31),J31) | K32: =IF(L31>0.25,K31,SQRT(J31*K31)) | L32: =SUMPRODUCT($B$4:$B$6,1-NORMSDIST((LN(SQRT(J32*K32))-LN($C$4:$C$6))/$B$9)) | M32: =IF(O31>0.09999999999999998,SQRT(M31*N31),M31) | N32: =IF(O31>0.09999999999999998,N31,SQRT(M31*N31)) | O32: =SUMPRODUCT($B$4:$B$6,1-NORMSDIST((LN(SQRT(M32*N32))-LN($C$4:$C$6))/$B$9))
A33: =IF(C32>0.5,SQRT(A32*B32),A32) | B33: =IF(C32>0.5,B32,SQRT(A32*B32)) | C33: =SUMPRODUCT($B$4:$B$6,1-NORMSDIST((LN(SQRT(A33*B33))-LN($C$4:$C$6))/$B$9)) | D33: =IF(F32>0.9,SQRT(D32*E32),D32) | E33: =IF(F32>0.9,E32,SQRT(D32*E32)) | F33: =SUMPRODUCT($B$4:$B$6,1-NORMSDIST((LN(SQRT(D33*E33))-LN($C$4:$C$6))/$B$9)) | G33: =IF(I32>0.75,SQRT(G32*H32),G32) | H33: =IF(I32>0.75,H32,SQRT(G32*H32)) | I33: =SUMPRODUCT($B$4:$B$6,1-NORMSDIST((LN(SQRT(G33*H33))-LN($C$4:$C$6))/$B$9)) | J33: =IF(L32>0.25,SQRT(J32*K32),J32) | K33: =IF(L32>0.25,K32,SQRT(J32*K32)) | L33: =SUMPRODUCT($B$4:$B$6,1-NORMSDIST((LN(SQRT(J33*K33))-LN($C$4:$C$6))/$B$9)) | M33: =IF(O32>0.09999999999999998,SQRT(M32*N32),M32) | N33: =IF(O32>0.09999999999999998,N32,SQRT(M32*N32)) | O33: =SUMPRODUCT($B$4:$B$6,1-NORMSDIST((LN(SQRT(M33*N33))-LN($C$4:$C$6))/$B$9))
... A60: =IF(C59>0.5,SQRT(A59*B59),A59) | B60: =IF(C59>0.5,B59,SQRT(A59*B59)) | C60: =SUMPRODUCT($B$4:$B$6,1-NORMSDIST((LN(SQRT(A60*B60))-LN($C$4:$C$6))/$B$9)) | D60: =IF(F59>0.9,SQRT(D59*E59),D59) | E60: =IF(F59>0.9,E59,SQRT(D59*E59)) | F60: =SUMPRODUCT($B$4:$B$6,1-NORMSDIST((LN(SQRT(D60*E60))-LN($C$4:$C$6))/$B$9)) | G60: =IF(I59>0.75,SQRT(G59*H59),G59) | H60: =IF(I59>0.75,H59,SQRT(G59*H59)) | I60: =SUMPRODUCT($B$4:$B$6,1-NORMSDIST((LN(SQRT(G60*H60))-LN($C$4:$C$6))/$B$9)) | J60: =IF(L59>0.25,SQRT(J59*K59),J59) | K60: =IF(L59>0.25,K59,SQRT(J59*K59)) | L60: =SUMPRODUCT($B$4:$B$6,1-NORMSDIST((LN(SQRT(J60*K60))-LN($C$4:$C$6))/$B$9)) | M60: =IF(O59>0.09999999999999998,SQRT(M59*N59),M59) | N60: =IF(O59>0.09999999999999998,N59,SQRT(M59*N59)) | O60: =SUMPRODUCT($B$4:$B$6,1-NORMSDIST((LN(SQRT(M60*N60))-LN($C$4:$C$6))/$B$9))

Sheet Calc - research target (12m)
A1: AMZN engine calculation: research target (12m) (reconciled set, no scenario deltas)
A2: Machinery behind the Valuation and Distribution tabs; drivers come from Model, assumptions from Valuation.
A4: Scenario Growth Δ | B4: 0
A5: Scenario Margin Δ | B5: 0
A6: Scenario Multiple Δ (turns) | B6: 0
A7: Scenario WACC Δ | B7: 0
A8: Scenario Multiple %Δ | B8: 0
A9: Scenario Stated EPS/FCF %Δ | B9: 0
A10: Scenario Custom %Δ | B10: 0
A12: WACC | B12: =Valuation!$B$51+B7
A13: Years from last FY end to target date | B13: =(Valuation!$B$45-Valuation!$B$49)/365.25
A14: Years from last FY end to balance date | B14: =(Valuation!$B$55-Valuation!$B$49)/365.25
A15: Years from last FY end to share count date | B15: =(Valuation!$B$61-Valuation!$B$49)/365.25
A16: Projected years | B16: 3
A18: Projection | B18: Base | C18: =Model!E5 | D18: =Model!F5 | E18: =Model!G5
A19: Year index | B19: 0 | C19: 1 | D19: 2 | E19: 3
A20: Period end | C20: =Valuation!$B$49+ROUND(365.25*C19,0) | D20: =Valuation!$B$49+ROUND(365.25*D19,0) | E20: =Valuation!$B$49+ROUND(365.25*E19,0)
A21: Revenue growth | C21: =C22/B22-1 | D21: =D22/C22-1 | E21: =E22/D22-1
A22: Revenue | B22: =Valuation!$B$50 | C22: =C139 | D22: =D139 | E22: =E139
A23: EBIT margin | C23: =C24/C22 | D23: =D24/D22 | E23: =E24/E22
A24: EBIT | C24: =C142 | D24: =D142 | E24: =E142
A25: Tax rate | C25: =Model!E63 | D25: =Model!F63 | E25: =Model!G63
A26: NOPAT | C26: =C24*(1-C25) | D26: =D24*(1-D25) | E26: =E24*(1-E25)
A27: D&A | C27: =C22*(Model!E64) | D27: =D22*(Model!F64) | E27: =E22*(Model!G64)
A28: Capex | C28: =C22*(Model!E65) | D28: =D22*(Model!F65) | E28: =E22*(Model!G65)
A29: Working capital increase | C29: =(Model!E66)*(C22-B22) | D29: =(Model!F66)*(D22-C22) | E29: =(Model!G66)*(E22-D22)
A30: Stock comp | C30: =C22*(Model!E67) | D30: =D22*(Model!F67) | E30: =E22*(Model!G67)
A31: Free cash flow to firm | C31: =C26+C27-C28-C29-IF(AND(Valuation!$B$47="adjusted",Valuation!$B$48="cost"),C30*(1-C25),0) | D31: =D26+D27-D28-D29-IF(AND(Valuation!$B$47="adjusted",Valuation!$B$48="cost"),D30*(1-D25),0) | E31: =E26+E27-E28-E29-IF(AND(Valuation!$B$47="adjusted",Valuation!$B$48="cost"),E30*(1-E25),0)
A32: EBITDA | C32: =C24+C27 | D32: =D24+D27 | E32: =E24+E27
A33: Adj. EBITDA | C33: =C24+C27+C22*(Model!E71) | D33: =D24+D27+D22*(Model!F71) | E33: =E24+E27+E22*(Model!G71)
A34: Shareholder returns + other uses | C34: =C22*Model!E69+Model!E68+Model!E70 | D34: =D22*Model!F69+Model!F68+Model!F70 | E34: =E22*Model!G69+Model!G68+Model!G70
A35: Share of year after target date | C35: =IF(C19<=$B$13,0,C19-MAX(C19-1,$B$13)) | D35: =IF(D19<=$B$13,0,D19-MAX(D19-1,$B$13)) | E35: =IF(E19<=$B$13,0,E19-MAX(E19-1,$B$13))
A36: PV at target date of FCFF | C36: =IF(C35=0,0,C31*C35/(1+$B$12)^(C19-$B$13)) | D36: =IF(D35=0,0,D31*D35/(1+$B$12)^(D19-$B$13)) | E36: =IF(E35=0,0,E31*E35/(1+$B$12)^(E19-$B$13))
A37: Overlap: balance date to target date | C37: =MAX(0,MIN(C19,$B$13)-MAX(C19-1,$B$14)) | D37: =MAX(0,MIN(D19,$B$13)-MAX(D19-1,$B$14)) | E37: =MAX(0,MIN(E19,$B$13)-MAX(E19-1,$B$14))
A38: NTM weight at target date | C38: =MAX(0,MIN(C19,$B$13+1)-MAX(C19-1,$B$13)) | D38: =MAX(0,MIN(D19,$B$13+1)-MAX(D19-1,$B$13)) | E38: =MAX(0,MIN(E19,$B$13+1)-MAX(E19-1,$B$13))
A39: LTM weight at target date | B39: =MAX(0,MIN(0,$B$13)-MAX(-1,$B$13-1)) | C39: =MAX(0,MIN(C19,$B$13)-MAX(C19-1,$B$13-1)) | D39: =MAX(0,MIN(D19,$B$13)-MAX(D19-1,$B$13-1)) | E39: =MAX(0,MIN(E19,$B$13)-MAX(E19-1,$B$13-1))
A41: Value at the target date
A42: PV of free cash flow after the target date | B42: =SUM($C$36:$E$36)
