Workbook

Sheet Summary
A1: AVGO standard model (trial) · research run 2026-10-29
A2: The supervisor's reconciled assumption set as a live model. Trial: shown beside the blended page target, not used for trade levels until its weight is decided. Edit blue cells on Model (drivers) and Valuation (assumptions).
A3: Price target box | B3: Value
A4: Live price | B4: =IFERROR(GOOGLEFINANCE("AVGO","price"),Valuation!$B$66)
A5: Price as of | B5: =NOW()
A6: Model target (12-month median) | B6: =Distribution!$B$13
A7: Upside to model target from live price | B7: =B6/B4-1
A8: Research target (12m) (no scenario deltas) | B8: =Valuation!$D$6
A9: Mean | B9: =Distribution!$B$10
A10: 10th percentile | B10: =Distribution!$B$14
A11: 25th percentile | B11: =Distribution!$B$15
A12: 75th percentile | B12: =Distribution!$B$16
A13: 90th percentile | B13: =Distribution!$B$17
A14: Target date | B14: =Valuation!$B$44
A15: Price at the run | B15: =Valuation!$B$66
A16: Blended page target (options 67% + agents 33%, not live) | B16: 399.2003
A17: Supervisor research target (12m) (its own methods) | B17: 488.51
A18: Thesis break price (supervisor) | B18: 260
A19: Supervisor confidence | B19: low
A21: Key estimates | B21: FY2025A | C21: =Model!E5 | D21: =Model!F5
A22: Net sales | B22: =IF(Model!D24="","",Model!D24) | C22: =Model!E24 | D22: =Model!F24
A23: % YoY | B23: =IF(Model!D25="","",Model!D25) | C23: =Model!E25 | D23: =Model!F25
A24: Pretax margin | B24: =IF(Model!D35="","",Model!D35) | C24: =Model!E35 | D24: =Model!F35
A25: Diluted EPS (model) | B25: =IF(Model!D42="","",Model!D42) | C25: =Model!E42 | D25: =Model!F42
A26: % YoY | B26: =IF(Model!D43="","",Model!D43) | C26: =Model!E43 | D26: =Model!F43
A27: Free cash flow to firm | B27: =IF(Model!D52="","",Model!D52) | C27: =Model!E52 | D27: =Model!F52
A28: Consensus: EPS () | D28: 17.45
A30: Valuation method | B30: Value per share | C30: Weight
A31: =Valuation!A4 | B31: =Valuation!D4 | C31: =Valuation!E4
A33: Case | B33: Percentile | C33: Value at target date | D33: What has to happen
A34: =Distribution!A4 | B34: =Distribution!B4 | C34: =Distribution!C4 | D34: =Distribution!D4
A35: =Distribution!A5 | B35: =Distribution!B5 | C35: =Distribution!C5 | D35: =Distribution!D5
A36: =Distribution!A6 | B36: =Distribution!B6 | C36: =Distribution!C6 | D36: =Distribution!D6
A38: Price at target date | B38: Probability above
A39: =ROUND(Valuation!$B$66*0.7,0) | B39: =1-NORMSDIST(LN(A39/Distribution!$C$5)/IF(A39<Distribution!$C$5,MAX(Distribution!$B$8,0.02),MAX(Distribution!$B$9,0.02)))
A40: =ROUND(Valuation!$B$66*0.8,0) | B40: =1-NORMSDIST(LN(A40/Distribution!$C$5)/IF(A40<Distribution!$C$5,MAX(Distribution!$B$8,0.02),MAX(Distribution!$B$9,0.02)))
A41: =ROUND(Valuation!$B$66*0.9,0) | B41: =1-NORMSDIST(LN(A41/Distribution!$C$5)/IF(A41<Distribution!$C$5,MAX(Distribution!$B$8,0.02),MAX(Distribution!$B$9,0.02)))
A42: =ROUND(Valuation!$B$66*1.0,0) | B42: =1-NORMSDIST(LN(A42/Distribution!$C$5)/IF(A42<Distribution!$C$5,MAX(Distribution!$B$8,0.02),MAX(Distribution!$B$9,0.02)))
A43: =ROUND(Valuation!$B$66*1.1,0) | B43: =1-NORMSDIST(LN(A43/Distribution!$C$5)/IF(A43<Distribution!$C$5,MAX(Distribution!$B$8,0.02),MAX(Distribution!$B$9,0.02)))
A44: =ROUND(Valuation!$B$66*1.2,0) | B44: =1-NORMSDIST(LN(A44/Distribution!$C$5)/IF(A44<Distribution!$C$5,MAX(Distribution!$B$8,0.02),MAX(Distribution!$B$9,0.02)))
...

Sheet Model
A1: AVGO: annual model, base case
A2: (M of US dollars except per share; fiscal years named by the calendar year they end in)
A3: Blue = input · black = formula · green = link to another tab · actuals from SEC filings (fact ids in the last column, links on Sources)
A5: Fiscal year | B5: FY2023A | C5: FY2024A | D5: FY2025A | E5: FY2026E | F5: FY2027E | G5: FY2028E | H5: Source / note
A6: Period end | B6: 45228 | C6: 45599 | D6: 45963 | E6: =IF(DAY(Valuation!$B$48+1)=1,EOMONTH(Valuation!$B$48,12*E7),EDATE(Valuation!$B$48,12*E7)) | F6: =IF(DAY(Valuation!$B$48+1)=1,EOMONTH(Valuation!$B$48,12*F7),EDATE(Valuation!$B$48,12*F7)) | G6: =IF(DAY(Valuation!$B$48+1)=1,EOMONTH(Valuation!$B$48,12*G7),EDATE(Valuation!$B$48,12*G7))
A7: Projection year | B7: -2 | C7: -1 | D7: 0 | E7: 1 | F7: 2 | G7: 3
A10: Segment build (blue = input: revenue growth and EBIT margin by segment and year)
A11: Semiconductor solutions | D11: =Valuation!$B$86 | E11: =Valuation!$B$86*(1+E12) | F11: =E11*(1+F12) | G11: =F11*(1+G12)
A12: Revenue growth | E12: 1.0284063 | F12: 0.77515616 | G12: 0.61055939
A13: Segment EBIT | E13: =E11*E14 | F13: =F11*F14 | G13: =G11*G14
A14: EBIT margin | E14: 0.61020589 | F14: 0.58905924 | G14: 0.57460851
A15: Infrastructure software | D15: =Valuation!$B$87 | E15: =Valuation!$B$87*(1+E16) | F15: =E15*(1+F16) | G15: =F15*(1+G16)
A16: Revenue growth | E16: 0.16452699 | F16: 0.14430042 | G16: 0.040007774
A17: Segment EBIT | E17: =E15*E18 | F17: =F15*F18 | G17: =G15*G18
A18: EBIT margin | E18: 0.8133578 | F18: 0.835 | G18: 0.835
A19: Total segment revenue (= net sales) | D19: =D11+D15 | E19: =E11+E15 | F19: =F11+F15 | G19: =G11+G15 | H19: base revenues on Valuation (segment build); net sales = this total
A20: Total segment EBIT | E20: =E13+E17 | F20: =F13+F17 | G20: =G13+G17
A21: Corporate / unallocated EBIT (blue = input) | E21: -8387 | F21: -9000 | G21: -9800 | H21: years[].corporate_ebit; EBIT = total segment EBIT + corporate
A23: Sales
A24: Net sales | B24: 35819 | C24: 51574 | D24: 63887 | E24: =E19 | F24: =F19 | G24: =G19 | H24: SEC XBRL F1, F2, F3
A25: % YoY | C25: =IF(OR(C24="",B24="",B24=0),"",C24/B24-1) | D25: =IF(OR(D24="",C24="",C24=0),"",D24/C24-1) | E25: =E24/Valuation!$B$49-1 | F25: =F24/E24-1 | G25: =G24/F24-1
A27: Operating profit
A28: EBIT (operating income) | E28: =E20+E21 | F28: =F20+F21 | G28: =G20+G21
A29: EBIT margin | E29: =E28/E24 | F29: =F28/F24 | G29: =G28/G24
A30: D&A | E30: =E24*E64 | F30: =F24*F64 | G30: =G24*G64
A31: EBITDA | E31: =E28+E30 | F31: =F28+F30 | G31: =G28+G30
A32: EBITDA margin | E32: =E31/E24 | F32: =F31/F24 | G32: =G31/G24
A33: Net interest income / (expense) | E33: =-Valuation!$B$57*Valuation!$B$55 | F33: =-Valuation!$B$57*E58 | G33: =-Valuation!$B$57*F58 | H33: rate x prior year-end net debt (memo roll)
A34: Pretax income | B34: 15097 | C34: 9916 | D34: 22729 | E34: =E28+E33 | F34: =F28+F33 | G34: =G28+G33 | H34: SEC XBRL F76, F77, F78
A35: Pretax margin | B35: =B34/B24 | C35: =C34/C24 | D35: =D34/D24 | E35: =E34/E24 | F35: =F34/F24 | G35: =G34/G24
A36: Income tax | B36: 1015 | C36: 3748 | D36: -397 | E36: =E34*E63 | F36: =F34*F63 | G36: =G34*G63 | H36: SEC XBRL F69, F70, F71
A37: Effective tax rate | B37: =B36/B34 | C37: =C36/C34 | D37: =D36/D34 | E37: =E36/E34 | F37: =F36/F34 | G37: =G36/G34
A38: Net income | B38: 14082 | C38: 5895 | D38: 23126 | E38: =E34-E36 | F38: =F34-F36 | G38: =G34-G36 | H38: SEC XBRL F15, F16, F17
A39: % YoY | C39: =IF(OR(C38="",B38="",B38=0),"",C38/B38-1) | D39: =IF(OR(D38="",C38="",C38=0),"",D38/C38-1) | E39: =IF(OR(D38="",D38=0),"",E38/D38-1) | F39: =IF(OR(E38="",E38=0),"",F38/E38-1) | G39: =IF(OR(F38="",F38=0),"",G38/F38-1)
A40: Diluted shares (M, average) | B40: 4272 | C40: 4778 | D40: 4853 | E40: =Valuation!$B$59*(1+Valuation!$B$61)^(E7-0.5-((Valuation!$B$60-Valuation!$B$48)/365.25)) | F40: =Valuation!$B$59*(1+Valuation!$B$61)^(F7-0.5-((Valuation!$B$60-Valuation!$B$48)/365.25)) | G40: =Valuation!$B$59*(1+Valuation!$B$61)^(G7-0.5-((Valuation!$B$60-Valuation!$B$48)/365.25)) | H40: diluted count rolled at the annual change to mid-year
A41: % YoY | C41: =IF(OR(C40="",B40="",B40=0),"",C40/B40-1) | D41: =IF(OR(D40="",C40="",C40=0),"",D40/C40-1) | E41: =IF(OR(D40="",D40=0),"",E40/D40-1) | F41: =IF(OR(E40="",E40=0),"",F40/E40-1) | G41: =IF(OR(F40="",F40=0),"",G40/F40-1)
A42: Diluted EPS | B42: 3.3 | C42: 1.23 | D42: 4.77 | E42: =E38/E40 | F42: =F38/F40 | G42: =G38/G40 | H42: SEC XBRL F22, F23, F24
A43: % YoY | C43: =IF(OR(C42="",B42="",B42=0),"",C42/B42-1) | D43: =IF(OR(D42="",C42="",C42=0),"",D42/C42-1) | E43: =IF(OR(D42="",D42=0),"",E42/D42-1) | F43: =IF(OR(E42="",E42=0),"",F42/E42-1) | G43: =IF(OR(F42="",F42=0),"",G42/F42-1)
A45: Cash flow
A46: NOPAT (EBIT x (1 - tax)) | E46: =E28*(1-E63) | F46: =F28*(1-F63) | G46: =G28*(1-G63)
...

Sheet Quarters
A1: AVGO quarter build (engine values: model_engine.quarter_rows; fiscal years on Model are the sums)
A2: Actual quarters are as reported (filings / XBRL); forecast quarters come from the drivers below through driver_build.quarters.
A4: Line item | B4: Q1 FY2026 | C4: Q2 FY2026 | D4: Q3 FY2026 | E4: Q4 FY2026 | F4: Q1 FY2027 | G4: Q2 FY2027 | H4: Q3 FY2027 | I4: Q4 FY2027 | J4: Q1 FY2028 | K4: Q2 FY2028 | L4: Q3 FY2028 | M4: Q4 FY2028
A5: Reported / forecast | B5: actual | C5: actual | D5: actual | E5: forecast | F5: forecast | G5: forecast | H5: forecast | I5: forecast | J5: forecast | K5: forecast | L5: forecast | M5: forecast
A6: Quarter end | B6: 46054 | C6: 46145 | D6: 46236 | E6: 46327 | F6: 46418 | G6: 46509 | H6: 46600 | I6: 46691 | J6: 46782 | K6: 46873 | L6: 46964 | M6: 47055
A7: Semiconductor solutions: revenue | B7: 12515 | C7: 15009 | D7: 20839 | E7: 26400 | F7: 28850 | G7: 31900 | H7: 33950 | I7: 38016 | J7: 44500 | K7: 50540 | L7: 56580 | M7: 62127
A8: Semiconductor solutions: EBIT | B8: 7503 | C8: 9281 | D8: 12770 | E8: 16066.82 | F8: 17259.49 | G8: 18895.58 | H8: 19940.41 | I8: 22082.1 | J8: 25775.32 | K8: 29093.05 | L8: 32451.5 | M8: 35500.97
A9: Infrastructure software: revenue | B9: 6796 | C9: 7178 | D9: 8752 | E9: 8750 | F9: 8850 | G9: 8950 | H9: 9050 | I9: 9168 | J9: 9250 | K9: 9320 | L9: 9400 | M9: 9489
A10: Infrastructure software: EBIT | B10: 5323 | C10: 5647 | D10: 7325 | E10: 7306.25 | F10: 7389.75 | G10: 7473.25 | H10: 7556.75 | I10: 7655.28 | J10: 7723.75 | K10: 7782.2 | L10: 7849 | M10: 7923.31
A11: Revenue | B11: 19311 | C11: 22187 | D11: 29591 | E11: 35150 | F11: 37700 | G11: 40850 | H11: 43000 | I11: 47184 | J11: 53750 | K11: 59860 | L11: 65980 | M11: 71616
A12: EBIT | B12: 10650 | C12: 12836 | D12: 18076 | E12: 21273.073 | F12: 22399.242 | G12: 24118.83 | H12: 25247.16 | I12: 27487.384 | J12: 31049.07 | K12: 34425.25 | L12: 37850.5 | M12: 40974.29
A13: EBIT margin | B13: 0.55149915 | C13: 0.57853698 | D13: 0.61086141 | E13: 0.60520834 | F13: 0.59414435 | G13: 0.59042424 | H13: 0.58714326 | I13: 0.58255731 | J13: 0.57765712 | K13: 0.57509606 | L13: 0.57366626 | M13: 0.57213877
A14: D&A | B14: 115.866 | C14: 133.122 | D14: 177.546 | E14: 210.9 | F14: 226.2 | G14: 245.1 | H14: 258 | I14: 283.104 | J14: 322.5 | K14: 359.16 | L14: 395.88 | M14: 429.696
A15: Capex | B15: 444.153 | C15: 510.301 | D15: 680.593 | E15: 808.45 | F15: 565.5 | G15: 612.75 | H15: 645 | I15: 707.76 | J15: 537.5 | K15: 598.6 | L15: 659.8 | M15: 716.16
A16: Stock comp | B16: 1544.88 | C16: 1774.96 | D16: 2367.28 | E16: 2812 | F16: 3016 | G16: 3268 | H16: 3440 | I16: 3774.72 | J16: 4300 | K16: 4788.8 | L16: 5278.4 | M16: 5729.28
A17: Free cash flow to firm | B17: 7693.9173 | C17: 9343.6837 | D17: 13265.225 | E17: 15590.333 | F17: 16800.483 | G17: 18076.585 | H17: 18909.475 | I17: 20567.649 | J17: 23748.656 | K17: 26319.495 | L17: 28931.118 | M17: 31310.519
A18: Model EPS (EBIT - interest, model tax and shares) | B18: 1.7496 | C18: 2.1213 | D18: 3.0123 | E18: 3.556 | F18: 3.7475 | G18: 4.0399 | H18: 4.2317 | I18: 4.6126 | J18: 5.2183 | K18: 5.7924 | L18: 6.3748 | M18: 6.906
A20: Drivers by quarter
A21: AI semiconductor revenue (custom XPUs + ($M per quarter, sum) | B21: 8400 | C21: 10800 | D21: 16700 | E21: 22100 | F21: 24500 | G21: 27500 | H21: 29500 | I21: 33500 | J21: 40000 | K21: 46000 | L21: 52000 | M21: 57500
A22: Custom XPU share of AI semiconductor rev (fraction, wmean:ai_rev) | B22: 0.6667 | C22: 0.61 | D22: 0.73 | E22: 0.72 | F22: 0.72 | G22: 0.73 | H22: 0.73 | I22: 0.74 | J22: 0.74 | K22: 0.75 | L22: 0.75 | M22: 0.75
A23: Custom XPU operating margin (non-GAAP, b (fraction, wmean:ai_rev*xpu_share) | B23: 0.5757 | C23: 0.597 | D23: 0.5945 | E23: 0.5811 | F23: 0.5628 | G23: 0.5544 | H23: 0.546 | I23: 0.5376 | J23: 0.5342 | K23: 0.5309 | L23: 0.5275 | M23: 0.5242
A24: Infrastructure software revenue (VMware ($M per quarter, sum) | B24: 6796 | C24: 7178 | D24: 8752 | E24: 8750 | F24: 8850 | G24: 8950 | H24: 9050 | I24: 9168 | J24: 9250 | K24: 9320 | L24: 9400 | M24: 9489
A25: Customer-financing exposure backed by Br ($M (stock, quarter-end), end) | B25: 0 | C25: 0 | D25: 49700 | E25: 79800 | F25: 79800 | G25: 94500 | H25: 94500 | I25: 94500 | J25: 94500 | K25: 105700 | L25: 105700 | M25: 105700
A26: Lifetime expected loss rate on Broadcom- (fraction of exposure, mean) | B26: 0.04321 | C26: 0.04321 | D26: 0.04321 | E26: 0.04321 | F26: 0.04321 | G26: 0.04321 | H26: 0.04321 | I26: 0.04321 | J26: 0.04321 | K26: 0.04321 | L26: 0.04321 | M26: 0.04321

Sheet Valuation
A1: AVGO: valuation and price target derivation
A2: Value per share at the target date = weighted methods below; the base case is the 12-month median, with the downside and upside cases as its 10th and 90th percentiles (Distribution tab).
A3: Method | B3: Multiple | C3: Metric at target date | D3: Value per share | E3: Weight | F3: Contribution
A4: ='Calc - research target (12m)'!A68 | B4: =IF('Calc - research target (12m)'!C68="","",'Calc - research target (12m)'!C68) | C4: =IF('Calc - research target (12m)'!I68="","",'Calc - research target (12m)'!I68) | D4: ='Calc - research target (12m)'!F68 | E4: ='Calc - research target (12m)'!G68 | F4: =D4*E4/SUM($E$4:$E$5)
A6: Research target (12m) per share | D6: ='Calc - research target (12m)'!$F$69 | F6: =SUM(F4:F5)
A8: 12-month EPS basis (what the P/E is applied to)
A9: Fiscal year | B9: =Model!E5 | C9: =Model!F5 | D9: =Model!G5
A10: Share of the 12 months after the target date | B10: ='Calc - research target (12m)'!C38 | C10: ='Calc - research target (12m)'!D38 | D10: ='Calc - research target (12m)'!E38
A11: Model EPS (Model tab) | B11: =Model!E42 | C11: =Model!F42 | D11: =Model!G42
A12: Model EPS, next 12 months after the target date | B12: =SUMPRODUCT(B10:D10,B11:D11)
A15: No DCF leg for this name (DCF weight 0), so no DCF build.
A41: Assumptions (blue = input; sources on the Sources tab)
A42: Input | B42: Value | C42: Basis / note
A43: Run date (valuation as of) | B43: 46324
A44: Target date (run date + 365 days) | B44: =B43+365 | C44: 12-month horizon
A45: Money unit | B45: $M
A46: EBIT basis (gaap / adjusted) | B46: gaap | C46: gaap = after stock comp
A47: Stock comp treatment (cost / dilution) | B47: cost | C47: used only when EBIT is adjusted
A48: Last reported fiscal year end | B48: 45963
A49: Net sales, last reported year ($M) | B49: 63887
A50: WACC | B50: 0.1 | C50: not used: no DCF leg (Kilian 2026-10-21); a placeholder so the DCF block still computes
A51: Terminal method (gordon / exit_multiple / steady_state) | B51: gordon
A52: Terminal growth | B52: 0.02
A53: Exit EV/EBITDA (exit_multiple only)
A54: Balance-sheet date | B54: 46236
A55: Net debt / (net cash) at balance date ($M) | B55: 35444 | C55: excludes operating leases
A56: Minority interests + preferred stock | B56: 0
A57: Interest rate on net debt / cash | B57: 0.0407
A58: Net debt at target date (override; blank = bridge)
A59: Diluted shares (M) | B59: 4940
A60: Share count date | B60: 46236
A61: Annual change in diluted shares | B61: 0 | C61: net of buybacks and stock-comp dilution
A62: Shares at target date (override; blank = from annual change)
A63: DCF weight | B63: 0 | C63: Kilian 2026-10-21: 0 unless the name has a DCF leg (dcf_policy)
A64: Sum-of-the-parts weight | B64: 0
A65: Spread on a side with no downside/upside case (lognormal vol) | B65: 0.313
A66: Share price at the run | B66: 345 | C66: close used by the run (2026-10-29)
A68: Target multiple | B68: Multiple | C68: Weight | D68: Basis (ntm / ltm) | E68: EBITDA basis | F68: Stated EPS | G68: Stated FCF/share | H68: Levered | I68: Peer basis
A69: P/E | B69: 19.81 | C69: 1 | D69: ntm | E69: gaap | H69: TRUE | I69: AVGO's own calendar-NTM P/E 19.81x (Zacks consensus, SBC kept as a cost, 2026-10-29 close), Kilian 2026-10-30 17:18Z: the exit rule's 21.9x is too high because the faster-growing peers skew the 8-peer median (32.73x: NVDA AMD MRVL TSM ANET CRDO ALAB COHR). Was 19x on non-GAAP ex-SBC EPS (Oct 6 set).
A71: Segment (sum of the parts) | B71: NTM metric | C71: Metric | D71: Multiple | E71: Note
...

Sheet Sensitivity
A1: AVGO: sensitivity tables (bold = current inputs; every cell recalculates from the live model)
A3: No DCF leg for this name (DCF weight 0), so no DCF sensitivity.
A11: Research target (12m) per share: P/E multiple (down) x metric at target date (across)
A12: Multiple \ metric | B12: ='Calc - research target (12m)'!$E$68*0.9 | C12: ='Calc - research target (12m)'!$E$68*0.95 | D12: ='Calc - research target (12m)'!$E$68*1.0 | E12: ='Calc - research target (12m)'!$E$68*1.05 | F12: ='Calc - research target (12m)'!$E$68*1.1
A13: =Valuation!$B$69+(-3) | B13: =((SUMPRODUCT('Calc - research target (12m)'!$F$67:$F$68,'Calc - research target (12m)'!$G$67:$G$68)-'Calc - research target (12m)'!$F$68*'Calc - research target (12m)'!$G$68)+'Calc - research target (12m)'!$G$68*($A13*(B$12-'Calc - research target (12m)'!$B$54)/'Calc - research target (12m)'!$B$53+'Calc - research target (12m)'!$B$52/'Calc - research target (12m)'!$B$53))/SUM('Calc - research target (12m)'!$G$67:$G$68) | C13: =((SUMPRODUCT('Calc - research target (12m)'!$F$67:$F$68,'Calc - research target (12m)'!$G$67:$G$68)-'Calc - research target (12m)'!$F$68*'Calc - research target (12m)'!$G$68)+'Calc - research target (12m)'!$G$68*($A13*(C$12-'Calc - research target (12m)'!$B$54)/'Calc - research target (12m)'!$B$53+'Calc - research target (12m)'!$B$52/'Calc - research target (12m)'!$B$53))/SUM('Calc - research target (12m)'!$G$67:$G$68) | D13: =((SUMPRODUCT('Calc - research target (12m)'!$F$67:$F$68,'Calc - research target (12m)'!$G$67:$G$68)-'Calc - research target (12m)'!$F$68*'Calc - research target (12m)'!$G$68)+'Calc - research target (12m)'!$G$68*($A13*(D$12-'Calc - research target (12m)'!$B$54)/'Calc - research target (12m)'!$B$53+'Calc - research target (12m)'!$B$52/'Calc - research target (12m)'!$B$53))/SUM('Calc - research target (12m)'!$G$67:$G$68) | E13: =((SUMPRODUCT('Calc - research target (12m)'!$F$67:$F$68,'Calc - research target (12m)'!$G$67:$G$68)-'Calc - research target (12m)'!$F$68*'Calc - research target (12m)'!$G$68)+'Calc - research target (12m)'!$G$68*($A13*(E$12-'Calc - research target (12m)'!$B$54)/'Calc - research target (12m)'!$B$53+'Calc - research target (12m)'!$B$52/'Calc - research target (12m)'!$B$53))/SUM('Calc - research target (12m)'!$G$67:$G$68) | F13: =((SUMPRODUCT('Calc - research target (12m)'!$F$67:$F$68,'Calc - research target (12m)'!$G$67:$G$68)-'Calc - research target (12m)'!$F$68*'Calc - research target (12m)'!$G$68)+'Calc - research target (12m)'!$G$68*($A13*(F$12-'Calc - research target (12m)'!$B$54)/'Calc - research target (12m)'!$B$53+'Calc - research target (12m)'!$B$52/'Calc - research target (12m)'!$B$53))/SUM('Calc - research target (12m)'!$G$67:$G$68)
A14: =Valuation!$B$69+(-2) | B14: =((SUMPRODUCT('Calc - research target (12m)'!$F$67:$F$68,'Calc - research target (12m)'!$G$67:$G$68)-'Calc - research target (12m)'!$F$68*'Calc - research target (12m)'!$G$68)+'Calc - research target (12m)'!$G$68*($A14*(B$12-'Calc - research target (12m)'!$B$54)/'Calc - research target (12m)'!$B$53+'Calc - research target (12m)'!$B$52/'Calc - research target (12m)'!$B$53))/SUM('Calc - research target (12m)'!$G$67:$G$68) | C14: =((SUMPRODUCT('Calc - research target (12m)'!$F$67:$F$68,'Calc - research target (12m)'!$G$67:$G$68)-'Calc - research target (12m)'!$F$68*'Calc - research target (12m)'!$G$68)+'Calc - research target (12m)'!$G$68*($A14*(C$12-'Calc - research target (12m)'!$B$54)/'Calc - research target (12m)'!$B$53+'Calc - research target (12m)'!$B$52/'Calc - research target (12m)'!$B$53))/SUM('Calc - research target (12m)'!$G$67:$G$68) | D14: =((SUMPRODUCT('Calc - research target (12m)'!$F$67:$F$68,'Calc - research target (12m)'!$G$67:$G$68)-'Calc - research target (12m)'!$F$68*'Calc - research target (12m)'!$G$68)+'Calc - research target (12m)'!$G$68*($A14*(D$12-'Calc - research target (12m)'!$B$54)/'Calc - research target (12m)'!$B$53+'Calc - research target (12m)'!$B$52/'Calc - research target (12m)'!$B$53))/SUM('Calc - research target (12m)'!$G$67:$G$68) | E14: =((SUMPRODUCT('Calc - research target (12m)'!$F$67:$F$68,'Calc - research target (12m)'!$G$67:$G$68)-'Calc - research target (12m)'!$F$68*'Calc - research target (12m)'!$G$68)+'Calc - research target (12m)'!$G$68*($A14*(E$12-'Calc - research target (12m)'!$B$54)/'Calc - research target (12m)'!$B$53+'Calc - research target (12m)'!$B$52/'Calc - research target (12m)'!$B$53))/SUM('Calc - research target (12m)'!$G$67:$G$68) | F14: =((SUMPRODUCT('Calc - research target (12m)'!$F$67:$F$68,'Calc - research target (12m)'!$G$67:$G$68)-'Calc - research target (12m)'!$F$68*'Calc - research target (12m)'!$G$68)+'Calc - research target (12m)'!$G$68*($A14*(F$12-'Calc - research target (12m)'!$B$54)/'Calc - research target (12m)'!$B$53+'Calc - research target (12m)'!$B$52/'Calc - research target (12m)'!$B$53))/SUM('Calc - research target (12m)'!$G$67:$G$68)
A15: =Valuation!$B$69+(-1) | B15: =((SUMPRODUCT('Calc - research target (12m)'!$F$67:$F$68,'Calc - research target (12m)'!$G$67:$G$68)-'Calc - research target (12m)'!$F$68*'Calc - research target (12m)'!$G$68)+'Calc - research target (12m)'!$G$68*($A15*(B$12-'Calc - research target (12m)'!$B$54)/'Calc - research target (12m)'!$B$53+'Calc - research target (12m)'!$B$52/'Calc - research target (12m)'!$B$53))/SUM('Calc - research target (12m)'!$G$67:$G$68) | C15: =((SUMPRODUCT('Calc - research target (12m)'!$F$67:$F$68,'Calc - research target (12m)'!$G$67:$G$68)-'Calc - research target (12m)'!$F$68*'Calc - research target (12m)'!$G$68)+'Calc - research target (12m)'!$G$68*($A15*(C$12-'Calc - research target (12m)'!$B$54)/'Calc - research target (12m)'!$B$53+'Calc - research target (12m)'!$B$52/'Calc - research target (12m)'!$B$53))/SUM('Calc - research target (12m)'!$G$67:$G$68) | D15: =((SUMPRODUCT('Calc - research target (12m)'!$F$67:$F$68,'Calc - research target (12m)'!$G$67:$G$68)-'Calc - research target (12m)'!$F$68*'Calc - research target (12m)'!$G$68)+'Calc - research target (12m)'!$G$68*($A15*(D$12-'Calc - research target (12m)'!$B$54)/'Calc - research target (12m)'!$B$53+'Calc - research target (12m)'!$B$52/'Calc - research target (12m)'!$B$53))/SUM('Calc - research target (12m)'!$G$67:$G$68) | E15: =((SUMPRODUCT('Calc - research target (12m)'!$F$67:$F$68,'Calc - research target (12m)'!$G$67:$G$68)-'Calc - research target (12m)'!$F$68*'Calc - research target (12m)'!$G$68)+'Calc - research target (12m)'!$G$68*($A15*(E$12-'Calc - research target (12m)'!$B$54)/'Calc - research target (12m)'!$B$53+'Calc - research target (12m)'!$B$52/'Calc - research target (12m)'!$B$53))/SUM('Calc - research target (12m)'!$G$67:$G$68) | F15: =((SUMPRODUCT('Calc - research target (12m)'!$F$67:$F$68,'Calc - research target (12m)'!$G$67:$G$68)-'Calc - research target (12m)'!$F$68*'Calc - research target (12m)'!$G$68)+'Calc - research target (12m)'!$G$68*($A15*(F$12-'Calc - research target (12m)'!$B$54)/'Calc - research target (12m)'!$B$53+'Calc - research target (12m)'!$B$52/'Calc - research target (12m)'!$B$53))/SUM('Calc - research target (12m)'!$G$67:$G$68)
A16: =Valuation!$B$69+(0) | B16: =((SUMPRODUCT('Calc - research target (12m)'!$F$67:$F$68,'Calc - research target (12m)'!$G$67:$G$68)-'Calc - research target (12m)'!$F$68*'Calc - research target (12m)'!$G$68)+'Calc - research target (12m)'!$G$68*($A16*(B$12-'Calc - research target (12m)'!$B$54)/'Calc - research target (12m)'!$B$53+'Calc - research target (12m)'!$B$52/'Calc - research target (12m)'!$B$53))/SUM('Calc - research target (12m)'!$G$67:$G$68) | C16: =((SUMPRODUCT('Calc - research target (12m)'!$F$67:$F$68,'Calc - research target (12m)'!$G$67:$G$68)-'Calc - research target (12m)'!$F$68*'Calc - research target (12m)'!$G$68)+'Calc - research target (12m)'!$G$68*($A16*(C$12-'Calc - research target (12m)'!$B$54)/'Calc - research target (12m)'!$B$53+'Calc - research target (12m)'!$B$52/'Calc - research target (12m)'!$B$53))/SUM('Calc - research target (12m)'!$G$67:$G$68) | D16: =((SUMPRODUCT('Calc - research target (12m)'!$F$67:$F$68,'Calc - research target (12m)'!$G$67:$G$68)-'Calc - research target (12m)'!$F$68*'Calc - research target (12m)'!$G$68)+'Calc - research target (12m)'!$G$68*($A16*(D$12-'Calc - research target (12m)'!$B$54)/'Calc - research target (12m)'!$B$53+'Calc - research target (12m)'!$B$52/'Calc - research target (12m)'!$B$53))/SUM('Calc - research target (12m)'!$G$67:$G$68) | E16: =((SUMPRODUCT('Calc - research target (12m)'!$F$67:$F$68,'Calc - research target (12m)'!$G$67:$G$68)-'Calc - research target (12m)'!$F$68*'Calc - research target (12m)'!$G$68)+'Calc - research target (12m)'!$G$68*($A16*(E$12-'Calc - research target (12m)'!$B$54)/'Calc - research target (12m)'!$B$53+'Calc - research target (12m)'!$B$52/'Calc - research target (12m)'!$B$53))/SUM('Calc - research target (12m)'!$G$67:$G$68) | F16: =((SUMPRODUCT('Calc - research target (12m)'!$F$67:$F$68,'Calc - research target (12m)'!$G$67:$G$68)-'Calc - research target (12m)'!$F$68*'Calc - research target (12m)'!$G$68)+'Calc - research target (12m)'!$G$68*($A16*(F$12-'Calc - research target (12m)'!$B$54)/'Calc - research target (12m)'!$B$53+'Calc - research target (12m)'!$B$52/'Calc - research target (12m)'!$B$53))/SUM('Calc - research target (12m)'!$G$67:$G$68)
A17: =Valuation!$B$69+(1) | B17: =((SUMPRODUCT('Calc - research target (12m)'!$F$67:$F$68,'Calc - research target (12m)'!$G$67:$G$68)-'Calc - research target (12m)'!$F$68*'Calc - research target (12m)'!$G$68)+'Calc - research target (12m)'!$G$68*($A17*(B$12-'Calc - research target (12m)'!$B$54)/'Calc - research target (12m)'!$B$53+'Calc - research target (12m)'!$B$52/'Calc - research target (12m)'!$B$53))/SUM('Calc - research target (12m)'!$G$67:$G$68) | C17: =((SUMPRODUCT('Calc - research target (12m)'!$F$67:$F$68,'Calc - research target (12m)'!$G$67:$G$68)-'Calc - research target (12m)'!$F$68*'Calc - research target (12m)'!$G$68)+'Calc - research target (12m)'!$G$68*($A17*(C$12-'Calc - research target (12m)'!$B$54)/'Calc - research target (12m)'!$B$53+'Calc - research target (12m)'!$B$52/'Calc - research target (12m)'!$B$53))/SUM('Calc - research target (12m)'!$G$67:$G$68) | D17: =((SUMPRODUCT('Calc - research target (12m)'!$F$67:$F$68,'Calc - research target (12m)'!$G$67:$G$68)-'Calc - research target (12m)'!$F$68*'Calc - research target (12m)'!$G$68)+'Calc - research target (12m)'!$G$68*($A17*(D$12-'Calc - research target (12m)'!$B$54)/'Calc - research target (12m)'!$B$53+'Calc - research target (12m)'!$B$52/'Calc - research target (12m)'!$B$53))/SUM('Calc - research target (12m)'!$G$67:$G$68) | E17: =((SUMPRODUCT('Calc - research target (12m)'!$F$67:$F$68,'Calc - research target (12m)'!$G$67:$G$68)-'Calc - research target (12m)'!$F$68*'Calc - research target (12m)'!$G$68)+'Calc - research target (12m)'!$G$68*($A17*(E$12-'Calc - research target (12m)'!$B$54)/'Calc - research target (12m)'!$B$53+'Calc - research target (12m)'!$B$52/'Calc - research target (12m)'!$B$53))/SUM('Calc - research target (12m)'!$G$67:$G$68) | F17: =((SUMPRODUCT('Calc - research target (12m)'!$F$67:$F$68,'Calc - research target (12m)'!$G$67:$G$68)-'Calc - research target (12m)'!$F$68*'Calc - research target (12m)'!$G$68)+'Calc - research target (12m)'!$G$68*($A17*(F$12-'Calc - research target (12m)'!$B$54)/'Calc - research target (12m)'!$B$53+'Calc - research target (12m)'!$B$52/'Calc - research target (12m)'!$B$53))/SUM('Calc - research target (12m)'!$G$67:$G$68)
A18: =Valuation!$B$69+(2) | B18: =((SUMPRODUCT('Calc - research target (12m)'!$F$67:$F$68,'Calc - research target (12m)'!$G$67:$G$68)-'Calc - research target (12m)'!$F$68*'Calc - research target (12m)'!$G$68)+'Calc - research target (12m)'!$G$68*($A18*(B$12-'Calc - research target (12m)'!$B$54)/'Calc - research target (12m)'!$B$53+'Calc - research target (12m)'!$B$52/'Calc - research target (12m)'!$B$53))/SUM('Calc - research target (12m)'!$G$67:$G$68) | C18: =((SUMPRODUCT('Calc - research target (12m)'!$F$67:$F$68,'Calc - research target (12m)'!$G$67:$G$68)-'Calc - research target (12m)'!$F$68*'Calc - research target (12m)'!$G$68)+'Calc - research target (12m)'!$G$68*($A18*(C$12-'Calc - research target (12m)'!$B$54)/'Calc - research target (12m)'!$B$53+'Calc - research target (12m)'!$B$52/'Calc - research target (12m)'!$B$53))/SUM('Calc - research target (12m)'!$G$67:$G$68) | D18: =((SUMPRODUCT('Calc - research target (12m)'!$F$67:$F$68,'Calc - research target (12m)'!$G$67:$G$68)-'Calc - research target (12m)'!$F$68*'Calc - research target (12m)'!$G$68)+'Calc - research target (12m)'!$G$68*($A18*(D$12-'Calc - research target (12m)'!$B$54)/'Calc - research target (12m)'!$B$53+'Calc - research target (12m)'!$B$52/'Calc - research target (12m)'!$B$53))/SUM('Calc - research target (12m)'!$G$67:$G$68) | E18: =((SUMPRODUCT('Calc - research target (12m)'!$F$67:$F$68,'Calc - research target (12m)'!$G$67:$G$68)-'Calc - research target (12m)'!$F$68*'Calc - research target (12m)'!$G$68)+'Calc - research target (12m)'!$G$68*($A18*(E$12-'Calc - research target (12m)'!$B$54)/'Calc - research target (12m)'!$B$53+'Calc - research target (12m)'!$B$52/'Calc - research target (12m)'!$B$53))/SUM('Calc - research target (12m)'!$G$67:$G$68) | F18: =((SUMPRODUCT('Calc - research target (12m)'!$F$67:$F$68,'Calc - research target (12m)'!$G$67:$G$68)-'Calc - research target (12m)'!$F$68*'Calc - research target (12m)'!$G$68)+'Calc - research target (12m)'!$G$68*($A18*(F$12-'Calc - research target (12m)'!$B$54)/'Calc - research target (12m)'!$B$53+'Calc - research target (12m)'!$B$52/'Calc - research target (12m)'!$B$53))/SUM('Calc - research target (12m)'!$G$67:$G$68)
A19: =Valuation!$B$69+(3) | B19: =((SUMPRODUCT('Calc - research target (12m)'!$F$67:$F$68,'Calc - research target (12m)'!$G$67:$G$68)-'Calc - research target (12m)'!$F$68*'Calc - research target (12m)'!$G$68)+'Calc - research target (12m)'!$G$68*($A19*(B$12-'Calc - research target (12m)'!$B$54)/'Calc - research target (12m)'!$B$53+'Calc - research target (12m)'!$B$52/'Calc - research target (12m)'!$B$53))/SUM('Calc - research target (12m)'!$G$67:$G$68) | C19: =((SUMPRODUCT('Calc - research target (12m)'!$F$67:$F$68,'Calc - research target (12m)'!$G$67:$G$68)-'Calc - research target (12m)'!$F$68*'Calc - research target (12m)'!$G$68)+'Calc - research target (12m)'!$G$68*($A19*(C$12-'Calc - research target (12m)'!$B$54)/'Calc - research target (12m)'!$B$53+'Calc - research target (12m)'!$B$52/'Calc - research target (12m)'!$B$53))/SUM('Calc - research target (12m)'!$G$67:$G$68) | D19: =((SUMPRODUCT('Calc - research target (12m)'!$F$67:$F$68,'Calc - research target (12m)'!$G$67:$G$68)-'Calc - research target (12m)'!$F$68*'Calc - research target (12m)'!$G$68)+'Calc - research target (12m)'!$G$68*($A19*(D$12-'Calc - research target (12m)'!$B$54)/'Calc - research target (12m)'!$B$53+'Calc - research target (12m)'!$B$52/'Calc - research target (12m)'!$B$53))/SUM('Calc - research target (12m)'!$G$67:$G$68) | E19: =((SUMPRODUCT('Calc - research target (12m)'!$F$67:$F$68,'Calc - research target (12m)'!$G$67:$G$68)-'Calc - research target (12m)'!$F$68*'Calc - research target (12m)'!$G$68)+'Calc - research target (12m)'!$G$68*($A19*(E$12-'Calc - research target (12m)'!$B$54)/'Calc - research target (12m)'!$B$53+'Calc - research target (12m)'!$B$52/'Calc - research target (12m)'!$B$53))/SUM('Calc - research target (12m)'!$G$67:$G$68) | F19: =((SUMPRODUCT('Calc - research target (12m)'!$F$67:$F$68,'Calc - research target (12m)'!$G$67:$G$68)-'Calc - research target (12m)'!$F$68*'Calc - research target (12m)'!$G$68)+'Calc - research target (12m)'!$G$68*($A19*(F$12-'Calc - research target (12m)'!$B$54)/'Calc - research target (12m)'!$B$53+'Calc - research target (12m)'!$B$52/'Calc - research target (12m)'!$B$53))/SUM('Calc - research target (12m)'!$G$67:$G$68)
A22: FY2027E diluted EPS: revenue growth change in every year (down) x EBIT margin change (across)
A23: Growth Δ \ margin Δ | B23: -0.01 | C23: -0.005 | D23: 0 | E23: 0.005 | F23: 0.01
A24: -0.02 | B24: =(Valuation!$B$86*(1+Model!E12+$A24)*(1+Model!F12+$A24)*(Model!F14+B$23)+Valuation!$B$87*(1+Model!E16+$A24)*(1+Model!F16+$A24)*(Model!F18+B$23)+Model!F21+Model!F33)*(1-Model!F63)/Model!F40 | C24: =(Valuation!$B$86*(1+Model!E12+$A24)*(1+Model!F12+$A24)*(Model!F14+C$23)+Valuation!$B$87*(1+Model!E16+$A24)*(1+Model!F16+$A24)*(Model!F18+C$23)+Model!F21+Model!F33)*(1-Model!F63)/Model!F40 | D24: =(Valuation!$B$86*(1+Model!E12+$A24)*(1+Model!F12+$A24)*(Model!F14+D$23)+Valuation!$B$87*(1+Model!E16+$A24)*(1+Model!F16+$A24)*(Model!F18+D$23)+Model!F21+Model!F33)*(1-Model!F63)/Model!F40 | E24: =(Valuation!$B$86*(1+Model!E12+$A24)*(1+Model!F12+$A24)*(Model!F14+E$23)+Valuation!$B$87*(1+Model!E16+$A24)*(1+Model!F16+$A24)*(Model!F18+E$23)+Model!F21+Model!F33)*(1-Model!F63)/Model!F40 | F24: =(Valuation!$B$86*(1+Model!E12+$A24)*(1+Model!F12+$A24)*(Model!F14+F$23)+Valuation!$B$87*(1+Model!E16+$A24)*(1+Model!F16+$A24)*(Model!F18+F$23)+Model!F21+Model!F33)*(1-Model!F63)/Model!F40
A25: -0.01 | B25: =(Valuation!$B$86*(1+Model!E12+$A25)*(1+Model!F12+$A25)*(Model!F14+B$23)+Valuation!$B$87*(1+Model!E16+$A25)*(1+Model!F16+$A25)*(Model!F18+B$23)+Model!F21+Model!F33)*(1-Model!F63)/Model!F40 | C25: =(Valuation!$B$86*(1+Model!E12+$A25)*(1+Model!F12+$A25)*(Model!F14+C$23)+Valuation!$B$87*(1+Model!E16+$A25)*(1+Model!F16+$A25)*(Model!F18+C$23)+Model!F21+Model!F33)*(1-Model!F63)/Model!F40 | D25: =(Valuation!$B$86*(1+Model!E12+$A25)*(1+Model!F12+$A25)*(Model!F14+D$23)+Valuation!$B$87*(1+Model!E16+$A25)*(1+Model!F16+$A25)*(Model!F18+D$23)+Model!F21+Model!F33)*(1-Model!F63)/Model!F40 | E25: =(Valuation!$B$86*(1+Model!E12+$A25)*(1+Model!F12+$A25)*(Model!F14+E$23)+Valuation!$B$87*(1+Model!E16+$A25)*(1+Model!F16+$A25)*(Model!F18+E$23)+Model!F21+Model!F33)*(1-Model!F63)/Model!F40 | F25: =(Valuation!$B$86*(1+Model!E12+$A25)*(1+Model!F12+$A25)*(Model!F14+F$23)+Valuation!$B$87*(1+Model!E16+$A25)*(1+Model!F16+$A25)*(Model!F18+F$23)+Model!F21+Model!F33)*(1-Model!F63)/Model!F40
A26: 0 | B26: =(Valuation!$B$86*(1+Model!E12+$A26)*(1+Model!F12+$A26)*(Model!F14+B$23)+Valuation!$B$87*(1+Model!E16+$A26)*(1+Model!F16+$A26)*(Model!F18+B$23)+Model!F21+Model!F33)*(1-Model!F63)/Model!F40 | C26: =(Valuation!$B$86*(1+Model!E12+$A26)*(1+Model!F12+$A26)*(Model!F14+C$23)+Valuation!$B$87*(1+Model!E16+$A26)*(1+Model!F16+$A26)*(Model!F18+C$23)+Model!F21+Model!F33)*(1-Model!F63)/Model!F40 | D26: =(Valuation!$B$86*(1+Model!E12+$A26)*(1+Model!F12+$A26)*(Model!F14+D$23)+Valuation!$B$87*(1+Model!E16+$A26)*(1+Model!F16+$A26)*(Model!F18+D$23)+Model!F21+Model!F33)*(1-Model!F63)/Model!F40 | E26: =(Valuation!$B$86*(1+Model!E12+$A26)*(1+Model!F12+$A26)*(Model!F14+E$23)+Valuation!$B$87*(1+Model!E16+$A26)*(1+Model!F16+$A26)*(Model!F18+E$23)+Model!F21+Model!F33)*(1-Model!F63)/Model!F40 | F26: =(Valuation!$B$86*(1+Model!E12+$A26)*(1+Model!F12+$A26)*(Model!F14+F$23)+Valuation!$B$87*(1+Model!E16+$A26)*(1+Model!F16+$A26)*(Model!F18+F$23)+Model!F21+Model!F33)*(1-Model!F63)/Model!F40
A27: 0.01 | B27: =(Valuation!$B$86*(1+Model!E12+$A27)*(1+Model!F12+$A27)*(Model!F14+B$23)+Valuation!$B$87*(1+Model!E16+$A27)*(1+Model!F16+$A27)*(Model!F18+B$23)+Model!F21+Model!F33)*(1-Model!F63)/Model!F40 | C27: =(Valuation!$B$86*(1+Model!E12+$A27)*(1+Model!F12+$A27)*(Model!F14+C$23)+Valuation!$B$87*(1+Model!E16+$A27)*(1+Model!F16+$A27)*(Model!F18+C$23)+Model!F21+Model!F33)*(1-Model!F63)/Model!F40 | D27: =(Valuation!$B$86*(1+Model!E12+$A27)*(1+Model!F12+$A27)*(Model!F14+D$23)+Valuation!$B$87*(1+Model!E16+$A27)*(1+Model!F16+$A27)*(Model!F18+D$23)+Model!F21+Model!F33)*(1-Model!F63)/Model!F40 | E27: =(Valuation!$B$86*(1+Model!E12+$A27)*(1+Model!F12+$A27)*(Model!F14+E$23)+Valuation!$B$87*(1+Model!E16+$A27)*(1+Model!F16+$A27)*(Model!F18+E$23)+Model!F21+Model!F33)*(1-Model!F63)/Model!F40 | F27: =(Valuation!$B$86*(1+Model!E12+$A27)*(1+Model!F12+$A27)*(Model!F14+F$23)+Valuation!$B$87*(1+Model!E16+$A27)*(1+Model!F16+$A27)*(Model!F18+F$23)+Model!F21+Model!F33)*(1-Model!F63)/Model!F40
A28: 0.02 | B28: =(Valuation!$B$86*(1+Model!E12+$A28)*(1+Model!F12+$A28)*(Model!F14+B$23)+Valuation!$B$87*(1+Model!E16+$A28)*(1+Model!F16+$A28)*(Model!F18+B$23)+Model!F21+Model!F33)*(1-Model!F63)/Model!F40 | C28: =(Valuation!$B$86*(1+Model!E12+$A28)*(1+Model!F12+$A28)*(Model!F14+C$23)+Valuation!$B$87*(1+Model!E16+$A28)*(1+Model!F16+$A28)*(Model!F18+C$23)+Model!F21+Model!F33)*(1-Model!F63)/Model!F40 | D28: =(Valuation!$B$86*(1+Model!E12+$A28)*(1+Model!F12+$A28)*(Model!F14+D$23)+Valuation!$B$87*(1+Model!E16+$A28)*(1+Model!F16+$A28)*(Model!F18+D$23)+Model!F21+Model!F33)*(1-Model!F63)/Model!F40 | E28: =(Valuation!$B$86*(1+Model!E12+$A28)*(1+Model!F12+$A28)*(Model!F14+E$23)+Valuation!$B$87*(1+Model!E16+$A28)*(1+Model!F16+$A28)*(Model!F18+E$23)+Model!F21+Model!F33)*(1-Model!F63)/Model!F40 | F28: =(Valuation!$B$86*(1+Model!E12+$A28)*(1+Model!F12+$A28)*(Model!F14+F$23)+Valuation!$B$87*(1+Model!E16+$A28)*(1+Model!F16+$A28)*(Model!F18+F$23)+Model!F21+Model!F33)*(1-Model!F63)/Model!F40
A30: Net interest and the share count are held at the base case in table 3.

Sheet Distribution
A1: AVGO: 12-month distribution (base case = median; downside = 10th, upside = 90th percentile; a lognormal with its own spread on each side)
A3: Case | B3: Percentile | C3: Value at target date | D3: Story
A4: downside | B4: 0.1 | C4: ='Calc - downside'!$F$69 | D4: =Valuation!J82
A5: base | B5: 0.5 | C5: ='Calc - research target (12m)'!$F$69 | D5: the reconciled set (research target (12m))
A6: upside | B6: 0.9 | C6: ='Calc - upside'!$F$69 | D6: =Valuation!J83
A8: Downside spread (log vol) | B8: =IF(ISNUMBER(C4),LN(C5/C4)/NORMSINV(0.9),Valuation!$B$65) | C8: =IF(B8<0.02,"FLAG: downside case at or above base","")
A9: Upside spread (log vol) | B9: =IF(ISNUMBER(C6),LN(C6/C5)/NORMSINV(0.9),Valuation!$B$65) | C9: =IF(B9<0.02,"FLAG: upside case at or below base","")
A10: Mean | B10: =C5*(EXP(B8^2/2)*NORMSDIST(-B8)+EXP(B9^2/2)*NORMSDIST(B9))
A12: Quantile | B12: Price
A13: Median (model target) | B13: =$C$5*EXP(NORMSINV(0.5)*MAX(Distribution!$B$9,0.02))
A14: 10th percentile | B14: =$C$5*EXP(NORMSINV(0.1)*MAX(Distribution!$B$8,0.02))
A15: 25th percentile | B15: =$C$5*EXP(NORMSINV(0.25)*MAX(Distribution!$B$8,0.02))
A16: 75th percentile | B16: =$C$5*EXP(NORMSINV(0.75)*MAX(Distribution!$B$9,0.02))
A17: 90th percentile | B17: =$C$5*EXP(NORMSINV(0.9)*MAX(Distribution!$B$9,0.02))

Sheet Calc - research target (12m)
A1: AVGO engine calculation: research target (12m) (reconciled set, no scenario deltas)
A2: Machinery behind the Valuation and Distribution tabs; drivers come from Model, assumptions from Valuation.
A4: Scenario Growth Δ | B4: 0
A5: Scenario Margin Δ | B5: 0
A6: Scenario Multiple Δ (turns) | B6: 0
A7: Scenario WACC Δ | B7: 0
A8: Scenario Multiple %Δ | B8: 0
A9: Scenario Stated EPS/FCF %Δ | B9: 0
A10: Scenario Custom %Δ | B10: 0
A12: WACC | B12: =Valuation!$B$50+B7
A13: Years from last FY end to target date | B13: =(Valuation!$B$44-Valuation!$B$48)/365.25
A14: Years from last FY end to balance date | B14: =(Valuation!$B$54-Valuation!$B$48)/365.25
A15: Years from last FY end to share count date | B15: =(Valuation!$B$60-Valuation!$B$48)/365.25
A16: Projected years | B16: 3
A18: Projection | B18: Base | C18: =Model!E5 | D18: =Model!F5 | E18: =Model!G5
A19: Year index | B19: 0 | C19: 1 | D19: 2 | E19: 3
A20: Period end | C20: =Valuation!$B$48+ROUND(365.25*C19,0) | D20: =Valuation!$B$48+ROUND(365.25*D19,0) | E20: =Valuation!$B$48+ROUND(365.25*E19,0)
A21: Revenue growth | C21: =C22/B22-1 | D21: =D22/C22-1 | E21: =E22/D22-1
A22: Revenue | B22: =Valuation!$B$49 | C22: =C139 | D22: =D139 | E22: =E139
A23: EBIT margin | C23: =C24/C22 | D23: =D24/D22 | E23: =E24/E22
A24: EBIT | C24: =C142 | D24: =D142 | E24: =E142
A25: Tax rate | C25: =Model!E63 | D25: =Model!F63 | E25: =Model!G63
A26: NOPAT | C26: =C24*(1-C25) | D26: =D24*(1-D25) | E26: =E24*(1-E25)
A27: D&A | C27: =C22*(Model!E64) | D27: =D22*(Model!F64) | E27: =E22*(Model!G64)
A28: Capex | C28: =C22*(Model!E65) | D28: =D22*(Model!F65) | E28: =E22*(Model!G65)
A29: Working capital increase | C29: =(Model!E66)*(C22-B22) | D29: =(Model!F66)*(D22-C22) | E29: =(Model!G66)*(E22-D22)
A30: Stock comp | C30: =C22*(Model!E67) | D30: =D22*(Model!F67) | E30: =E22*(Model!G67)
A31: Free cash flow to firm | C31: =C26+C27-C28-C29-IF(AND(Valuation!$B$46="adjusted",Valuation!$B$47="cost"),C30*(1-C25),0) | D31: =D26+D27-D28-D29-IF(AND(Valuation!$B$46="adjusted",Valuation!$B$47="cost"),D30*(1-D25),0) | E31: =E26+E27-E28-E29-IF(AND(Valuation!$B$46="adjusted",Valuation!$B$47="cost"),E30*(1-E25),0)
A32: EBITDA | C32: =C24+C27 | D32: =D24+D27 | E32: =E24+E27
A33: Adj. EBITDA | C33: =C24+C27+C22*(Model!E71) | D33: =D24+D27+D22*(Model!F71) | E33: =E24+E27+E22*(Model!G71)
A34: Shareholder returns + other uses | C34: =C22*Model!E69+Model!E68+Model!E70 | D34: =D22*Model!F69+Model!F68+Model!F70 | E34: =E22*Model!G69+Model!G68+Model!G70
A35: Share of year after target date | C35: =IF(C19<=$B$13,0,C19-MAX(C19-1,$B$13)) | D35: =IF(D19<=$B$13,0,D19-MAX(D19-1,$B$13)) | E35: =IF(E19<=$B$13,0,E19-MAX(E19-1,$B$13))
A36: PV at target date of FCFF | C36: =IF(C35=0,0,C31*C35/(1+$B$12)^(C19-$B$13)) | D36: =IF(D35=0,0,D31*D35/(1+$B$12)^(D19-$B$13)) | E36: =IF(E35=0,0,E31*E35/(1+$B$12)^(E19-$B$13))
A37: Overlap: balance date to target date | C37: =MAX(0,MIN(C19,$B$13)-MAX(C19-1,$B$14)) | D37: =MAX(0,MIN(D19,$B$13)-MAX(D19-1,$B$14)) | E37: =MAX(0,MIN(E19,$B$13)-MAX(E19-1,$B$14))
A38: NTM weight at target date | C38: =MAX(0,MIN(C19,$B$13+1)-MAX(C19-1,$B$13)) | D38: =MAX(0,MIN(D19,$B$13+1)-MAX(D19-1,$B$13)) | E38: =MAX(0,MIN(E19,$B$13+1)-MAX(E19-1,$B$13))
A39: LTM weight at target date | B39: =MAX(0,MIN(0,$B$13)-MAX(-1,$B$13-1)) | C39: =MAX(0,MIN(C19,$B$13)-MAX(C19-1,$B$13-1)) | D39: =MAX(0,MIN(D19,$B$13)-MAX(D19-1,$B$13-1)) | E39: =MAX(0,MIN(E19,$B$13)-MAX(E19-1,$B$13-1))
A41: Value at the target date
A42: PV of free cash flow after the target date | B42: =SUM($C$36:$E$36)
A43: Terminal value at final year | B43: =IF(Valuation!$B$51="exit_multiple",Valuation!$B$53*E32,E31*(1+Valuation!$B$52)/($B$12-Valuation!$B$52))
A44: PV of terminal value at target date | B44: =B43/(1+$B$12)^($B$16-$B$13)
...

Sheet Calc - downside
A1: AVGO engine calculation: downside scenario
A2: Machinery behind the Valuation and Distribution tabs; drivers come from Model, assumptions from Valuation.
A4: Scenario Growth Δ | B4: =N(Valuation!C82)
A5: Scenario Margin Δ | B5: =N(Valuation!D82)
A6: Scenario Multiple Δ (turns) | B6: =N(Valuation!E82)
A7: Scenario WACC Δ | B7: =N(Valuation!F82)
A8: Scenario Multiple %Δ | B8: =N(Valuation!G82)
A9: Scenario Stated EPS/FCF %Δ | B9: =N(Valuation!H82)
A10: Scenario Custom %Δ | B10: =N(Valuation!I82)
A12: WACC | B12: =Valuation!$B$50+B7
A13: Years from last FY end to target date | B13: =(Valuation!$B$44-Valuation!$B$48)/365.25
A14: Years from last FY end to balance date | B14: =(Valuation!$B$54-Valuation!$B$48)/365.25
A15: Years from last FY end to share count date | B15: =(Valuation!$B$60-Valuation!$B$48)/365.25
A16: Projected years | B16: 3
A18: Projection | B18: Base | C18: =Model!E5 | D18: =Model!F5 | E18: =Model!G5
A19: Year index | B19: 0 | C19: 1 | D19: 2 | E19: 3
A20: Period end | C20: =Valuation!$B$48+ROUND(365.25*C19,0) | D20: =Valuation!$B$48+ROUND(365.25*D19,0) | E20: =Valuation!$B$48+ROUND(365.25*E19,0)
A21: Revenue growth | C21: =C22/B22-1 | D21: =D22/C22-1 | E21: =E22/D22-1
A22: Revenue | B22: =Valuation!$B$49 | C22: =C139 | D22: =D139 | E22: =E139
A23: EBIT margin | C23: =C24/C22 | D23: =D24/D22 | E23: =E24/E22
A24: EBIT | C24: =C142 | D24: =D142 | E24: =E142
A25: Tax rate | C25: =Model!E63 | D25: =Model!F63 | E25: =Model!G63
A26: NOPAT | C26: =C24*(1-C25) | D26: =D24*(1-D25) | E26: =E24*(1-E25)
A27: D&A | C27: =C22*(Model!E64) | D27: =D22*(Model!F64) | E27: =E22*(Model!G64)
A28: Capex | C28: =C22*(Model!E65) | D28: =D22*(Model!F65) | E28: =E22*(Model!G65)
A29: Working capital increase | C29: =(Model!E66)*(C22-B22) | D29: =(Model!F66)*(D22-C22) | E29: =(Model!G66)*(E22-D22)
A30: Stock comp | C30: =C22*(Model!E67) | D30: =D22*(Model!F67) | E30: =E22*(Model!G67)
A31: Free cash flow to firm | C31: =C26+C27-C28-C29-IF(AND(Valuation!$B$46="adjusted",Valuation!$B$47="cost"),C30*(1-C25),0) | D31: =D26+D27-D28-D29-IF(AND(Valuation!$B$46="adjusted",Valuation!$B$47="cost"),D30*(1-D25),0) | E31: =E26+E27-E28-E29-IF(AND(Valuation!$B$46="adjusted",Valuation!$B$47="cost"),E30*(1-E25),0)
A32: EBITDA | C32: =C24+C27 | D32: =D24+D27 | E32: =E24+E27
A33: Adj. EBITDA | C33: =C24+C27+C22*(Model!E71) | D33: =D24+D27+D22*(Model!F71) | E33: =E24+E27+E22*(Model!G71)
A34: Shareholder returns + other uses | C34: =C22*Model!E69+Model!E68+Model!E70 | D34: =D22*Model!F69+Model!F68+Model!F70 | E34: =E22*Model!G69+Model!G68+Model!G70
A35: Share of year after target date | C35: =IF(C19<=$B$13,0,C19-MAX(C19-1,$B$13)) | D35: =IF(D19<=$B$13,0,D19-MAX(D19-1,$B$13)) | E35: =IF(E19<=$B$13,0,E19-MAX(E19-1,$B$13))
A36: PV at target date of FCFF | C36: =IF(C35=0,0,C31*C35/(1+$B$12)^(C19-$B$13)) | D36: =IF(D35=0,0,D31*D35/(1+$B$12)^(D19-$B$13)) | E36: =IF(E35=0,0,E31*E35/(1+$B$12)^(E19-$B$13))
A37: Overlap: balance date to target date | C37: =MAX(0,MIN(C19,$B$13)-MAX(C19-1,$B$14)) | D37: =MAX(0,MIN(D19,$B$13)-MAX(D19-1,$B$14)) | E37: =MAX(0,MIN(E19,$B$13)-MAX(E19-1,$B$14))
A38: NTM weight at target date | C38: =MAX(0,MIN(C19,$B$13+1)-MAX(C19-1,$B$13)) | D38: =MAX(0,MIN(D19,$B$13+1)-MAX(D19-1,$B$13)) | E38: =MAX(0,MIN(E19,$B$13+1)-MAX(E19-1,$B$13))
A39: LTM weight at target date | B39: =MAX(0,MIN(0,$B$13)-MAX(-1,$B$13-1)) | C39: =MAX(0,MIN(C19,$B$13)-MAX(C19-1,$B$13-1)) | D39: =MAX(0,MIN(D19,$B$13)-MAX(D19-1,$B$13-1)) | E39: =MAX(0,MIN(E19,$B$13)-MAX(E19-1,$B$13-1))
A41: Value at the target date
A42: PV of free cash flow after the target date | B42: =SUM($C$36:$E$36)
A43: Terminal value at final year | B43: =IF(Valuation!$B$51="exit_multiple",Valuation!$B$53*E32,E31*(1+Valuation!$B$52)/($B$12-Valuation!$B$52))
A44: PV of terminal value at target date | B44: =B43/(1+$B$12)^($B$16-$B$13)
...

Sheet Calc - upside
A1: AVGO engine calculation: upside scenario
A2: Machinery behind the Valuation and Distribution tabs; drivers come from Model, assumptions from Valuation.
A4: Scenario Growth Δ | B4: =N(Valuation!C83)
A5: Scenario Margin Δ | B5: =N(Valuation!D83)
A6: Scenario Multiple Δ (turns) | B6: =N(Valuation!E83)
A7: Scenario WACC Δ | B7: =N(Valuation!F83)
A8: Scenario Multiple %Δ | B8: =N(Valuation!G83)
A9: Scenario Stated EPS/FCF %Δ | B9: =N(Valuation!H83)
A10: Scenario Custom %Δ | B10: =N(Valuation!I83)
A12: WACC | B12: =Valuation!$B$50+B7
A13: Years from last FY end to target date | B13: =(Valuation!$B$44-Valuation!$B$48)/365.25
A14: Years from last FY end to balance date | B14: =(Valuation!$B$54-Valuation!$B$48)/365.25
A15: Years from last FY end to share count date | B15: =(Valuation!$B$60-Valuation!$B$48)/365.25
A16: Projected years | B16: 3
A18: Projection | B18: Base | C18: =Model!E5 | D18: =Model!F5 | E18: =Model!G5
A19: Year index | B19: 0 | C19: 1 | D19: 2 | E19: 3
A20: Period end | C20: =Valuation!$B$48+ROUND(365.25*C19,0) | D20: =Valuation!$B$48+ROUND(365.25*D19,0) | E20: =Valuation!$B$48+ROUND(365.25*E19,0)
A21: Revenue growth | C21: =C22/B22-1 | D21: =D22/C22-1 | E21: =E22/D22-1
A22: Revenue | B22: =Valuation!$B$49 | C22: =C139 | D22: =D139 | E22: =E139
A23: EBIT margin | C23: =C24/C22 | D23: =D24/D22 | E23: =E24/E22
A24: EBIT | C24: =C142 | D24: =D142 | E24: =E142
A25: Tax rate | C25: =Model!E63 | D25: =Model!F63 | E25: =Model!G63
A26: NOPAT | C26: =C24*(1-C25) | D26: =D24*(1-D25) | E26: =E24*(1-E25)
A27: D&A | C27: =C22*(Model!E64) | D27: =D22*(Model!F64) | E27: =E22*(Model!G64)
A28: Capex | C28: =C22*(Model!E65) | D28: =D22*(Model!F65) | E28: =E22*(Model!G65)
A29: Working capital increase | C29: =(Model!E66)*(C22-B22) | D29: =(Model!F66)*(D22-C22) | E29: =(Model!G66)*(E22-D22)
A30: Stock comp | C30: =C22*(Model!E67) | D30: =D22*(Model!F67) | E30: =E22*(Model!G67)
A31: Free cash flow to firm | C31: =C26+C27-C28-C29-IF(AND(Valuation!$B$46="adjusted",Valuation!$B$47="cost"),C30*(1-C25),0) | D31: =D26+D27-D28-D29-IF(AND(Valuation!$B$46="adjusted",Valuation!$B$47="cost"),D30*(1-D25),0) | E31: =E26+E27-E28-E29-IF(AND(Valuation!$B$46="adjusted",Valuation!$B$47="cost"),E30*(1-E25),0)
A32: EBITDA | C32: =C24+C27 | D32: =D24+D27 | E32: =E24+E27
A33: Adj. EBITDA | C33: =C24+C27+C22*(Model!E71) | D33: =D24+D27+D22*(Model!F71) | E33: =E24+E27+E22*(Model!G71)
A34: Shareholder returns + other uses | C34: =C22*Model!E69+Model!E68+Model!E70 | D34: =D22*Model!F69+Model!F68+Model!F70 | E34: =E22*Model!G69+Model!G68+Model!G70
A35: Share of year after target date | C35: =IF(C19<=$B$13,0,C19-MAX(C19-1,$B$13)) | D35: =IF(D19<=$B$13,0,D19-MAX(D19-1,$B$13)) | E35: =IF(E19<=$B$13,0,E19-MAX(E19-1,$B$13))
A36: PV at target date of FCFF | C36: =IF(C35=0,0,C31*C35/(1+$B$12)^(C19-$B$13)) | D36: =IF(D35=0,0,D31*D35/(1+$B$12)^(D19-$B$13)) | E36: =IF(E35=0,0,E31*E35/(1+$B$12)^(E19-$B$13))
A37: Overlap: balance date to target date | C37: =MAX(0,MIN(C19,$B$13)-MAX(C19-1,$B$14)) | D37: =MAX(0,MIN(D19,$B$13)-MAX(D19-1,$B$14)) | E37: =MAX(0,MIN(E19,$B$13)-MAX(E19-1,$B$14))
A38: NTM weight at target date | C38: =MAX(0,MIN(C19,$B$13+1)-MAX(C19-1,$B$13)) | D38: =MAX(0,MIN(D19,$B$13+1)-MAX(D19-1,$B$13)) | E38: =MAX(0,MIN(E19,$B$13+1)-MAX(E19-1,$B$13))
A39: LTM weight at target date | B39: =MAX(0,MIN(0,$B$13)-MAX(-1,$B$13-1)) | C39: =MAX(0,MIN(C19,$B$13)-MAX(C19-1,$B$13-1)) | D39: =MAX(0,MIN(D19,$B$13)-MAX(D19-1,$B$13-1)) | E39: =MAX(0,MIN(E19,$B$13)-MAX(E19-1,$B$13-1))
A41: Value at the target date
A42: PV of free cash flow after the target date | B42: =SUM($C$36:$E$36)
A43: Terminal value at final year | B43: =IF(Valuation!$B$51="exit_multiple",Valuation!$B$53*E32,E31*(1+Valuation!$B$52)/($B$12-Valuation!$B$52))
A44: PV of terminal value at target date | B44: =B43/(1+$B$12)^($B$16-$B$13)
...

Sheet Agents
A1: AVGO: each forecaster's own assumption set through the same engine (from model_engine.json, not live)
A3: Set | B3: Research target (12m) | C3: Median | D3: 25th pct | E3: 75th pct | F3: WACC | G3: Y1 growth | H3: Y1 margin | I3: Terminal growth | J3: DCF weight | K3: Years | L3: Multiples | M3: Supervisor's note
A4: supervisor | B4: 490.10049 | C4: 490.10049 | D4: 361.47671 | E4: 544.7875 | J4: 0 | K4: 3 | L4: P/E 19.81 (ntm)
A5: agent_1 | M5: engine error: no model_inputs found
A6: agent_2 | M6: engine error: no model_inputs found
A7: agent_3 | M7: engine error: no model_inputs found
A8: agent_4 | M8: engine error: no model_inputs found
A9: agent_5 | M9: engine error: no model_inputs found

Sheet Sources
A1: AVGO: where each input comes from (source numbers point to the list below; F ids to the SEC fact table)
A3: Input | B3: Value | C3: Basis | D3: Sources | E3: SEC fact ids | F3: Derivation
A4: Base revenue FY2025 (fiscal year ended 2025-11-02) | B4: $63,887M | C4: reported | D4: 55 | E4: F3 | F4: 10-K filed 2025-12-18, us-gaap revenue (fact pack F3).
A5: AI revenue per GW deployed (price driver) | B5: $11,500M per GW | C5: estimate | D5: 47, 48, 37 | F5: Two anchors: (1) Rasgon on the Q3 call: management's $115B / $230B outlook against the customers' stated deployments gives 'between $11 and $12 billion per gigawatt' (~10 GW in 2027, ~20 GW in 2028); (2) Mizuho (April 2026): $42B of 2027 Broadcom AI revenue from Anthropic on the ~3.5 GW deal = $12.0B per GW. Tan's 'content in the range of $20 to $30 billion per gigawatt' is full content per GW and, on management's own outlook, spreads over more than one fiscal year (StreetSignal notes the two may compare Broadcom revenue with customer spending). Used: $11.5B per GW of the year's deployments, which reproduces the $115B FY27 outlook on ~10 GW.
A6: FY2027 AI revenue (units x price) | B6: $115,000M = (Anthropic 5.0 + OpenAI 1.3 + others 3.7 GW) x $11.5B | C6: estimate | D6: 37, 38, 47 | F6: Anthropic: 'another 5 gigawatts of TPU version 8i in 2027'; OpenAI: 'planned deployment of 1.3 gigawatts in 2027'; others (Google TPU 'multi tens of billions of dollars ... annually', Meta MTIA, ByteDance, the sixth customer) 3.7 GW = Rasgon's ~10 GW total less 6.3. 10.0 x $11.5B = $115B = management's 'approximately $115 billion' with supply secured.
A7: FY2028 Anthropic GW realised | B7: 8.5 GW of 10 GW line of sight (85%) = $97,750M | C7: estimate | D7: 37, 51, 44, 46 | F7: Q3 call: 'in 2028 we have clear line of sight to deliver another, an incremental, 10 gigawatts'; Anthropic 'on track to become our largest XPU customer in 2027 and sustain that in 2028'. Support: Q3 revenue $16.8B (+45% q/q), profitable on an adjusted basis, IPO discussed at ~$1.5T (Reuters, 2026-10-15); $125.2B five-year TPU lease commitment; financing in place ($35B XPV tranche, $60B package syndicating). Haircut 15% for deployment timing (the Q3 call names land, power and shells alongside silicon, substrates, HBM and lasers as constraints) and IPO timing. 8.5 x $11.5B = $97.75B.
A8: FY2028 OpenAI GW realised | B8: 3.5 GW of >5 GW line of sight (70%) = $40,250M | C8: estimate | D8: 37, 52, 45 | F8: Q3 call: 'line of sight for OpenAI to deploy over 5 gigawatts of Jalapeno and its successor generation of XPU' in 2028. Haircut 30%: OpenAI's annualized revenue was 'approaching $50 billion at the end of September' (FT, below the ~$70B reported earlier); the chip project 'hit an $18 billion financing snag' in May (The Information); the >$50B financing Broadcom is arranging is in early talks (WSJ). 3.5 x $11.5B = $40.25B.
A9: FY2028 other customers GW (Google, Meta, ByteDance, sixth customer) | B9: 5.0 GW = $57,500M | C9: estimate | D9: 37, 47 | F9: Rasgon: ~20 GW in 2028, ~15 of which Anthropic and OpenAI, so ~5 GW for the others; Google: long-term agreement to deliver 'multi tens of billions of dollars of TPUs annually'; Meta: 'line of sight to deploy 3 gigawatts through 28'. Self-funded hyperscalers: no haircut. 5.0 x $11.5B = $57.5B.
A10: FY2028 AI revenue (sum) | B10: $195,500M (17.0 GW x $11.5B), -15% vs management $230B | C10: estimate | D10: 37, 47, 41 | F10: 97.75 + 40.25 + 57.5 = $195.5B. Management: 'line of sight for fiscal 2028 AI semiconductor revenue growth to again double to $230 billion' (20 GW x $11.5B). House capex file: 195.5 / 2,255 (2028 base) = 8.7% of customer AI capex vs 115 / 1,841 = 6.2% in 2027. Supervisor's original $180B and every forecaster's $175-184B are below; the set is above them because the customer GW lines (not a capex share) carry it.
A11: AI networking vs XPU split (memo) | B11: XPU 73% / networking 27% of AI revenue, held | C11: estimate | D11: 38, 37 | F11: Q3: XPUs 'representing 73% of AI revenue'; 'our AI networking revenue is expected to grow just as fast as XPUs over the next few years'. FY28: XPU $142.7B, networking $52.8B. Memo only: both carry the same per-GW price and AI margin.
A12: Tax rate | B12: 16% | C12: estimate | D12: 37, 35 | F12: Non-GAAP tax rate ~16% for Q4 and FY26 (global minimum tax), held. Our estimate: the guided ~16% non-GAAP rate held (FY26 9M GAAP rate is distorted by discrete items).
A13: D&A (depreciation) | B13: 0.6% of revenue | C13: estimate | D13: 55 | E13: F6 | F13: Depreciation 9M FY26 $484M / revenue $71,089M = 0.68% (XBRL Depreciation); non-GAAP operating income is after depreciation and before amortization of acquired intangibles (not a cash cost), so 0.6% is added back in FCFF.
A14: Capex | B14: FY26 2.3%, FY27 1.5%, FY28-FY30 1.0% of revenue | C14: estimate | D14: 35, 37, 54 | E14: F53 | F14: 9M capex $1,013M (8-K) + Q4 guide ~$1.4B = $2.41B / $105.9B = 2.3%; FY27 consensus capex $2,506M / $173,968M = 1.44% (MarketScreener) -> 1.5%; FY28 $2,055M / $271,925M = 0.76% -> 1.0% (Singapore substrate fab).
A15: Working capital | B15: 12% of the revenue increase | C15: estimate | D15: 55 | F15: Receivables $13,707M + inventory $4,523M at 2026-08-02 = $18,230M = 15.4% of annualised Q3 revenue ($29,591M x 4); less payables and accruals ~3.5% (judgment) = 12%. Replaces the transcribed one-line leakage (capex_pct_rev 8.38%), which mixed capex, working capital and cash-tax timing.
A16: Net debt at balance date 2026-08-02 | B16: $35,444M | C16: reported | D16: 35, 24 | E16: F84, F83, F89 | F16: Short-term debt $2,252M + long-term debt $57,167M = $59,419M carrying, less cash $23,975M (F89). Principal $61,079M (10-Q).
A17: Interest rate on debt | B17: 4.07% | C17: estimate | D17: 35 | E17: F84 | F17: Net interest $2,420M / debt $59,419M (transcribed); used only by the engine interest drag, which net_debt_horizon overrides.
A18: Customer financing: Backstop (disclosed) | B18: $29,000M max undiscounted; 70% average utilisation; LGD 45% | C18: estimate | D18: 29, 31, 38, 37 | F18: 10-Q: Backstop liability = '85% of the outstanding amounts owed' less 'the value of the AI racks', maximum ~$29B on full deployment, 5-year leases, fair value not material, nothing paid. The 10-Q names no customer; the size is consistent with the first $35B XPV tranche closed in June for Anthropic's 1 GW (0.85 x 35 = $29.75B; inference). Utilisation 70% (leases amortise over 5 years); LGD 45% of the maximum (rack resale after ~2 years in a downturn).
A19: Customer financing: Anthropic $42B senior tranche | B19: $42,000M, backed by Broadcom; 70% utilisation; LGD 35% | C19: estimate | D19: 44, 46, 45, 50, 29 | F19: Broadcom agreed to lend Anthropic up to $42B in convertible notes, restricted to TPU lease payments, ~a third of a $125.2B five-year lease commitment (Reuters, prospectus); the $60B package is a $42B Class A senior-secured tranche and an $18B Class B junior tranche led by Blackstone; FT: the $42B senior is 'backed by Broadcom', the junior 'without its guarantees'; Seoul Economic Daily: senior 'guaranteed by Broadcom'. LGD 35%: the $18B junior (30% of the stack) takes first loss and the racks are collateral.
A20: Customer financing: OpenAI package | B20: $35,000M Broadcom share x 0.6 probability; LGD 35% | C20: estimate | D20: 45 | F20: WSJ: Broadcom arranging 'more than $50 billion' with Apollo and Blackstone for OpenAI's custom chips, early talks, size may change; no report says whether Broadcom guarantees any of it. Assumed Anthropic-like: 70% senior = $35B, probability 0.6 that Broadcom backs it.
A21: Customer financing: future XPV backstops | B21: $32,000M x 0.5 probability; LGD 40% (was $75,000M) | C21: estimate | D21: 37, 38, 67 | F21: Was $75B of further Broadcom-backed exposure; the Oct 27 2026 8-K Backstop (~$43B max, Anthropic SPV) is the first of these to be signed, so it moves to its own row and the bucket keeps 75,000 - 43,000 = 32,000. XPV aims 'to enable more than 20 gigawatts of compute infrastructure for OpenAI and Anthropic by the end of 2028'; management 'may provide modest residual value guarantees' and will evaluate financings case by case. 20 GW at ~$20-30B content is $400-600B; $75B of further Broadcom-backed exposure is judgment.
A22: Customer financing: default probabilities | B22: Anthropic 10.5%, OpenAI 16.75%, mixed 12.5% (5-year, unconditional); bear 30/45/35%, base 5/9/6%, bull 2/4/3% | C22: estimate | D22: 49, 50, 51, 52 | F22: S&P 1981-2024 five-year cumulative defaults: BB 5.05%, B 14.69%. Anthropic's junior pays a 10% coupon vs ~7% for BB credits (ICE BofA BB index), so the market prices it between BB and B: 10.5% unconditional; OpenAI (revenue ~$50B annualized, unprofitable, financing snag) a B-or-worse 16.75%. Scenario-conditional PDs put most defaults in the bear (an AI-funding bust), weighted 0.25/0.5/0.25.
